File: ZFC_FC/MPMS_Li0.6Al0.4 FC 1k Oe.dc.dat
[Header]
TITLE,MPMS DC Measurement
BYAPP,MPMS Measurement,2.1,Summary
FILEOPENTIME, 1687521323.720000 6/23/2023, 1:55:23 PM

INFO, APPNAME, MPMS MultiVu Application, Revision 1.60,  Build 081

INFO, NAME, Li0.6Al0.4Fe5O8
INFO, WEIGHT, 85.250
INFO, AREA, 0.000
INFO, LENGTH, 0.000
INFO, SHAPE,
INFO, COMMENT, cotton: 29.92 mg, capsule:40.26 mg
INFO, SEQUENCE FILE: ZFCF.seq


INFO, BACKGROUND DATA FILE:, None


STARTUPAXIS,X,4,LINEAR,AUTO,0.000000,0.000000
STARTUPAXIS,Y1,5,LINEAR,AUTO,0.000000,0.000000


STARTUPGROUP,Longitudinal
FIELDGROUP,Longitudinal,1,2,3,4,5,6,7,8,9,15,16,17,18,27,28
FIELDGROUP,Transverse,1,2,3,4,10,11,12,13,14,19,20,21,22,27,28

PLOT_APPEARANCE,ALL,HORZ_GRID_ON,VERT_GRID_ON,MARKERS_AND_LINES

[Data]
Time,Comment,Field (Oe),Temperature (K),Long Moment (emu),Long Scan Std Dev,Long Algorithm,Long Reg Fit,Long Percent Error (%),Trans Moment (emu),Trans Scan Std Dev,Trans Algorithm,Trans Reg Fit,Trans Percent Error (%),Long Moment [w/o ABS] (emu),Long Scan Std Dev [w/o ABS],Long Reg Fit [w/o ABS],Long Percent Error [w/o ABS] (%),Trans Moment [w/o ABS] (emu),Trans Scan Std Dev [w/o ABS],Trans Reg Fit [w/o ABS],Trans Percent Error [w/o ABS] (%),Points per Scan,Scans per Measurement,Scan Length (cm),Delta Temp (K),Rot Position (deg),Error,EC Comp. Running,Using ABS,
1687529228.450,,9.999999e+002,4.997879e+000,1.227186e+000,0.000000e+000,3,9.884288e-001,0.000000e+000,,,,,,,,,,,,,,24,1,4.000000e+000,2.243996e-003,0.000000e+000,0,,0,
1687529303.839,,9.999999e+002,1.268183e+001,1.227412e+000,0.000000e+000,3,9.885408e-001,0.000000e+000,,,,,,,,,,,,,,24,1,4.000000e+000,1.879830e+000,0.000000e+000,0,,0,
1687529350.750,,9.999999e+002,1.963433e+001,1.227679e+000,0.000000e+000,3,9.884145e-001,0.000000e+000,,,,,,,,,,,,,,24,1,4.000000e+000,2.867748e+000,0.000000e+000,0,,0,
1687529392.570,,9.999999e+002,2.642381e+001,1.228006e+000,0.000000e+000,3,9.885442e-001,0.000000e+000,,,,,,,,,,,,,,24,1,4.000000e+000,2.418591e+000,0.000000e+000,0,,0,
1687529432.199,,9.999999e+002,3.290565e+001,1.228164e+000,0.000000e+000,3,9.884621e-001,0.000000e+000,,,,,,,,,,,,,,24,1,4.000000e+000,2.441570e+000,0.000000e+000,0,,0,
1687529472.878,,9.999999e+002,3.935122e+001,1.228207e+000,0.000000e+000,3,9.884434e-001,0.000000e+000,,,,,,,,,,,,,,24,1,4.000000e+000,2.502609e+000,0.000000e+000,0,,0,
1687529512.140,,9.999999e+002,4.552524e+001,1.228426e+000,0.000000e+000,3,9.885330e-001,0.000000e+000,,,,,,,,,,,,,,24,1,4.000000e+000,2.470600e+000,0.000000e+000,0,,0,
1687529553.250,,9.999999e+002,5.239956e+001,1.228418e+000,0.000000e+000,3,9.885244e-001,0.000000e+000,,,,,,,,,,,,,,24,1,4.000000e+000,2.370838e+000,0.000000e+000,0,,0,
1687529591.558,,9.999999e+002,5.856987e+001,1.228519e+000,0.000000e+000,3,9.885038e-001,0.000000e+000,,,,,,,,,,,,,,24,1,4.000000e+000,2.367409e+000,0.000000e+000,0,,0,
1687529632.355,,9.999999e+002,6.545956e+001,1.228461e+000,0.000000e+000,3,9.885483e-001,0.000000e+000,,,,,,,,,,,,,,24,1,4.000000e+000,2.454414e+000,0.000000e+000,0,,0,
1687529672.851,,9.999999e+002,7.208348e+001,1.228413e+000,0.000000e+000,3,9.886252e-001,0.000000e+000,,,,,,,,,,,,,,24,1,4.000000e+000,2.513817e+000,0.000000e+000,0,,0,
1687529713.548,,9.999999e+002,7.895960e+001,1.228164e+000,0.000000e+000,3,9.886714e-001,0.000000e+000,,,,,,,,,,,,,,24,1,4.000000e+000,2.590851e+000,0.000000e+000,0,,0,
1687529748.347,,9.999999e+002,8.474239e+001,1.227999e+000,0.000000e+000,3,9.886513e-001,0.000000e+000,,,,,,,,,,,,,,24,1,4.000000e+000,2.444313e+000,0.000000e+000,0,,0,
1687529789.613,,9.999999e+002,9.179663e+001,1.227903e+000,0.000000e+000,3,9.887524e-001,0.000000e+000,,,,,,,,,,,,,,24,1,4.000000e+000,2.568031e+000,0.000000e+000,0,,0,
1687529826.250,,9.999999e+002,9.793578e+001,1.227685e+000,0.000000e+000,3,9.887919e-001,0.000000e+000,,,,,,,,,,,,,,24,1,4.000000e+000,2.380760e+000,0.000000e+000,0,,0,
1687529867.095,,9.999999e+002,1.048533e+002,1.227360e+000,0.000000e+000,3,9.887852e-001,0.000000e+000,,,,,,,,,,,,,,24,1,4.000000e+000,2.356102e+000,0.000000e+000,0,,0,
1687529902.894,,9.999999e+002,1.108400e+002,1.227330e+000,0.000000e+000,3,9.887462e-001,0.000000e+000,,,,,,,,,,,,,,24,1,4.000000e+000,2.767998e+000,0.000000e+000,0,,0,
1687529945.441,,9.999999e+002,1.180230e+002,1.227147e+000,0.000000e+000,3,9.887723e-001,0.000000e+000,,,,,,,,,,,,,,24,1,4.000000e+000,2.607201e+000,0.000000e+000,0,,0,
1687529980.914,,9.999999e+002,1.241694e+002,1.226793e+000,0.000000e+000,3,9.887052e-001,0.000000e+000,,,,,,,,,,,,,,24,1,4.000000e+000,2.392502e+000,0.000000e+000,0,,0,
1687530022.220,,9.999999e+002,1.310638e+002,1.226128e+000,0.000000e+000,3,9.887724e-001,0.000000e+000,,,,,,,,,,,,,,24,1,4.000000e+000,2.802902e+000,0.000000e+000,0,,0,
1687530056.873,,9.999999e+002,1.368087e+002,1.225431e+000,0.000000e+000,3,9.888477e-001,0.000000e+000,,,,,,,,,,,,,,24,1,4.000000e+000,2.563904e+000,0.000000e+000,0,,0,
1687530097.873,,9.999999e+002,1.438144e+002,1.224482e+000,0.000000e+000,3,9.888675e-001,0.000000e+000,,,,,,,,,,,,,,24,1,4.000000e+000,2.343399e+000,0.000000e+000,0,,0,
1687530136.612,,9.999999e+002,1.503353e+002,1.223509e+000,0.000000e+000,3,9.889163e-001,0.000000e+000,,,,,,,,,,,,,,24,1,4.000000e+000,2.434906e+000,0.000000e+000,0,,0,
1687530172.786,,9.999999e+002,1.563707e+002,1.222319e+000,0.000000e+000,3,9.889531e-001,0.000000e+000,,,,,,,,,,,,,,24,1,4.000000e+000,2.534912e+000,0.000000e+000,0,,0,
1687530215.764,,9.999999e+002,1.636523e+002,1.220899e+000,0.000000e+000,3,9.889792e-001,0.000000e+000,,,,,,,,,,,,,,24,1,4.000000e+000,2.331100e+000,0.000000e+000,0,,0,
1687530252.587,,9.999999e+002,1.698434e+002,1.219737e+000,0.000000e+000,3,9.890231e-001,0.000000e+000,,,,,,,,,,,,,,24,1,4.000000e+000,2.293213e+000,0.000000e+000,0,,0,
1687530330.875,,9.999999e+002,1.828650e+002,1.216511e+000,0.000000e+000,3,9.889525e-001,0.000000e+000,,,,,,,,,,,,,,24,1,4.000000e+000,2.525406e+000,0.000000e+000,0,,0,
1687530370.353,,9.999999e+002,1.894603e+002,1.214993e+000,0.000000e+000,3,9.890971e-001,0.000000e+000,,,,,,,,,,,,,,24,1,4.000000e+000,2.501709e+000,0.000000e+000,0,,0,
1687530413.824,,9.999999e+002,1.968048e+002,1.212812e+000,0.000000e+000,3,9.890513e-001,0.000000e+000,,,,,,,,,,,,,,24,1,4.000000e+000,2.836105e+000,0.000000e+000,0,,0,
1687530445.886,,9.999999e+002,2.020743e+002,1.211177e+000,0.000000e+000,3,9.890526e-001,0.000000e+000,,,,,,,,,,,,,,24,1,4.000000e+000,2.595901e+000,0.000000e+000,0,,0,
1687530487.358,,9.999999e+002,2.090150e+002,1.208916e+000,0.000000e+000,3,9.891645e-001,0.000000e+000,,,,,,,,,,,,,,24,1,4.000000e+000,2.406708e+000,0.000000e+000,0,,0,
1687530525.040,,9.999999e+002,2.153657e+002,1.206847e+000,0.000000e+000,3,9.891043e-001,0.000000e+000,,,,,,,,,,,,,,24,1,4.000000e+000,2.585403e+000,0.000000e+000,0,,0,
1687530567.753,,9.999999e+002,2.225565e+002,1.204220e+000,0.000000e+000,3,9.892392e-001,0.000000e+000,,,,,,,,,,,,,,24,1,4.000000e+000,2.531708e+000,0.000000e+000,0,,0,
1687530601.839,,9.999999e+002,2.281990e+002,1.201858e+000,0.000000e+000,3,9.892455e-001,0.000000e+000,,,,,,,,,,,,,,24,1,4.000000e+000,2.559998e+000,0.000000e+000,0,,0,
1687530644.156,,9.999999e+002,2.351079e+002,1.199034e+000,0.000000e+000,3,9.893298e-001,0.000000e+000,,,,,,,,,,,,,,24,1,4.000000e+000,2.635300e+000,0.000000e+000,0,,0,
1687530681.392,,9.999999e+002,2.414624e+002,1.196676e+000,0.000000e+000,3,9.893585e-001,0.000000e+000,,,,,,,,,,,,,,24,1,4.000000e+000,2.632202e+000,0.000000e+000,0,,0,
1687530723.433,,9.999999e+002,2.485637e+002,1.193522e+000,0.000000e+000,3,9.892977e-001,0.000000e+000,,,,,,,,,,,,,,24,1,4.000000e+000,2.604599e+000,0.000000e+000,0,,0,
1687530760.335,,9.999999e+002,2.548048e+002,1.190694e+000,0.000000e+000,3,9.894802e-001,0.000000e+000,,,,,,,,,,,,,,24,1,4.000000e+000,2.533691e+000,0.000000e+000,0,,0,
1687530800.814,,9.999999e+002,2.612690e+002,1.187119e+000,0.000000e+000,3,9.895718e-001,0.000000e+000,,,,,,,,,,,,,,24,1,4.000000e+000,2.461090e+000,0.000000e+000,0,,0,
1687530837.595,,9.999999e+002,2.673914e+002,1.184120e+000,0.000000e+000,3,9.896381e-001,0.000000e+000,,,,,,,,,,,,,,24,1,4.000000e+000,2.404999e+000,0.000000e+000,0,,0,
1687530878.115,,9.999999e+002,2.743316e+002,1.180668e+000,0.000000e+000,3,9.895584e-001,0.000000e+000,,,,,,,,,,,,,,24,1,4.000000e+000,2.523621e+000,0.000000e+000,0,,0,
1687530918.458,,9.999999e+002,2.809711e+002,1.177740e+000,0.000000e+000,3,9.892824e-001,0.000000e+000,,,,,,,,,,,,,,24,1,4.000000e+000,2.929993e+000,0.000000e+000,0,,0,
1687530955.454,,9.999999e+002,2.872676e+002,1.174683e+000,0.000000e+000,3,9.892184e-001,0.000000e+000,,,,,,,,,,,,,,24,1,4.000000e+000,2.518707e+000,0.000000e+000,0,,0,
1687530995.883,,9.999999e+002,2.941673e+002,1.171014e+000,0.000000e+000,3,9.891134e-001,0.000000e+000,,,,,,,,,,,,,,24,1,4.000000e+000,2.469604e+000,0.000000e+000,0,,0,
1687531034.192,,9.999999e+002,3.003494e+002,1.167444e+000,0.000000e+000,3,9.890631e-001,0.000000e+000,,,,,,,,,,,,,,24,1,4.000000e+000,2.593719e+000,0.000000e+000,0,,0,
1687531071.641,,9.999999e+002,3.066549e+002,1.163595e+000,0.000000e+000,3,9.891014e-001,0.000000e+000,,,,,,,,,,,,,,24,1,4.000000e+000,2.025604e+000,0.000000e+000,0,,0,
1687531113.504,,9.999999e+002,3.135645e+002,1.159318e+000,0.000000e+000,3,9.888988e-001,0.000000e+000,,,,,,,,,,,,,,24,1,4.000000e+000,2.642181e+000,0.000000e+000,0,,0,
1687531149.497,,9.999999e+002,3.195850e+002,1.155439e+000,0.000000e+000,3,9.890159e-001,0.000000e+000,,,,,,,,,,,,,,24,1,4.000000e+000,2.415680e+000,0.000000e+000,0,,0,
1687531191.790,,9.999999e+002,3.266005e+002,1.150946e+000,0.000000e+000,3,9.888991e-001,0.000000e+000,,,,,,,,,,,,,,24,1,4.000000e+000,2.677094e+000,0.000000e+000,0,,0,
1687531229.063,,9.999999e+002,3.328904e+002,1.146560e+000,0.000000e+000,3,9.888979e-001,0.000000e+000,,,,,,,,,,,,,,24,1,4.000000e+000,2.162201e+000,0.000000e+000,0,,0,
1687531270.146,,9.999999e+002,3.397380e+002,1.141782e+000,0.000000e+000,3,9.888694e-001,0.000000e+000,,,,,,,,,,,,,,24,1,4.000000e+000,2.293610e+000,0.000000e+000,0,,0,
1687531307.764,,9.999999e+002,3.459637e+002,1.137564e+000,0.000000e+000,3,9.887014e-001,0.000000e+000,,,,,,,,,,,,,,24,1,4.000000e+000,3.059082e+000,0.000000e+000,0,,0,
1687531347.470,,9.999999e+002,3.526353e+002,1.132751e+000,0.000000e+000,3,9.886342e-001,0.000000e+000,,,,,,,,,,,,,,24,1,4.000000e+000,2.735291e+000,0.000000e+000,0,,0,
1687531386.708,,9.999999e+002,3.592479e+002,1.128094e+000,0.000000e+000,3,9.887030e-001,0.000000e+000,,,,,,,,,,,,,,24,1,4.000000e+000,2.477997e+000,0.000000e+000,0,,0,
1687531424.694,,9.999999e+002,3.652820e+002,1.123616e+000,0.000000e+000,3,9.885206e-001,0.000000e+000,,,,,,,,,,,,,,24,1,4.000000e+000,2.355103e+000,0.000000e+000,0,,0,
1687531466.305,,9.999999e+002,3.722954e+002,1.118494e+000,0.000000e+000,3,9.884613e-001,0.000000e+000,,,,,,,,,,,,,,24,1,4.000000e+000,2.668182e+000,0.000000e+000,0,,0,
1687531504.902,,9.999999e+002,3.784116e+002,1.113933e+000,0.000000e+000,3,9.882808e-001,0.000000e+000,,,,,,,,,,,,,,24,1,4.000000e+000,2.713989e+000,0.000000e+000,0,,0,
1687531547.538,,9.999999e+002,3.857468e+002,1.108080e+000,0.000000e+000,3,9.880536e-001,0.000000e+000,,,,,,,,,,,,,,24,1,4.000000e+000,2.916718e+000,0.000000e+000,0,,0,
1687531839.002,,9.999999e+002,3.900109e+002,1.098076e+000,0.000000e+000,3,9.874429e-001,0.000000e+000,,,,,,,,,,,,,,24,1,4.000000e+000,7.199097e-002,0.000000e+000,0,,0,