File: ZFC_FC/MPMS_Li0.5Al0.5 FC 10 Oe.dc.dat
[Header]
TITLE,MPMS DC Measurement
BYAPP,MPMS Measurement,2.1,Summary
FILEOPENTIME, 1687364009.333000 6/21/2023, 6:13:29 PM

INFO, APPNAME, MPMS MultiVu Application, Revision 1.60,  Build 081

INFO, NAME, Li0.5Al0.5Fe5O8
INFO, WEIGHT, 84.430
INFO, AREA, 0.000
INFO, LENGTH, 0.000
INFO, SHAPE,
INFO, COMMENT, cotton: 15.1 mg, capsule:39.07 mg
INFO, SEQUENCE FILE: ZFCF.seq


INFO, BACKGROUND DATA FILE:, None


STARTUPAXIS,X,4,LINEAR,AUTO,0.000000,0.000000
STARTUPAXIS,Y1,5,LINEAR,AUTO,0.000000,0.000000


STARTUPGROUP,Longitudinal
FIELDGROUP,Longitudinal,1,2,3,4,5,6,7,8,9,15,16,17,18,27,28
FIELDGROUP,Transverse,1,2,3,4,10,11,12,13,14,19,20,21,22,27,28

PLOT_APPEARANCE,ALL,HORZ_GRID_ON,VERT_GRID_ON,MARKERS_AND_LINES

[Data]
Time,Comment,Field (Oe),Temperature (K),Long Moment (emu),Long Scan Std Dev,Long Algorithm,Long Reg Fit,Long Percent Error (%),Trans Moment (emu),Trans Scan Std Dev,Trans Algorithm,Trans Reg Fit,Trans Percent Error (%),Long Moment [w/o ABS] (emu),Long Scan Std Dev [w/o ABS],Long Reg Fit [w/o ABS],Long Percent Error [w/o ABS] (%),Trans Moment [w/o ABS] (emu),Trans Scan Std Dev [w/o ABS],Trans Reg Fit [w/o ABS],Trans Percent Error [w/o ABS] (%),Points per Scan,Scans per Measurement,Scan Length (cm),Delta Temp (K),Rot Position (deg),Error,EC Comp. Running,Using ABS,
1687375237.961,,1.000000e+001,1.272698e+001,4.543918e-002,0.000000e+000,3,9.979857e-001,0.000000e+000,,,,,,,,,,,,,,24,1,4.000000e+000,1.949850e+000,0.000000e+000,0,,0,
1687375282.759,,1.000000e+001,1.953343e+001,4.544841e-002,0.000000e+000,3,9.979098e-001,0.000000e+000,,,,,,,,,,,,,,24,1,4.000000e+000,2.563320e+000,0.000000e+000,0,,0,
1687375325.346,,1.000000e+001,2.653017e+001,4.546466e-002,0.000000e+000,3,9.977956e-001,0.000000e+000,,,,,,,,,,,,,,24,1,4.000000e+000,2.587780e+000,0.000000e+000,0,,0,
1687375365.627,,1.000000e+001,3.300039e+001,4.547800e-002,0.000000e+000,3,9.977289e-001,0.000000e+000,,,,,,,,,,,,,,24,1,4.000000e+000,2.288939e+000,0.000000e+000,0,,0,
1687375402.573,,1.000000e+001,3.889445e+001,4.549129e-002,0.000000e+000,3,9.977592e-001,0.000000e+000,,,,,,,,,,,,,,24,1,4.000000e+000,2.475700e+000,0.000000e+000,0,,0,
1687375445.553,,1.000000e+001,4.583117e+001,4.550911e-002,0.000000e+000,3,9.977593e-001,0.000000e+000,,,,,,,,,,,,,,24,1,4.000000e+000,2.333870e+000,0.000000e+000,0,,0,
1687375484.983,,1.000000e+001,5.231287e+001,4.552891e-002,0.000000e+000,3,9.978428e-001,0.000000e+000,,,,,,,,,,,,,,24,1,4.000000e+000,2.375076e+000,0.000000e+000,0,,0,
1687375527.463,,1.000000e+001,5.905653e+001,4.555425e-002,0.000000e+000,3,9.978822e-001,0.000000e+000,,,,,,,,,,,,,,24,1,4.000000e+000,2.617950e+000,0.000000e+000,0,,0,
1687375564.385,,1.000000e+001,6.508601e+001,4.557641e-002,0.000000e+000,3,9.979477e-001,0.000000e+000,,,,,,,,,,,,,,24,1,4.000000e+000,2.646217e+000,0.000000e+000,0,,0,
1687375607.522,,1.000000e+001,7.230805e+001,4.561133e-002,0.000000e+000,3,9.978827e-001,0.000000e+000,,,,,,,,,,,,,,24,1,4.000000e+000,2.547241e+000,0.000000e+000,0,,0,
1687375642.491,,1.000000e+001,7.841109e+001,4.563991e-002,0.000000e+000,3,9.979162e-001,0.000000e+000,,,,,,,,,,,,,,24,1,4.000000e+000,2.502365e+000,0.000000e+000,0,,0,
1687375683.066,,1.000000e+001,8.522571e+001,4.567440e-002,0.000000e+000,3,9.978092e-001,0.000000e+000,,,,,,,,,,,,,,24,1,4.000000e+000,2.592216e+000,0.000000e+000,0,,0,
1687375720.191,,1.000000e+001,9.147511e+001,4.571058e-002,0.000000e+000,3,9.977713e-001,0.000000e+000,,,,,,,,,,,,,,24,1,4.000000e+000,2.401512e+000,0.000000e+000,0,,0,
1687375760.491,,1.000000e+001,9.808733e+001,4.574191e-002,0.000000e+000,3,9.977880e-001,0.000000e+000,,,,,,,,,,,,,,24,1,4.000000e+000,2.860374e+000,0.000000e+000,0,,0,
1687375798.116,,1.000000e+001,1.045518e+002,4.577091e-002,0.000000e+000,3,9.977865e-001,0.000000e+000,,,,,,,,,,,,,,24,1,4.000000e+000,2.807396e+000,0.000000e+000,0,,0,
1687375840.206,,1.000000e+001,1.116171e+002,4.579568e-002,0.000000e+000,3,9.976003e-001,0.000000e+000,,,,,,,,,,,,,,24,1,4.000000e+000,2.595306e+000,0.000000e+000,0,,0,
1687375876.519,,1.000000e+001,1.176407e+002,4.581869e-002,0.000000e+000,3,9.976380e-001,0.000000e+000,,,,,,,,,,,,,,24,1,4.000000e+000,2.928398e+000,0.000000e+000,0,,0,
1687375912.781,,1.000000e+001,1.239391e+002,4.584038e-002,0.000000e+000,3,9.977448e-001,0.000000e+000,,,,,,,,,,,,,,24,1,4.000000e+000,2.389801e+000,0.000000e+000,0,,0,
1687375953.730,,1.000000e+001,1.308311e+002,4.586280e-002,0.000000e+000,3,9.976284e-001,0.000000e+000,,,,,,,,,,,,,,24,1,4.000000e+000,2.451706e+000,0.000000e+000,0,,0,
1687375992.750,,1.000000e+001,1.372585e+002,4.587966e-002,0.000000e+000,3,9.976317e-001,0.000000e+000,,,,,,,,,,,,,,24,1,4.000000e+000,2.597305e+000,0.000000e+000,0,,0,
1687376028.629,,1.000000e+001,1.434286e+002,4.589729e-002,0.000000e+000,3,9.976507e-001,0.000000e+000,,,,,,,,,,,,,,24,1,4.000000e+000,2.685898e+000,0.000000e+000,0,,0,
1687376069.277,,1.000000e+001,1.502386e+002,4.591555e-002,0.000000e+000,3,9.976278e-001,0.000000e+000,,,,,,,,,,,,,,24,1,4.000000e+000,2.372894e+000,0.000000e+000,0,,0,
1687376106.320,,1.000000e+001,1.564193e+002,4.592607e-002,0.000000e+000,3,9.976781e-001,0.000000e+000,,,,,,,,,,,,,,24,1,4.000000e+000,2.663498e+000,0.000000e+000,0,,0,
1687376148.363,,1.000000e+001,1.635045e+002,4.594183e-002,0.000000e+000,3,9.975637e-001,0.000000e+000,,,,,,,,,,,,,,24,1,4.000000e+000,2.783997e+000,0.000000e+000,0,,0,
1687376184.464,,1.000000e+001,1.697057e+002,4.594909e-002,0.000000e+000,3,9.975828e-001,0.000000e+000,,,,,,,,,,,,,,24,1,4.000000e+000,2.437500e+000,0.000000e+000,0,,0,
1687376226.851,,1.000000e+001,1.766677e+002,4.596030e-002,0.000000e+000,3,9.976506e-001,0.000000e+000,,,,,,,,,,,,,,24,1,4.000000e+000,2.556000e+000,0.000000e+000,0,,0,
1687376263.312,,1.000000e+001,1.828301e+002,4.596995e-002,0.000000e+000,3,9.975348e-001,0.000000e+000,,,,,,,,,,,,,,24,1,4.000000e+000,2.444992e+000,0.000000e+000,0,,0,
1687376303.206,,1.000000e+001,1.896923e+002,4.596939e-002,0.000000e+000,3,9.976556e-001,0.000000e+000,,,,,,,,,,,,,,24,1,4.000000e+000,2.450607e+000,0.000000e+000,0,,0,
1687376342.191,,1.000000e+001,1.960553e+002,4.597824e-002,0.000000e+000,3,9.976602e-001,0.000000e+000,,,,,,,,,,,,,,24,1,4.000000e+000,2.472397e+000,0.000000e+000,0,,0,
1687376379.851,,1.000000e+001,2.022018e+002,4.597082e-002,0.000000e+000,3,9.975910e-001,0.000000e+000,,,,,,,,,,,,,,24,1,4.000000e+000,2.573395e+000,0.000000e+000,0,,0,
1687376422.114,,1.000000e+001,2.094222e+002,4.597445e-002,0.000000e+000,3,9.976471e-001,0.000000e+000,,,,,,,,,,,,,,24,1,4.000000e+000,2.750107e+000,0.000000e+000,0,,0,
1687376458.555,,1.000000e+001,2.155450e+002,4.597850e-002,0.000000e+000,3,9.976321e-001,0.000000e+000,,,,,,,,,,,,,,24,1,4.000000e+000,2.416504e+000,0.000000e+000,0,,0,
1687376498.826,,1.000000e+001,2.221281e+002,4.597911e-002,0.000000e+000,3,9.976605e-001,0.000000e+000,,,,,,,,,,,,,,24,1,4.000000e+000,2.598709e+000,0.000000e+000,0,,0,
1687376535.156,,1.000000e+001,2.283063e+002,4.597840e-002,0.000000e+000,3,9.976610e-001,0.000000e+000,,,,,,,,,,,,,,24,1,4.000000e+000,2.280197e+000,0.000000e+000,0,,0,
1687376578.628,,1.000000e+001,2.354760e+002,4.598393e-002,0.000000e+000,3,9.976670e-001,0.000000e+000,,,,,,,,,,,,,,24,1,4.000000e+000,2.780197e+000,0.000000e+000,0,,0,
1687376615.286,,1.000000e+001,2.417424e+002,4.598872e-002,0.000000e+000,3,9.977525e-001,0.000000e+000,,,,,,,,,,,,,,24,1,4.000000e+000,2.854401e+000,0.000000e+000,0,,0,
1687376653.345,,1.000000e+001,2.480648e+002,4.599475e-002,0.000000e+000,3,9.975748e-001,0.000000e+000,,,,,,,,,,,,,,24,1,4.000000e+000,2.452301e+000,0.000000e+000,0,,0,
1687376695.212,,1.000000e+001,2.550056e+002,4.600010e-002,0.000000e+000,3,9.976742e-001,0.000000e+000,,,,,,,,,,,,,,24,1,4.000000e+000,2.757401e+000,0.000000e+000,0,,0,
1687376731.893,,1.000000e+001,2.611168e+002,4.600045e-002,0.000000e+000,3,9.977134e-001,0.000000e+000,,,,,,,,,,,,,,24,1,4.000000e+000,2.343292e+000,0.000000e+000,0,,0,
1687376773.420,,1.000000e+001,2.679315e+002,4.601200e-002,0.000000e+000,3,9.976880e-001,0.000000e+000,,,,,,,,,,,,,,24,1,4.000000e+000,2.591492e+000,0.000000e+000,0,,0,
1687376809.670,,1.000000e+001,2.740355e+002,4.602851e-002,0.000000e+000,3,9.976907e-001,0.000000e+000,,,,,,,,,,,,,,24,1,4.000000e+000,2.229279e+000,0.000000e+000,0,,0,
1687376851.323,,1.000000e+001,2.808721e+002,4.603734e-002,0.000000e+000,3,9.977284e-001,0.000000e+000,,,,,,,,,,,,,,24,1,4.000000e+000,2.587799e+000,0.000000e+000,0,,0,
1687376887.754,,1.000000e+001,2.871584e+002,4.604617e-002,0.000000e+000,3,9.976892e-001,0.000000e+000,,,,,,,,,,,,,,24,1,4.000000e+000,2.224396e+000,0.000000e+000,0,,0,
1687376928.748,,1.000000e+001,2.939813e+002,4.606847e-002,0.000000e+000,3,9.976512e-001,0.000000e+000,,,,,,,,,,,,,,24,1,4.000000e+000,2.626495e+000,0.000000e+000,0,,0,
1687376966.477,,1.000000e+001,3.002933e+002,4.608331e-002,0.000000e+000,3,9.977089e-001,0.000000e+000,,,,,,,,,,,,,,24,1,4.000000e+000,2.536987e+000,0.000000e+000,0,,0,
1687377006.119,,1.000000e+001,3.068102e+002,4.610739e-002,0.000000e+000,3,9.976785e-001,0.000000e+000,,,,,,,,,,,,,,24,1,4.000000e+000,2.567505e+000,0.000000e+000,0,,0,
1687377045.176,,1.000000e+001,3.134331e+002,4.612413e-002,0.000000e+000,3,9.976230e-001,0.000000e+000,,,,,,,,,,,,,,24,1,4.000000e+000,2.258301e+000,0.000000e+000,0,,0,
1687377085.797,,1.000000e+001,3.201096e+002,4.614791e-002,0.000000e+000,3,9.976758e-001,0.000000e+000,,,,,,,,,,,,,,24,1,4.000000e+000,2.232697e+000,0.000000e+000,0,,0,
1687377123.141,,1.000000e+001,3.263018e+002,4.617195e-002,0.000000e+000,3,9.976308e-001,0.000000e+000,,,,,,,,,,,,,,24,1,4.000000e+000,2.771606e+000,0.000000e+000,0,,0,
1687377164.848,,1.000000e+001,3.332547e+002,4.620667e-002,0.000000e+000,3,9.975958e-001,0.000000e+000,,,,,,,,,,,,,,24,1,4.000000e+000,2.340576e+000,0.000000e+000,0,,0,
1687377201.442,,1.000000e+001,3.396299e+002,4.623910e-002,0.000000e+000,3,9.975867e-001,0.000000e+000,,,,,,,,,,,,,,24,1,4.000000e+000,2.364197e+000,0.000000e+000,0,,0,
1687377243.539,,1.000000e+001,3.466475e+002,4.628815e-002,0.000000e+000,3,9.975801e-001,0.000000e+000,,,,,,,,,,,,,,24,1,4.000000e+000,2.412292e+000,0.000000e+000,0,,0,
1687377279.571,,1.000000e+001,3.524499e+002,4.632838e-002,0.000000e+000,3,9.975182e-001,0.000000e+000,,,,,,,,,,,,,,24,1,4.000000e+000,2.751801e+000,0.000000e+000,0,,0,
1687377317.701,,1.000000e+001,3.588416e+002,4.637324e-002,0.000000e+000,3,9.974977e-001,0.000000e+000,,,,,,,,,,,,,,24,1,4.000000e+000,2.310120e+000,0.000000e+000,0,,0,
1687377359.584,,1.000000e+001,3.658206e+002,4.642776e-002,0.000000e+000,3,9.975494e-001,0.000000e+000,,,,,,,,,,,,,,24,1,4.000000e+000,2.805206e+000,0.000000e+000,0,,0,
1687377396.500,,1.000000e+001,3.718699e+002,4.648787e-002,0.000000e+000,3,9.974986e-001,0.000000e+000,,,,,,,,,,,,,,24,1,4.000000e+000,2.770905e+000,0.000000e+000,0,,0,
1687377438.253,,1.000000e+001,3.787838e+002,4.655973e-002,0.000000e+000,3,9.974655e-001,0.000000e+000,,,,,,,,,,,,,,24,1,4.000000e+000,2.334106e+000,0.000000e+000,0,,0,
1687377477.247,,1.000000e+001,3.852630e+002,4.663797e-002,0.000000e+000,3,9.974871e-001,0.000000e+000,,,,,,,,,,,,,,24,1,4.000000e+000,2.275818e+000,0.000000e+000,0,,0,
1687377771.719,,1.000000e+001,3.899989e+002,4.683548e-002,0.000000e+000,3,9.978468e-001,0.000000e+000,,,,,,,,,,,,,,24,1,4.000000e+000,4.797363e-002,0.000000e+000,0,,0,