File: ZFC_FC/MPMS_Li0.5Al0.5 FC 100 Oe.dc.dat
[Header]
TITLE,MPMS DC Measurement
BYAPP,MPMS Measurement,2.1,Summary
FILEOPENTIME, 1687338696.455000 6/21/2023, 11:11:36 AM

INFO, APPNAME, MPMS MultiVu Application, Revision 1.60,  Build 081

INFO, NAME, Li0.5Al0.5Fe5O8
INFO, WEIGHT, 84.430
INFO, AREA, 0.000
INFO, LENGTH, 0.000
INFO, SHAPE,
INFO, COMMENT, cotton: 15.1 mg, capsule:39.07 mg
INFO, SEQUENCE FILE: ZFCFC_RSO 1O0 Oe.seq


INFO, BACKGROUND DATA FILE:, None


STARTUPAXIS,X,4,LINEAR,AUTO,0.000000,0.000000
STARTUPAXIS,Y1,5,LINEAR,AUTO,0.000000,0.000000


STARTUPGROUP,Longitudinal
FIELDGROUP,Longitudinal,1,2,3,4,5,6,7,8,9,15,16,17,18,27,28
FIELDGROUP,Transverse,1,2,3,4,10,11,12,13,14,19,20,21,22,27,28

PLOT_APPEARANCE,ALL,HORZ_GRID_ON,VERT_GRID_ON,MARKERS_AND_LINES

[Data]
Time,Comment,Field (Oe),Temperature (K),Long Moment (emu),Long Scan Std Dev,Long Algorithm,Long Reg Fit,Long Percent Error (%),Trans Moment (emu),Trans Scan Std Dev,Trans Algorithm,Trans Reg Fit,Trans Percent Error (%),Long Moment [w/o ABS] (emu),Long Scan Std Dev [w/o ABS],Long Reg Fit [w/o ABS],Long Percent Error [w/o ABS] (%),Trans Moment [w/o ABS] (emu),Trans Scan Std Dev [w/o ABS],Trans Reg Fit [w/o ABS],Trans Percent Error [w/o ABS] (%),Points per Scan,Scans per Measurement,Scan Length (cm),Delta Temp (K),Rot Position (deg),Error,EC Comp. Running,Using ABS,
1687338696.455,,1.000000e+002,1.798152e+000,5.646142e-001,0.000000e+000,3,9.970676e-001,0.000000e+000,,,,,,,,,,,,,,24,1,4.000000e+000,4.190207e-004,0.000000e+000,0,,0,
1687338782.587,,1.000000e+002,3.372865e+000,5.627668e-001,0.000000e+000,3,9.970024e-001,0.000000e+000,,,,,,,,,,,,,,24,1,4.000000e+000,4.272981e-001,0.000000e+000,0,,0,
1687338812.490,,1.000000e+002,5.222051e+000,5.623959e-001,0.000000e+000,3,9.966361e-001,0.000000e+000,,,,,,,,,,,,,,24,1,4.000000e+000,1.004357e+000,0.000000e+000,0,,0,
1687338835.398,,1.000000e+002,7.381656e+000,5.621281e-001,0.000000e+000,3,9.965781e-001,0.000000e+000,,,,,,,,,,,,,,24,1,4.000000e+000,3.314854e+000,0.000000e+000,0,,0,
1687338859.640,,1.000000e+002,1.088712e+001,5.612925e-001,0.000000e+000,3,9.964288e-001,0.000000e+000,,,,,,,,,,,,,,24,1,4.000000e+000,3.070696e+000,0.000000e+000,0,,0,
1687338912.706,,1.000000e+002,1.867150e+001,5.614277e-001,0.000000e+000,3,9.966869e-001,0.000000e+000,,,,,,,,,,,,,,24,1,4.000000e+000,3.454241e+000,0.000000e+000,0,,0,
1687338936.920,,1.000000e+002,2.259530e+001,5.612599e-001,0.000000e+000,3,9.965681e-001,0.000000e+000,,,,,,,,,,,,,,24,1,4.000000e+000,3.212561e+000,0.000000e+000,0,,0,
1687338963.170,,1.000000e+002,2.658117e+001,5.608035e-001,0.000000e+000,3,9.964596e-001,0.000000e+000,,,,,,,,,,,,,,24,1,4.000000e+000,3.985069e+000,0.000000e+000,0,,0,
1687338990.149,,1.000000e+002,3.114386e+001,5.607926e-001,0.000000e+000,3,9.964390e-001,0.000000e+000,,,,,,,,,,,,,,24,1,4.000000e+000,3.546709e+000,0.000000e+000,0,,0,
1687339015.008,,1.000000e+002,3.515128e+001,5.605917e-001,0.000000e+000,3,9.964308e-001,0.000000e+000,,,,,,,,,,,,,,24,1,4.000000e+000,3.881851e+000,0.000000e+000,0,,0,
1687339039.276,,1.000000e+002,3.899255e+001,5.605770e-001,0.000000e+000,3,9.966239e-001,0.000000e+000,,,,,,,,,,,,,,24,1,4.000000e+000,3.474030e+000,0.000000e+000,0,,0,
1687339065.442,,1.000000e+002,4.319934e+001,5.601029e-001,0.000000e+000,3,9.965791e-001,0.000000e+000,,,,,,,,,,,,,,24,1,4.000000e+000,3.567871e+000,0.000000e+000,0,,0,
1687339091.647,,1.000000e+002,4.724477e+001,5.600888e-001,0.000000e+000,3,9.963965e-001,0.000000e+000,,,,,,,,,,,,,,24,1,4.000000e+000,3.812599e+000,0.000000e+000,0,,0,
1687339117.383,,1.000000e+002,5.148092e+001,5.598545e-001,0.000000e+000,3,9.966095e-001,0.000000e+000,,,,,,,,,,,,,,24,1,4.000000e+000,3.971481e+000,0.000000e+000,0,,0,
1687339143.401,,1.000000e+002,5.587674e+001,5.596124e-001,0.000000e+000,3,9.962915e-001,0.000000e+000,,,,,,,,,,,,,,24,1,4.000000e+000,3.587662e+000,0.000000e+000,0,,0,
1687339167.364,,1.000000e+002,5.982858e+001,5.595799e-001,0.000000e+000,3,9.966136e-001,0.000000e+000,,,,,,,,,,,,,,24,1,4.000000e+000,3.409241e+000,0.000000e+000,0,,0,
1687339190.293,,1.000000e+002,6.374129e+001,5.594041e-001,0.000000e+000,3,9.968630e-001,0.000000e+000,,,,,,,,,,,,,,24,1,4.000000e+000,3.147690e+000,0.000000e+000,0,,0,
1687339213.882,,1.000000e+002,6.748689e+001,5.593087e-001,0.000000e+000,3,9.965358e-001,0.000000e+000,,,,,,,,,,,,,,24,1,4.000000e+000,3.742462e+000,0.000000e+000,0,,0,
1687339239.932,,1.000000e+002,7.163477e+001,5.587206e-001,0.000000e+000,3,9.967249e-001,0.000000e+000,,,,,,,,,,,,,,24,1,4.000000e+000,4.060799e+000,0.000000e+000,0,,0,
1687339264.932,,1.000000e+002,7.608344e+001,5.587117e-001,0.000000e+000,3,9.965348e-001,0.000000e+000,,,,,,,,,,,,,,24,1,4.000000e+000,3.573608e+000,0.000000e+000,0,,0,
1687339290.092,,1.000000e+002,8.021675e+001,5.580951e-001,0.000000e+000,3,9.965259e-001,0.000000e+000,,,,,,,,,,,,,,24,1,4.000000e+000,4.057442e+000,0.000000e+000,0,,0,
1687339315.604,,1.000000e+002,8.445336e+001,5.577217e-001,0.000000e+000,3,9.966331e-001,0.000000e+000,,,,,,,,,,,,,,24,1,4.000000e+000,3.758362e+000,0.000000e+000,0,,0,
1687339341.955,,1.000000e+002,8.894056e+001,5.571327e-001,0.000000e+000,3,9.966148e-001,0.000000e+000,,,,,,,,,,,,,,24,1,4.000000e+000,3.884354e+000,0.000000e+000,0,,0,
1687339391.004,,1.000000e+002,9.711273e+001,5.564912e-001,0.000000e+000,3,9.966955e-001,0.000000e+000,,,,,,,,,,,,,,24,1,4.000000e+000,4.126152e+000,0.000000e+000,0,,0,
1687339415.233,,1.000000e+002,1.014537e+002,5.561340e-001,0.000000e+000,3,9.963716e-001,0.000000e+000,,,,,,,,,,,,,,24,1,4.000000e+000,3.290085e+000,0.000000e+000,0,,0,
1687339439.623,,1.000000e+002,1.056153e+002,5.557386e-001,0.000000e+000,3,9.966550e-001,0.000000e+000,,,,,,,,,,,,,,24,1,4.000000e+000,3.749596e+000,0.000000e+000,0,,0,
1687339463.498,,1.000000e+002,1.096570e+002,5.555501e-001,0.000000e+000,3,9.966020e-001,0.000000e+000,,,,,,,,,,,,,,24,1,4.000000e+000,3.397598e+000,0.000000e+000,0,,0,
1687339487.221,,1.000000e+002,1.135189e+002,5.548948e-001,0.000000e+000,3,9.964921e-001,0.000000e+000,,,,,,,,,,,,,,24,1,4.000000e+000,3.671204e+000,0.000000e+000,0,,0,
1687339511.740,,1.000000e+002,1.179058e+002,5.547460e-001,0.000000e+000,3,9.964294e-001,0.000000e+000,,,,,,,,,,,,,,24,1,4.000000e+000,3.524399e+000,0.000000e+000,0,,0,
1687339535.609,,1.000000e+002,1.218849e+002,5.541002e-001,0.000000e+000,3,9.963281e-001,0.000000e+000,,,,,,,,,,,,,,24,1,4.000000e+000,3.528099e+000,0.000000e+000,0,,0,
1687339563.509,,1.000000e+002,1.263775e+002,5.535751e-001,0.000000e+000,3,9.963667e-001,0.000000e+000,,,,,,,,,,,,,,24,1,4.000000e+000,3.836403e+000,0.000000e+000,0,,0,
1687339589.197,,1.000000e+002,1.308325e+002,5.531251e-001,0.000000e+000,3,9.963737e-001,0.000000e+000,,,,,,,,,,,,,,24,1,4.000000e+000,3.752792e+000,0.000000e+000,0,,0,
1687339612.958,,1.000000e+002,1.348219e+002,5.529348e-001,0.000000e+000,3,9.963848e-001,0.000000e+000,,,,,,,,,,,,,,24,1,4.000000e+000,3.533905e+000,0.000000e+000,0,,0,
1687339640.161,,1.000000e+002,1.392376e+002,5.522734e-001,0.000000e+000,3,9.965134e-001,0.000000e+000,,,,,,,,,,,,,,24,1,4.000000e+000,3.714493e+000,0.000000e+000,0,,0,
1687339665.365,,1.000000e+002,1.436443e+002,5.520803e-001,0.000000e+000,3,9.964353e-001,0.000000e+000,,,,,,,,,,,,,,24,1,4.000000e+000,3.824905e+000,0.000000e+000,0,,0,
1687339690.935,,1.000000e+002,1.476337e+002,5.515154e-001,0.000000e+000,3,9.963619e-001,0.000000e+000,,,,,,,,,,,,,,24,1,4.000000e+000,4.153992e+000,0.000000e+000,0,,0,
1687339716.767,,1.000000e+002,1.522771e+002,5.509499e-001,0.000000e+000,3,9.964410e-001,0.000000e+000,,,,,,,,,,,,,,24,1,4.000000e+000,3.612701e+000,0.000000e+000,0,,0,
1687339741.517,,1.000000e+002,1.563061e+002,5.506312e-001,0.000000e+000,3,9.964412e-001,0.000000e+000,,,,,,,,,,,,,,24,1,4.000000e+000,3.731796e+000,0.000000e+000,0,,0,
1687339767.915,,1.000000e+002,1.607007e+002,5.499331e-001,0.000000e+000,3,9.964734e-001,0.000000e+000,,,,,,,,,,,,,,24,1,4.000000e+000,4.374710e+000,0.000000e+000,0,,0,
1687339793.036,,1.000000e+002,1.652052e+002,5.496004e-001,0.000000e+000,3,9.962650e-001,0.000000e+000,,,,,,,,,,,,,,24,1,4.000000e+000,3.707306e+000,0.000000e+000,0,,0,
1687339818.655,,1.000000e+002,1.693696e+002,5.490696e-001,0.000000e+000,3,9.966060e-001,0.000000e+000,,,,,,,,,,,,,,24,1,4.000000e+000,4.028809e+000,0.000000e+000,0,,0,
1687339843.748,,1.000000e+002,1.736204e+002,5.486556e-001,0.000000e+000,3,9.962938e-001,0.000000e+000,,,,,,,,,,,,,,24,1,4.000000e+000,3.813400e+000,0.000000e+000,0,,0,
1687339870.805,,1.000000e+002,1.780000e+002,5.479839e-001,0.000000e+000,3,9.964431e-001,0.000000e+000,,,,,,,,,,,,,,24,1,4.000000e+000,3.821899e+000,0.000000e+000,0,,0,
1687339896.440,,1.000000e+002,1.822737e+002,5.474258e-001,0.000000e+000,3,9.965071e-001,0.000000e+000,,,,,,,,,,,,,,24,1,4.000000e+000,4.138092e+000,0.000000e+000,0,,0,
1687339921.688,,1.000000e+002,1.864048e+002,5.469604e-001,0.000000e+000,3,9.967965e-001,0.000000e+000,,,,,,,,,,,,,,24,1,4.000000e+000,4.124298e+000,0.000000e+000,0,,0,
1687339947.596,,1.000000e+002,1.908773e+002,5.463683e-001,0.000000e+000,3,9.965458e-001,0.000000e+000,,,,,,,,,,,,,,24,1,4.000000e+000,3.752701e+000,0.000000e+000,0,,0,
1687339973.801,,1.000000e+002,1.953783e+002,5.458941e-001,0.000000e+000,3,9.966553e-001,0.000000e+000,,,,,,,,,,,,,,24,1,4.000000e+000,3.936310e+000,0.000000e+000,0,,0,
1687339999.576,,1.000000e+002,1.995711e+002,5.453543e-001,0.000000e+000,3,9.966384e-001,0.000000e+000,,,,,,,,,,,,,,24,1,4.000000e+000,3.801498e+000,0.000000e+000,0,,0,
1687340024.282,,1.000000e+002,2.037687e+002,5.447814e-001,0.000000e+000,3,9.964597e-001,0.000000e+000,,,,,,,,,,,,,,24,1,4.000000e+000,3.627304e+000,0.000000e+000,0,,0,
1687340050.525,,1.000000e+002,2.081904e+002,5.440703e-001,0.000000e+000,3,9.964888e-001,0.000000e+000,,,,,,,,,,,,,,24,1,4.000000e+000,4.000793e+000,0.000000e+000,0,,0,
1687340076.417,,1.000000e+002,2.125147e+002,5.435651e-001,0.000000e+000,3,9.966328e-001,0.000000e+000,,,,,,,,,,,,,,24,1,4.000000e+000,4.000900e+000,0.000000e+000,0,,0,
1687340101.155,,1.000000e+002,2.167728e+002,5.430830e-001,0.000000e+000,3,9.966591e-001,0.000000e+000,,,,,,,,,,,,,,24,1,4.000000e+000,3.784805e+000,0.000000e+000,0,,0,
1687340124.819,,1.000000e+002,2.206405e+002,5.424850e-001,0.000000e+000,3,9.968380e-001,0.000000e+000,,,,,,,,,,,,,,24,1,4.000000e+000,3.297195e+000,0.000000e+000,0,,0,
1687340150.368,,1.000000e+002,2.247995e+002,5.418409e-001,0.000000e+000,3,9.968102e-001,0.000000e+000,,,,,,,,,,,,,,24,1,4.000000e+000,3.777496e+000,0.000000e+000,0,,0,
1687340175.118,,1.000000e+002,2.289923e+002,5.412025e-001,0.000000e+000,3,9.968390e-001,0.000000e+000,,,,,,,,,,,,,,24,1,4.000000e+000,4.003189e+000,0.000000e+000,0,,0,
1687340200.066,,1.000000e+002,2.331558e+002,5.406585e-001,0.000000e+000,3,9.967304e-001,0.000000e+000,,,,,,,,,,,,,,24,1,4.000000e+000,3.779099e+000,0.000000e+000,0,,0,
1687340226.201,,1.000000e+002,2.374877e+002,5.400221e-001,0.000000e+000,3,9.967996e-001,0.000000e+000,,,,,,,,,,,,,,24,1,4.000000e+000,3.739990e+000,0.000000e+000,0,,0,
1687340249.890,,1.000000e+002,2.416100e+002,5.396224e-001,0.000000e+000,3,9.968031e-001,0.000000e+000,,,,,,,,,,,,,,24,1,4.000000e+000,3.264999e+000,0.000000e+000,0,,0,
1687340276.751,,1.000000e+002,2.462251e+002,5.386413e-001,0.000000e+000,3,9.969800e-001,0.000000e+000,,,,,,,,,,,,,,24,1,4.000000e+000,3.639496e+000,0.000000e+000,0,,0,
1687340300.634,,1.000000e+002,2.500378e+002,5.381089e-001,0.000000e+000,3,9.968292e-001,0.000000e+000,,,,,,,,,,,,,,24,1,4.000000e+000,3.701889e+000,0.000000e+000,0,,0,
1687340325.587,,1.000000e+002,2.541573e+002,5.373525e-001,0.000000e+000,3,9.967424e-001,0.000000e+000,,,,,,,,,,,,,,24,1,4.000000e+000,3.990112e+000,0.000000e+000,0,,0,
1687340375.573,,1.000000e+002,2.623063e+002,5.361711e-001,0.000000e+000,3,9.966764e-001,0.000000e+000,,,,,,,,,,,,,,24,1,4.000000e+000,3.620789e+000,0.000000e+000,0,,0,
1687340398.780,,1.000000e+002,2.663276e+002,5.355957e-001,0.000000e+000,3,9.969812e-001,0.000000e+000,,,,,,,,,,,,,,24,1,4.000000e+000,3.735809e+000,0.000000e+000,0,,0,
1687340422.561,,1.000000e+002,2.703918e+002,5.352555e-001,0.000000e+000,3,9.968872e-001,0.000000e+000,,,,,,,,,,,,,,24,1,4.000000e+000,3.595795e+000,0.000000e+000,0,,0,
1687340447.445,,1.000000e+002,2.743846e+002,5.344862e-001,0.000000e+000,3,9.970211e-001,0.000000e+000,,,,,,,,,,,,,,24,1,4.000000e+000,3.682709e+000,0.000000e+000,0,,0,
1687340472.367,,1.000000e+002,2.786097e+002,5.339544e-001,0.000000e+000,3,9.966965e-001,0.000000e+000,,,,,,,,,,,,,,24,1,4.000000e+000,4.014984e+000,0.000000e+000,0,,0,
1687340497.108,,1.000000e+002,2.828906e+002,5.334456e-001,0.000000e+000,3,9.968226e-001,0.000000e+000,,,,,,,,,,,,,,24,1,4.000000e+000,3.550507e+000,0.000000e+000,0,,0,
1687340521.920,,1.000000e+002,2.869374e+002,5.329065e-001,0.000000e+000,3,9.965922e-001,0.000000e+000,,,,,,,,,,,,,,24,1,4.000000e+000,3.692902e+000,0.000000e+000,0,,0,
1687340547.966,,1.000000e+002,2.911360e+002,5.320565e-001,0.000000e+000,3,9.969597e-001,0.000000e+000,,,,,,,,,,,,,,24,1,4.000000e+000,3.725281e+000,0.000000e+000,0,,0,
1687340573.517,,1.000000e+002,2.954645e+002,5.314289e-001,0.000000e+000,3,9.968499e-001,0.000000e+000,,,,,,,,,,,,,,24,1,4.000000e+000,3.524506e+000,0.000000e+000,0,,0,
1687340598.863,,1.000000e+002,2.996602e+002,5.307493e-001,0.000000e+000,3,9.966054e-001,0.000000e+000,,,,,,,,,,,,,,24,1,4.000000e+000,3.718903e+000,0.000000e+000,0,,0,
1687340623.636,,1.000000e+002,3.037636e+002,5.301419e-001,0.000000e+000,3,9.968833e-001,0.000000e+000,,,,,,,,,,,,,,24,1,4.000000e+000,3.727905e+000,0.000000e+000,0,,0,
1687340651.312,,1.000000e+002,3.083112e+002,5.292314e-001,0.000000e+000,3,9.967605e-001,0.000000e+000,,,,,,,,,,,,,,24,1,4.000000e+000,3.596313e+000,0.000000e+000,0,,0,
1687340677.361,,1.000000e+002,3.127330e+002,5.283691e-001,0.000000e+000,3,9.970579e-001,0.000000e+000,,,,,,,,,,,,,,24,1,4.000000e+000,3.781708e+000,0.000000e+000,0,,0,
1687340702.400,,1.000000e+002,3.171174e+002,5.278667e-001,0.000000e+000,3,9.971952e-001,0.000000e+000,,,,,,,,,,,,,,24,1,4.000000e+000,3.846710e+000,0.000000e+000,0,,0,
1687340728.832,,1.000000e+002,3.212632e+002,5.271002e-001,0.000000e+000,3,9.970248e-001,0.000000e+000,,,,,,,,,,,,,,24,1,4.000000e+000,4.032898e+000,0.000000e+000,0,,0,
1687340753.889,,1.000000e+002,3.257617e+002,5.268276e-001,0.000000e+000,3,9.968175e-001,0.000000e+000,,,,,,,,,,,,,,24,1,4.000000e+000,3.985901e+000,0.000000e+000,0,,0,
1687340778.235,,1.000000e+002,3.296859e+002,5.263938e-001,0.000000e+000,3,9.968238e-001,0.000000e+000,,,,,,,,,,,,,,24,1,4.000000e+000,3.594391e+000,0.000000e+000,0,,0,
1687340802.630,,1.000000e+002,3.337119e+002,5.265476e-001,0.000000e+000,3,9.965550e-001,0.000000e+000,,,,,,,,,,,,,,24,1,4.000000e+000,3.598877e+000,0.000000e+000,0,,0,
1687340826.452,,1.000000e+002,3.376451e+002,5.265863e-001,0.000000e+000,3,9.961907e-001,0.000000e+000,,,,,,,,,,,,,,24,1,4.000000e+000,3.618195e+000,0.000000e+000,0,,0,
1687340850.531,,1.000000e+002,3.415429e+002,5.262864e-001,0.000000e+000,3,9.960803e-001,0.000000e+000,,,,,,,,,,,,,,24,1,4.000000e+000,3.780609e+000,0.000000e+000,0,,0,
1687340875.784,,1.000000e+002,3.459009e+002,5.259929e-001,0.000000e+000,3,9.958553e-001,0.000000e+000,,,,,,,,,,,,,,24,1,4.000000e+000,3.639496e+000,0.000000e+000,0,,0,
1687340897.870,,1.000000e+002,3.498196e+002,5.255595e-001,0.000000e+000,3,9.954886e-001,0.000000e+000,,,,,,,,,,,,,,24,1,4.000000e+000,3.400299e+000,0.000000e+000,0,,0,
1687340921.988,,1.000000e+002,3.537188e+002,5.252454e-001,0.000000e+000,3,9.952961e-001,0.000000e+000,,,,,,,,,,,,,,24,1,4.000000e+000,3.853882e+000,0.000000e+000,0,,0,
1687340946.999,,1.000000e+002,3.579763e+002,5.249312e-001,0.000000e+000,3,9.949853e-001,0.000000e+000,,,,,,,,,,,,,,24,1,4.000000e+000,3.266113e+000,0.000000e+000,0,,0,
1687340972.327,,1.000000e+002,3.620272e+002,5.240781e-001,0.000000e+000,3,9.949112e-001,0.000000e+000,,,,,,,,,,,,,,24,1,4.000000e+000,3.611908e+000,0.000000e+000,0,,0,
1687340994.890,,1.000000e+002,3.656967e+002,5.233095e-001,0.000000e+000,3,9.947931e-001,0.000000e+000,,,,,,,,,,,,,,24,1,4.000000e+000,3.393402e+000,0.000000e+000,0,,0,
1687341019.152,,1.000000e+002,3.698546e+002,5.225412e-001,0.000000e+000,3,9.945110e-001,0.000000e+000,,,,,,,,,,,,,,24,1,4.000000e+000,3.344299e+000,0.000000e+000,0,,0,
1687341045.206,,1.000000e+002,3.740911e+002,5.216343e-001,0.000000e+000,3,9.942351e-001,0.000000e+000,,,,,,,,,,,,,,24,1,4.000000e+000,3.688690e+000,0.000000e+000,0,,0,
1687341068.011,,1.000000e+002,3.779639e+002,5.209022e-001,0.000000e+000,3,9.942228e-001,0.000000e+000,,,,,,,,,,,,,,24,1,4.000000e+000,3.654877e+000,0.000000e+000,0,,0,
1687341093.984,,1.000000e+002,3.822678e+002,5.199525e-001,0.000000e+000,3,9.942686e-001,0.000000e+000,,,,,,,,,,,,,,24,1,4.000000e+000,3.994598e+000,0.000000e+000,0,,0,
1687341119.510,,1.000000e+002,3.864357e+002,5.190626e-001,0.000000e+000,3,9.944436e-001,0.000000e+000,,,,,,,,,,,,,,24,1,4.000000e+000,4.107697e+000,0.000000e+000,0,,0,
1687341145.793,,1.000000e+002,3.904895e+002,5.187061e-001,0.000000e+000,3,9.939458e-001,0.000000e+000,,,,,,,,,,,,,,24,1,4.000000e+000,3.713623e+000,0.000000e+000,0,,0,
1687341410.306,,1.000000e+002,3.901553e+002,5.173225e-001,0.000000e+000,3,9.913424e-001,0.000000e+000,,,,,,,,,,,,,,24,1,4.000000e+000,2.167053e-001,0.000000e+000,0,,0,
1687341436.568,,1.000000e+002,3.902275e+002,5.170167e-001,0.000000e+000,3,9.917471e-001,0.000000e+000,,,,,,,,,,,,,,24,1,4.000000e+000,2.398682e-002,0.000000e+000,0,,0,
1687341462.138,,1.000000e+002,3.901673e+002,5.172541e-001,0.000000e+000,3,9.918696e-001,0.000000e+000,,,,,,,,,,,,,,24,1,4.000000e+000,9.640503e-002,0.000000e+000,0,,0,
1687341486.603,,1.000000e+002,3.899868e+002,5.173165e-001,0.000000e+000,3,9.919962e-001,0.000000e+000,,,,,,,,,,,,,,24,1,4.000000e+000,2.164917e-001,0.000000e+000,0,,0,
1687341509.865,,1.000000e+002,3.900710e+002,5.172557e-001,0.000000e+000,3,9.920872e-001,0.000000e+000,,,,,,,,,,,,,,24,1,4.000000e+000,4.818726e-002,0.000000e+000,0,,0,
1687341534.592,,1.000000e+002,3.899988e+002,5.169396e-001,0.000000e+000,3,9.921616e-001,0.000000e+000,,,,,,,,,,,,,,24,1,4.000000e+000,9.619141e-002,0.000000e+000,0,,0,
1687341560.517,,1.000000e+002,3.901071e+002,5.169125e-001,0.000000e+000,3,9.918786e-001,0.000000e+000,,,,,,,,,,,,,,24,1,4.000000e+000,1.685181e-001,0.000000e+000,0,,0,
1687341586.970,,1.000000e+002,3.900109e+002,5.167918e-001,0.000000e+000,3,9.921040e-001,0.000000e+000,,,,,,,,,,,,,,24,1,4.000000e+000,2.645874e-001,0.000000e+000,0,,0,
1687341612.910,,1.000000e+002,3.900830e+002,5.168765e-001,0.000000e+000,3,9.922427e-001,0.000000e+000,,,,,,,,,,,,,,24,1,4.000000e+000,1.203003e-001,0.000000e+000,0,,0,
1687341638.342,,1.000000e+002,3.899147e+002,5.169812e-001,0.000000e+000,3,9.919126e-001,0.000000e+000,,,,,,,,,,,,,,24,1,4.000000e+000,7.211304e-002,0.000000e+000,0,,0,
1687341662.258,,1.000000e+002,3.901191e+002,5.170169e-001,0.000000e+000,3,9.921035e-001,0.000000e+000,,,,,,,,,,,,,,24,1,4.000000e+000,2.406921e-001,0.000000e+000,0,,0,
1687341688.277,,1.000000e+002,3.901072e+002,5.167255e-001,0.000000e+000,3,9.920496e-001,0.000000e+000,,,,,,,,,,,,,,24,1,4.000000e+000,2.645874e-001,0.000000e+000,0,,0,
1687341712.356,,1.000000e+002,3.899628e+002,5.169649e-001,0.000000e+000,3,9.921166e-001,0.000000e+000,,,,,,,,,,,,,,24,1,4.000000e+000,2.420044e-002,0.000000e+000,0,,0,
1687341737.352,,1.000000e+002,3.899868e+002,5.168248e-001,0.000000e+000,3,9.919537e-001,0.000000e+000,,,,,,,,,,,,,,24,1,4.000000e+000,7.217407e-002,0.000000e+000,0,,0,
1687341763.729,,1.000000e+002,3.899989e+002,5.167881e-001,0.000000e+000,3,9.919281e-001,0.000000e+000,,,,,,,,,,,,,,24,1,4.000000e+000,4.797363e-002,0.000000e+000,0,,0,
1687341787.393,,1.000000e+002,3.900469e+002,5.171002e-001,0.000000e+000,3,9.920651e-001,0.000000e+000,,,,,,,,,,,,,,24,1,4.000000e+000,0.000000e+000,0.000000e+000,0,,0,
1687341835.905,,1.000000e+002,3.901071e+002,5.170974e-001,0.000000e+000,3,9.919616e-001,0.000000e+000,,,,,,,,,,,,,,24,1,4.000000e+000,1.203918e-001,0.000000e+000,0,,0,
1687341862.714,,1.000000e+002,3.901191e+002,5.169236e-001,0.000000e+000,3,9.920249e-001,0.000000e+000,,,,,,,,,,,,,,24,1,4.000000e+000,4.809570e-002,0.000000e+000,0,,0,
1687341887.671,,1.000000e+002,3.901312e+002,5.167378e-001,0.000000e+000,3,9.920254e-001,0.000000e+000,,,,,,,,,,,,,,24,1,4.000000e+000,7.220459e-002,0.000000e+000,0,,0,
1687341912.618,,1.000000e+002,3.899628e+002,5.170494e-001,0.000000e+000,3,9.920584e-001,0.000000e+000,,,,,,,,,,,,,,24,1,4.000000e+000,3.126221e-001,0.000000e+000,0,,0,
1687341939.876,,1.000000e+002,3.901553e+002,5.168330e-001,0.000000e+000,3,9.919397e-001,0.000000e+000,,,,,,,,,,,,,,24,1,4.000000e+000,7.229614e-002,0.000000e+000,0,,0,
1687341963.778,,1.000000e+002,3.899507e+002,5.167566e-001,0.000000e+000,3,9.922519e-001,0.000000e+000,,,,,,,,,,,,,,24,1,4.000000e+000,1.922913e-001,0.000000e+000,0,,0,
1687341988.920,,1.000000e+002,3.898666e+002,5.168948e-001,0.000000e+000,3,9.920149e-001,0.000000e+000,,,,,,,,,,,,,,24,1,4.000000e+000,1.682129e-001,0.000000e+000,0,,0,
1687342016.664,,1.000000e+002,3.901552e+002,5.166945e-001,0.000000e+000,3,9.921893e-001,0.000000e+000,,,,,,,,,,,,,,24,1,4.000000e+000,2.410889e-002,0.000000e+000,0,,0,
1687342042.518,,1.000000e+002,3.900832e+002,5.167825e-001,0.000000e+000,3,9.919868e-001,0.000000e+000,,,,,,,,,,,,,,24,1,4.000000e+000,2.164917e-001,0.000000e+000,0,,0,
1687342068.020,,1.000000e+002,3.901432e+002,5.168794e-001,0.000000e+000,3,9.922103e-001,0.000000e+000,,,,,,,,,,,,,,24,1,4.000000e+000,9.631348e-002,0.000000e+000,0,,0,
1687342092.991,,1.000000e+002,3.899628e+002,5.169146e-001,0.000000e+000,3,9.919677e-001,0.000000e+000,,,,,,,,,,,,,,24,1,4.000000e+000,7.211304e-002,0.000000e+000,0,,0,
1687342116.600,,1.000000e+002,3.902035e+002,5.168023e-001,0.000000e+000,3,9.919850e-001,0.000000e+000,,,,,,,,,,,,,,24,1,4.000000e+000,2.410889e-002,0.000000e+000,0,,0,
1687342141.929,,1.000000e+002,3.901191e+002,5.167962e-001,0.000000e+000,3,9.919596e-001,0.000000e+000,,,,,,,,,,,,,,24,1,4.000000e+000,1.445007e-001,0.000000e+000,0,,0,
1687342167.284,,1.000000e+002,3.898546e+002,5.168155e-001,0.000000e+000,3,9.919281e-001,0.000000e+000,,,,,,,,,,,,,,24,1,4.000000e+000,4.800415e-002,0.000000e+000,0,,0,
1687342192.354,,1.000000e+002,3.898907e+002,5.167678e-001,0.000000e+000,3,9.922696e-001,0.000000e+000,,,,,,,,,,,,,,24,1,4.000000e+000,1.201172e-001,0.000000e+000,0,,0,
1687342217.784,,1.000000e+002,3.899748e+002,5.168149e-001,0.000000e+000,3,9.920978e-001,0.000000e+000,,,,,,,,,,,,,,24,1,4.000000e+000,4.809570e-002,0.000000e+000,0,,0,
1687342244.491,,1.000000e+002,3.900349e+002,5.164893e-001,0.000000e+000,3,9.917669e-001,0.000000e+000,,,,,,,,,,,,,,24,1,4.000000e+000,2.401733e-002,0.000000e+000,0,,0,
1687342269.944,,1.000000e+002,3.900229e+002,5.166200e-001,0.000000e+000,3,9.922405e-001,0.000000e+000,,,,,,,,,,,,,,24,1,4.000000e+000,1.924133e-001,0.000000e+000,0,,0,
1687342319.881,,1.000000e+002,3.900710e+002,5.167688e-001,0.000000e+000,3,9.920771e-001,0.000000e+000,,,,,,,,,,,,,,24,1,4.000000e+000,4.818726e-002,0.000000e+000,0,,0,
1687342345.750,,1.000000e+002,3.901072e+002,5.169286e-001,0.000000e+000,3,9.920654e-001,0.000000e+000,,,,,,,,,,,,,,24,1,4.000000e+000,2.167053e-001,0.000000e+000,0,,0,
1687342371.690,,1.000000e+002,3.900469e+002,5.168207e-001,0.000000e+000,3,9.920270e-001,0.000000e+000,,,,,,,,,,,,,,24,1,4.000000e+000,9.628296e-002,0.000000e+000,0,,0,
1687342395.692,,1.000000e+002,3.899508e+002,5.168956e-001,0.000000e+000,3,9.920166e-001,0.000000e+000,,,,,,,,,,,,,,24,1,4.000000e+000,2.886047e-001,0.000000e+000,0,,0,
1687342422.108,,1.000000e+002,3.898306e+002,5.168876e-001,0.000000e+000,3,9.920973e-001,0.000000e+000,,,,,,,,,,,,,,24,1,4.000000e+000,4.812622e-002,0.000000e+000,0,,0,
1687342448.381,,1.000000e+002,3.898907e+002,5.167581e-001,0.000000e+000,3,9.920687e-001,0.000000e+000,,,,,,,,,,,,,,24,1,4.000000e+000,7.208252e-002,0.000000e+000,0,,0,
1687342472.453,,1.000000e+002,3.899507e+002,5.168654e-001,0.000000e+000,3,9.919052e-001,0.000000e+000,,,,,,,,,,,,,,24,1,4.000000e+000,1.922913e-001,0.000000e+000,0,,0,
1687342498.323,,1.000000e+002,3.900109e+002,5.166638e-001,0.000000e+000,3,9.921938e-001,0.000000e+000,,,,,,,,,,,,,,24,1,4.000000e+000,1.683960e-001,0.000000e+000,0,,0,
1687342522.823,,1.000000e+002,3.899988e+002,5.168576e-001,0.000000e+000,3,9.919843e-001,0.000000e+000,,,,,,,,,,,,,,24,1,4.000000e+000,1.925049e-001,0.000000e+000,0,,0,
1687342548.184,,1.000000e+002,3.899868e+002,5.169165e-001,0.000000e+000,3,9.920044e-001,0.000000e+000,,,,,,,,,,,,,,24,1,4.000000e+000,1.202087e-001,0.000000e+000,0,,0,
1687342572.295,,1.000000e+002,3.899628e+002,5.165724e-001,0.000000e+000,3,9.919741e-001,0.000000e+000,,,,,,,,,,,,,,24,1,4.000000e+000,7.211304e-002,0.000000e+000,0,,0,
1687342596.717,,1.000000e+002,3.898906e+002,5.168233e-001,0.000000e+000,3,9.920953e-001,0.000000e+000,,,,,,,,,,,,,,24,1,4.000000e+000,2.398682e-002,0.000000e+000,0,,0,
1687342621.360,,1.000000e+002,3.899387e+002,5.167495e-001,0.000000e+000,3,9.921632e-001,0.000000e+000,,,,,,,,,,,,,,24,1,4.000000e+000,1.202087e-001,0.000000e+000,0,,0,
1687342646.080,,1.000000e+002,3.899147e+002,5.167578e-001,0.000000e+000,3,9.919550e-001,0.000000e+000,,,,,,,,,,,,,,24,1,4.000000e+000,7.211304e-002,0.000000e+000,0,,0,
1687342672.127,,1.000000e+002,3.898786e+002,5.166114e-001,0.000000e+000,3,9.921525e-001,0.000000e+000,,,,,,,,,,,,,,24,1,4.000000e+000,0.000000e+000,0.000000e+000,0,,0,
1687342695.629,,1.000000e+002,3.899748e+002,5.167761e-001,0.000000e+000,3,9.920507e-001,0.000000e+000,,,,,,,,,,,,,,24,1,4.000000e+000,1.924133e-001,0.000000e+000,0,,0,
1687342721.037,,1.000000e+002,3.900469e+002,5.165074e-001,0.000000e+000,3,9.921959e-001,0.000000e+000,,,,,,,,,,,,,,24,1,4.000000e+000,9.628296e-002,0.000000e+000,0,,0,
1687342746.389,,1.000000e+002,3.899507e+002,5.166907e-001,0.000000e+000,3,9.920137e-001,0.000000e+000,,,,,,,,,,,,,,24,1,4.000000e+000,9.622192e-002,0.000000e+000,0,,0,
1687342796.359,,1.000000e+002,3.899989e+002,5.167397e-001,0.000000e+000,3,9.920903e-001,0.000000e+000,,,,,,,,,,,,,,24,1,4.000000e+000,4.797363e-002,0.000000e+000,0,,0,
1687342820.249,,1.000000e+002,3.899988e+002,5.167366e-001,0.000000e+000,3,9.920753e-001,0.000000e+000,,,,,,,,,,,,,,24,1,4.000000e+000,9.619141e-002,0.000000e+000,0,,0,
1687342844.745,,1.000000e+002,3.900469e+002,5.168222e-001,0.000000e+000,3,9.921290e-001,0.000000e+000,,,,,,,,,,,,,,24,1,4.000000e+000,1.924744e-001,0.000000e+000,0,,0,
1687342867.495,,1.000000e+002,3.900229e+002,5.167815e-001,0.000000e+000,3,9.920308e-001,0.000000e+000,,,,,,,,,,,,,,24,1,4.000000e+000,2.406006e-001,0.000000e+000,0,,0,
1687342892.906,,1.000000e+002,3.899507e+002,5.165704e-001,0.000000e+000,3,9.920925e-001,0.000000e+000,,,,,,,,,,,,,,24,1,4.000000e+000,0.000000e+000,0.000000e+000,0,,0,
1687342919.267,,1.000000e+002,3.898666e+002,5.165142e-001,0.000000e+000,3,9.921907e-001,0.000000e+000,,,,,,,,,,,,,,24,1,4.000000e+000,1.682129e-001,0.000000e+000,0,,0,
1687342944.618,,1.000000e+002,3.900349e+002,5.167528e-001,0.000000e+000,3,9.920559e-001,0.000000e+000,,,,,,,,,,,,,,24,1,4.000000e+000,2.401733e-002,0.000000e+000,0,,0,
1687342970.503,,1.000000e+002,3.900710e+002,5.165910e-001,0.000000e+000,3,9.920095e-001,0.000000e+000,,,,,,,,,,,,,,24,1,4.000000e+000,4.818726e-002,0.000000e+000,0,,0,
1687342995.490,,1.000000e+002,3.900229e+002,5.165499e-001,0.000000e+000,3,9.922364e-001,0.000000e+000,,,,,,,,,,,,,,24,1,4.000000e+000,1.443787e-001,0.000000e+000,0,,0,
1687343020.882,,1.000000e+002,3.899267e+002,5.167978e-001,0.000000e+000,3,9.920544e-001,0.000000e+000,,,,,,,,,,,,,,24,1,4.000000e+000,1.441956e-001,0.000000e+000,0,,0,
1687343044.005,,1.000000e+002,3.900109e+002,5.167521e-001,0.000000e+000,3,9.921790e-001,0.000000e+000,,,,,,,,,,,,,,24,1,4.000000e+000,2.407837e-002,0.000000e+000,0,,0,
1687343072.177,,1.000000e+002,3.900349e+002,5.166363e-001,0.000000e+000,3,9.922194e-001,0.000000e+000,,,,,,,,,,,,,,24,1,4.000000e+000,2.401733e-002,0.000000e+000,0,,0,
1687343095.798,,1.000000e+002,3.900950e+002,5.167511e-001,0.000000e+000,3,9.921445e-001,0.000000e+000,,,,,,,,,,,,,,24,1,4.000000e+000,9.628296e-002,0.000000e+000,0,,0,
1687343122.572,,1.000000e+002,3.900469e+002,5.165370e-001,0.000000e+000,3,9.920500e-001,0.000000e+000,,,,,,,,,,,,,,24,1,4.000000e+000,1.924744e-001,0.000000e+000,0,,0,
1687343150.191,,1.000000e+002,3.899989e+002,5.164712e-001,0.000000e+000,3,9.920828e-001,0.000000e+000,,,,,,,,,,,,,,24,1,4.000000e+000,4.797363e-002,0.000000e+000,0,,0,
1687343175.115,,1.000000e+002,3.900830e+002,5.167252e-001,0.000000e+000,3,9.920807e-001,0.000000e+000,,,,,,,,,,,,,,24,1,4.000000e+000,1.203003e-001,0.000000e+000,0,,0,
1687343199.694,,1.000000e+002,3.899748e+002,5.166747e-001,0.000000e+000,3,9.919891e-001,0.000000e+000,,,,,,,,,,,,,,24,1,4.000000e+000,1.924133e-001,0.000000e+000,0,,0,
1687343224.251,,1.000000e+002,3.899989e+002,5.165932e-001,0.000000e+000,3,9.921313e-001,0.000000e+000,,,,,,,,,,,,,,24,1,4.000000e+000,2.885742e-001,0.000000e+000,0,,0,
1687343248.704,,1.000000e+002,3.900950e+002,5.166765e-001,0.000000e+000,3,9.920458e-001,0.000000e+000,,,,,,,,,,,,,,24,1,4.000000e+000,9.628296e-002,0.000000e+000,0,,0,
1687343272.845,,1.000000e+002,3.900229e+002,5.167503e-001,0.000000e+000,3,9.920960e-001,0.000000e+000,,,,,,,,,,,,,,24,1,4.000000e+000,4.809570e-002,0.000000e+000,0,,0,
1687343297.224,,1.000000e+002,3.899628e+002,5.166944e-001,0.000000e+000,3,9.920366e-001,0.000000e+000,,,,,,,,,,,,,,24,1,4.000000e+000,7.211304e-002,0.000000e+000,0,,0,
1687343321.685,,1.000000e+002,3.900229e+002,5.167654e-001,0.000000e+000,3,9.920125e-001,0.000000e+000,,,,,,,,,,,,,,24,1,4.000000e+000,1.924133e-001,0.000000e+000,0,,0,
1687343346.646,,1.000000e+002,3.900110e+002,5.165450e-001,0.000000e+000,3,9.921951e-001,0.000000e+000,,,,,,,,,,,,,,24,1,4.000000e+000,3.126831e-001,0.000000e+000,0,,0,
1687343372.048,,1.000000e+002,3.899749e+002,5.164880e-001,0.000000e+000,3,9.920339e-001,0.000000e+000,,,,,,,,,,,,,,24,1,4.000000e+000,2.404785e-001,0.000000e+000,0,,0,
1687343396.954,,1.000000e+002,3.900349e+002,5.165866e-001,0.000000e+000,3,9.919930e-001,0.000000e+000,,,,,,,,,,,,,,24,1,4.000000e+000,1.683960e-001,0.000000e+000,0,,0,
1687343421.891,,1.000000e+002,3.901191e+002,5.165342e-001,0.000000e+000,3,9.921455e-001,0.000000e+000,,,,,,,,,,,,,,24,1,4.000000e+000,0.000000e+000,0.000000e+000,0,,0,
1687343446.364,,1.000000e+002,3.899988e+002,5.166621e-001,0.000000e+000,3,9.920025e-001,0.000000e+000,,,,,,,,,,,,,,24,1,4.000000e+000,2.405090e-001,0.000000e+000,0,,0,
1687343470.998,,1.000000e+002,3.899147e+002,5.166213e-001,0.000000e+000,3,9.920698e-001,0.000000e+000,,,,,,,,,,,,,,24,1,4.000000e+000,7.211304e-002,0.000000e+000,0,,0,
1687343497.787,,1.000000e+002,3.900951e+002,5.165672e-001,0.000000e+000,3,9.921992e-001,0.000000e+000,,,,,,,,,,,,,,24,1,4.000000e+000,2.887878e-001,0.000000e+000,0,,0,
1687343523.185,,1.000000e+002,3.899748e+002,5.164909e-001,0.000000e+000,3,9.922503e-001,0.000000e+000,,,,,,,,,,,,,,24,1,4.000000e+000,4.809570e-002,0.000000e+000,0,,0,
1687343546.341,,1.000000e+002,3.900950e+002,5.165447e-001,0.000000e+000,3,9.920352e-001,0.000000e+000,,,,,,,,,,,,,,24,1,4.000000e+000,9.628296e-002,0.000000e+000,0,,0,
1687343571.688,,1.000000e+002,3.899868e+002,5.165293e-001,0.000000e+000,3,9.921374e-001,0.000000e+000,,,,,,,,,,,,,,24,1,4.000000e+000,1.202087e-001,0.000000e+000,0,,0,
1687343598.383,,1.000000e+002,3.900710e+002,5.167540e-001,0.000000e+000,3,9.920685e-001,0.000000e+000,,,,,,,,,,,,,,24,1,4.000000e+000,1.443787e-001,0.000000e+000,0,,0,
1687343624.830,,1.000000e+002,3.899026e+002,5.164939e-001,0.000000e+000,3,9.919806e-001,0.000000e+000,,,,,,,,,,,,,,24,1,4.000000e+000,1.923218e-001,0.000000e+000,0,,0,
1687343650.294,,1.000000e+002,3.898666e+002,5.163806e-001,0.000000e+000,3,9.920357e-001,0.000000e+000,,,,,,,,,,,,,,24,1,4.000000e+000,1.202087e-001,0.000000e+000,0,,0,
1687343675.107,,1.000000e+002,3.898786e+002,5.165330e-001,0.000000e+000,3,9.918462e-001,0.000000e+000,,,,,,,,,,,,,,24,1,4.000000e+000,1.442261e-001,0.000000e+000,0,,0,
1687343699.549,,1.000000e+002,3.899026e+002,5.165424e-001,0.000000e+000,3,9.922026e-001,0.000000e+000,,,,,,,,,,,,,,24,1,4.000000e+000,9.609985e-002,0.000000e+000,0,,0,
1687343726.481,,1.000000e+002,3.898786e+002,5.165564e-001,0.000000e+000,3,9.920790e-001,0.000000e+000,,,,,,,,,,,,,,24,1,4.000000e+000,4.797363e-002,0.000000e+000,0,,0,
1687343754.192,,1.000000e+002,3.899627e+002,5.164750e-001,0.000000e+000,3,9.920493e-001,0.000000e+000,,,,,,,,,,,,,,24,1,4.000000e+000,1.203003e-001,0.000000e+000,0,,0,
1687343779.084,,1.000000e+002,3.899748e+002,5.164802e-001,0.000000e+000,3,9.921061e-001,0.000000e+000,,,,,,,,,,,,,,24,1,4.000000e+000,9.619141e-002,0.000000e+000,0,,0,
1687343804.180,,1.000000e+002,3.899387e+002,5.165852e-001,0.000000e+000,3,9.921998e-001,0.000000e+000,,,,,,,,,,,,,,24,1,4.000000e+000,2.401733e-002,0.000000e+000,0,,0,
1687343829.580,,1.000000e+002,3.898907e+002,5.167615e-001,0.000000e+000,3,9.919401e-001,0.000000e+000,,,,,,,,,,,,,,24,1,4.000000e+000,7.208252e-002,0.000000e+000,0,,0,
1687343853.731,,1.000000e+002,3.898185e+002,5.165708e-001,0.000000e+000,3,9.921319e-001,0.000000e+000,,,,,,,,,,,,,,24,1,4.000000e+000,7.211304e-002,0.000000e+000,0,,0,
1687343879.028,,1.000000e+002,3.898425e+002,5.163549e-001,0.000000e+000,3,9.919540e-001,0.000000e+000,,,,,,,,,,,,,,24,1,4.000000e+000,1.200867e-001,0.000000e+000,0,,0,
1687343904.412,,1.000000e+002,3.899868e+002,5.165386e-001,0.000000e+000,3,9.920002e-001,0.000000e+000,,,,,,,,,,,,,,24,1,4.000000e+000,1.684265e-001,0.000000e+000,0,,0,
1687343928.485,,1.000000e+002,3.899387e+002,5.166280e-001,0.000000e+000,3,9.920136e-001,0.000000e+000,,,,,,,,,,,,,,24,1,4.000000e+000,2.401733e-002,0.000000e+000,0,,0,
1687343953.469,,1.000000e+002,3.900831e+002,5.165828e-001,0.000000e+000,3,9.921364e-001,0.000000e+000,,,,,,,,,,,,,,24,1,4.000000e+000,1.684875e-001,0.000000e+000,0,,0,
1687343979.369,,1.000000e+002,3.900349e+002,5.163400e-001,0.000000e+000,3,9.920518e-001,0.000000e+000,,,,,,,,,,,,,,24,1,4.000000e+000,1.683960e-001,0.000000e+000,0,,0,
1687344005.373,,1.000000e+002,3.900109e+002,5.165932e-001,0.000000e+000,3,9.920506e-001,0.000000e+000,,,,,,,,,,,,,,24,1,4.000000e+000,2.407837e-002,0.000000e+000,0,,0,
1687344028.812,,1.000000e+002,3.899988e+002,5.168476e-001,0.000000e+000,3,9.921060e-001,0.000000e+000,,,,,,,,,,,,,,24,1,4.000000e+000,0.000000e+000,0.000000e+000,0,,0,
1687344054.247,,1.000000e+002,3.901071e+002,5.164614e-001,0.000000e+000,3,9.920804e-001,0.000000e+000,,,,,,,,,,,,,,24,1,4.000000e+000,1.203918e-001,0.000000e+000,0,,0,
1687344078.804,,1.000000e+002,3.900830e+002,5.163953e-001,0.000000e+000,3,9.920303e-001,0.000000e+000,,,,,,,,,,,,,,24,1,4.000000e+000,7.220459e-002,0.000000e+000,0,,0,
1687344105.618,,1.000000e+002,3.899868e+002,5.166515e-001,0.000000e+000,3,9.921721e-001,0.000000e+000,,,,,,,,,,,,,,24,1,4.000000e+000,2.164917e-001,0.000000e+000,0,,0,
1687344129.699,,1.000000e+002,3.899147e+002,5.166630e-001,0.000000e+000,3,9.920979e-001,0.000000e+000,,,,,,,,,,,,,,24,1,4.000000e+000,2.644043e-001,0.000000e+000,0,,0,
1687344155.066,,1.000000e+002,3.899026e+002,5.164717e-001,0.000000e+000,3,9.919403e-001,0.000000e+000,,,,,,,,,,,,,,24,1,4.000000e+000,4.809570e-002,0.000000e+000,0,,0,
1687344181.366,,1.000000e+002,3.901191e+002,5.165332e-001,0.000000e+000,3,9.922239e-001,0.000000e+000,,,,,,,,,,,,,,24,1,4.000000e+000,1.445007e-001,0.000000e+000,0,,0,
1687344232.414,,1.000000e+002,3.901553e+002,5.165802e-001,0.000000e+000,3,9.920353e-001,0.000000e+000,,,,,,,,,,,,,,24,1,4.000000e+000,1.204224e-001,0.000000e+000,0,,0,
1687344258.235,,1.000000e+002,3.899748e+002,5.165651e-001,0.000000e+000,3,9.921145e-001,0.000000e+000,,,,,,,,,,,,,,24,1,4.000000e+000,9.619141e-002,0.000000e+000,0,,0,
1687344282.729,,1.000000e+002,3.900229e+002,5.167447e-001,0.000000e+000,3,9.920611e-001,0.000000e+000,,,,,,,,,,,,,,24,1,4.000000e+000,1.924133e-001,0.000000e+000,0,,0,
1687344307.299,,1.000000e+002,3.900710e+002,5.164912e-001,0.000000e+000,3,9.920195e-001,0.000000e+000,,,,,,,,,,,,,,24,1,4.000000e+000,9.622192e-002,0.000000e+000,0,,0,
1687344334.168,,1.000000e+002,3.899989e+002,5.164255e-001,0.000000e+000,3,9.920161e-001,0.000000e+000,,,,,,,,,,,,,,24,1,4.000000e+000,4.797363e-002,0.000000e+000,0,,0,
1687344358.639,,1.000000e+002,3.898547e+002,5.165737e-001,0.000000e+000,3,9.923059e-001,0.000000e+000,,,,,,,,,,,,,,24,1,4.000000e+000,2.405090e-001,0.000000e+000,0,,0,
1687344384.032,,1.000000e+002,3.898787e+002,5.164863e-001,0.000000e+000,3,9.920710e-001,0.000000e+000,,,,,,,,,,,,,,24,1,4.000000e+000,2.884827e-001,0.000000e+000,0,,0,
1687344407.182,,1.000000e+002,3.899387e+002,5.166833e-001,0.000000e+000,3,9.921493e-001,0.000000e+000,,,,,,,,,,,,,,24,1,4.000000e+000,2.401733e-002,0.000000e+000,0,,0,
1687344431.754,,1.000000e+002,3.899267e+002,5.167113e-001,0.000000e+000,3,9.921253e-001,0.000000e+000,,,,,,,,,,,,,,24,1,4.000000e+000,0.000000e+000,0.000000e+000,0,,0,
1687344457.670,,1.000000e+002,3.899748e+002,5.167370e-001,0.000000e+000,3,9.921920e-001,0.000000e+000,,,,,,,,,,,,,,24,1,4.000000e+000,4.809570e-002,0.000000e+000,0,,0,
1687344483.428,,1.000000e+002,3.899989e+002,5.162169e-001,0.000000e+000,3,9.921333e-001,0.000000e+000,,,,,,,,,,,,,,24,1,4.000000e+000,4.797363e-002,0.000000e+000,0,,0,
1687344507.563,,1.000000e+002,3.900590e+002,5.165936e-001,0.000000e+000,3,9.920323e-001,0.000000e+000,,,,,,,,,,,,,,24,1,4.000000e+000,7.220459e-002,0.000000e+000,0,,0,
1687344534.424,,1.000000e+002,3.900710e+002,5.167169e-001,0.000000e+000,3,9.921135e-001,0.000000e+000,,,,,,,,,,,,,,24,1,4.000000e+000,2.406921e-001,0.000000e+000,0,,0,
1687344560.299,,1.000000e+002,3.899988e+002,5.164994e-001,0.000000e+000,3,9.921814e-001,0.000000e+000,,,,,,,,,,,,,,24,1,4.000000e+000,9.619141e-002,0.000000e+000,0,,0,
1687344584.801,,1.000000e+002,3.900830e+002,5.164036e-001,0.000000e+000,3,9.923019e-001,0.000000e+000,,,,,,,,,,,,,,24,1,4.000000e+000,7.220459e-002,0.000000e+000,0,,0,
1687344611.257,,1.000000e+002,3.901071e+002,5.164544e-001,0.000000e+000,3,9.920481e-001,0.000000e+000,,,,,,,,,,,,,,24,1,4.000000e+000,1.203918e-001,0.000000e+000,0,,0,
1687344635.306,,1.000000e+002,3.901673e+002,5.165293e-001,0.000000e+000,3,9.920823e-001,0.000000e+000,,,,,,,,,,,,,,24,1,4.000000e+000,0.000000e+000,0.000000e+000,0,,0,
1687344661.183,,1.000000e+002,3.899869e+002,5.161887e-001,0.000000e+000,3,9.921007e-001,0.000000e+000,,,,,,,,,,,,,,24,1,4.000000e+000,3.608093e-001,0.000000e+000,0,,0,
1687344686.652,,1.000000e+002,3.900590e+002,5.165198e-001,0.000000e+000,3,9.921481e-001,0.000000e+000,,,,,,,,,,,,,,24,1,4.000000e+000,2.410889e-002,0.000000e+000,0,,0,
1687344711.090,,1.000000e+002,3.900590e+002,5.164928e-001,0.000000e+000,3,9.920107e-001,0.000000e+000,,,,,,,,,,,,,,24,1,4.000000e+000,2.410889e-002,0.000000e+000,0,,0,
1687344737.085,,1.000000e+002,3.900229e+002,5.164701e-001,0.000000e+000,3,9.921652e-001,0.000000e+000,,,,,,,,,,,,,,24,1,4.000000e+000,4.809570e-002,0.000000e+000,0,,0,
1687344761.585,,1.000000e+002,3.899628e+002,5.164594e-001,0.000000e+000,3,9.921823e-001,0.000000e+000,,,,,,,,,,,,,,24,1,4.000000e+000,2.420044e-002,0.000000e+000,0,,0,
1687344785.571,,1.000000e+002,3.899869e+002,5.165529e-001,0.000000e+000,3,9.924140e-001,0.000000e+000,,,,,,,,,,,,,,24,1,4.000000e+000,2.389526e-002,0.000000e+000,0,,0,
1687344809.722,,1.000000e+002,3.899388e+002,5.166726e-001,0.000000e+000,3,9.923518e-001,0.000000e+000,,,,,,,,,,,,,,24,1,4.000000e+000,2.163086e-001,0.000000e+000,0,,0,
1687344836.097,,1.000000e+002,3.900469e+002,5.163310e-001,0.000000e+000,3,9.921809e-001,0.000000e+000,,,,,,,,,,,,,,24,1,4.000000e+000,4.812622e-002,0.000000e+000,0,,0,
1687344886.992,,1.000000e+002,3.901312e+002,5.163612e-001,0.000000e+000,3,9.921729e-001,0.000000e+000,,,,,,,,,,,,,,24,1,4.000000e+000,2.407837e-002,0.000000e+000,0,,0,
1687344911.406,,1.000000e+002,3.899748e+002,5.165523e-001,0.000000e+000,3,9.921815e-001,0.000000e+000,,,,,,,,,,,,,,24,1,4.000000e+000,4.809570e-002,0.000000e+000,0,,0,
1687344935.921,,1.000000e+002,3.899868e+002,5.164918e-001,0.000000e+000,3,9.920880e-001,0.000000e+000,,,,,,,,,,,,,,24,1,4.000000e+000,2.164917e-001,0.000000e+000,0,,0,
1687344960.941,,1.000000e+002,3.899387e+002,5.163640e-001,0.000000e+000,3,9.919587e-001,0.000000e+000,,,,,,,,,,,,,,24,1,4.000000e+000,1.202087e-001,0.000000e+000,0,,0,
1687344986.402,,1.000000e+002,3.898666e+002,5.162310e-001,0.000000e+000,3,9.923620e-001,0.000000e+000,,,,,,,,,,,,,,24,1,4.000000e+000,1.202087e-001,0.000000e+000,0,,0,
1687345013.191,,1.000000e+002,3.899749e+002,5.163882e-001,0.000000e+000,3,9.920565e-001,0.000000e+000,,,,,,,,,,,,,,24,1,4.000000e+000,3.367004e-001,0.000000e+000,0,,0,
1687345036.956,,1.000000e+002,3.900950e+002,5.165138e-001,0.000000e+000,3,9.922677e-001,0.000000e+000,,,,,,,,,,,,,,24,1,4.000000e+000,9.628296e-002,0.000000e+000,0,,0,
1687345063.675,,1.000000e+002,3.899027e+002,5.163659e-001,0.000000e+000,3,9.922189e-001,0.000000e+000,,,,,,,,,,,,,,24,1,4.000000e+000,2.883911e-001,0.000000e+000,0,,0,
1687345087.247,,1.000000e+002,3.899267e+002,5.165910e-001,0.000000e+000,3,9.920222e-001,0.000000e+000,,,,,,,,,,,,,,24,1,4.000000e+000,1.441956e-001,0.000000e+000,0,,0,
1687345112.218,,1.000000e+002,3.898907e+002,5.164698e-001,0.000000e+000,3,9.921529e-001,0.000000e+000,,,,,,,,,,,,,,24,1,4.000000e+000,2.163086e-001,0.000000e+000,0,,0,
1687345138.056,,1.000000e+002,3.898426e+002,5.164387e-001,0.000000e+000,3,9.920443e-001,0.000000e+000,,,,,,,,,,,,,,24,1,4.000000e+000,2.401733e-002,0.000000e+000,0,,0,
1687345163.245,,1.000000e+002,3.899388e+002,5.162911e-001,0.000000e+000,3,9.924399e-001,0.000000e+000,,,,,,,,,,,,,,24,1,4.000000e+000,1.682739e-001,0.000000e+000,0,,0,
1687345187.542,,1.000000e+002,3.899147e+002,5.167119e-001,0.000000e+000,3,9.920844e-001,0.000000e+000,,,,,,,,,,,,,,24,1,4.000000e+000,2.164001e-001,0.000000e+000,0,,0,
1687345211.248,,1.000000e+002,3.898786e+002,5.165197e-001,0.000000e+000,3,9.920830e-001,0.000000e+000,,,,,,,,,,,,,,24,1,4.000000e+000,1.442261e-001,0.000000e+000,0,,0,
1687345237.625,,1.000000e+002,3.901312e+002,5.165692e-001,0.000000e+000,3,9.921852e-001,0.000000e+000,,,,,,,,,,,,,,24,1,4.000000e+000,2.407837e-002,0.000000e+000,0,,0,
1687345263.034,,1.000000e+002,3.899989e+002,5.165566e-001,0.000000e+000,3,9.919507e-001,0.000000e+000,,,,,,,,,,,,,,24,1,4.000000e+000,2.885742e-001,0.000000e+000,0,,0,
1687345286.684,,1.000000e+002,3.901552e+002,5.166379e-001,0.000000e+000,3,9.921229e-001,0.000000e+000,,,,,,,,,,,,,,24,1,4.000000e+000,2.410889e-002,0.000000e+000,0,,0,
1687345310.272,,1.000000e+002,3.900591e+002,5.166241e-001,0.000000e+000,3,9.920828e-001,0.000000e+000,,,,,,,,,,,,,,24,1,4.000000e+000,1.682739e-001,0.000000e+000,0,,0,
1687345337.053,,1.000000e+002,3.900350e+002,5.165110e-001,0.000000e+000,3,9.921563e-001,0.000000e+000,,,,,,,,,,,,,,24,1,4.000000e+000,1.201782e-001,0.000000e+000,0,,0,
1687345387.065,,1.000000e+002,3.899508e+002,5.165074e-001,0.000000e+000,3,9.921519e-001,0.000000e+000,,,,,,,,,,,,,,24,1,4.000000e+000,2.404175e-001,0.000000e+000,0,,0,
1687345412.948,,1.000000e+002,3.900831e+002,5.163697e-001,0.000000e+000,3,9.923427e-001,0.000000e+000,,,,,,,,,,,,,,24,1,4.000000e+000,2.407837e-002,0.000000e+000,0,,0,
1687345437.474,,1.000000e+002,3.899749e+002,5.165632e-001,0.000000e+000,3,9.922740e-001,0.000000e+000,,,,,,,,,,,,,,24,1,4.000000e+000,2.404785e-001,0.000000e+000,0,,0,
1687345462.476,,1.000000e+002,3.899387e+002,5.165189e-001,0.000000e+000,3,9.923350e-001,0.000000e+000,,,,,,,,,,,,,,24,1,4.000000e+000,2.401733e-002,0.000000e+000,0,,0,
1687345487.853,,1.000000e+002,3.900830e+002,5.165750e-001,0.000000e+000,3,9.920393e-001,0.000000e+000,,,,,,,,,,,,,,24,1,4.000000e+000,1.203003e-001,0.000000e+000,0,,0,
1687345512.915,,1.000000e+002,3.899628e+002,5.164900e-001,0.000000e+000,3,9.922464e-001,0.000000e+000,,,,,,,,,,,,,,24,1,4.000000e+000,1.683044e-001,0.000000e+000,0,,0,
1687345536.900,,1.000000e+002,3.900710e+002,5.165447e-001,0.000000e+000,3,9.922629e-001,0.000000e+000,,,,,,,,,,,,,,24,1,4.000000e+000,4.818726e-002,0.000000e+000,0,,0,
1687345562.816,,1.000000e+002,3.899749e+002,5.164420e-001,0.000000e+000,3,9.920241e-001,0.000000e+000,,,,,,,,,,,,,,24,1,4.000000e+000,0.000000e+000,0.000000e+000,0,,0,
1687345588.255,,1.000000e+002,3.899749e+002,5.165149e-001,0.000000e+000,3,9.921356e-001,0.000000e+000,,,,,,,,,,,,,,24,1,4.000000e+000,0.000000e+000,0.000000e+000,0,,0,
1687345615.695,,1.000000e+002,3.900830e+002,5.163426e-001,0.000000e+000,3,9.921781e-001,0.000000e+000,,,,,,,,,,,,,,24,1,4.000000e+000,1.203003e-001,0.000000e+000,0,,0,
1687345641.502,,1.000000e+002,3.899267e+002,5.163290e-001,0.000000e+000,3,9.919744e-001,0.000000e+000,,,,,,,,,,,,,,24,1,4.000000e+000,1.441956e-001,0.000000e+000,0,,0,
1687345667.832,,1.000000e+002,3.899508e+002,5.164620e-001,0.000000e+000,3,9.921570e-001,0.000000e+000,,,,,,,,,,,,,,24,1,4.000000e+000,2.404175e-001,0.000000e+000,0,,0,
1687345692.772,,1.000000e+002,3.897945e+002,5.164844e-001,0.000000e+000,3,9.920796e-001,0.000000e+000,,,,,,,,,,,,,,24,1,4.000000e+000,2.398682e-002,0.000000e+000,0,,0,
1687345718.295,,1.000000e+002,3.899508e+002,5.165144e-001,0.000000e+000,3,9.921031e-001,0.000000e+000,,,,,,,,,,,,,,24,1,4.000000e+000,3.366089e-001,0.000000e+000,0,,0,
1687345746.032,,1.000000e+002,3.900109e+002,5.162376e-001,0.000000e+000,3,9.919552e-001,0.000000e+000,,,,,,,,,,,,,,24,1,4.000000e+000,2.407837e-002,0.000000e+000,0,,0,
1687345772.432,,1.000000e+002,3.898907e+002,5.164482e-001,0.000000e+000,3,9.922196e-001,0.000000e+000,,,,,,,,,,,,,,24,1,4.000000e+000,2.163086e-001,0.000000e+000,0,,0,
1687345822.278,,1.000000e+002,3.899988e+002,5.164171e-001,0.000000e+000,3,9.922091e-001,0.000000e+000,,,,,,,,,,,,,,24,1,4.000000e+000,2.405090e-001,0.000000e+000,0,,0,
1687345846.379,,1.000000e+002,3.898666e+002,5.164051e-001,0.000000e+000,3,9.919170e-001,0.000000e+000,,,,,,,,,,,,,,24,1,4.000000e+000,7.199097e-002,0.000000e+000,0,,0,
1687345870.059,,1.000000e+002,3.899868e+002,5.163617e-001,0.000000e+000,3,9.921516e-001,0.000000e+000,,,,,,,,,,,,,,24,1,4.000000e+000,2.164917e-001,0.000000e+000,0,,0,
1687345895.398,,1.000000e+002,3.900109e+002,5.166205e-001,0.000000e+000,3,9.920279e-001,0.000000e+000,,,,,,,,,,,,,,24,1,4.000000e+000,7.199097e-002,0.000000e+000,0,,0,
1687345920.868,,1.000000e+002,3.900950e+002,5.164645e-001,0.000000e+000,3,9.921370e-001,0.000000e+000,,,,,,,,,,,,,,24,1,4.000000e+000,9.628296e-002,0.000000e+000,0,,0,
1687345944.887,,1.000000e+002,3.900229e+002,5.165178e-001,0.000000e+000,3,9.922032e-001,0.000000e+000,,,,,,,,,,,,,,24,1,4.000000e+000,4.809570e-002,0.000000e+000,0,,0,
1687345969.787,,1.000000e+002,3.900830e+002,5.164519e-001,0.000000e+000,3,9.920302e-001,0.000000e+000,,,,,,,,,,,,,,24,1,4.000000e+000,7.220459e-002,0.000000e+000,0,,0,
1687345994.430,,1.000000e+002,3.899508e+002,5.164187e-001,0.000000e+000,3,9.922130e-001,0.000000e+000,,,,,,,,,,,,,,24,1,4.000000e+000,3.366089e-001,0.000000e+000,0,,0,
1687346020.793,,1.000000e+002,3.900229e+002,5.165616e-001,0.000000e+000,3,9.921533e-001,0.000000e+000,,,,,,,,,,,,,,24,1,4.000000e+000,1.924133e-001,0.000000e+000,0,,0,
1687346044.762,,1.000000e+002,3.899988e+002,5.165267e-001,0.000000e+000,3,9.921044e-001,0.000000e+000,,,,,,,,,,,,,,24,1,4.000000e+000,2.405090e-001,0.000000e+000,0,,0,
1687346067.364,,1.000000e+002,3.899268e+002,5.167059e-001,0.000000e+000,3,9.920440e-001,0.000000e+000,,,,,,,,,,,,,,24,1,4.000000e+000,9.631348e-002,0.000000e+000,0,,0,
1687346092.571,,1.000000e+002,3.899748e+002,5.165423e-001,0.000000e+000,3,9.919894e-001,0.000000e+000,,,,,,,,,,,,,,24,1,4.000000e+000,1.924133e-001,0.000000e+000,0,,0,
1687346115.521,,1.000000e+002,3.900109e+002,5.166451e-001,0.000000e+000,3,9.920340e-001,0.000000e+000,,,,,,,,,,,,,,24,1,4.000000e+000,2.645874e-001,0.000000e+000,0,,0,
1687346139.615,,1.000000e+002,3.900349e+002,5.166264e-001,0.000000e+000,3,9.921672e-001,0.000000e+000,,,,,,,,,,,,,,24,1,4.000000e+000,7.220459e-002,0.000000e+000,0,,0,
1687346163.158,,1.000000e+002,3.899988e+002,5.166658e-001,0.000000e+000,3,9.920674e-001,0.000000e+000,,,,,,,,,,,,,,24,1,4.000000e+000,0.000000e+000,0.000000e+000,0,,0,
1687346187.743,,1.000000e+002,3.899387e+002,5.168025e-001,0.000000e+000,3,9.921913e-001,0.000000e+000,,,,,,,,,,,,,,24,1,4.000000e+000,1.202087e-001,0.000000e+000,0,,0,
1687346212.658,,1.000000e+002,3.898666e+002,5.165344e-001,0.000000e+000,3,9.921842e-001,0.000000e+000,,,,,,,,,,,,,,24,1,4.000000e+000,2.398682e-002,0.000000e+000,0,,0,
1687346238.919,,1.000000e+002,3.900710e+002,5.163307e-001,0.000000e+000,3,9.922122e-001,0.000000e+000,,,,,,,,,,,,,,24,1,4.000000e+000,4.818726e-002,0.000000e+000,0,,0,
1687346264.466,,1.000000e+002,3.900229e+002,5.165923e-001,0.000000e+000,3,9.920644e-001,0.000000e+000,,,,,,,,,,,,,,24,1,4.000000e+000,1.443787e-001,0.000000e+000,0,,0,
1687346288.365,,1.000000e+002,3.900470e+002,5.166363e-001,0.000000e+000,3,9.922545e-001,0.000000e+000,,,,,,,,,,,,,,24,1,4.000000e+000,1.441956e-001,0.000000e+000,0,,0,
1687346312.047,,1.000000e+002,3.899749e+002,5.166894e-001,0.000000e+000,3,9.922677e-001,0.000000e+000,,,,,,,,,,,,,,24,1,4.000000e+000,0.000000e+000,0.000000e+000,0,,0,
1687346339.266,,1.000000e+002,3.901191e+002,5.163139e-001,0.000000e+000,3,9.921300e-001,0.000000e+000,,,,,,,,,,,,,,24,1,4.000000e+000,1.445007e-001,0.000000e+000,0,,0,
1687346365.196,,1.000000e+002,3.901432e+002,5.164757e-001,0.000000e+000,3,9.923468e-001,0.000000e+000,,,,,,,,,,,,,,24,1,4.000000e+000,9.631348e-002,0.000000e+000,0,,0,
1687346389.285,,1.000000e+002,3.899868e+002,5.166343e-001,0.000000e+000,3,9.921541e-001,0.000000e+000,,,,,,,,,,,,,,24,1,4.000000e+000,7.217407e-002,0.000000e+000,0,,0,
1687346439.191,,1.000000e+002,3.900349e+002,5.164042e-001,0.000000e+000,3,9.921191e-001,0.000000e+000,,,,,,,,,,,,,,24,1,4.000000e+000,2.401733e-002,0.000000e+000,0,,0,
1687346464.233,,1.000000e+002,3.901794e+002,5.164890e-001,0.000000e+000,3,9.920982e-001,0.000000e+000,,,,,,,,,,,,,,24,1,4.000000e+000,2.410889e-002,0.000000e+000,0,,0,
1687346489.618,,1.000000e+002,3.900832e+002,5.164335e-001,0.000000e+000,3,9.920340e-001,0.000000e+000,,,,,,,,,,,,,,24,1,4.000000e+000,2.164917e-001,0.000000e+000,0,,0,