File: ZFC_FC/MPMS_Li0.6Al0.4 FC 10 Oe.dc.dat
[Header]
TITLE,MPMS DC Measurement
BYAPP,MPMS Measurement,2.1,Summary
FILEOPENTIME, 1687505566.319000 6/23/2023, 9:32:46 AM

INFO, APPNAME, MPMS MultiVu Application, Revision 1.60,  Build 081

INFO, NAME, Li0.6Al0.4Fe5O8
INFO, WEIGHT, 85.250
INFO, AREA, 0.000
INFO, LENGTH, 0.000
INFO, SHAPE,
INFO, COMMENT, cotton: 29.92 mg, capsule:40.26 mg
INFO, SEQUENCE FILE: ZFCF.seq


INFO, BACKGROUND DATA FILE:, None


STARTUPAXIS,X,4,LINEAR,AUTO,0.000000,0.000000
STARTUPAXIS,Y1,5,LINEAR,AUTO,0.000000,0.000000


STARTUPGROUP,Longitudinal
FIELDGROUP,Longitudinal,1,2,3,4,5,6,7,8,9,15,16,17,18,27,28
FIELDGROUP,Transverse,1,2,3,4,10,11,12,13,14,19,20,21,22,27,28

PLOT_APPEARANCE,ALL,HORZ_GRID_ON,VERT_GRID_ON,MARKERS_AND_LINES

[Data]
Time,Comment,Field (Oe),Temperature (K),Long Moment (emu),Long Scan Std Dev,Long Algorithm,Long Reg Fit,Long Percent Error (%),Trans Moment (emu),Trans Scan Std Dev,Trans Algorithm,Trans Reg Fit,Trans Percent Error (%),Long Moment [w/o ABS] (emu),Long Scan Std Dev [w/o ABS],Long Reg Fit [w/o ABS],Long Percent Error [w/o ABS] (%),Trans Moment [w/o ABS] (emu),Trans Scan Std Dev [w/o ABS],Trans Reg Fit [w/o ABS],Trans Percent Error [w/o ABS] (%),Points per Scan,Scans per Measurement,Scan Length (cm),Delta Temp (K),Rot Position (deg),Error,EC Comp. Running,Using ABS,
1687513464.488,,1.000000e+001,4.997587e+000,2.322566e-002,0.000000e+000,3,9.896343e-001,0.000000e+000,,,,,,,,,,,,,,24,1,4.000000e+000,1.163006e-003,0.000000e+000,0,,0,
1687513540.723,,1.000000e+001,1.259114e+001,2.322737e-002,0.000000e+000,3,9.898009e-001,0.000000e+000,,,,,,,,,,,,,,24,1,4.000000e+000,1.548611e+000,0.000000e+000,0,,0,
1687513586.528,,1.000000e+001,1.965805e+001,2.322719e-002,0.000000e+000,3,9.898235e-001,0.000000e+000,,,,,,,,,,,,,,24,1,4.000000e+000,2.272970e+000,0.000000e+000,0,,0,
1687513627.883,,1.000000e+001,2.627435e+001,2.323052e-002,0.000000e+000,3,9.897572e-001,0.000000e+000,,,,,,,,,,,,,,24,1,4.000000e+000,2.427679e+000,0.000000e+000,0,,0,
1687513667.141,,1.000000e+001,3.254461e+001,2.323072e-002,0.000000e+000,3,9.897801e-001,0.000000e+000,,,,,,,,,,,,,,24,1,4.000000e+000,2.619370e+000,0.000000e+000,0,,0,
1687513707.192,,1.000000e+001,3.913500e+001,2.323068e-002,0.000000e+000,3,9.897833e-001,0.000000e+000,,,,,,,,,,,,,,24,1,4.000000e+000,2.387600e+000,0.000000e+000,0,,0,
1687513747.200,,1.000000e+001,4.549815e+001,2.323131e-002,0.000000e+000,3,9.897904e-001,0.000000e+000,,,,,,,,,,,,,,24,1,4.000000e+000,2.232910e+000,0.000000e+000,0,,0,
1687513789.477,,1.000000e+001,5.234586e+001,2.323013e-002,0.000000e+000,3,9.898303e-001,0.000000e+000,,,,,,,,,,,,,,24,1,4.000000e+000,2.236759e+000,0.000000e+000,0,,0,
1687513829.500,,1.000000e+001,5.885011e+001,2.322915e-002,0.000000e+000,3,9.899526e-001,0.000000e+000,,,,,,,,,,,,,,24,1,4.000000e+000,2.835228e+000,0.000000e+000,0,,0,
1687513867.432,,1.000000e+001,6.507983e+001,2.322893e-002,0.000000e+000,3,9.899679e-001,0.000000e+000,,,,,,,,,,,,,,24,1,4.000000e+000,2.581642e+000,0.000000e+000,0,,0,
1687513908.036,,1.000000e+001,7.185278e+001,2.322747e-002,0.000000e+000,3,9.901009e-001,0.000000e+000,,,,,,,,,,,,,,24,1,4.000000e+000,2.528343e+000,0.000000e+000,0,,0,
1687513946.311,,1.000000e+001,7.832287e+001,2.322675e-002,0.000000e+000,3,9.900960e-001,0.000000e+000,,,,,,,,,,,,,,24,1,4.000000e+000,2.334930e+000,0.000000e+000,0,,0,
1687513987.211,,1.000000e+001,8.512337e+001,2.322498e-002,0.000000e+000,3,9.902470e-001,0.000000e+000,,,,,,,,,,,,,,24,1,4.000000e+000,2.434975e+000,0.000000e+000,0,,0,
1687514024.846,,1.000000e+001,9.153555e+001,2.322584e-002,0.000000e+000,3,9.902869e-001,0.000000e+000,,,,,,,,,,,,,,24,1,4.000000e+000,2.564491e+000,0.000000e+000,0,,0,
1687514066.286,,1.000000e+001,9.855183e+001,2.322626e-002,0.000000e+000,3,9.903127e-001,0.000000e+000,,,,,,,,,,,,,,24,1,4.000000e+000,2.513565e+000,0.000000e+000,0,,0,
1687514102.280,,1.000000e+001,1.045974e+002,2.322676e-002,0.000000e+000,3,9.903238e-001,0.000000e+000,,,,,,,,,,,,,,24,1,4.000000e+000,2.342102e+000,0.000000e+000,0,,0,
1687514140.165,,1.000000e+001,1.111447e+002,2.322827e-002,0.000000e+000,3,9.903311e-001,0.000000e+000,,,,,,,,,,,,,,24,1,4.000000e+000,2.614799e+000,0.000000e+000,0,,0,
1687514186.410,,1.000000e+001,1.188332e+002,2.323344e-002,0.000000e+000,3,9.902592e-001,0.000000e+000,,,,,,,,,,,,,,24,1,4.000000e+000,2.605400e+000,0.000000e+000,0,,0,
1687514218.138,,1.000000e+001,1.241625e+002,2.323229e-002,0.000000e+000,3,9.902332e-001,0.000000e+000,,,,,,,,,,,,,,24,1,4.000000e+000,2.503601e+000,0.000000e+000,0,,0,
1687514255.810,,1.000000e+001,1.305512e+002,2.323113e-002,0.000000e+000,3,9.902620e-001,0.000000e+000,,,,,,,,,,,,,,24,1,4.000000e+000,2.940598e+000,0.000000e+000,0,,0,
1687514296.165,,1.000000e+001,1.374716e+002,2.322805e-002,0.000000e+000,3,9.903243e-001,0.000000e+000,,,,,,,,,,,,,,24,1,4.000000e+000,2.414597e+000,0.000000e+000,0,,0,
1687514333.893,,1.000000e+001,1.437216e+002,2.322462e-002,0.000000e+000,3,9.903896e-001,0.000000e+000,,,,,,,,,,,,,,24,1,4.000000e+000,2.695694e+000,0.000000e+000,0,,0,
1687514374.459,,1.000000e+001,1.503928e+002,2.322024e-002,0.000000e+000,3,9.904895e-001,0.000000e+000,,,,,,,,,,,,,,24,1,4.000000e+000,2.695801e+000,0.000000e+000,0,,0,
1687514411.134,,1.000000e+001,1.567930e+002,2.321566e-002,0.000000e+000,3,9.904500e-001,0.000000e+000,,,,,,,,,,,,,,24,1,4.000000e+000,2.547302e+000,0.000000e+000,0,,0,
1687514452.026,,1.000000e+001,1.634789e+002,2.321060e-002,0.000000e+000,3,9.906061e-001,0.000000e+000,,,,,,,,,,,,,,24,1,4.000000e+000,2.800507e+000,0.000000e+000,0,,0,
1687514488.942,,1.000000e+001,1.698401e+002,2.320670e-002,0.000000e+000,3,9.906119e-001,0.000000e+000,,,,,,,,,,,,,,24,1,4.000000e+000,2.487289e+000,0.000000e+000,0,,0,
1687514530.533,,1.000000e+001,1.767972e+002,2.319983e-002,0.000000e+000,3,9.907143e-001,0.000000e+000,,,,,,,,,,,,,,24,1,4.000000e+000,2.579391e+000,0.000000e+000,0,,0,
1687514565.300,,1.000000e+001,1.824604e+002,2.319230e-002,0.000000e+000,3,9.907668e-001,0.000000e+000,,,,,,,,,,,,,,24,1,4.000000e+000,2.520309e+000,0.000000e+000,0,,0,
1687514607.738,,1.000000e+001,1.897194e+002,2.318744e-002,0.000000e+000,3,9.907287e-001,0.000000e+000,,,,,,,,,,,,,,24,1,4.000000e+000,2.706497e+000,0.000000e+000,0,,0,
1687514645.282,,1.000000e+001,1.959836e+002,2.318075e-002,0.000000e+000,3,9.907714e-001,0.000000e+000,,,,,,,,,,,,,,24,1,4.000000e+000,2.567108e+000,0.000000e+000,0,,0,
1687514684.063,,1.000000e+001,2.024606e+002,2.317347e-002,0.000000e+000,3,9.908000e-001,0.000000e+000,,,,,,,,,,,,,,24,1,4.000000e+000,2.534698e+000,0.000000e+000,0,,0,
1687514724.254,,1.000000e+001,2.091931e+002,2.316605e-002,0.000000e+000,3,9.908059e-001,0.000000e+000,,,,,,,,,,,,,,24,1,4.000000e+000,2.614899e+000,0.000000e+000,0,,0,
1687514762.366,,1.000000e+001,2.153594e+002,2.315928e-002,0.000000e+000,3,9.909393e-001,0.000000e+000,,,,,,,,,,,,,,24,1,4.000000e+000,2.743790e+000,0.000000e+000,0,,0,
1687514802.602,,1.000000e+001,2.223487e+002,2.315333e-002,0.000000e+000,3,9.908872e-001,0.000000e+000,,,,,,,,,,,,,,24,1,4.000000e+000,2.358597e+000,0.000000e+000,0,,0,
1687514839.200,,1.000000e+001,2.285410e+002,2.314436e-002,0.000000e+000,3,9.909915e-001,0.000000e+000,,,,,,,,,,,,,,24,1,4.000000e+000,2.446198e+000,0.000000e+000,0,,0,
1687514879.661,,1.000000e+001,2.350355e+002,2.313801e-002,0.000000e+000,3,9.910039e-001,0.000000e+000,,,,,,,,,,,,,,24,1,4.000000e+000,2.642197e+000,0.000000e+000,0,,0,
1687514916.938,,1.000000e+001,2.413686e+002,2.313667e-002,0.000000e+000,3,9.909529e-001,0.000000e+000,,,,,,,,,,,,,,24,1,4.000000e+000,2.728989e+000,0.000000e+000,0,,0,
1687514959.376,,1.000000e+001,2.484309e+002,2.313042e-002,0.000000e+000,3,9.909577e-001,0.000000e+000,,,,,,,,,,,,,,24,1,4.000000e+000,2.658798e+000,0.000000e+000,0,,0,
1687514997.286,,1.000000e+001,2.547408e+002,2.312262e-002,0.000000e+000,3,9.909911e-001,0.000000e+000,,,,,,,,,,,,,,24,1,4.000000e+000,2.681992e+000,0.000000e+000,0,,0,
1687515035.911,,1.000000e+001,2.611823e+002,2.311481e-002,0.000000e+000,3,9.910690e-001,0.000000e+000,,,,,,,,,,,,,,24,1,4.000000e+000,2.909576e+000,0.000000e+000,0,,0,
1687515077.321,,1.000000e+001,2.679980e+002,2.310848e-002,0.000000e+000,3,9.911512e-001,0.000000e+000,,,,,,,,,,,,,,24,1,4.000000e+000,2.659027e+000,0.000000e+000,0,,0,
1687515112.266,,1.000000e+001,2.739267e+002,2.310689e-002,0.000000e+000,3,9.911064e-001,0.000000e+000,,,,,,,,,,,,,,24,1,4.000000e+000,2.446777e+000,0.000000e+000,0,,0,
1687515156.145,,1.000000e+001,2.810247e+002,2.311656e-002,0.000000e+000,3,9.909180e-001,0.000000e+000,,,,,,,,,,,,,,24,1,4.000000e+000,2.700104e+000,0.000000e+000,0,,0,
1687515190.822,,1.000000e+001,2.872227e+002,2.312071e-002,0.000000e+000,3,9.907634e-001,0.000000e+000,,,,,,,,,,,,,,24,1,4.000000e+000,2.428894e+000,0.000000e+000,0,,0,
1687515238.027,,1.000000e+001,2.948168e+002,2.312596e-002,0.000000e+000,3,9.906579e-001,0.000000e+000,,,,,,,,,,,,,,24,1,4.000000e+000,2.628326e+000,0.000000e+000,0,,0,
1687515271.542,,1.000000e+001,3.005154e+002,2.312751e-002,0.000000e+000,3,9.906676e-001,0.000000e+000,,,,,,,,,,,,,,24,1,4.000000e+000,2.261719e+000,0.000000e+000,0,,0,
1687515309.046,,1.000000e+001,3.069917e+002,2.312888e-002,0.000000e+000,3,9.906185e-001,0.000000e+000,,,,,,,,,,,,,,24,1,4.000000e+000,2.351624e+000,0.000000e+000,0,,0,
1687515356.486,,1.000000e+001,3.146907e+002,2.313348e-002,0.000000e+000,3,9.905732e-001,0.000000e+000,,,,,,,,,,,,,,24,1,4.000000e+000,2.523621e+000,0.000000e+000,0,,0,
1687515385.381,,1.000000e+001,3.196473e+002,2.313578e-002,0.000000e+000,3,9.905530e-001,0.000000e+000,,,,,,,,,,,,,,24,1,4.000000e+000,2.098694e+000,0.000000e+000,0,,0,
1687515428.514,,1.000000e+001,3.265505e+002,2.314123e-002,0.000000e+000,3,9.905208e-001,0.000000e+000,,,,,,,,,,,,,,24,1,4.000000e+000,2.676300e+000,0.000000e+000,0,,0,
1687515465.448,,1.000000e+001,3.327722e+002,2.314603e-002,0.000000e+000,3,9.905096e-001,0.000000e+000,,,,,,,,,,,,,,24,1,4.000000e+000,2.886627e+000,0.000000e+000,0,,0,
1687515505.802,,1.000000e+001,3.395948e+002,2.315174e-002,0.000000e+000,3,9.905686e-001,0.000000e+000,,,,,,,,,,,,,,24,1,4.000000e+000,2.616302e+000,0.000000e+000,0,,0,
1687515543.708,,1.000000e+001,3.458858e+002,2.316224e-002,0.000000e+000,3,9.906010e-001,0.000000e+000,,,,,,,,,,,,,,24,1,4.000000e+000,2.382385e+000,0.000000e+000,0,,0,
1687515586.376,,1.000000e+001,3.527824e+002,2.317462e-002,0.000000e+000,3,9.904848e-001,0.000000e+000,,,,,,,,,,,,,,24,1,4.000000e+000,2.835419e+000,0.000000e+000,0,,0,
1687515622.042,,1.000000e+001,3.588624e+002,2.318840e-002,0.000000e+000,3,9.906207e-001,0.000000e+000,,,,,,,,,,,,,,24,1,4.000000e+000,2.472412e+000,0.000000e+000,0,,0,
1687515660.741,,1.000000e+001,3.653776e+002,2.321038e-002,0.000000e+000,3,9.905474e-001,0.000000e+000,,,,,,,,,,,,,,24,1,4.000000e+000,2.629700e+000,0.000000e+000,0,,0,
1687515702.690,,1.000000e+001,3.723159e+002,2.323434e-002,0.000000e+000,3,9.904615e-001,0.000000e+000,,,,,,,,,,,,,,24,1,4.000000e+000,2.231110e+000,0.000000e+000,0,,0,
1687515738.389,,1.000000e+001,3.782869e+002,2.325852e-002,0.000000e+000,3,9.905767e-001,0.000000e+000,,,,,,,,,,,,,,24,1,4.000000e+000,2.599091e+000,0.000000e+000,0,,0,
1687515781.694,,1.000000e+001,3.853238e+002,2.328941e-002,0.000000e+000,3,9.905137e-001,0.000000e+000,,,,,,,,,,,,,,24,1,4.000000e+000,2.910187e+000,0.000000e+000,0,,0,
1687516072.421,,1.000000e+001,3.899387e+002,2.330926e-002,0.000000e+000,3,9.896570e-001,0.000000e+000,,,,,,,,,,,,,,24,1,4.000000e+000,2.401733e-002,0.000000e+000,0,,0,