File: ZFC_FC/MPMS_Li0.5Al0.5 ZFC 10 Oe.dc.dat
[Header]
TITLE,MPMS DC Measurement
BYAPP,MPMS Measurement,2.1,Summary
FILEOPENTIME, 1687364009.333000 6/21/2023, 6:13:29 PM

INFO, APPNAME, MPMS MultiVu Application, Revision 1.60,  Build 081

INFO, NAME, Li0.5Al0.5Fe5O8
INFO, WEIGHT, 84.430
INFO, AREA, 0.000
INFO, LENGTH, 0.000
INFO, SHAPE,
INFO, COMMENT, cotton: 15.1 mg, capsule:39.07 mg
INFO, SEQUENCE FILE: ZFCF.seq


INFO, BACKGROUND DATA FILE:, None


STARTUPAXIS,X,4,LINEAR,AUTO,0.000000,0.000000
STARTUPAXIS,Y1,5,LINEAR,AUTO,0.000000,0.000000


STARTUPGROUP,Longitudinal
FIELDGROUP,Longitudinal,1,2,3,4,5,6,7,8,9,15,16,17,18,27,28
FIELDGROUP,Transverse,1,2,3,4,10,11,12,13,14,19,20,21,22,27,28

PLOT_APPEARANCE,ALL,HORZ_GRID_ON,VERT_GRID_ON,MARKERS_AND_LINES

[Data]
Time,Comment,Field (Oe),Temperature (K),Long Moment (emu),Long Scan Std Dev,Long Algorithm,Long Reg Fit,Long Percent Error (%),Trans Moment (emu),Trans Scan Std Dev,Trans Algorithm,Trans Reg Fit,Trans Percent Error (%),Long Moment [w/o ABS] (emu),Long Scan Std Dev [w/o ABS],Long Reg Fit [w/o ABS],Long Percent Error [w/o ABS] (%),Trans Moment [w/o ABS] (emu),Trans Scan Std Dev [w/o ABS],Trans Reg Fit [w/o ABS],Trans Percent Error [w/o ABS] (%),Points per Scan,Scans per Measurement,Scan Length (cm),Delta Temp (K),Rot Position (deg),Error,EC Comp. Running,Using ABS,
1687364100.159,,1.000000e+001,1.474908e+001,7.817598e-003,0.000000e+000,3,9.958825e-001,0.000000e+000,,,,,,,,,,,,,,24,1,4.000000e+000,2.297920e+000,0.000000e+000,0,,0,
1687364118.888,,1.000000e+001,1.767893e+001,8.176853e-003,0.000000e+000,3,9.959532e-001,0.000000e+000,,,,,,,,,,,,,,24,1,4.000000e+000,2.436390e+000,0.000000e+000,0,,0,
1687364137.615,,1.000000e+001,2.070139e+001,8.536197e-003,0.000000e+000,3,9.961435e-001,0.000000e+000,,,,,,,,,,,,,,24,1,4.000000e+000,2.398859e+000,0.000000e+000,0,,0,
1687364156.492,,1.000000e+001,2.359549e+001,8.924915e-003,0.000000e+000,3,9.962552e-001,0.000000e+000,,,,,,,,,,,,,,24,1,4.000000e+000,2.794910e+000,0.000000e+000,0,,0,
1687364174.556,,1.000000e+001,2.676923e+001,9.339130e-003,0.000000e+000,3,9.963420e-001,0.000000e+000,,,,,,,,,,,,,,24,1,4.000000e+000,2.583858e+000,0.000000e+000,0,,0,
1687364191.728,,1.000000e+001,2.955797e+001,9.731006e-003,0.000000e+000,3,9.964697e-001,0.000000e+000,,,,,,,,,,,,,,24,1,4.000000e+000,2.033661e+000,0.000000e+000,0,,0,
1687364210.462,,1.000000e+001,3.246611e+001,1.012306e-002,0.000000e+000,3,9.964266e-001,0.000000e+000,,,,,,,,,,,,,,24,1,4.000000e+000,2.584620e+000,0.000000e+000,0,,0,
1687364228.243,,1.000000e+001,3.531036e+001,1.056629e-002,0.000000e+000,3,9.965025e-001,0.000000e+000,,,,,,,,,,,,,,24,1,4.000000e+000,2.194172e+000,0.000000e+000,0,,0,
1687364245.841,,1.000000e+001,3.823807e+001,1.100112e-002,0.000000e+000,3,9.966599e-001,0.000000e+000,,,,,,,,,,,,,,24,1,4.000000e+000,2.366772e+000,0.000000e+000,0,,0,
1687364264.341,,1.000000e+001,4.118979e+001,1.146752e-002,0.000000e+000,3,9.967270e-001,0.000000e+000,,,,,,,,,,,,,,24,1,4.000000e+000,2.300346e+000,0.000000e+000,0,,0,
1687364282.919,,1.000000e+001,4.411021e+001,1.197566e-002,0.000000e+000,3,9.967477e-001,0.000000e+000,,,,,,,,,,,,,,24,1,4.000000e+000,2.623329e+000,0.000000e+000,0,,0,
1687364302.154,,1.000000e+001,4.715988e+001,1.250921e-002,0.000000e+000,3,9.968449e-001,0.000000e+000,,,,,,,,,,,,,,24,1,4.000000e+000,2.568241e+000,0.000000e+000,0,,0,
1687364321.158,,1.000000e+001,5.029794e+001,1.307181e-002,0.000000e+000,3,9.969809e-001,0.000000e+000,,,,,,,,,,,,,,24,1,4.000000e+000,2.679489e+000,0.000000e+000,0,,0,
1687364338.587,,1.000000e+001,5.331181e+001,1.366149e-002,0.000000e+000,3,9.971559e-001,0.000000e+000,,,,,,,,,,,,,,24,1,4.000000e+000,2.405369e+000,0.000000e+000,0,,0,
1687364356.447,,1.000000e+001,5.617236e+001,1.422963e-002,0.000000e+000,3,9.972630e-001,0.000000e+000,,,,,,,,,,,,,,24,1,4.000000e+000,2.394920e+000,0.000000e+000,0,,0,
1687364375.368,,1.000000e+001,5.914288e+001,1.485521e-002,0.000000e+000,3,9.973584e-001,0.000000e+000,,,,,,,,,,,,,,24,1,4.000000e+000,2.647350e+000,0.000000e+000,0,,0,
1687364394.552,,1.000000e+001,6.225555e+001,1.552118e-002,0.000000e+000,3,9.974201e-001,0.000000e+000,,,,,,,,,,,,,,24,1,4.000000e+000,2.637310e+000,0.000000e+000,0,,0,
1687364412.338,,1.000000e+001,6.540137e+001,1.617713e-002,0.000000e+000,3,9.974555e-001,0.000000e+000,,,,,,,,,,,,,,24,1,4.000000e+000,2.542587e+000,0.000000e+000,0,,0,
1687364449.809,,1.000000e+001,7.149644e+001,1.754498e-002,0.000000e+000,3,9.976081e-001,0.000000e+000,,,,,,,,,,,,,,24,1,4.000000e+000,2.697952e+000,0.000000e+000,0,,0,
1687364468.483,,1.000000e+001,7.458673e+001,1.824042e-002,0.000000e+000,3,9.976191e-001,0.000000e+000,,,,,,,,,,,,,,24,1,4.000000e+000,2.359840e+000,0.000000e+000,0,,0,
1687364487.655,,1.000000e+001,7.771538e+001,1.890120e-002,0.000000e+000,3,9.976427e-001,0.000000e+000,,,,,,,,,,,,,,24,1,4.000000e+000,2.715012e+000,0.000000e+000,0,,0,
1687364505.266,,1.000000e+001,8.078102e+001,1.954020e-002,0.000000e+000,3,9.976712e-001,0.000000e+000,,,,,,,,,,,,,,24,1,4.000000e+000,2.447823e+000,0.000000e+000,0,,0,
1687364524.291,,1.000000e+001,8.397552e+001,2.016180e-002,0.000000e+000,3,9.977161e-001,0.000000e+000,,,,,,,,,,,,,,24,1,4.000000e+000,2.274223e+000,0.000000e+000,0,,0,
1687364543.143,,1.000000e+001,8.716322e+001,2.073358e-002,0.000000e+000,3,9.977961e-001,0.000000e+000,,,,,,,,,,,,,,24,1,4.000000e+000,2.446938e+000,0.000000e+000,0,,0,
1687364560.131,,1.000000e+001,9.007675e+001,2.122572e-002,0.000000e+000,3,9.978028e-001,0.000000e+000,,,,,,,,,,,,,,24,1,4.000000e+000,2.412666e+000,0.000000e+000,0,,0,
1687364579.530,,1.000000e+001,9.336453e+001,2.173129e-002,0.000000e+000,3,9.977722e-001,0.000000e+000,,,,,,,,,,,,,,24,1,4.000000e+000,2.903641e+000,0.000000e+000,0,,0,
1687364597.405,,1.000000e+001,9.647720e+001,2.219770e-002,0.000000e+000,3,9.978441e-001,0.000000e+000,,,,,,,,,,,,,,24,1,4.000000e+000,2.393074e+000,0.000000e+000,0,,0,
1687364615.108,,1.000000e+001,9.941469e+001,2.261177e-002,0.000000e+000,3,9.978485e-001,0.000000e+000,,,,,,,,,,,,,,24,1,4.000000e+000,2.538223e+000,0.000000e+000,0,,0,
1687364633.955,,1.000000e+001,1.024228e+002,2.300086e-002,0.000000e+000,3,9.979011e-001,0.000000e+000,,,,,,,,,,,,,,24,1,4.000000e+000,2.827599e+000,0.000000e+000,0,,0,
1687364652.737,,1.000000e+001,1.056087e+002,2.338364e-002,0.000000e+000,3,9.978554e-001,0.000000e+000,,,,,,,,,,,,,,24,1,4.000000e+000,2.663696e+000,0.000000e+000,0,,0,
1687364671.674,,1.000000e+001,1.088147e+002,2.372005e-002,0.000000e+000,3,9.977888e-001,0.000000e+000,,,,,,,,,,,,,,24,1,4.000000e+000,2.812599e+000,0.000000e+000,0,,0,
1687364689.760,,1.000000e+001,1.118341e+002,2.401909e-002,0.000000e+000,3,9.978082e-001,0.000000e+000,,,,,,,,,,,,,,24,1,4.000000e+000,2.626198e+000,0.000000e+000,0,,0,
1687364709.184,,1.000000e+001,1.152136e+002,2.430038e-002,0.000000e+000,3,9.978102e-001,0.000000e+000,,,,,,,,,,,,,,24,1,4.000000e+000,2.916794e+000,0.000000e+000,0,,0,
1687364727.991,,1.000000e+001,1.184671e+002,2.457696e-002,0.000000e+000,3,9.978666e-001,0.000000e+000,,,,,,,,,,,,,,24,1,4.000000e+000,2.620102e+000,0.000000e+000,0,,0,
1687364747.272,,1.000000e+001,1.216826e+002,2.480379e-002,0.000000e+000,3,9.979212e-001,0.000000e+000,,,,,,,,,,,,,,24,1,4.000000e+000,2.623001e+000,0.000000e+000,0,,0,
1687364765.665,,1.000000e+001,1.248705e+002,2.501403e-002,0.000000e+000,3,9.979853e-001,0.000000e+000,,,,,,,,,,,,,,24,1,4.000000e+000,2.674301e+000,0.000000e+000,0,,0,
1687364784.642,,1.000000e+001,1.280025e+002,2.521365e-002,0.000000e+000,3,9.979548e-001,0.000000e+000,,,,,,,,,,,,,,24,1,4.000000e+000,2.657600e+000,0.000000e+000,0,,0,
1687364802.630,,1.000000e+001,1.311379e+002,2.537652e-002,0.000000e+000,3,9.979038e-001,0.000000e+000,,,,,,,,,,,,,,24,1,4.000000e+000,2.607193e+000,0.000000e+000,0,,0,
1687364821.857,,1.000000e+001,1.343141e+002,2.554153e-002,0.000000e+000,3,9.978258e-001,0.000000e+000,,,,,,,,,,,,,,24,1,4.000000e+000,2.721603e+000,0.000000e+000,0,,0,
1687364840.007,,1.000000e+001,1.374697e+002,2.568298e-002,0.000000e+000,3,9.978446e-001,0.000000e+000,,,,,,,,,,,,,,24,1,4.000000e+000,2.572510e+000,0.000000e+000,0,,0,
1687364858.298,,1.000000e+001,1.405383e+002,2.582202e-002,0.000000e+000,3,9.979075e-001,0.000000e+000,,,,,,,,,,,,,,24,1,4.000000e+000,2.546906e+000,0.000000e+000,0,,0,
1687364877.228,,1.000000e+001,1.435531e+002,2.594977e-002,0.000000e+000,3,9.979588e-001,0.000000e+000,,,,,,,,,,,,,,24,1,4.000000e+000,2.519806e+000,0.000000e+000,0,,0,
1687364895.329,,1.000000e+001,1.466551e+002,2.605969e-002,0.000000e+000,3,9.979684e-001,0.000000e+000,,,,,,,,,,,,,,24,1,4.000000e+000,2.392197e+000,0.000000e+000,0,,0,
1687364913.986,,1.000000e+001,1.499117e+002,2.616965e-002,0.000000e+000,3,9.979479e-001,0.000000e+000,,,,,,,,,,,,,,24,1,4.000000e+000,2.547699e+000,0.000000e+000,0,,0,
1687364931.927,,1.000000e+001,1.528091e+002,2.626619e-002,0.000000e+000,3,9.979563e-001,0.000000e+000,,,,,,,,,,,,,,24,1,4.000000e+000,2.347702e+000,0.000000e+000,0,,0,
1687364951.138,,1.000000e+001,1.559949e+002,2.636496e-002,0.000000e+000,3,9.979524e-001,0.000000e+000,,,,,,,,,,,,,,24,1,4.000000e+000,2.642593e+000,0.000000e+000,0,,0,
1687364969.786,,1.000000e+001,1.590678e+002,2.645476e-002,0.000000e+000,3,9.979123e-001,0.000000e+000,,,,,,,,,,,,,,24,1,4.000000e+000,2.794907e+000,0.000000e+000,0,,0,
1687364988.310,,1.000000e+001,1.622917e+002,2.654086e-002,0.000000e+000,3,9.979180e-001,0.000000e+000,,,,,,,,,,,,,,24,1,4.000000e+000,2.533310e+000,0.000000e+000,0,,0,
1687365007.775,,1.000000e+001,1.654771e+002,2.663063e-002,0.000000e+000,3,9.978852e-001,0.000000e+000,,,,,,,,,,,,,,24,1,4.000000e+000,2.626007e+000,0.000000e+000,0,,0,
1687365026.665,,1.000000e+001,1.688537e+002,2.671409e-002,0.000000e+000,3,9.978619e-001,0.000000e+000,,,,,,,,,,,,,,24,1,4.000000e+000,2.780701e+000,0.000000e+000,0,,0,
1687365045.236,,1.000000e+001,1.718986e+002,2.679766e-002,0.000000e+000,3,9.978987e-001,0.000000e+000,,,,,,,,,,,,,,24,1,4.000000e+000,2.751205e+000,0.000000e+000,0,,0,
1687365064.175,,1.000000e+001,1.748324e+002,2.688098e-002,0.000000e+000,3,9.979391e-001,0.000000e+000,,,,,,,,,,,,,,24,1,4.000000e+000,2.770508e+000,0.000000e+000,0,,0,
1687365083.255,,1.000000e+001,1.781105e+002,2.696405e-002,0.000000e+000,3,9.978867e-001,0.000000e+000,,,,,,,,,,,,,,24,1,4.000000e+000,2.554398e+000,0.000000e+000,0,,0,
1687365101.312,,1.000000e+001,1.812417e+002,2.704052e-002,0.000000e+000,3,9.977906e-001,0.000000e+000,,,,,,,,,,,,,,24,1,4.000000e+000,2.434906e+000,0.000000e+000,0,,0,
1687365120.249,,1.000000e+001,1.844348e+002,2.712192e-002,0.000000e+000,3,9.977869e-001,0.000000e+000,,,,,,,,,,,,,,24,1,4.000000e+000,2.633392e+000,0.000000e+000,0,,0,
1687365138.796,,1.000000e+001,1.874705e+002,2.720249e-002,0.000000e+000,3,9.977819e-001,0.000000e+000,,,,,,,,,,,,,,24,1,4.000000e+000,2.464401e+000,0.000000e+000,0,,0,
1687365156.072,,1.000000e+001,1.904103e+002,2.728001e-002,0.000000e+000,3,9.978391e-001,0.000000e+000,,,,,,,,,,,,,,24,1,4.000000e+000,2.085007e+000,0.000000e+000,0,,0,
1687365174.597,,1.000000e+001,1.935370e+002,2.735761e-002,0.000000e+000,3,9.978583e-001,0.000000e+000,,,,,,,,,,,,,,24,1,4.000000e+000,2.778900e+000,0.000000e+000,0,,0,
1687365193.120,,1.000000e+001,1.964709e+002,2.744002e-002,0.000000e+000,3,9.978568e-001,0.000000e+000,,,,,,,,,,,,,,24,1,4.000000e+000,2.766693e+000,0.000000e+000,0,,0,
1687365211.279,,1.000000e+001,1.996945e+002,2.752372e-002,0.000000e+000,3,9.978032e-001,0.000000e+000,,,,,,,,,,,,,,24,1,4.000000e+000,2.302307e+000,0.000000e+000,0,,0,
1687365229.788,,1.000000e+001,2.026660e+002,2.760589e-002,0.000000e+000,3,9.977223e-001,0.000000e+000,,,,,,,,,,,,,,24,1,4.000000e+000,2.616394e+000,0.000000e+000,0,,0,
1687365248.038,,1.000000e+001,2.056236e+002,2.769016e-002,0.000000e+000,3,9.977251e-001,0.000000e+000,,,,,,,,,,,,,,24,1,4.000000e+000,2.675003e+000,0.000000e+000,0,,0,
1687365266.558,,1.000000e+001,2.088557e+002,2.778001e-002,0.000000e+000,3,9.978034e-001,0.000000e+000,,,,,,,,,,,,,,24,1,4.000000e+000,2.464294e+000,0.000000e+000,0,,0,
1687365285.831,,1.000000e+001,2.120205e+002,2.787399e-002,0.000000e+000,3,9.978969e-001,0.000000e+000,,,,,,,,,,,,,,24,1,4.000000e+000,2.501785e+000,0.000000e+000,0,,0,
1687365303.347,,1.000000e+001,2.151167e+002,2.796240e-002,0.000000e+000,3,9.978743e-001,0.000000e+000,,,,,,,,,,,,,,24,1,4.000000e+000,2.443207e+000,0.000000e+000,0,,0,
1687365322.589,,1.000000e+001,2.181346e+002,2.805475e-002,0.000000e+000,3,9.979171e-001,0.000000e+000,,,,,,,,,,,,,,24,1,4.000000e+000,2.295502e+000,0.000000e+000,0,,0,
1687365340.536,,1.000000e+001,2.211764e+002,2.815064e-002,0.000000e+000,3,9.979203e-001,0.000000e+000,,,,,,,,,,,,,,24,1,4.000000e+000,2.531906e+000,0.000000e+000,0,,0,
1687365359.288,,1.000000e+001,2.243513e+002,2.824850e-002,0.000000e+000,3,9.978929e-001,0.000000e+000,,,,,,,,,,,,,,24,1,4.000000e+000,2.742508e+000,0.000000e+000,0,,0,
1687365378.132,,1.000000e+001,2.274973e+002,2.834518e-002,0.000000e+000,3,9.979454e-001,0.000000e+000,,,,,,,,,,,,,,24,1,4.000000e+000,2.664795e+000,0.000000e+000,0,,0,
1687365396.898,,1.000000e+001,2.304922e+002,2.844763e-002,0.000000e+000,3,9.979821e-001,0.000000e+000,,,,,,,,,,,,,,24,1,4.000000e+000,2.790192e+000,0.000000e+000,0,,0,
1687365414.635,,1.000000e+001,2.336223e+002,2.854954e-002,0.000000e+000,3,9.979436e-001,0.000000e+000,,,,,,,,,,,,,,24,1,4.000000e+000,2.505096e+000,0.000000e+000,0,,0,
1687365434.338,,1.000000e+001,2.367826e+002,2.865323e-002,0.000000e+000,3,9.979225e-001,0.000000e+000,,,,,,,,,,,,,,24,1,4.000000e+000,2.672012e+000,0.000000e+000,0,,0,
1687365453.373,,1.000000e+001,2.398885e+002,2.876187e-002,0.000000e+000,3,9.979759e-001,0.000000e+000,,,,,,,,,,,,,,24,1,4.000000e+000,2.909393e+000,0.000000e+000,0,,0,
1687365470.998,,1.000000e+001,2.428984e+002,2.886708e-002,0.000000e+000,3,9.979993e-001,0.000000e+000,,,,,,,,,,,,,,24,1,4.000000e+000,2.517502e+000,0.000000e+000,0,,0,
1687365490.084,,1.000000e+001,2.461314e+002,2.897745e-002,0.000000e+000,3,9.979656e-001,0.000000e+000,,,,,,,,,,,,,,24,1,4.000000e+000,2.862900e+000,0.000000e+000,0,,0,
1687365507.438,,1.000000e+001,2.491152e+002,2.908378e-002,0.000000e+000,3,9.979268e-001,0.000000e+000,,,,,,,,,,,,,,24,1,4.000000e+000,2.405807e+000,0.000000e+000,0,,0,
1687365527.469,,1.000000e+001,2.522578e+002,2.920410e-002,0.000000e+000,3,9.979716e-001,0.000000e+000,,,,,,,,,,,,,,24,1,4.000000e+000,2.817307e+000,0.000000e+000,0,,0,
1687365545.758,,1.000000e+001,2.554597e+002,2.932324e-002,0.000000e+000,3,9.979687e-001,0.000000e+000,,,,,,,,,,,,,,24,1,4.000000e+000,2.496201e+000,0.000000e+000,0,,0,
1687365565.588,,1.000000e+001,2.586677e+002,2.944210e-002,0.000000e+000,3,9.980370e-001,0.000000e+000,,,,,,,,,,,,,,24,1,4.000000e+000,2.803925e+000,0.000000e+000,0,,0,
1687365585.200,,1.000000e+001,2.619988e+002,2.957715e-002,0.000000e+000,3,9.980686e-001,0.000000e+000,,,,,,,,,,,,,,24,1,4.000000e+000,2.422089e+000,0.000000e+000,0,,0,
1687365603.075,,1.000000e+001,2.650308e+002,2.969881e-002,0.000000e+000,3,9.980090e-001,0.000000e+000,,,,,,,,,,,,,,24,1,4.000000e+000,2.512299e+000,0.000000e+000,0,,0,
1687365621.194,,1.000000e+001,2.679977e+002,2.982087e-002,0.000000e+000,3,9.979462e-001,0.000000e+000,,,,,,,,,,,,,,24,1,4.000000e+000,2.592804e+000,0.000000e+000,0,,0,
1687365639.602,,1.000000e+001,2.711906e+002,2.995828e-002,0.000000e+000,3,9.979638e-001,0.000000e+000,,,,,,,,,,,,,,24,1,4.000000e+000,2.340302e+000,0.000000e+000,0,,0,
1687365658.110,,1.000000e+001,2.742112e+002,3.008351e-002,0.000000e+000,3,9.980243e-001,0.000000e+000,,,,,,,,,,,,,,24,1,4.000000e+000,2.741089e+000,0.000000e+000,0,,0,
1687365675.831,,1.000000e+001,2.772090e+002,3.022176e-002,0.000000e+000,3,9.981134e-001,0.000000e+000,,,,,,,,,,,,,,24,1,4.000000e+000,2.318115e+000,0.000000e+000,0,,0,
1687365694.646,,1.000000e+001,2.801331e+002,3.036397e-002,0.000000e+000,3,9.981850e-001,0.000000e+000,,,,,,,,,,,,,,24,1,4.000000e+000,2.597992e+000,0.000000e+000,0,,0,
1687365713.685,,1.000000e+001,2.835028e+002,3.050747e-002,0.000000e+000,3,9.981592e-001,0.000000e+000,,,,,,,,,,,,,,24,1,4.000000e+000,2.550812e+000,0.000000e+000,0,,0,
1687365733.503,,1.000000e+001,2.867607e+002,3.066367e-002,0.000000e+000,3,9.981588e-001,0.000000e+000,,,,,,,,,,,,,,24,1,4.000000e+000,2.712402e+000,0.000000e+000,0,,0,
1687365752.064,,1.000000e+001,2.899919e+002,3.081336e-002,0.000000e+000,3,9.981549e-001,0.000000e+000,,,,,,,,,,,,,,24,1,4.000000e+000,2.852814e+000,0.000000e+000,0,,0,
1687365770.873,,1.000000e+001,2.930637e+002,3.097130e-002,0.000000e+000,3,9.981905e-001,0.000000e+000,,,,,,,,,,,,,,24,1,4.000000e+000,2.503815e+000,0.000000e+000,0,,0,
1687365788.326,,1.000000e+001,2.959401e+002,3.112349e-002,0.000000e+000,3,9.982015e-001,0.000000e+000,,,,,,,,,,,,,,24,1,4.000000e+000,2.472809e+000,0.000000e+000,0,,0,
1687365806.834,,1.000000e+001,2.989281e+002,3.128199e-002,0.000000e+000,3,9.982196e-001,0.000000e+000,,,,,,,,,,,,,,24,1,4.000000e+000,2.774780e+000,0.000000e+000,0,,0,
1687365824.196,,1.000000e+001,3.019138e+002,3.143142e-002,0.000000e+000,3,9.981992e-001,0.000000e+000,,,,,,,,,,,,,,24,1,4.000000e+000,2.805908e+000,0.000000e+000,0,,0,
1687365843.924,,1.000000e+001,3.052444e+002,3.160398e-002,0.000000e+000,3,9.982472e-001,0.000000e+000,,,,,,,,,,,,,,24,1,4.000000e+000,2.828491e+000,0.000000e+000,0,,0,
1687365862.869,,1.000000e+001,3.083578e+002,3.178199e-002,0.000000e+000,3,9.982325e-001,0.000000e+000,,,,,,,,,,,,,,24,1,4.000000e+000,2.668701e+000,0.000000e+000,0,,0,
1687365881.729,,1.000000e+001,3.114955e+002,3.195865e-002,0.000000e+000,3,9.982256e-001,0.000000e+000,,,,,,,,,,,,,,24,1,4.000000e+000,2.891693e+000,0.000000e+000,0,,0,
1687365901.192,,1.000000e+001,3.147459e+002,3.213776e-002,0.000000e+000,3,9.982116e-001,0.000000e+000,,,,,,,,,,,,,,24,1,4.000000e+000,2.816986e+000,0.000000e+000,0,,0,
1687365919.897,,1.000000e+001,3.178397e+002,3.231737e-002,0.000000e+000,3,9.982247e-001,0.000000e+000,,,,,,,,,,,,,,24,1,4.000000e+000,2.623901e+000,0.000000e+000,0,,0,
1687365938.178,,1.000000e+001,3.209510e+002,3.249820e-002,0.000000e+000,3,9.982715e-001,0.000000e+000,,,,,,,,,,,,,,24,1,4.000000e+000,2.709991e+000,0.000000e+000,0,,0,
1687365956.397,,1.000000e+001,3.240023e+002,3.267466e-002,0.000000e+000,3,9.983205e-001,0.000000e+000,,,,,,,,,,,,,,24,1,4.000000e+000,2.420288e+000,0.000000e+000,0,,0,
1687365974.977,,1.000000e+001,3.270846e+002,3.286304e-002,0.000000e+000,3,9.983256e-001,0.000000e+000,,,,,,,,,,,,,,24,1,4.000000e+000,2.952209e+000,0.000000e+000,0,,0,
1687365994.369,,1.000000e+001,3.302841e+002,3.304578e-002,0.000000e+000,3,9.982684e-001,0.000000e+000,,,,,,,,,,,,,,24,1,4.000000e+000,2.604004e+000,0.000000e+000,0,,0,
1687366012.354,,1.000000e+001,3.334545e+002,3.322811e-002,0.000000e+000,3,9.982466e-001,0.000000e+000,,,,,,,,,,,,,,24,1,4.000000e+000,2.430176e+000,0.000000e+000,0,,0,
1687366031.284,,1.000000e+001,3.364463e+002,3.340910e-002,0.000000e+000,3,9.983419e-001,0.000000e+000,,,,,,,,,,,,,,24,1,4.000000e+000,2.537384e+000,0.000000e+000,0,,0,
1687366049.355,,1.000000e+001,3.394048e+002,3.359264e-002,0.000000e+000,3,9.984722e-001,0.000000e+000,,,,,,,,,,,,,,24,1,4.000000e+000,2.450897e+000,0.000000e+000,0,,0,
1687366067.436,,1.000000e+001,3.425248e+002,3.377275e-002,0.000000e+000,3,9.985436e-001,0.000000e+000,,,,,,,,,,,,,,24,1,4.000000e+000,2.223511e+000,0.000000e+000,0,,0,
1687366084.809,,1.000000e+001,3.454362e+002,3.394675e-002,0.000000e+000,3,9.985468e-001,0.000000e+000,,,,,,,,,,,,,,24,1,4.000000e+000,2.375824e+000,0.000000e+000,0,,0,
1687366102.309,,1.000000e+001,3.484283e+002,3.411907e-002,0.000000e+000,3,9.985146e-001,0.000000e+000,,,,,,,,,,,,,,24,1,4.000000e+000,2.362305e+000,0.000000e+000,0,,0,
1687366120.334,,1.000000e+001,3.513326e+002,3.429122e-002,0.000000e+000,3,9.984564e-001,0.000000e+000,,,,,,,,,,,,,,24,1,4.000000e+000,2.985474e+000,0.000000e+000,0,,0,
1687366138.266,,1.000000e+001,3.544412e+002,3.446988e-002,0.000000e+000,3,9.985271e-001,0.000000e+000,,,,,,,,,,,,,,24,1,4.000000e+000,2.448700e+000,0.000000e+000,0,,0,
1687366156.125,,1.000000e+001,3.573692e+002,3.464318e-002,0.000000e+000,3,9.985519e-001,0.000000e+000,,,,,,,,,,,,,,24,1,4.000000e+000,2.450989e+000,0.000000e+000,0,,0,
1687366174.276,,1.000000e+001,3.604202e+002,3.481943e-002,0.000000e+000,3,9.985600e-001,0.000000e+000,,,,,,,,,,,,,,24,1,4.000000e+000,2.597198e+000,0.000000e+000,0,,0,
1687366192.490,,1.000000e+001,3.633375e+002,3.499506e-002,0.000000e+000,3,9.985575e-001,0.000000e+000,,,,,,,,,,,,,,24,1,4.000000e+000,2.412323e+000,0.000000e+000,0,,0,
1687366210.795,,1.000000e+001,3.662217e+002,3.517084e-002,0.000000e+000,3,9.985951e-001,0.000000e+000,,,,,,,,,,,,,,24,1,4.000000e+000,2.811493e+000,0.000000e+000,0,,0,
1687366228.063,,1.000000e+001,3.692585e+002,3.534280e-002,0.000000e+000,3,9.985931e-001,0.000000e+000,,,,,,,,,,,,,,24,1,4.000000e+000,2.408417e+000,0.000000e+000,0,,0,
1687366247.244,,1.000000e+001,3.723388e+002,3.552246e-002,0.000000e+000,3,9.986008e-001,0.000000e+000,,,,,,,,,,,,,,24,1,4.000000e+000,2.581299e+000,0.000000e+000,0,,0,
1687366266.244,,1.000000e+001,3.754830e+002,3.569939e-002,0.000000e+000,3,9.985836e-001,0.000000e+000,,,,,,,,,,,,,,24,1,4.000000e+000,2.515106e+000,0.000000e+000,0,,0,
1687366283.996,,1.000000e+001,3.785909e+002,3.587621e-002,0.000000e+000,3,9.985201e-001,0.000000e+000,,,,,,,,,,,,,,24,1,4.000000e+000,2.173279e+000,0.000000e+000,0,,0,
1687366303.342,,1.000000e+001,3.815822e+002,3.605405e-002,0.000000e+000,3,9.985235e-001,0.000000e+000,,,,,,,,,,,,,,24,1,4.000000e+000,2.760681e+000,0.000000e+000,0,,0,
1687366320.467,,1.000000e+001,3.846310e+002,3.622581e-002,0.000000e+000,3,9.984965e-001,0.000000e+000,,,,,,,,,,,,,,24,1,4.000000e+000,2.408508e+000,0.000000e+000,0,,0,
1687366339.522,,1.000000e+001,3.877183e+002,3.640113e-002,0.000000e+000,3,9.985846e-001,0.000000e+000,,,,,,,,,,,,,,24,1,4.000000e+000,2.067902e+000,0.000000e+000,0,,0,
1687366359.297,,1.000000e+001,3.906887e+002,3.658188e-002,0.000000e+000,3,9.986058e-001,0.000000e+000,,,,,,,,,,,,,,24,1,4.000000e+000,2.148499e+000,0.000000e+000,0,,0,
1687366613.592,,1.000000e+001,3.900469e+002,3.717903e-002,0.000000e+000,3,9.988377e-001,0.000000e+000,,,,,,,,,,,,,,24,1,4.000000e+000,1.924744e-001,0.000000e+000,0,,0,
1687366632.545,,1.000000e+001,3.899148e+002,3.718118e-002,0.000000e+000,3,9.989436e-001,0.000000e+000,,,,,,,,,,,,,,24,1,4.000000e+000,1.203003e-001,0.000000e+000,0,,0,
1687366649.881,,1.000000e+001,3.901312e+002,3.718432e-002,0.000000e+000,3,9.989735e-001,0.000000e+000,,,,,,,,,,,,,,24,1,4.000000e+000,7.220459e-002,0.000000e+000,0,,0,
1687366668.594,,1.000000e+001,3.901071e+002,3.718526e-002,0.000000e+000,3,9.989647e-001,0.000000e+000,,,,,,,,,,,,,,24,1,4.000000e+000,1.685181e-001,0.000000e+000,0,,0,
1687366687.823,,1.000000e+001,3.899628e+002,3.718724e-002,0.000000e+000,3,9.989755e-001,0.000000e+000,,,,,,,,,,,,,,24,1,4.000000e+000,3.126221e-001,0.000000e+000,0,,0,
1687366705.737,,1.000000e+001,3.900109e+002,3.718840e-002,0.000000e+000,3,9.989689e-001,0.000000e+000,,,,,,,,,,,,,,24,1,4.000000e+000,2.407837e-002,0.000000e+000,0,,0,
1687366724.073,,1.000000e+001,3.900831e+002,3.718876e-002,0.000000e+000,3,9.989709e-001,0.000000e+000,,,,,,,,,,,,,,24,1,4.000000e+000,2.407837e-002,0.000000e+000,0,,0,
1687366743.746,,1.000000e+001,3.901312e+002,3.718985e-002,0.000000e+000,3,9.989755e-001,0.000000e+000,,,,,,,,,,,,,,24,1,4.000000e+000,2.648010e-001,0.000000e+000,0,,0,
1687366761.819,,1.000000e+001,3.901193e+002,3.719028e-002,0.000000e+000,3,9.989837e-001,0.000000e+000,,,,,,,,,,,,,,24,1,4.000000e+000,2.886963e-001,0.000000e+000,0,,0,
1687366780.305,,1.000000e+001,3.899267e+002,3.719034e-002,0.000000e+000,3,9.989752e-001,0.000000e+000,,,,,,,,,,,,,,24,1,4.000000e+000,1.441956e-001,0.000000e+000,0,,0,
1687366799.734,,1.000000e+001,3.899748e+002,3.719096e-002,0.000000e+000,3,9.989840e-001,0.000000e+000,,,,,,,,,,,,,,24,1,4.000000e+000,1.924133e-001,0.000000e+000,0,,0,
1687366818.671,,1.000000e+001,3.899628e+002,3.719202e-002,0.000000e+000,3,9.989789e-001,0.000000e+000,,,,,,,,,,,,,,24,1,4.000000e+000,7.211304e-002,0.000000e+000,0,,0,
1687366837.129,,1.000000e+001,3.899989e+002,3.719295e-002,0.000000e+000,3,9.989892e-001,0.000000e+000,,,,,,,,,,,,,,24,1,4.000000e+000,4.797363e-002,0.000000e+000,0,,0,
1687366855.067,,1.000000e+001,3.900229e+002,3.719277e-002,0.000000e+000,3,9.989889e-001,0.000000e+000,,,,,,,,,,,,,,24,1,4.000000e+000,2.406006e-001,0.000000e+000,0,,0,
1687366873.134,,1.000000e+001,3.899028e+002,3.719260e-002,0.000000e+000,3,9.990060e-001,0.000000e+000,,,,,,,,,,,,,,24,1,4.000000e+000,1.443176e-001,0.000000e+000,0,,0,
1687366891.776,,1.000000e+001,3.899147e+002,3.719313e-002,0.000000e+000,3,9.989992e-001,0.000000e+000,,,,,,,,,,,,,,24,1,4.000000e+000,1.682129e-001,0.000000e+000,0,,0,
1687366909.481,,1.000000e+001,3.899267e+002,3.719397e-002,0.000000e+000,3,9.990066e-001,0.000000e+000,,,,,,,,,,,,,,24,1,4.000000e+000,1.441956e-001,0.000000e+000,0,,0,
1687366928.574,,1.000000e+001,3.900230e+002,3.719347e-002,0.000000e+000,3,9.990006e-001,0.000000e+000,,,,,,,,,,,,,,24,1,4.000000e+000,3.367920e-001,0.000000e+000,0,,0,
1687366946.738,,1.000000e+001,3.900349e+002,3.719557e-002,0.000000e+000,3,9.990061e-001,0.000000e+000,,,,,,,,,,,,,,24,1,4.000000e+000,1.683960e-001,0.000000e+000,0,,0,
1687366966.293,,1.000000e+001,3.900711e+002,3.719493e-002,0.000000e+000,3,9.989927e-001,0.000000e+000,,,,,,,,,,,,,,24,1,4.000000e+000,2.888184e-001,0.000000e+000,0,,0,
1687366983.303,,1.000000e+001,3.900469e+002,3.719601e-002,0.000000e+000,3,9.990060e-001,0.000000e+000,,,,,,,,,,,,,,24,1,4.000000e+000,0.000000e+000,0.000000e+000,0,,0,
1687367001.787,,1.000000e+001,3.900109e+002,3.719666e-002,0.000000e+000,3,9.989975e-001,0.000000e+000,,,,,,,,,,,,,,24,1,4.000000e+000,2.645874e-001,0.000000e+000,0,,0,
1687367020.123,,1.000000e+001,3.899628e+002,3.719679e-002,0.000000e+000,3,9.990113e-001,0.000000e+000,,,,,,,,,,,,,,24,1,4.000000e+000,2.420044e-002,0.000000e+000,0,,0,
1687367038.677,,1.000000e+001,3.901191e+002,3.719749e-002,0.000000e+000,3,9.990277e-001,0.000000e+000,,,,,,,,,,,,,,24,1,4.000000e+000,4.809570e-002,0.000000e+000,0,,0,
1687367057.271,,1.000000e+001,3.901432e+002,3.719804e-002,0.000000e+000,3,9.990205e-001,0.000000e+000,,,,,,,,,,,,,,24,1,4.000000e+000,1.925964e-001,0.000000e+000,0,,0,
1687367075.624,,1.000000e+001,3.900831e+002,3.719734e-002,0.000000e+000,3,9.990197e-001,0.000000e+000,,,,,,,,,,,,,,24,1,4.000000e+000,2.407837e-002,0.000000e+000,0,,0,
1687367094.437,,1.000000e+001,3.900229e+002,3.719866e-002,0.000000e+000,3,9.990161e-001,0.000000e+000,,,,,,,,,,,,,,24,1,4.000000e+000,2.406006e-001,0.000000e+000,0,,0,
1687367112.189,,1.000000e+001,3.899988e+002,3.719959e-002,0.000000e+000,3,9.990279e-001,0.000000e+000,,,,,,,,,,,,,,24,1,4.000000e+000,2.405090e-001,0.000000e+000,0,,0,
1687367130.675,,1.000000e+001,3.899266e+002,3.719920e-002,0.000000e+000,3,9.990050e-001,0.000000e+000,,,,,,,,,,,,,,24,1,4.000000e+000,4.812622e-002,0.000000e+000,0,,0,
1687367148.488,,1.000000e+001,3.900831e+002,3.719955e-002,0.000000e+000,3,9.990057e-001,0.000000e+000,,,,,,,,,,,,,,24,1,4.000000e+000,2.407837e-002,0.000000e+000,0,,0,
1687367166.261,,1.000000e+001,3.901071e+002,3.720026e-002,0.000000e+000,3,9.990258e-001,0.000000e+000,,,,,,,,,,,,,,24,1,4.000000e+000,2.401733e-002,0.000000e+000,0,,0,
1687367184.863,,1.000000e+001,3.901432e+002,3.719929e-002,0.000000e+000,3,9.990242e-001,0.000000e+000,,,,,,,,,,,,,,24,1,4.000000e+000,9.631348e-002,0.000000e+000,0,,0,
1687367204.312,,1.000000e+001,3.898425e+002,3.720021e-002,0.000000e+000,3,9.990177e-001,0.000000e+000,,,,,,,,,,,,,,24,1,4.000000e+000,7.211304e-002,0.000000e+000,0,,0,
1687367223.117,,1.000000e+001,3.900711e+002,3.720083e-002,0.000000e+000,3,9.990245e-001,0.000000e+000,,,,,,,,,,,,,,24,1,4.000000e+000,2.888184e-001,0.000000e+000,0,,0,
1687367241.749,,1.000000e+001,3.900229e+002,3.720053e-002,0.000000e+000,3,9.990054e-001,0.000000e+000,,,,,,,,,,,,,,24,1,4.000000e+000,0.000000e+000,0.000000e+000,0,,0,
1687367259.679,,1.000000e+001,3.901553e+002,3.720165e-002,0.000000e+000,3,9.990200e-001,0.000000e+000,,,,,,,,,,,,,,24,1,4.000000e+000,2.648010e-001,0.000000e+000,0,,0,
1687367278.620,,1.000000e+001,3.900830e+002,3.720273e-002,0.000000e+000,3,9.990158e-001,0.000000e+000,,,,,,,,,,,,,,24,1,4.000000e+000,1.203003e-001,0.000000e+000,0,,0,
1687367297.175,,1.000000e+001,3.899027e+002,3.720269e-002,0.000000e+000,3,9.990174e-001,0.000000e+000,,,,,,,,,,,,,,24,1,4.000000e+000,2.883911e-001,0.000000e+000,0,,0,
1687367316.027,,1.000000e+001,3.901914e+002,3.720145e-002,0.000000e+000,3,9.990183e-001,0.000000e+000,,,,,,,,,,,,,,24,1,4.000000e+000,4.821777e-002,0.000000e+000,0,,0,
1687367334.636,,1.000000e+001,3.900109e+002,3.720199e-002,0.000000e+000,3,9.990144e-001,0.000000e+000,,,,,,,,,,,,,,24,1,4.000000e+000,7.199097e-002,0.000000e+000,0,,0,
1687367352.242,,1.000000e+001,3.899869e+002,3.720238e-002,0.000000e+000,3,9.990200e-001,0.000000e+000,,,,,,,,,,,,,,24,1,4.000000e+000,2.389526e-002,0.000000e+000,0,,0,
1687367370.585,,1.000000e+001,3.899508e+002,3.720398e-002,0.000000e+000,3,9.990350e-001,0.000000e+000,,,,,,,,,,,,,,24,1,4.000000e+000,3.366089e-001,0.000000e+000,0,,0,
1687367389.257,,1.000000e+001,3.900349e+002,3.720374e-002,0.000000e+000,3,9.990136e-001,0.000000e+000,,,,,,,,,,,,,,24,1,4.000000e+000,2.164917e-001,0.000000e+000,0,,0,
1687367408.593,,1.000000e+001,3.899988e+002,3.720351e-002,0.000000e+000,3,9.990239e-001,0.000000e+000,,,,,,,,,,,,,,24,1,4.000000e+000,2.405090e-001,0.000000e+000,0,,0,
1687367427.533,,1.000000e+001,3.899988e+002,3.720267e-002,0.000000e+000,3,9.990212e-001,0.000000e+000,,,,,,,,,,,,,,24,1,4.000000e+000,1.443176e-001,0.000000e+000,0,,0,
1687367445.933,,1.000000e+001,3.899387e+002,3.720262e-002,0.000000e+000,3,9.990209e-001,0.000000e+000,,,,,,,,,,,,,,24,1,4.000000e+000,2.401733e-002,0.000000e+000,0,,0,
1687367465.394,,1.000000e+001,3.899868e+002,3.720355e-002,0.000000e+000,3,9.990268e-001,0.000000e+000,,,,,,,,,,,,,,24,1,4.000000e+000,1.202087e-001,0.000000e+000,0,,0,
1687367482.904,,1.000000e+001,3.901191e+002,3.720421e-002,0.000000e+000,3,9.990284e-001,0.000000e+000,,,,,,,,,,,,,,24,1,4.000000e+000,4.809570e-002,0.000000e+000,0,,0,
1687367501.475,,1.000000e+001,3.899507e+002,3.720377e-002,0.000000e+000,3,9.990304e-001,0.000000e+000,,,,,,,,,,,,,,24,1,4.000000e+000,9.622192e-002,0.000000e+000,0,,0,
1687367520.188,,1.000000e+001,3.899748e+002,3.720357e-002,0.000000e+000,3,9.990358e-001,0.000000e+000,,,,,,,,,,,,,,24,1,4.000000e+000,4.809570e-002,0.000000e+000,0,,0,
1687367538.977,,1.000000e+001,3.900591e+002,3.720421e-002,0.000000e+000,3,9.990322e-001,0.000000e+000,,,,,,,,,,,,,,24,1,4.000000e+000,4.089966e-001,0.000000e+000,0,,0,
1687367557.383,,1.000000e+001,3.899748e+002,3.720414e-002,0.000000e+000,3,9.990441e-001,0.000000e+000,,,,,,,,,,,,,,24,1,4.000000e+000,4.809570e-002,0.000000e+000,0,,0,
1687367575.534,,1.000000e+001,3.899387e+002,3.720447e-002,0.000000e+000,3,9.990432e-001,0.000000e+000,,,,,,,,,,,,,,24,1,4.000000e+000,1.202087e-001,0.000000e+000,0,,0,
1687367593.810,,1.000000e+001,3.899868e+002,3.720498e-002,0.000000e+000,3,9.990361e-001,0.000000e+000,,,,,,,,,,,,,,24,1,4.000000e+000,7.217407e-002,0.000000e+000,0,,0,
1687367612.427,,1.000000e+001,3.898907e+002,3.720497e-002,0.000000e+000,3,9.990309e-001,0.000000e+000,,,,,,,,,,,,,,24,1,4.000000e+000,7.208252e-002,0.000000e+000,0,,0,
1687367630.576,,1.000000e+001,3.900591e+002,3.720580e-002,0.000000e+000,3,9.990023e-001,0.000000e+000,,,,,,,,,,,,,,24,1,4.000000e+000,1.682739e-001,0.000000e+000,0,,0,
1687367648.497,,1.000000e+001,3.899147e+002,3.720543e-002,0.000000e+000,3,9.990042e-001,0.000000e+000,,,,,,,,,,,,,,24,1,4.000000e+000,7.211304e-002,0.000000e+000,0,,0,
1687367667.008,,1.000000e+001,3.899869e+002,3.720571e-002,0.000000e+000,3,9.990029e-001,0.000000e+000,,,,,,,,,,,,,,24,1,4.000000e+000,2.389526e-002,0.000000e+000,0,,0,
1687367686.039,,1.000000e+001,3.900470e+002,3.720601e-002,0.000000e+000,3,9.990396e-001,0.000000e+000,,,,,,,,,,,,,,24,1,4.000000e+000,2.406006e-001,0.000000e+000,0,,0,
1687367704.164,,1.000000e+001,3.899990e+002,3.720620e-002,0.000000e+000,3,9.990283e-001,0.000000e+000,,,,,,,,,,,,,,24,1,4.000000e+000,3.367004e-001,0.000000e+000,0,,0,
1687367722.500,,1.000000e+001,3.899387e+002,3.720696e-002,0.000000e+000,3,9.990278e-001,0.000000e+000,,,,,,,,,,,,,,24,1,4.000000e+000,2.401733e-002,0.000000e+000,0,,0,
1687367739.856,,1.000000e+001,3.899869e+002,3.720646e-002,0.000000e+000,3,9.990243e-001,0.000000e+000,,,,,,,,,,,,,,24,1,4.000000e+000,2.389526e-002,0.000000e+000,0,,0,
1687367759.059,,1.000000e+001,3.901432e+002,3.720786e-002,0.000000e+000,3,9.990284e-001,0.000000e+000,,,,,,,,,,,,,,24,1,4.000000e+000,2.407227e-001,0.000000e+000,0,,0,
1687367776.357,,1.000000e+001,3.901914e+002,3.720797e-002,0.000000e+000,3,9.990267e-001,0.000000e+000,,,,,,,,,,,,,,24,1,4.000000e+000,4.821777e-002,0.000000e+000,0,,0,
1687367795.672,,1.000000e+001,3.898787e+002,3.720692e-002,0.000000e+000,3,9.990368e-001,0.000000e+000,,,,,,,,,,,,,,24,1,4.000000e+000,2.884827e-001,0.000000e+000,0,,0,
1687367813.571,,1.000000e+001,3.898906e+002,3.720878e-002,0.000000e+000,3,9.990406e-001,0.000000e+000,,,,,,,,,,,,,,24,1,4.000000e+000,2.398682e-002,0.000000e+000,0,,0,
1687367832.573,,1.000000e+001,3.900590e+002,3.720912e-002,0.000000e+000,3,9.990359e-001,0.000000e+000,,,,,,,,,,,,,,24,1,4.000000e+000,7.220459e-002,0.000000e+000,0,,0,
1687367850.934,,1.000000e+001,3.900109e+002,3.720828e-002,0.000000e+000,3,9.990214e-001,0.000000e+000,,,,,,,,,,,,,,24,1,4.000000e+000,2.407837e-002,0.000000e+000,0,,0,
1687367869.793,,1.000000e+001,3.900349e+002,3.720751e-002,0.000000e+000,3,9.990277e-001,0.000000e+000,,,,,,,,,,,,,,24,1,4.000000e+000,1.683960e-001,0.000000e+000,0,,0,
1687367888.270,,1.000000e+001,3.900831e+002,3.720836e-002,0.000000e+000,3,9.990313e-001,0.000000e+000,,,,,,,,,,,,,,24,1,4.000000e+000,1.684875e-001,0.000000e+000,0,,0,
1687367907.444,,1.000000e+001,3.901432e+002,3.720900e-002,0.000000e+000,3,9.990361e-001,0.000000e+000,,,,,,,,,,,,,,24,1,4.000000e+000,0.000000e+000,0.000000e+000,0,,0,
1687367926.860,,1.000000e+001,3.898546e+002,3.721027e-002,0.000000e+000,3,9.990438e-001,0.000000e+000,,,,,,,,,,,,,,24,1,4.000000e+000,0.000000e+000,0.000000e+000,0,,0,
1687367946.485,,1.000000e+001,3.899028e+002,3.721017e-002,0.000000e+000,3,9.990361e-001,0.000000e+000,,,,,,,,,,,,,,24,1,4.000000e+000,1.443176e-001,0.000000e+000,0,,0,
1687367964.914,,1.000000e+001,3.900830e+002,3.720957e-002,0.000000e+000,3,9.990422e-001,0.000000e+000,,,,,,,,,,,,,,24,1,4.000000e+000,7.220459e-002,0.000000e+000,0,,0,
1687367983.612,,1.000000e+001,3.900830e+002,3.721042e-002,0.000000e+000,3,9.990093e-001,0.000000e+000,,,,,,,,,,,,,,24,1,4.000000e+000,7.220459e-002,0.000000e+000,0,,0,
1687368001.817,,1.000000e+001,3.900590e+002,3.721053e-002,0.000000e+000,3,9.990362e-001,0.000000e+000,,,,,,,,,,,,,,24,1,4.000000e+000,2.165833e-001,0.000000e+000,0,,0,
1687368021.442,,1.000000e+001,3.901071e+002,3.721172e-002,0.000000e+000,3,9.990402e-001,0.000000e+000,,,,,,,,,,,,,,24,1,4.000000e+000,1.685181e-001,0.000000e+000,0,,0,
1687368039.910,,1.000000e+001,3.900710e+002,3.721007e-002,0.000000e+000,3,9.990397e-001,0.000000e+000,,,,,,,,,,,,,,24,1,4.000000e+000,0.000000e+000,0.000000e+000,0,,0,
1687368058.778,,1.000000e+001,3.901191e+002,3.721079e-002,0.000000e+000,3,9.990343e-001,0.000000e+000,,,,,,,,,,,,,,24,1,4.000000e+000,2.406921e-001,0.000000e+000,0,,0,
1687368076.977,,1.000000e+001,3.899509e+002,3.721245e-002,0.000000e+000,3,9.990436e-001,0.000000e+000,,,,,,,,,,,,,,24,1,4.000000e+000,3.846741e-001,0.000000e+000,0,,0,
1687368095.488,,1.000000e+001,3.900950e+002,3.721102e-002,0.000000e+000,3,9.990437e-001,0.000000e+000,,,,,,,,,,,,,,24,1,4.000000e+000,9.628296e-002,0.000000e+000,0,,0,
1687368114.784,,1.000000e+001,3.900349e+002,3.721109e-002,0.000000e+000,3,9.990363e-001,0.000000e+000,,,,,,,,,,,,,,24,1,4.000000e+000,7.220459e-002,0.000000e+000,0,,0,
1687368134.187,,1.000000e+001,3.900109e+002,3.721124e-002,0.000000e+000,3,9.990363e-001,0.000000e+000,,,,,,,,,,,,,,24,1,4.000000e+000,1.683960e-001,0.000000e+000,0,,0,
1687368152.210,,1.000000e+001,3.899268e+002,3.721220e-002,0.000000e+000,3,9.990411e-001,0.000000e+000,,,,,,,,,,,,,,24,1,4.000000e+000,9.631348e-002,0.000000e+000,0,,0,
1687368171.242,,1.000000e+001,3.900831e+002,3.721170e-002,0.000000e+000,3,9.990233e-001,0.000000e+000,,,,,,,,,,,,,,24,1,4.000000e+000,1.684875e-001,0.000000e+000,0,,0,
1687368190.218,,1.000000e+001,3.899507e+002,3.721147e-002,0.000000e+000,3,9.990372e-001,0.000000e+000,,,,,,,,,,,,,,24,1,4.000000e+000,9.622192e-002,0.000000e+000,0,,0,
1687368208.589,,1.000000e+001,3.900470e+002,3.721192e-002,0.000000e+000,3,9.990389e-001,0.000000e+000,,,,,,,,,,,,,,24,1,4.000000e+000,2.406006e-001,0.000000e+000,0,,0,
1687368226.464,,1.000000e+001,3.900590e+002,3.721264e-002,0.000000e+000,3,9.990442e-001,0.000000e+000,,,,,,,,,,,,,,24,1,4.000000e+000,2.410889e-002,0.000000e+000,0,,0,
1687368245.599,,1.000000e+001,3.901673e+002,3.721390e-002,0.000000e+000,3,9.990467e-001,0.000000e+000,,,,,,,,,,,,,,24,1,4.000000e+000,1.925964e-001,0.000000e+000,0,,0,
1687368263.968,,1.000000e+001,3.900590e+002,3.721405e-002,0.000000e+000,3,9.990339e-001,0.000000e+000,,,,,,,,,,,,,,24,1,4.000000e+000,2.410889e-002,0.000000e+000,0,,0,
1687368281.718,,1.000000e+001,3.900710e+002,3.721182e-002,0.000000e+000,3,9.990329e-001,0.000000e+000,,,,,,,,,,,,,,24,1,4.000000e+000,4.818726e-002,0.000000e+000,0,,0,
1687368300.509,,1.000000e+001,3.899868e+002,3.721217e-002,0.000000e+000,3,9.990302e-001,0.000000e+000,,,,,,,,,,,,,,24,1,4.000000e+000,1.202087e-001,0.000000e+000,0,,0,
1687368319.613,,1.000000e+001,3.900349e+002,3.721311e-002,0.000000e+000,3,9.990402e-001,0.000000e+000,,,,,,,,,,,,,,24,1,4.000000e+000,1.683960e-001,0.000000e+000,0,,0,
1687368338.878,,1.000000e+001,3.898787e+002,3.721349e-002,0.000000e+000,3,9.990278e-001,0.000000e+000,,,,,,,,,,,,,,24,1,4.000000e+000,9.609985e-002,0.000000e+000,0,,0,
1687368358.636,,1.000000e+001,3.901071e+002,3.721268e-002,0.000000e+000,3,9.990429e-001,0.000000e+000,,,,,,,,,,,,,,24,1,4.000000e+000,1.685181e-001,0.000000e+000,0,,0,
1687368377.131,,1.000000e+001,3.900591e+002,3.721391e-002,0.000000e+000,3,9.990440e-001,0.000000e+000,,,,,,,,,,,,,,24,1,4.000000e+000,1.682739e-001,0.000000e+000,0,,0,
1687368395.039,,1.000000e+001,3.900350e+002,3.721503e-002,0.000000e+000,3,9.990345e-001,0.000000e+000,,,,,,,,,,,,,,24,1,4.000000e+000,1.201782e-001,0.000000e+000,0,,0,
1687368414.321,,1.000000e+001,3.901192e+002,3.721391e-002,0.000000e+000,3,9.990473e-001,0.000000e+000,,,,,,,,,,,,,,24,1,4.000000e+000,1.926270e-001,0.000000e+000,0,,0,
1687368433.680,,1.000000e+001,3.899868e+002,3.721385e-002,0.000000e+000,3,9.990130e-001,0.000000e+000,,,,,,,,,,,,,,24,1,4.000000e+000,7.217407e-002,0.000000e+000,0,,0,
1687368452.657,,1.000000e+001,3.900950e+002,3.721465e-002,0.000000e+000,3,9.990365e-001,0.000000e+000,,,,,,,,,,,,,,24,1,4.000000e+000,9.628296e-002,0.000000e+000,0,,0,
1687368472.090,,1.000000e+001,3.900710e+002,3.721453e-002,0.000000e+000,3,9.990365e-001,0.000000e+000,,,,,,,,,,,,,,24,1,4.000000e+000,2.406921e-001,0.000000e+000,0,,0,
1687368490.453,,1.000000e+001,3.898546e+002,3.721473e-002,0.000000e+000,3,9.990371e-001,0.000000e+000,,,,,,,,,,,,,,24,1,4.000000e+000,4.800415e-002,0.000000e+000,0,,0,
1687368508.977,,1.000000e+001,3.900109e+002,3.721413e-002,0.000000e+000,3,9.990548e-001,0.000000e+000,,,,,,,,,,,,,,24,1,4.000000e+000,2.407837e-002,0.000000e+000,0,,0,
1687368527.557,,1.000000e+001,3.899628e+002,3.721226e-002,0.000000e+000,3,9.990399e-001,0.000000e+000,,,,,,,,,,,,,,24,1,4.000000e+000,2.420044e-002,0.000000e+000,0,,0,
1687368546.895,,1.000000e+001,3.899748e+002,3.721486e-002,0.000000e+000,3,9.990289e-001,0.000000e+000,,,,,,,,,,,,,,24,1,4.000000e+000,4.809570e-002,0.000000e+000,0,,0,
1687368565.317,,1.000000e+001,3.899988e+002,3.721493e-002,0.000000e+000,3,9.990641e-001,0.000000e+000,,,,,,,,,,,,,,24,1,4.000000e+000,9.619141e-002,0.000000e+000,0,,0,
1687368584.614,,1.000000e+001,3.900711e+002,3.721539e-002,0.000000e+000,3,9.990491e-001,0.000000e+000,,,,,,,,,,,,,,24,1,4.000000e+000,1.923828e-001,0.000000e+000,0,,0,
1687368602.765,,1.000000e+001,3.900710e+002,3.721664e-002,0.000000e+000,3,9.990377e-001,0.000000e+000,,,,,,,,,,,,,,24,1,4.000000e+000,4.818726e-002,0.000000e+000,0,,0,
1687368622.192,,1.000000e+001,3.898786e+002,3.721533e-002,0.000000e+000,3,9.990447e-001,0.000000e+000,,,,,,,,,,,,,,24,1,4.000000e+000,0.000000e+000,0.000000e+000,0,,0,
1687368641.991,,1.000000e+001,3.899388e+002,3.721584e-002,0.000000e+000,3,9.990537e-001,0.000000e+000,,,,,,,,,,,,,,24,1,4.000000e+000,7.232666e-002,0.000000e+000,0,,0,
1687368659.975,,1.000000e+001,3.898786e+002,3.721716e-002,0.000000e+000,3,9.990565e-001,0.000000e+000,,,,,,,,,,,,,,24,1,4.000000e+000,1.442261e-001,0.000000e+000,0,,0,
1687368678.959,,1.000000e+001,3.898906e+002,3.721755e-002,0.000000e+000,3,9.990657e-001,0.000000e+000,,,,,,,,,,,,,,24,1,4.000000e+000,2.398682e-002,0.000000e+000,0,,0,
1687368697.067,,1.000000e+001,3.900590e+002,3.721705e-002,0.000000e+000,3,9.990677e-001,0.000000e+000,,,,,,,,,,,,,,24,1,4.000000e+000,1.203003e-001,0.000000e+000,0,,0,
1687368715.558,,1.000000e+001,3.899388e+002,3.721617e-002,0.000000e+000,3,9.990520e-001,0.000000e+000,,,,,,,,,,,,,,24,1,4.000000e+000,7.232666e-002,0.000000e+000,0,,0,
1687368734.661,,1.000000e+001,3.899267e+002,3.721854e-002,0.000000e+000,3,9.990593e-001,0.000000e+000,,,,,,,,,,,,,,24,1,4.000000e+000,2.404175e-001,0.000000e+000,0,,0,
1687368754.392,,1.000000e+001,3.900830e+002,3.721790e-002,0.000000e+000,3,9.990529e-001,0.000000e+000,,,,,,,,,,,,,,24,1,4.000000e+000,7.220459e-002,0.000000e+000,0,,0,
1687368773.642,,1.000000e+001,3.899507e+002,3.721859e-002,0.000000e+000,3,9.990526e-001,0.000000e+000,,,,,,,,,,,,,,24,1,4.000000e+000,9.622192e-002,0.000000e+000,0,,0,
1687368793.062,,1.000000e+001,3.901312e+002,3.721820e-002,0.000000e+000,3,9.990503e-001,0.000000e+000,,,,,,,,,,,,,,24,1,4.000000e+000,1.686096e-001,0.000000e+000,0,,0,
1687368812.275,,1.000000e+001,3.899147e+002,3.721869e-002,0.000000e+000,3,9.990602e-001,0.000000e+000,,,,,,,,,,,,,,24,1,4.000000e+000,7.211304e-002,0.000000e+000,0,,0,
1687368830.978,,1.000000e+001,3.899988e+002,3.721916e-002,0.000000e+000,3,9.990575e-001,0.000000e+000,,,,,,,,,,,,,,24,1,4.000000e+000,9.619141e-002,0.000000e+000,0,,0,
1687368850.152,,1.000000e+001,3.900229e+002,3.721782e-002,0.000000e+000,3,9.990515e-001,0.000000e+000,,,,,,,,,,,,,,24,1,4.000000e+000,9.609985e-002,0.000000e+000,0,,0,
1687368868.880,,1.000000e+001,3.901312e+002,3.721828e-002,0.000000e+000,3,9.990515e-001,0.000000e+000,,,,,,,,,,,,,,24,1,4.000000e+000,1.203918e-001,0.000000e+000,0,,0,
1687368887.115,,1.000000e+001,3.899748e+002,3.721887e-002,0.000000e+000,3,9.990592e-001,0.000000e+000,,,,,,,,,,,,,,24,1,4.000000e+000,9.619141e-002,0.000000e+000,0,,0,
1687368905.633,,1.000000e+001,3.899868e+002,3.721958e-002,0.000000e+000,3,9.990637e-001,0.000000e+000,,,,,,,,,,,,,,24,1,4.000000e+000,7.217407e-002,0.000000e+000,0,,0,
1687368924.211,,1.000000e+001,3.899988e+002,3.721992e-002,0.000000e+000,3,9.990672e-001,0.000000e+000,,,,,,,,,,,,,,24,1,4.000000e+000,0.000000e+000,0.000000e+000,0,,0,
1687368943.508,,1.000000e+001,3.901191e+002,3.721973e-002,0.000000e+000,3,9.990459e-001,0.000000e+000,,,,,,,,,,,,,,24,1,4.000000e+000,2.406921e-001,0.000000e+000,0,,0,
1687368963.165,,1.000000e+001,3.899267e+002,3.722052e-002,0.000000e+000,3,9.990425e-001,0.000000e+000,,,,,,,,,,,,,,24,1,4.000000e+000,1.441956e-001,0.000000e+000,0,,0,
1687368981.145,,1.000000e+001,3.899748e+002,3.721901e-002,0.000000e+000,3,9.990562e-001,0.000000e+000,,,,,,,,,,,,,,24,1,4.000000e+000,1.924133e-001,0.000000e+000,0,,0,
1687369000.332,,1.000000e+001,3.899988e+002,3.722076e-002,0.000000e+000,3,9.990759e-001,0.000000e+000,,,,,,,,,,,,,,24,1,4.000000e+000,1.443176e-001,0.000000e+000,0,,0,
1687369020.234,,1.000000e+001,3.900710e+002,3.722102e-002,0.000000e+000,3,9.990580e-001,0.000000e+000,,,,,,,,,,,,,,24,1,4.000000e+000,1.443787e-001,0.000000e+000,0,,0,
1687369038.837,,1.000000e+001,3.900109e+002,3.721953e-002,0.000000e+000,3,9.990659e-001,0.000000e+000,,,,,,,,,,,,,,24,1,4.000000e+000,2.407837e-002,0.000000e+000,0,,0,
1687369058.353,,1.000000e+001,3.899148e+002,3.721998e-002,0.000000e+000,3,9.990711e-001,0.000000e+000,,,,,,,,,,,,,,24,1,4.000000e+000,1.203003e-001,0.000000e+000,0,,0,
1687369076.995,,1.000000e+001,3.899266e+002,3.722007e-002,0.000000e+000,3,9.990766e-001,0.000000e+000,,,,,,,,,,,,,,24,1,4.000000e+000,4.812622e-002,0.000000e+000,0,,0,
1687369095.490,,1.000000e+001,3.899387e+002,3.722192e-002,0.000000e+000,3,9.990855e-001,0.000000e+000,,,,,,,,,,,,,,24,1,4.000000e+000,2.401733e-002,0.000000e+000,0,,0,
1687369113.958,,1.000000e+001,3.899508e+002,3.722034e-002,0.000000e+000,3,9.990858e-001,0.000000e+000,,,,,,,,,,,,,,24,1,4.000000e+000,4.821777e-002,0.000000e+000,0,,0,
1687369133.430,,1.000000e+001,3.899507e+002,3.721998e-002,0.000000e+000,3,9.990844e-001,0.000000e+000,,,,,,,,,,,,,,24,1,4.000000e+000,1.922913e-001,0.000000e+000,0,,0,
1687369151.993,,1.000000e+001,3.900349e+002,3.722069e-002,0.000000e+000,3,9.990783e-001,0.000000e+000,,,,,,,,,,,,,,24,1,4.000000e+000,7.220459e-002,0.000000e+000,0,,0,
1687369169.328,,1.000000e+001,3.899388e+002,3.722143e-002,0.000000e+000,3,9.990864e-001,0.000000e+000,,,,,,,,,,,,,,24,1,4.000000e+000,3.125916e-001,0.000000e+000,0,,0,
1687369189.430,,1.000000e+001,3.901312e+002,3.722151e-002,0.000000e+000,3,9.990854e-001,0.000000e+000,,,,,,,,,,,,,,24,1,4.000000e+000,2.166138e-001,0.000000e+000,0,,0,
1687369207.351,,1.000000e+001,3.901191e+002,3.722138e-002,0.000000e+000,3,9.990907e-001,0.000000e+000,,,,,,,,,,,,,,24,1,4.000000e+000,2.406921e-001,0.000000e+000,0,,0,
1687369225.687,,1.000000e+001,3.901432e+002,3.722152e-002,0.000000e+000,3,9.990869e-001,0.000000e+000,,,,,,,,,,,,,,24,1,4.000000e+000,4.818726e-002,0.000000e+000,0,,0,
1687369246.072,,1.000000e+001,3.900229e+002,3.722144e-002,0.000000e+000,3,9.990808e-001,0.000000e+000,,,,,,,,,,,,,,24,1,4.000000e+000,9.609985e-002,0.000000e+000,0,,0,
1687369264.666,,1.000000e+001,3.900229e+002,3.722239e-002,0.000000e+000,3,9.990582e-001,0.000000e+000,,,,,,,,,,,,,,24,1,4.000000e+000,9.609985e-002,0.000000e+000,0,,0,
1687369282.418,,1.000000e+001,3.900950e+002,3.722151e-002,0.000000e+000,3,9.990700e-001,0.000000e+000,,,,,,,,,,,,,,24,1,4.000000e+000,9.628296e-002,0.000000e+000,0,,0,
1687369301.683,,1.000000e+001,3.900471e+002,3.722140e-002,0.000000e+000,3,9.990575e-001,0.000000e+000,,,,,,,,,,,,,,24,1,4.000000e+000,3.369141e-001,0.000000e+000,0,,0,
1687369320.925,,1.000000e+001,3.899748e+002,3.722125e-002,0.000000e+000,3,9.990879e-001,0.000000e+000,,,,,,,,,,,,,,24,1,4.000000e+000,1.924133e-001,0.000000e+000,0,,0,
1687369339.763,,1.000000e+001,3.900349e+002,3.722286e-002,0.000000e+000,3,9.990784e-001,0.000000e+000,,,,,,,,,,,,,,24,1,4.000000e+000,2.401733e-002,0.000000e+000,0,,0,
1687369358.890,,1.000000e+001,3.901673e+002,3.722083e-002,0.000000e+000,3,9.990847e-001,0.000000e+000,,,,,,,,,,,,,,24,1,4.000000e+000,0.000000e+000,0.000000e+000,0,,0,
1687369377.109,,1.000000e+001,3.901191e+002,3.722200e-002,0.000000e+000,3,9.990975e-001,0.000000e+000,,,,,,,,,,,,,,24,1,4.000000e+000,0.000000e+000,0.000000e+000,0,,0,
1687369395.447,,1.000000e+001,3.899387e+002,3.722241e-002,0.000000e+000,3,9.991230e-001,0.000000e+000,,,,,,,,,,,,,,24,1,4.000000e+000,1.202087e-001,0.000000e+000,0,,0,
1687369414.455,,1.000000e+001,3.900469e+002,3.722170e-002,0.000000e+000,3,9.991204e-001,0.000000e+000,,,,,,,,,,,,,,24,1,4.000000e+000,9.628296e-002,0.000000e+000,0,,0,
1687369432.948,,1.000000e+001,3.900109e+002,3.722126e-002,0.000000e+000,3,9.990907e-001,0.000000e+000,,,,,,,,,,,,,,24,1,4.000000e+000,7.199097e-002,0.000000e+000,0,,0,
1687369451.533,,1.000000e+001,3.900229e+002,3.722331e-002,0.000000e+000,3,9.990857e-001,0.000000e+000,,,,,,,,,,,,,,24,1,4.000000e+000,4.809570e-002,0.000000e+000,0,,0,
1687369469.740,,1.000000e+001,3.900229e+002,3.722363e-002,0.000000e+000,3,9.990790e-001,0.000000e+000,,,,,,,,,,,,,,24,1,4.000000e+000,1.924133e-001,0.000000e+000,0,,0,
1687369489.052,,1.000000e+001,3.900109e+002,3.722266e-002,0.000000e+000,3,9.990879e-001,0.000000e+000,,,,,,,,,,,,,,24,1,4.000000e+000,2.407837e-002,0.000000e+000,0,,0,
1687369506.514,,1.000000e+001,3.901673e+002,3.722354e-002,0.000000e+000,3,9.990785e-001,0.000000e+000,,,,,,,,,,,,,,24,1,4.000000e+000,9.640503e-002,0.000000e+000,0,,0,
1687369525.524,,1.000000e+001,3.899507e+002,3.722417e-002,0.000000e+000,3,9.991109e-001,0.000000e+000,,,,,,,,,,,,,,24,1,4.000000e+000,1.922913e-001,0.000000e+000,0,,0,
1687369542.821,,1.000000e+001,3.900831e+002,3.722532e-002,0.000000e+000,3,9.991074e-001,0.000000e+000,,,,,,,,,,,,,,24,1,4.000000e+000,2.648010e-001,0.000000e+000,0,,0,
1687369561.407,,1.000000e+001,3.900591e+002,3.722376e-002,0.000000e+000,3,9.990832e-001,0.000000e+000,,,,,,,,,,,,,,24,1,4.000000e+000,3.129272e-001,0.000000e+000,0,,0,
1687369580.532,,1.000000e+001,3.899748e+002,3.722321e-002,0.000000e+000,3,9.990780e-001,0.000000e+000,,,,,,,,,,,,,,24,1,4.000000e+000,4.809570e-002,0.000000e+000,0,,0,
1687369598.965,,1.000000e+001,3.899628e+002,3.722319e-002,0.000000e+000,3,9.991003e-001,0.000000e+000,,,,,,,,,,,,,,24,1,4.000000e+000,7.211304e-002,0.000000e+000,0,,0,
1687369618.379,,1.000000e+001,3.900469e+002,3.722434e-002,0.000000e+000,3,9.990799e-001,0.000000e+000,,,,,,,,,,,,,,24,1,4.000000e+000,9.628296e-002,0.000000e+000,0,,0,
1687369636.881,,1.000000e+001,3.899627e+002,3.722399e-002,0.000000e+000,3,9.990663e-001,0.000000e+000,,,,,,,,,,,,,,24,1,4.000000e+000,1.203003e-001,0.000000e+000,0,,0,
1687369655.383,,1.000000e+001,3.900470e+002,3.722484e-002,0.000000e+000,3,9.990833e-001,0.000000e+000,,,,,,,,,,,,,,24,1,4.000000e+000,1.441956e-001,0.000000e+000,0,,0,
1687369674.039,,1.000000e+001,3.902035e+002,3.722388e-002,0.000000e+000,3,9.990894e-001,0.000000e+000,,,,,,,,,,,,,,24,1,4.000000e+000,2.410889e-002,0.000000e+000,0,,0,
1687369692.464,,1.000000e+001,3.900952e+002,3.722527e-002,0.000000e+000,3,9.990954e-001,0.000000e+000,,,,,,,,,,,,,,24,1,4.000000e+000,2.406006e-001,0.000000e+000,0,,0,
1687369710.152,,1.000000e+001,3.900711e+002,3.722503e-002,0.000000e+000,3,9.990951e-001,0.000000e+000,,,,,,,,,,,,,,24,1,4.000000e+000,1.923828e-001,0.000000e+000,0,,0,
1687369728.284,,1.000000e+001,3.899507e+002,3.722551e-002,0.000000e+000,3,9.990865e-001,0.000000e+000,,,,,,,,,,,,,,24,1,4.000000e+000,0.000000e+000,0.000000e+000,0,,0,
1687369746.870,,1.000000e+001,3.898546e+002,3.722546e-002,0.000000e+000,3,9.990962e-001,0.000000e+000,,,,,,,,,,,,,,24,1,4.000000e+000,9.609985e-002,0.000000e+000,0,,0,
1687369764.671,,1.000000e+001,3.900950e+002,3.722585e-002,0.000000e+000,3,9.990734e-001,0.000000e+000,,,,,,,,,,,,,,24,1,4.000000e+000,9.628296e-002,0.000000e+000,0,,0,
1687369782.273,,1.000000e+001,3.900109e+002,3.722643e-002,0.000000e+000,3,9.990834e-001,0.000000e+000,,,,,,,,,,,,,,24,1,4.000000e+000,1.683960e-001,0.000000e+000,0,,0,
1687369801.179,,1.000000e+001,3.899868e+002,3.722520e-002,0.000000e+000,3,9.990832e-001,0.000000e+000,,,,,,,,,,,,,,24,1,4.000000e+000,1.202087e-001,0.000000e+000,0,,0,
1687369820.143,,1.000000e+001,3.900109e+002,3.722528e-002,0.000000e+000,3,9.990959e-001,0.000000e+000,,,,,,,,,,,,,,24,1,4.000000e+000,2.645874e-001,0.000000e+000,0,,0,
1687369837.762,,1.000000e+001,3.899628e+002,3.722626e-002,0.000000e+000,3,9.990772e-001,0.000000e+000,,,,,,,,,,,,,,24,1,4.000000e+000,2.420044e-002,0.000000e+000,0,,0,