File: ZFC_FC/MPMS_Li0.6Al0.4 ZFC 1k Oe.dc.dat
[Header]
TITLE,MPMS DC Measurement
BYAPP,MPMS Measurement,2.1,Summary
FILEOPENTIME, 1687521323.720000 6/23/2023, 1:55:23 PM

INFO, APPNAME, MPMS MultiVu Application, Revision 1.60,  Build 081

INFO, NAME, Li0.6Al0.4Fe5O8
INFO, WEIGHT, 85.250
INFO, AREA, 0.000
INFO, LENGTH, 0.000
INFO, SHAPE,
INFO, COMMENT, cotton: 29.92 mg, capsule:40.26 mg
INFO, SEQUENCE FILE: ZFCF.seq


INFO, BACKGROUND DATA FILE:, None


STARTUPAXIS,X,4,LINEAR,AUTO,0.000000,0.000000
STARTUPAXIS,Y1,5,LINEAR,AUTO,0.000000,0.000000


STARTUPGROUP,Longitudinal
FIELDGROUP,Longitudinal,1,2,3,4,5,6,7,8,9,15,16,17,18,27,28
FIELDGROUP,Transverse,1,2,3,4,10,11,12,13,14,19,20,21,22,27,28

PLOT_APPEARANCE,ALL,HORZ_GRID_ON,VERT_GRID_ON,MARKERS_AND_LINES

[Data]
Time,Comment,Field (Oe),Temperature (K),Long Moment (emu),Long Scan Std Dev,Long Algorithm,Long Reg Fit,Long Percent Error (%),Trans Moment (emu),Trans Scan Std Dev,Trans Algorithm,Trans Reg Fit,Trans Percent Error (%),Long Moment [w/o ABS] (emu),Long Scan Std Dev [w/o ABS],Long Reg Fit [w/o ABS],Long Percent Error [w/o ABS] (%),Trans Moment [w/o ABS] (emu),Trans Scan Std Dev [w/o ABS],Trans Reg Fit [w/o ABS],Trans Percent Error [w/o ABS] (%),Points per Scan,Scans per Measurement,Scan Length (cm),Delta Temp (K),Rot Position (deg),Error,EC Comp. Running,Using ABS,
1687521323.712,,9.999999e+002,4.997795e+000,1.208266e+000,0.000000e+000,3,9.888126e-001,0.000000e+000,,,,,,,,,,,,,,24,1,4.000000e+000,7.481575e-004,0.000000e+000,0,,0,
1687521400.973,,9.999999e+002,1.278947e+001,1.209331e+000,0.000000e+000,3,9.891651e-001,0.000000e+000,,,,,,,,,,,,,,24,1,4.000000e+000,1.864430e+000,0.000000e+000,0,,0,
1687521444.047,,9.999999e+002,1.951488e+001,1.210203e+000,0.000000e+000,3,9.891553e-001,0.000000e+000,,,,,,,,,,,,,,24,1,4.000000e+000,2.145390e+000,0.000000e+000,0,,0,
1687521485.643,,9.999999e+002,2.611311e+001,1.210686e+000,0.000000e+000,3,9.890087e-001,0.000000e+000,,,,,,,,,,,,,,24,1,4.000000e+000,2.244110e+000,0.000000e+000,0,,0,
1687521525.583,,9.999999e+002,3.268987e+001,1.211623e+000,0.000000e+000,3,9.891414e-001,0.000000e+000,,,,,,,,,,,,,,24,1,4.000000e+000,2.448660e+000,0.000000e+000,0,,0,
1687521568.024,,9.999999e+002,3.932869e+001,1.212159e+000,0.000000e+000,3,9.890900e-001,0.000000e+000,,,,,,,,,,,,,,24,1,4.000000e+000,2.144463e+000,0.000000e+000,0,,0,
1687521607.227,,9.999999e+002,4.571313e+001,1.212718e+000,0.000000e+000,3,9.891713e-001,0.000000e+000,,,,,,,,,,,,,,24,1,4.000000e+000,2.290352e+000,0.000000e+000,0,,0,
1687521649.224,,9.999999e+002,5.234639e+001,1.213022e+000,0.000000e+000,3,9.891761e-001,0.000000e+000,,,,,,,,,,,,,,24,1,4.000000e+000,2.778030e+000,0.000000e+000,0,,0,
1687521688.695,,9.999999e+002,5.881575e+001,1.213464e+000,0.000000e+000,3,9.891716e-001,0.000000e+000,,,,,,,,,,,,,,24,1,4.000000e+000,2.526123e+000,0.000000e+000,0,,0,
1687521728.517,,9.999999e+002,6.557535e+001,1.213843e+000,0.000000e+000,3,9.892083e-001,0.000000e+000,,,,,,,,,,,,,,24,1,4.000000e+000,2.533882e+000,0.000000e+000,0,,0,
1687521766.237,,9.999999e+002,7.176493e+001,1.214025e+000,0.000000e+000,3,9.892265e-001,0.000000e+000,,,,,,,,,,,,,,24,1,4.000000e+000,2.671021e+000,0.000000e+000,0,,0,
1687521804.546,,9.999999e+002,7.821786e+001,1.214207e+000,0.000000e+000,3,9.892937e-001,0.000000e+000,,,,,,,,,,,,,,24,1,4.000000e+000,2.764511e+000,0.000000e+000,0,,0,
1687521845.968,,9.999999e+002,8.520567e+001,1.214341e+000,0.000000e+000,3,9.893382e-001,0.000000e+000,,,,,,,,,,,,,,24,1,4.000000e+000,2.414955e+000,0.000000e+000,0,,0,
1687521883.363,,9.999999e+002,9.152350e+001,1.214588e+000,0.000000e+000,3,9.893454e-001,0.000000e+000,,,,,,,,,,,,,,24,1,4.000000e+000,2.708710e+000,0.000000e+000,0,,0,
1687521925.531,,9.999999e+002,9.853804e+001,1.214572e+000,0.000000e+000,3,9.894077e-001,0.000000e+000,,,,,,,,,,,,,,24,1,4.000000e+000,2.684807e+000,0.000000e+000,0,,0,
1687521959.697,,9.999999e+002,1.045097e+002,1.214614e+000,0.000000e+000,3,9.893870e-001,0.000000e+000,,,,,,,,,,,,,,24,1,4.000000e+000,2.334801e+000,0.000000e+000,0,,0,
1687522001.902,,9.999999e+002,1.114476e+002,1.214636e+000,0.000000e+000,3,9.893612e-001,0.000000e+000,,,,,,,,,,,,,,24,1,4.000000e+000,2.470497e+000,0.000000e+000,0,,0,
1687522038.208,,9.999999e+002,1.176563e+002,1.214815e+000,0.000000e+000,3,9.893499e-001,0.000000e+000,,,,,,,,,,,,,,24,1,4.000000e+000,2.327896e+000,0.000000e+000,0,,0,
1687522075.922,,9.999999e+002,1.239922e+002,1.214535e+000,0.000000e+000,3,9.894170e-001,0.000000e+000,,,,,,,,,,,,,,24,1,4.000000e+000,2.412804e+000,0.000000e+000,0,,0,
1687522115.981,,9.999999e+002,1.308918e+002,1.214080e+000,0.000000e+000,3,9.893803e-001,0.000000e+000,,,,,,,,,,,,,,24,1,4.000000e+000,2.412903e+000,0.000000e+000,0,,0,
1687522152.958,,9.999999e+002,1.370807e+002,1.213555e+000,0.000000e+000,3,9.894841e-001,0.000000e+000,,,,,,,,,,,,,,24,1,4.000000e+000,2.415405e+000,0.000000e+000,0,,0,
1687522193.641,,9.999999e+002,1.438604e+002,1.212850e+000,0.000000e+000,3,9.895692e-001,0.000000e+000,,,,,,,,,,,,,,24,1,4.000000e+000,2.556686e+000,0.000000e+000,0,,0,
1687522231.083,,9.999999e+002,1.500396e+002,1.212089e+000,0.000000e+000,3,9.895148e-001,0.000000e+000,,,,,,,,,,,,,,24,1,4.000000e+000,2.876007e+000,0.000000e+000,0,,0,
1687522272.215,,9.999999e+002,1.571648e+002,1.211007e+000,0.000000e+000,3,9.896694e-001,0.000000e+000,,,,,,,,,,,,,,24,1,4.000000e+000,2.518204e+000,0.000000e+000,0,,0,
1687522309.711,,9.999999e+002,1.633947e+002,1.210007e+000,0.000000e+000,3,9.896587e-001,0.000000e+000,,,,,,,,,,,,,,24,1,4.000000e+000,2.496506e+000,0.000000e+000,0,,0,
1687522348.180,,9.999999e+002,1.698436e+002,1.208962e+000,0.000000e+000,3,9.896358e-001,0.000000e+000,,,,,,,,,,,,,,24,1,4.000000e+000,2.968002e+000,0.000000e+000,0,,0,
1687522389.856,,9.999999e+002,1.766292e+002,1.207527e+000,0.000000e+000,3,9.897012e-001,0.000000e+000,,,,,,,,,,,,,,24,1,4.000000e+000,2.733887e+000,0.000000e+000,0,,0,
1687522427.049,,9.999999e+002,1.828885e+002,1.206186e+000,0.000000e+000,3,9.897105e-001,0.000000e+000,,,,,,,,,,,,,,24,1,4.000000e+000,3.199295e+000,0.000000e+000,0,,0,
1687522464.919,,9.999999e+002,1.892670e+002,1.204814e+000,0.000000e+000,3,9.897153e-001,0.000000e+000,,,,,,,,,,,,,,24,1,4.000000e+000,2.785004e+000,0.000000e+000,0,,0,
1687522505.764,,9.999999e+002,1.961123e+002,1.202924e+000,0.000000e+000,3,9.897672e-001,0.000000e+000,,,,,,,,,,,,,,24,1,4.000000e+000,2.419403e+000,0.000000e+000,0,,0,
1687522542.795,,9.999999e+002,2.022735e+002,1.201268e+000,0.000000e+000,3,9.898115e-001,0.000000e+000,,,,,,,,,,,,,,24,1,4.000000e+000,2.792297e+000,0.000000e+000,0,,0,
1687522584.920,,9.999999e+002,2.093640e+002,1.199160e+000,0.000000e+000,3,9.898435e-001,0.000000e+000,,,,,,,,,,,,,,24,1,4.000000e+000,2.714600e+000,0.000000e+000,0,,0,
1687522621.752,,9.999999e+002,2.155592e+002,1.197266e+000,0.000000e+000,3,9.899184e-001,0.000000e+000,,,,,,,,,,,,,,24,1,4.000000e+000,2.388000e+000,0.000000e+000,0,,0,
1687522660.161,,9.999999e+002,2.220780e+002,1.195041e+000,0.000000e+000,3,9.899181e-001,0.000000e+000,,,,,,,,,,,,,,24,1,4.000000e+000,2.528900e+000,0.000000e+000,0,,0,
1687522703.202,,9.999999e+002,2.291733e+002,1.192276e+000,0.000000e+000,3,9.899856e-001,0.000000e+000,,,,,,,,,,,,,,24,1,4.000000e+000,2.621597e+000,0.000000e+000,0,,0,
1687522738.516,,9.999999e+002,2.352094e+002,1.190110e+000,0.000000e+000,3,9.900199e-001,0.000000e+000,,,,,,,,,,,,,,24,1,4.000000e+000,2.483902e+000,0.000000e+000,0,,0,
1687522779.049,,9.999999e+002,2.419071e+002,1.187662e+000,0.000000e+000,3,9.899929e-001,0.000000e+000,,,,,,,,,,,,,,24,1,4.000000e+000,2.488403e+000,0.000000e+000,0,,0,
1687522815.872,,9.999999e+002,2.479344e+002,1.185235e+000,0.000000e+000,3,9.900461e-001,0.000000e+000,,,,,,,,,,,,,,24,1,4.000000e+000,2.847107e+000,0.000000e+000,0,,0,
1687522856.741,,9.999999e+002,2.548514e+002,1.182145e+000,0.000000e+000,3,9.901529e-001,0.000000e+000,,,,,,,,,,,,,,24,1,4.000000e+000,2.863892e+000,0.000000e+000,0,,0,
1687522894.465,,9.999999e+002,2.611801e+002,1.179129e+000,0.000000e+000,3,9.901910e-001,0.000000e+000,,,,,,,,,,,,,,24,1,4.000000e+000,2.470001e+000,0.000000e+000,0,,0,
1687522934.248,,9.999999e+002,2.676951e+002,1.176042e+000,0.000000e+000,3,9.901637e-001,0.000000e+000,,,,,,,,,,,,,,24,1,4.000000e+000,2.685791e+000,0.000000e+000,0,,0,
1687522977.080,,9.999999e+002,2.748032e+002,1.172636e+000,0.000000e+000,3,9.901553e-001,0.000000e+000,,,,,,,,,,,,,,24,1,4.000000e+000,2.892700e+000,0.000000e+000,0,,0,
1687523011.767,,9.999999e+002,2.807380e+002,1.170335e+000,0.000000e+000,3,9.899703e-001,0.000000e+000,,,,,,,,,,,,,,24,1,4.000000e+000,2.463806e+000,0.000000e+000,0,,0,
1687523053.530,,9.999999e+002,2.876508e+002,1.167068e+000,0.000000e+000,3,9.897941e-001,0.000000e+000,,,,,,,,,,,,,,24,1,4.000000e+000,2.729492e+000,0.000000e+000,0,,0,
1687523090.860,,9.999999e+002,2.938066e+002,1.163924e+000,0.000000e+000,3,9.897827e-001,0.000000e+000,,,,,,,,,,,,,,24,1,4.000000e+000,2.303711e+000,0.000000e+000,0,,0,
1687523130.770,,9.999999e+002,3.005817e+002,1.160173e+000,0.000000e+000,3,9.896021e-001,0.000000e+000,,,,,,,,,,,,,,24,1,4.000000e+000,3.003082e+000,0.000000e+000,0,,0,
1687523169.229,,9.999999e+002,3.071022e+002,1.156553e+000,0.000000e+000,3,9.897138e-001,0.000000e+000,,,,,,,,,,,,,,24,1,4.000000e+000,2.572601e+000,0.000000e+000,0,,0,
1687523207.036,,9.999999e+002,3.134491e+002,1.152865e+000,0.000000e+000,3,9.895580e-001,0.000000e+000,,,,,,,,,,,,,,24,1,4.000000e+000,2.441803e+000,0.000000e+000,0,,0,
1687523250.311,,9.999999e+002,3.203032e+002,1.148558e+000,0.000000e+000,3,9.895241e-001,0.000000e+000,,,,,,,,,,,,,,24,1,4.000000e+000,2.746490e+000,0.000000e+000,0,,0,
1687523286.374,,9.999999e+002,3.266243e+002,1.144796e+000,0.000000e+000,3,9.895408e-001,0.000000e+000,,,,,,,,,,,,,,24,1,4.000000e+000,2.394775e+000,0.000000e+000,0,,0,
1687523325.181,,9.999999e+002,3.331516e+002,1.140608e+000,0.000000e+000,3,9.894006e-001,0.000000e+000,,,,,,,,,,,,,,24,1,4.000000e+000,2.581604e+000,0.000000e+000,0,,0,
1687523364.228,,9.999999e+002,3.394671e+002,1.136147e+000,0.000000e+000,3,9.895903e-001,0.000000e+000,,,,,,,,,,,,,,24,1,4.000000e+000,2.217590e+000,0.000000e+000,0,,0,
1687523402.123,,9.999999e+002,3.456802e+002,1.132065e+000,0.000000e+000,3,9.893951e-001,0.000000e+000,,,,,,,,,,,,,,24,1,4.000000e+000,2.566681e+000,0.000000e+000,0,,0,
1687523441.341,,9.999999e+002,3.523421e+002,1.127436e+000,0.000000e+000,3,9.894323e-001,0.000000e+000,,,,,,,,,,,,,,24,1,4.000000e+000,2.613403e+000,0.000000e+000,0,,0,
1687523479.581,,9.999999e+002,3.587411e+002,1.123043e+000,0.000000e+000,3,9.894052e-001,0.000000e+000,,,,,,,,,,,,,,24,1,4.000000e+000,2.551697e+000,0.000000e+000,0,,0,
1687523519.879,,9.999999e+002,3.653445e+002,1.118481e+000,0.000000e+000,3,9.892412e-001,0.000000e+000,,,,,,,,,,,,,,24,1,4.000000e+000,2.187683e+000,0.000000e+000,0,,0,
1687523560.444,,9.999999e+002,3.721750e+002,1.113856e+000,0.000000e+000,3,9.892265e-001,0.000000e+000,,,,,,,,,,,,,,24,1,4.000000e+000,2.600891e+000,0.000000e+000,0,,0,
1687523602.104,,9.999999e+002,3.792039e+002,1.108904e+000,0.000000e+000,3,9.890341e-001,0.000000e+000,,,,,,,,,,,,,,24,1,4.000000e+000,2.453003e+000,0.000000e+000,0,,0,
1687523639.754,,9.999999e+002,3.854277e+002,1.103895e+000,0.000000e+000,3,9.890211e-001,0.000000e+000,,,,,,,,,,,,,,24,1,4.000000e+000,2.418671e+000,0.000000e+000,0,,0,
1687523934.926,,9.999999e+002,3.899267e+002,1.093765e+000,0.000000e+000,3,9.883685e-001,0.000000e+000,,,,,,,,,,,,,,24,1,4.000000e+000,1.441956e-001,0.000000e+000,0,,0,