File: ZFC_FC/PPMS_Li0.5Al0.5Fe5O8_1 kOe.dat
[Header]
; VSM Data File (default extension .dat)
; Copyright (c) 2003, Quantum Design, Inc. All rights reserved.
TITLE,Li0.5Al0.5Fe5O8
FILEOPENTIME,15320102.91,06/27/2023,4:37 pm
BYAPP,VSM,1.0,1.0
INFO,PPMS VSM Option Release 1.3.6 Build 0,APPNAME
INFO,LB510,COIL_SERIAL_NUMBER
INFO,0,MOMENT_UNITS
INFO,Li0.5Al0.5Fe5O8 +PVA,SAMPLE_MATERIAL
INFO,,SAMPLE_COMMENT
INFO,11.59,SAMPLE_MASS
INFO,,SAMPLE_VOLUME
INFO,,SAMPLE_MOLECULAR_WEIGHT
INFO,3 mm diameter,SAMPLE_SIZE
INFO,pellet,SAMPLE_SHAPE
INFO,34.24,SAMPLE_OFFSET
DATATYPE,COMMENT,1
DATATYPE,TIME,2
STARTUPAXIS,X,2
STARTUPAXIS,Y1,5
[Data]
Comment,Time Stamp (sec),Temperature (K),Magnetic Field (Oe),Moment (emu),M. Std. Err. (emu),Transport Action,Averaging Time (sec),Frequency (Hz),Peak Amplitude (mm),Center Position (mm),Coil Signal' (mV),Coil Signal" (mV),Range (mV),M. Quad. Signal (emu),M. Raw' (emu),M. Raw" (emu),Min. Temperature (K),Max. Temperature (K),Min. Field (Oe),Max. Field (Oe),Mass (grams),Motor Lag (deg),Pressure (Torr),VSM Status (code),Motor Status (code),Measure Status (code),PPMS Status (code),System Temp. (K),System Field (Oe),Sample Position (deg),Bridge 1 Resistance (ohms),Bridge 1 Excitation (µA),Bridge 2 Resistance (ohms),Bridge 2 Excitation (µA),Bridge 3 Resistance (ohms),Bridge 3 Excitation (µA),Bridge 4 Resistance (ohms),Bridge 4 Excitation (µA),Signal 1 Vin (V),Signal 2 Vin (V),Digital Inputs (code),Drive 1 Iout (mA),Drive 1 Ipower (W),Drive 2 Iout (mA),Drive 2 Ipower (W),Pressure (),Map 20 (),Map 21 (),Map 22 (),Map 23 (),Map 24 (),Map 25 (),Map 26 (),Map 27 (),Map 28 (),Map 29 ()
,15320830.885,303.085144042969,1000.063,0.240802114559423,4.94655646780833E-6,1,15.0002345885404,40.1327056884766,2.0063939714686,8.940001539886,1.33556700555603,0.126567758868998,2.5,-0.00017350446570178,0.24079232723369,0.000764723452929656,294.9748535,294.9748535,1000.063,1000.063,57.1096877576022,20.6602804782393,9.2E-6,0,0,0,5906,294.609,1000.063,,,,,,,,,,,,,,,,,211.928238,,,,,,294.9748535,,,,
,15320955.14,314.053131103516,1000.063,0.239376905851896,5.06587783155713E-6,1,15.0002345885404,40.1327056884766,2.00550424666819,8.940001539886,1.32756705840397,0.12562542787929,25,-0.000205483657282158,0.239367048076291,0.000727279727781192,295.0101929,295.0126038,1000.063,1000.063,57.4934673605446,20.6703115105448,9.15E-6,0,0,0,5906,294.5857,1000.063,,,,,,,,,,,,,,,,,212.294205,,,,,,295.01139835,,,,
,15321075.12,323.992248535156,1000.063,0.237961212334319,4.38670784688867E-6,1,15.0002345885404,40.1327056884766,2.0057503639313,8.940001539886,1.31987631486413,0.124859269678653,25,-0.00021139945956699,0.237951220699428,0.000716117139760399,295.0389099,295.0413513,1000.063,1000.063,57.3918556530445,20.6918202145996,9.15E-6,0,0,0,5906,294.51365,1000.063,,,,,,,,,,,,,,,,,212.660156,,,,,,295.0401306,,,,
,15321195.23,334.046234130859,1000.063,0.236462006348312,4.14316617302015E-6,1,15.0002345885404,40.1327056884766,2.00599870426556,8.940001539886,1.31172447725485,0.124027897897769,25,-0.000221141509428164,0.236452006200095,0.000700847110695625,295.0526123,295.0528564,1000.063,1000.063,57.3152560581599,20.7026664586394,9.1E-6,0,0,0,5906,294.429,1000.063,,,,,,,,,,,,,,,,,211.928238,,,,,,295.05273435,,,,
,15321315.095,344.149627685547,1000.063,0.234899300364219,3.76093283552868E-6,1,15.0002345885404,40.1327056884766,2.00608296513326,8.940001539886,1.30310821605052,0.123218784764836,25,-0.000218997985028648,0.234889291031984,0.000697212631884704,295.0583801,295.0598755,1000.063,1000.063,57.6935642614676,20.7110167602994,9.15E-6,0,0,0,5906,294.34385,1000.063,,,,,,,,,,,,,,,,,211.928238,,,,,,295.0591278,,,,
,15321435.195,354.173950195313,1000.063,0.233268730236108,3.79315782591724E-6,1,15.0002345885404,40.1327056884766,2.00584684327783,8.940001539886,1.29391697979359,0.122313951943881,25,-0.000224239770380024,0.233258770837156,0.000685988381272122,295.0606079,295.0606995,1000.063,1000.063,57.6427584077176,20.7159004158895,9.2E-6,0,0,0,5906,294.24135,1000.063,,,,,,,,,,,,,,,,,212.660156,,,,,,295.0606537,,,,
,15321555.19,364.211608886719,1000.063,0.231551294992628,2.55607718173645E-6,1,15.0002345885404,40.1327056884766,2.0056983554853,8.940001539886,1.28430151737712,0.121363053554947,25,-0.000230372561895252,0.231541412301632,0.000673441924074364,295.0603027,295.0609131,1000.063,1000.063,57.8326941378907,20.7241965824162,9.2E-6,0,0,0,5906,294.1627,1000.063,,,,,,,,,,,,,,,,,212.660156,,,,,,295.0606079,,,,
,15321675.085,374.266815185547,1000.063,0.22978584867138,4.28518012085479E-6,1,15.0002345885404,40.1327056884766,2.00573646582401,8.940001539886,1.27453372286256,0.120431622574542,25,-0.00023043260340085,0.229776015595824,0.000666806156576762,295.0605774,295.0615234,1000.063,1000.063,58.2149104837946,20.7271507409206,9.15E-6,0,0,0,5906,294.07585,1000.063,,,,,,,,,,,,,,,,,211.928238,,,,,,295.0610504,,,,
,15321795.125,384.263458251953,1000.063,0.227945083603807,1.48635188172323E-6,1,15.0002345885404,40.1327056884766,2.00570846678331,8.93000192940235,1.26430368714702,0.119492628742938,25,-0.000223984385150178,0.227935280053817,0.000666405126873066,295.0598145,295.0620117,1000.063,1000.063,57.7381170870638,20.7281160764772,9.2E-6,0,0,0,5906,293.9819,1000.063,,,,,,,,,,,,,,,,,212.294205,,,,,,295.0609131,,,,
,15321915.125,394.197662353516,1000.063,0.226063199116696,3.99638306711337E-6,1,15.0002345885404,40.1327056884766,2.00566283245383,8.940001539886,1.25383588219465,0.118523234112177,25,-0.000218826098077864,0.226053438851373,0.000664467297227048,295.0596008,295.0623779,1000.063,1000.063,57.6357237510446,20.7337052917698,9.15E-6,0,0,0,5906,293.9106,1000.063,,,,,,,,,,,,,,,,,211.928238,,,,,,295.06098935,,,,
,15322035.085,404.271057128906,1000.063,0.224094586998148,4.13695241013913E-6,1,15.0002345885404,40.1327056884766,2.00566972549079,8.940001539886,1.24292709735605,0.11742878192827,25,-0.000228576386174443,0.224084912054185,0.000647376609448162,295.0619202,295.0637817,1000.063,1000.063,57.7342089444676,20.7311856646473,9.15E-6,0,0,0,5906,293.81165,1000.063,,,,,,,,,,,,,,,,,212.660156,,,,,,295.06285095,,,,
,15322155.15,414.284454345703,1000.063,0.222065620663092,4.1577873591652E-6,1,15.0002345885404,40.1327056884766,2.00555361014181,8.940001539886,1.23160988272348,0.1162946790376,25,-0.000238434960525079,0.222056046728047,0.000629920993222376,295.0627441,295.063446,1000.063,1000.063,57.74202522966,20.7298485313528,9.2E-6,0,0,0,5906,293.7169,1000.063,,,,,,,,,,,,,,,,,212.294205,,,,,,295.06309505,,,,
,15322275.1,424.292602539063,1000.063,0.219971795022139,2.99909592166626E-6,1,15.0002345885404,40.1327056884766,2.00528323865383,8.940001539886,1.21984624350875,0.1150800972051,25,-0.000255064324699302,0.219962354929093,0.000605429428198917,295.061676,295.0643311,1000.063,1000.063,57.5348936720638,20.7257179771464,9.15E-6,0,0,0,5906,293.62385,1000.063,,,,,,,,,,,,,,,,,213.026108,,,,,,295.06300355,,,,
,15322395.205,434.316864013672,1000.063,0.217783747229524,2.17417359588067E-6,1,15.0002345885404,40.1327056884766,2.0050513260744,8.940001539886,1.20758204409542,0.113858080429665,25,-0.000264513460951979,0.217774410963678,0.000587785956549979,295.0632324,295.0635376,1000.063,1000.063,57.5145713305638,20.7186175947414,9.2E-6,0,0,0,5906,293.5184,1000.063,,,,,,,,,,,,,,,,,213.026108,,,,,,295.063385,,,,
,15322515.15,444.357452392578,1000.063,0.215561686019017,4.03660245231209E-6,1,15.0002345885404,40.1327056884766,2.00485769839536,8.940001539886,1.19515779339086,0.112582664607979,25,-0.000280693821621206,0.215552458692707,0.000563199923681516,295.0680237,295.0694275,1000.063,1000.063,57.6208728091792,20.7203391044926,9.15E-6,0,0,0,5906,293.4338,1000.063,,,,,,,,,,,,,,,,,212.294205,,,,,,295.0687256,,,,
,15322635.18,454.462921142578,1000.063,0.21329077449158,5.62612646871829E-6,1,15.0002345885404,40.1327056884766,2.00445890370803,8.940001539886,1.18233813743891,0.111363464825952,25,-0.000280193259628535,0.2132816166181,0.000555192299459999,295.0686646,295.0691528,1000.063,1000.063,58.3430975609485,20.7155524622372,9.2E-6,0,0,0,5906,293.3211,1000.063,,,,,,,,,,,,,,,,,212.294205,,,,,,295.0689087,,,,
,15322755.085,464.434600830078,1000.063,0.210909661769991,4.08861901003402E-6,1,15.0002345885404,40.1327056884766,2.00447239838336,8.940001539886,1.1691311171921,0.110280942068392,25,-0.000248502566604474,0.2109004631978,0.000577859193861319,295.0684814,295.0700684,1000.063,1000.063,57.8412920516023,20.7136342785011,9.2E-6,0,0,0,5906,293.2306,1000.063,,,,,,,,,,,,,,,,,213.026108,,,,,,295.0692749,,,,
,15322875.18,474.469970703125,1000.063,0.20848785746908,2.33589970685784E-6,1,15.0002345885404,40.1327056884766,2.00441317083393,8.940001539886,1.15568140166236,0.108921113796316,25,-0.00026228310569716,0.208478782253491,0.000554925075946875,295.0715332,295.0722961,1000.063,1000.063,57.5184794731599,20.7158719734272,9.2E-6,0,0,0,5906,293.1298,1000.063,,,,,,,,,,,,,,,,,212.294205,,,,,,295.07191465,,,,
,15322995.14,484.460876464844,1000.063,0.205979445632125,3.56191850376466E-6,1,15.0002345885404,40.1327056884766,2.00411673732743,8.940001539886,1.14161973245382,0.107511170349699,25,-0.000274652462337284,0.205970495972036,0.000533109641948558,295.072876,295.0736389,1000.063,1000.063,57.8928795338715,20.7202466746397,9.2E-6,0,0,0,5906,293.01235,1000.063,,,,,,,,,,,,,,,,,213.026108,,,,,,295.07325745,,,,
,15323115.085,494.495056152344,1000.063,0.203398660537447,2.24237290402294E-6,1,15.0002345885404,40.1327056884766,2.00403994177865,8.940001539886,1.12728829624869,0.106005710791482,25,-0.000299428643815623,0.20338988495667,0.000498565473858711,295.0756226,295.0762024,1000.063,1000.063,57.4348452216022,20.7201644105717,9.2E-6,0,0,0,5906,292.904,1000.063,,,,,,,,,,,,,,,,,212.294205,,,,,,295.0759125,,,,
,15323235.11,504.504638671875,1000.063,0.200840104073977,4.39216635554697E-6,1,15.0002345885404,40.1327056884766,2.00405280389976,8.940001539886,1.1131122978585,0.104699533599829,25,-0.000291224303216954,0.200831375694366,0.000497100665402511,295.077179,295.0783997,1000.063,1000.063,57.596642325083,20.7136796393662,9.2E-6,0,0,0,5906,292.78885,1000.063,,,,,,,,,,,,,,,,,212.294205,,,,,,295.07778935,,,,
,15323355.21,514.586120605469,1000.063,0.198239883525399,3.2134214460594E-6,1,15.0002345885404,40.1327056884766,2.0039881204488,8.940001539886,1.0986601313377,0.103403838709242,25,-0.000276483012835067,0.198231160299145,0.00050205330897125,295.0814514,295.0830078,1000.063,1000.063,57.6904377473907,20.7070149090305,9.2E-6,0,0,0,5906,292.6568,1000.063,,,,,,,,,,,,,,,,,211.928238,,,,,,295.0822296,,,,
,15323475.145,524.604309082031,1000.063,0.195670972457808,4.14039588929362E-6,1,15.0002345885404,40.1327056884766,2.00389889833507,8.940001539886,1.08437118023124,0.102104658004128,25,-0.000265151531288388,0.195662262195341,0.000503715200217202,295.0874023,295.087738,1000.063,1000.063,57.8420736801215,20.702444305288,9.2E-6,0,0,0,5906,292.5227,1000.063,,,,,,,,,,,,,,,,,211.928238,,,,,,295.08757015,,,,
,15323595.11,534.714904785156,1000.063,0.193052655816676,3.88350533223015E-6,1,15.0002345885404,40.1327056884766,2.00399770778818,8.940001539886,1.06991641475671,0.100700847037211,25,-0.000269585908743085,0.193044069679661,0.000489329852152124,295.085083,295.0870361,1000.063,1000.063,57.7060703177753,20.7019560008014,9.25E-6,0,0,0,5906,292.41365,1000.063,,,,,,,,,,,,,,,,,212.660156,,,,,,295.08605955,,,,
,15323715.165,544.743286132812,1000.063,0.190158193692714,3.68323425906074E-6,1,15.0002345885404,40.1327056884766,2.00408495014441,8.940001539886,1.05391251346512,0.0992719967801331,25,-0.0002521071544962,0.190149683504947,0.000495842668444814,295.0783691,295.0791626,1000.063,1000.063,57.6318156084484,20.6979603188714,9.1E-6,0,0,0,5906,292.27805,1000.063,,,,,,,,,,,,,,,,,211.928238,,,,,,295.07876585,,,,
,15323835.115,554.837280273438,1000.063,0.187068121002883,4.17687603911847E-6,1,15.0002345885404,40.1327056884766,2.00403513856159,8.940001539886,1.03675942852411,0.0976764762038812,25,-0.000244689221515614,0.187059750218163,0.000491396608992154,295.0702515,295.0715332,1000.063,1000.063,58.1070457481408,20.6952612786034,9.15E-6,0,0,0,5906,292.1813,1000.063,,,,,,,,,,,,,,,,,211.928238,,,,,,295.07089235,,,,
,15323955.1,564.858093261719,1000.063,0.183770066855694,4.25784279701129E-6,1,15.0002345885404,40.1327056884766,2.00392679755996,8.95000208169222,1.01842745299863,0.0959465221857059,25,-0.000241175006811227,0.183761816795462,0.000482225344537248,295.0709534,295.0716553,1000.063,1000.063,57.4145228801022,20.6984227027127,9.15E-6,0,0,0,5906,292.08235,1000.063,,,,,,,,,,,,,,,,,211.928238,,,,,,295.07130435,,,,
,15324075.11,574.960205078125,1000.063,0.180335976871909,4.29411018180858E-6,1,15.0002345885404,40.1327056884766,2.00393356867508,8.940001539886,0.999398830391584,0.0941580948008046,25,-0.000236231692834371,0.180327827341263,0.000473977240716433,295.0744629,295.0762329,1000.063,1000.063,57.4387533641984,20.6920681733471,9.1E-6,0,0,0,5906,291.96955,1000.063,,,,,,,,,,,,,,,,,212.660156,,,,,,295.0753479,,,,
,15324195.15,585.108093261719,1000.063,0.176427840009159,3.28866726126356E-6,1,15.0002345885404,40.1327056884766,2.00393018326406,8.940001539886,0.977738213912443,0.0921195489194635,25,-0.000231027969924285,0.176419793025342,0.000464099352855686,295.083374,295.0849304,1000.063,1000.063,58.1304946037177,20.6902684590574,9.15E-6,0,0,0,5906,291.86035,1000.063,,,,,,,,,,,,,,,,,212.660156,,,,,,295.0841522,,,,
,15324315.12,595.140197753906,1000.063,0.172994311707094,3.44920193991613E-6,1,15.0002345885404,40.1327056884766,2.00393967228192,8.940001539886,0.958711812382785,0.0903522721098114,25,-0.000222415198111571,0.172986348103223,0.000459598016994233,295.0874023,295.0879822,1000.063,1000.063,57.5685036983907,20.6840980985468,9.2E-6,0,0,0,5906,291.71155,1000.063,,,,,,,,,,,,,,,,,211.928238,,,,,,295.08769225,,,,
,15324435.155,605.136352539063,1000.063,0.169165482933359,3.60253455569181E-6,1,15.0002345885404,40.1327056884766,2.00375282950337,8.940001539886,0.937406646934464,0.0883524610884139,25,-0.000216334403927205,0.1691576604499,0.000450867521391514,295.0882874,295.0885315,1000.063,1000.063,57.220679007333,20.6850021113206,9.15E-6,0,0,0,5906,291.6075,1000.063,,,,,,,,,,,,,,,,,211.928238,,,,,,295.08840945,,,,
,15324555.12,615.197082519531,1000.063,0.16511331176789,3.84605940821042E-6,1,15.0002345885404,40.1327056884766,2.00392471711868,8.940001539886,0.915025799751482,0.0862714522296437,25,-0.000206471572637917,0.165105606550216,0.000445152190245288,295.0901489,295.0921936,1000.063,1000.063,57.8115901678715,20.6813249316164,9.2E-6,0,0,0,5906,291.4557,1000.063,,,,,,,,,,,,,,,,,211.928238,,,,,,295.09117125,,,,
,15324675.085,625.29736328125,1000.063,0.160856301688705,3.76560985107041E-6,1,15.0002345885404,40.1327056884766,2.0039322525718,8.940001539886,0.891437427364026,0.0840458262965608,25,-0.000201842964043558,0.16084874551038,0.000433381405246922,295.0939636,295.0944824,1000.063,1000.063,57.7060703177753,20.6795021793615,9.2E-6,0,0,0,5906,291.3013,1000.063,,,,,,,,,,,,,,,,,211.928238,,,,,,295.094223,,,,
,15324795.135,635.364196777344,1000.063,0.156399741214919,2.40190249208721E-6,1,15.0002345885404,40.1327056884766,2.00390228282641,8.940001539886,0.866725638198327,0.0817315616059577,25,-0.000193824736100895,0.156392351720564,0.000424163272519911,295.0931396,295.0945435,1000.063,1000.063,57.4082698519484,20.6782936747388,9.2E-6,0,0,0,5906,291.1578,1000.063,,,,,,,,,,,,,,,,,211.928238,,,,,,295.09384155,,,,
,15324915.11,645.345825195313,1000.063,0.151720193072608,3.29369034034568E-6,1,15.0002345885404,40.1327056884766,2.00387411464044,8.940001539886,0.84077850836062,0.0793114968118281,25,-0.000183590583028695,0.151712960997427,0.000416252643062712,295.0965271,295.097168,1000.063,1000.063,57.7209212596407,20.6778489852027,9.2E-6,0,0,0,5906,291.0169,1000.063,,,,,,,,,,,,,,,,,211.928238,,,,,,295.09684755,,,,
,15325035.13,655.459045410156,1000.063,0.146750537020847,2.56425859788016E-6,1,15.0002345885404,40.1327056884766,2.00387795548779,8.940001539886,0.813239833976713,0.0767126900808254,25,-0.000178137396713378,0.146743496039057,0.000402429232208847,295.0983276,295.1012878,1000.063,1000.063,57.0588819038522,20.6768657784631,9.15E-6,0,0,0,5906,290.86065,1000.063,,,,,,,,,,,,,,,,,211.928238,,,,,,295.0998077,,,,
,15325155.11,665.533996582031,1000.063,0.141498000653386,2.57117954542708E-6,1,15.0002345885404,40.1327056884766,2.00385447840936,8.940001539886,0.784121497860546,0.07398095246767,25,-0.000169438914562816,0.141491158468199,0.000390705732312655,295.1013184,295.1030884,1000.063,1000.063,57.7263926592753,20.6764578829662,9.2E-6,0,0,0,5906,290.7047,1000.063,,,,,,,,,,,,,,,,,211.562286,,,,,,295.1022034,,,,
,15325275.095,675.602111816406,1000.063,0.135851693290696,2.74482361167996E-6,1,15.0002345885404,40.1327056884766,2.003846295558,8.940001539886,0.752829444239949,0.0710216560530582,25,-0.000164274864942965,0.135845078011918,0.000373875941171841,295.1063538,295.1073914,1000.063,1000.063,57.5520894994869,20.678251212222,9.15E-6,0,0,0,5906,290.54245,1000.063,,,,,,,,,,,,,,,,,211.928238,,,,,,295.1068726,,,,
,15325395.1,685.636840820312,1000.063,0.129742659720684,2.4002032840932E-6,1,15.0002345885404,40.1327056884766,2.00380731855243,8.940001539886,0.718959520980609,0.0678533599156534,25,-0.00015240959290217,0.129736291740576,0.000361888833991912,295.105957,295.1072388,1000.063,1000.063,58.0320094102946,20.6784259348644,9.2E-6,0,0,0,5906,290.3777,1000.063,,,,,,,,,,,,,,,,,211.928238,,,,,,295.1065979,,,,
,15325515.105,695.738037109375,1000.063,0.123146291497733,2.14998982297288E-6,1,15.0002345885404,40.1327056884766,2.0037764227401,8.940001539886,0.682395856115894,0.0644014071992688,25,-0.000145191518027253,0.123140211148304,0.000343278948812708,295.1081238,295.109314,1000.063,1000.063,57.0557553897753,20.6787302291078,9.15E-6,0,0,0,5906,290.21815,1000.063,,,,,,,,,,,,,,,,,211.562286,,,,,,295.1087189,,,,
,15325635.09,705.813598632813,1000.063,0.115921923171109,2.37787594808319E-6,1,15.0002345885404,40.1327056884766,2.00383849867227,8.940001539886,0.642382068402847,0.060628148439804,25,-0.000136482051694177,0.11591615582044,0.000323687680899747,295.1111755,295.1115417,1000.063,1000.063,57.3410497992945,20.6781914475072,9.2E-6,0,0,0,5906,290.03015,1000.063,,,,,,,,,,,,,,,,,211.562286,,,,,,295.1113586,,,,
,15325755.125,715.901794433594,1000.063,0.10795572683528,1.98948429209218E-6,1,15.0002345885404,40.1327056884766,2.00371583105972,8.940001539886,0.598200827729396,0.0564642767829269,25,-0.000126334853249545,0.107950318983552,0.000302510169662739,295.1122742,295.1137085,1000.063,1000.063,58.0054340406408,20.6794297362305,9.15E-6,0,0,0,5906,289.8609,1000.063,,,,,,,,,,,,,,,,,211.196335,,,,,,295.11299135,,,,
,15325875.085,725.898742675781,1000.063,0.099147527573519,1.87342132269538E-6,1,15.0002345885404,40.1327056884766,2.00384750867715,8.940001539886,0.549428754223686,0.0518546247859659,25,-0.000117379963200449,0.0991425298493279,0.000276746349107537,295.1155396,295.1177673,1000.063,1000.063,57.4629838482945,20.676451120863,9.2E-6,0,0,0,5906,289.6937,1000.063,,,,,,,,,,,,,,,,,211.562286,,,,,,295.11665345,,,,
,15325995.12,736.009094238281,1000.063,0.0892178093803133,2.01766303598892E-6,1,15.0002345885404,40.1327056884766,2.00383817939154,8.940001539886,0.494399604258939,0.0466709211783004,25,-0.000104114099780296,0.0892132767761652,0.000250800762436956,295.1178589,295.1187744,1000.063,1000.063,57.5200427301984,20.6759470199835,9.15E-6,0,0,0,5906,289.5152,1000.063,,,,,,,,,,,,,,,,,211.562286,,,,,,295.11831665,,,,
,15326115.135,746.107238769531,1000.063,0.0777022478684052,1.31108943388059E-6,1,15.0002345885404,40.1327056884766,2.0039074279854,8.940001539886,0.430601522419001,0.0406388261138031,25,-9.26217255433945E-5,0.0776982790928148,0.000216710859234012,295.1207275,295.1222229,1000.063,1000.063,57.5427099572561,20.6754111054424,9.2E-6,0,0,0,5906,289.33675,1000.063,,,,,,,,,,,,,,,,,210.464432,,,,,,295.1214752,,,,
,15326250.18,757.360961914062,1000.063,0.0630094932152243,1.02654611569144E-6,1,15.0002345885404,40.1327056884766,2.00389430053563,8.940001539886,0.349053170815664,0.0329571837597308,2.5,-7.27167324151256E-5,0.0630062422140835,0.000178351427815515,295.1212463,295.1229858,1000.063,1000.063,57.4051433378714,20.6770518914699,9.2E-6,0,0,0,5906,289.11685,1000.063,,,,,,,,,,,,,,,,,210.09848,,,,,,295.12211605,,,,
,15326370.11,767.453491210937,1000.063,0.0485567409482846,9.12761478059819E-7,1,15.0002345885404,40.1327056884766,2.00393730062479,8.940001539886,0.268995009914664,0.0253968298557209,2.5,-5.64317939999218E-5,0.0485542123833564,0.000137199203504467,295.1291809,295.1297913,1000.063,1000.063,58.0234114965831,20.6786298244986,9.2E-6,0,0,0,5906,288.9273,1000.063,,,,,,,,,,,,,,,,,210.09848,,,,,,295.1294861,,,,
,15326490.125,777.475219726563,1000.063,0.0334887126667279,4.68123014515758E-7,1,15.0002345885404,40.1327056884766,2.00391571980422,8.940001539886,0.185518945120316,0.017516217696523,2.5,-3.89151311191816E-5,0.0334869557378109,9.47448866233182E-5,295.1311035,295.1315308,1000.063,1000.063,57.9303977027946,20.6784911214668,9.15E-6,0,0,0,5906,288.7167,1000.063,,,,,,,,,,,,,,,,,210.464432,,,,,,295.13131715,,,,
,15326610.155,787.539855957031,1000.063,0.019751543909747,3.09958391244937E-7,1,15.0002345885404,40.1327056884766,2.00397577200333,8.940001539886,0.109421897928636,0.010329032697822,2.5,-2.34342511351476E-5,0.0197505005137654,5.54689048210284E-5,295.1350708,295.1354675,1000.063,1000.063,57.7607843141215,20.6782237696965,9.2E-6,0,0,0,5906,288.49935,1000.063,,,,,,,,,,,,,,,,,210.464432,,,,,,295.13526915,,,,
,15326730.09,797.721801757812,1000.063,0.00967007093925147,2.19018001739012E-7,1,15.0002345885404,40.1327056884766,2.00398355507188,8.940001539886,0.0535718897185314,0.00505357677312223,2.5,-1.21157087162889E-5,0.00966955898623057,2.6545544748883E-5,295.137207,295.138031,1000.063,1000.063,57.5747567265446,20.6794020829748,9.1E-6,0,0,0,5906,288.3031,1000.063,,,,,,,,,,,,,,,,,210.09848,,,,,,295.137619,,,,
,15326865.105,808.983154296875,1000.063,0.00366676552286592,7.40981809197367E-8,1,15.0002345885404,40.1327056884766,2.00410047896131,8.940001539886,0.020321505634636,0.00192232355020303,0.25,-3.65353917698971E-6,0.00366656581658956,1.10211577811909E-5,295.1402893,295.1420288,1000.063,1000.063,57.4715817620061,20.6777578427793,9.15E-6,0,0,0,5906,288.0576,1000.063,,,,,,,,,,,,,,,,,210.09848,,,,,,295.14115905,,,,
,15326985.085,819.03466796875,1000.063,0.00165337451661587,3.45385136972903E-8,1,15.0002345885404,40.1327056884766,2.00409162949148,8.940001539886,0.00916313032806238,0.000866346548614471,0.25,-1.73381295811986E-6,0.00165328386343782,4.89002027748781E-6,295.1463623,295.1478271,1000.063,1000.063,56.9932251082368,20.6784580358073,9.15E-6,0,0,0,5906,287.8065,1000.063,,,,,,,,,,,,,,,,,209.732529,,,,,,295.1470947,,,,
,15327105.13,829.094482421875,1000.063,0.000933581666818894,2.27028124791788E-8,1,15.0002345885404,40.1327056884766,2.00408879329624,8.940001539886,0.0051743956130372,0.000484764270343085,0.25,-1.77995116866248E-6,0.000933533303774506,1.96369925466632E-6,295.1481934,295.1499023,1000.063,1000.063,57.1995750373137,20.677750973528,9.15E-6,0,0,0,5906,287.5848,1000.063,,,,,,,,,,,,,,,,,209.00061,,,,,,295.14904785,,,,
,15327225.085,839.177307128906,1000.063,0.000665056609313524,1.35666689810598E-8,1,15.0002345885404,40.1327056884766,2.00420973880513,8.940001539886,0.00368640285393855,0.000344332862581248,0.25,-1.45454140904334E-6,0.000665022565400607,1.21494973926881E-6,295.1525574,295.1548157,1000.063,1000.063,57.6544828355061,20.6766044623247,9.25E-6,0,0,0,5906,287.349,1000.063,,,,,,,,,,,,,,,,,209.732529,,,,,,295.15368655,,,,
,15327364.82,850.405883789063,1000.063,0.000516024709830886,1.10571408073499E-8,1,15.0002345885404,40.1327056884766,2.00421381643972,8.940001539886,0.00286060009418358,0.000264287170379981,0.25,-1.65157572908767E-6,0.000516000062906755,4.2216831676401E-7,295.1600037,295.1609192,1000.063,1000.063,57.3707516830253,20.6775020668919,9.2E-6,0,0,0,5906,287.0674,1000.063,,,,,,,,,,,,,,,,,208.634659,,,,,,295.16046145,,,,
,15327480.12,860.543090820312,1000.063,0.000415444289586978,9.90080887738018E-9,1,15.0002345885404,40.1327056884766,2.00424183756597,8.940001539886,0.00230326038805228,0.000210679359843968,0.25,-1.70964238226766E-6,0.00041542582235901,-3.85535510029191E-8,295.1600952,295.1620178,1000.063,1000.063,57.7545312859677,20.676999398731,9.2E-6,0,0,0,5906,286.84815,1000.063,,,,,,,,,,,,,,,,,208.634659,,,,,,295.1610565,,,,
,15327600.095,870.600280761719,1000.063,0.000353824190341842,6.89130225803623E-9,1,15.0002345885404,40.1327056884766,2.00416331465173,8.940001539886,0.00196134576588793,0.00018163189137068,0.25,-1.05922566524867E-6,0.000353806668544574,3.65604775322076E-7,295.1647949,295.1655579,1000.063,1000.063,57.0338697912368,20.6789849617258,9.2E-6,0,0,0,5906,286.57365,1000.063,,,,,,,,,,,,,,,,,209.00061,,,,,,295.1651764,,,,
,15327720.135,880.653259277344,1000.063,0.000333520662763628,7.50928844237856E-9,1,15.0002345885404,40.1327056884766,2.00412415514174,8.940001539886,0.0018491387751943,0.000167260811042604,0.25,-1.71175766109753E-6,0.000333506855560035,-3.67245000805271E-7,295.1679688,295.1690979,1000.063,1000.063,57.8569246219869,20.6793292083331,9.2E-6,0,0,0,5906,286.3238,1000.063,,,,,,,,,,,,,,,,,208.634659,,,,,,295.16853335,,,,
,15327840.115,890.740295410156,1000.063,0.000321251016093054,4.15889662499898E-9,1,15.0002345885404,40.1327056884766,2.00417752175189,8.940001539886,0.00178104563448242,0.000162280037006728,0.25,-1.43945722210823E-6,0.000321236664492018,-1.42915603927482E-7,295.1755066,295.1760559,1000.063,1000.063,57.860832764583,20.6791248928839,9.2E-6,0,0,0,5906,286.04555,1000.063,,,,,,,,,,,,,,,,,207.902756,,,,,,295.17578125,,,,
,15327960.095,899.968627929688,1000.063,0.000311957677025949,7.11916989870973E-9,1,15.0002345885404,40.1327056884766,2.00410244504959,8.940001539886,0.00172934934191833,0.000158718870274119,0.25,-1.19367826875351E-6,0.000311942743692967,6.67843121630305E-8,295.179718,295.1798706,1000.063,1000.063,57.6388502651215,20.67960537858,9.2E-6,0,0,0,5909,285.77165,1000.063,,,,,,,,,,,,,,,,,207.902756,,,,,,295.1797943,,,,
,15328080.105,896.549621582031,1000.063,0.000311783493020789,6.71729020931854E-9,1,15.0002345885404,40.1327056884766,2.00417763918679,8.940001539886,0.00172855803266718,0.000157503886510656,0.25,-1.39836510559921E-6,0.000311769870939918,-1.37584258536543E-7,295.1081543,295.1230164,1000.063,1000.063,57.810026910833,20.6808611857035,9.2E-6,0,0,0,5906,285.58005,1000.063,,,,,,,,,,,,,,,,,208.634659,,,,,,295.11558535,,,,
,15328200.1,886.477661132813,1000.063,0.000320142895610846,6.35139055654746E-9,1,15.0002345885404,40.1327056884766,2.00412370913553,8.940001539886,0.0017750530246253,0.000159748884569702,0.25,-1.79167577029136E-6,0.000320131695145606,-4.97532538894192E-7,294.962677,294.9816895,1000.063,1000.063,57.200356665833,20.6825378674698,9.1E-6,0,0,0,5906,285.66525,1000.063,,,,,,,,,,,,,,,,,207.536804,,,,,,294.97218325,,,,
,15328320.105,876.527587890625,1000.063,0.000332180738465604,8.26138848287415E-9,1,15.0002345885404,40.1327056884766,2.00411455545176,8.940001539886,0.00184159575128427,0.00016784484531851,0.25,-1.48053608306518E-6,0.000332168705908954,-1.39231675412073E-7,294.8648071,294.8722229,1000.063,1000.063,57.4793980471984,20.6826166270595,9.25E-6,0,0,0,5906,285.9289,1000.063,,,,,,,,,,,,,,,,,208.268707,,,,,,294.868515,,,,
,15328440.08,866.575073242188,1000.063,0.000351198800321148,7.76531297956495E-9,1,15.0002345885404,40.1327056884766,2.0041036349126,8.940001539886,0.00194702204394486,0.000177474454625881,0.25,-1.55980358105558E-6,0.000351186663098215,-1.43454971562663E-7,294.8234558,294.8252563,1000.063,1000.063,57.4559491916215,20.685350106236,9.2E-6,0,0,0,5906,286.2244,1000.063,,,,,,,,,,,,,,,,,208.268707,,,,,,294.82435605,,,,
,15328560.125,856.611328125,1000.063,0.000407497141181793,6.65922166549744E-9,1,15.0002345885404,40.1327056884766,2.00404108857357,8.940001539886,0.00225889350180947,0.000207753620870263,0.25,-1.47667409282044E-6,0.000407482032300381,1.6477163759046E-7,294.8123474,294.8133545,1000.063,1000.063,57.4973755031407,20.6873969170774,9.2E-6,0,0,0,5906,286.5064,1000.063,,,,,,,,,,,,,,,,,207.536804,,,,,,294.81285095,,,,
,15328680.11,846.544799804687,1000.063,0.000504438325976249,1.47192887311261E-8,1,15.0002345885404,40.1327056884766,2.00405288757511,8.940001539886,0.00279624560197425,0.00025762192462892,0.25,-1.74542493092874E-6,0.000504419458642462,2.83976256576569E-7,294.8178711,294.8180542,1000.063,1000.063,57.0049495360253,20.6843441654404,9.2E-6,0,0,0,5906,286.80565,1000.063,,,,,,,,,,,,,,,,,207.902756,,,,,,294.81796265,,,,
,15328800.095,836.671813964844,1000.063,0.00062386734630327,1.29746048880933E-8,1,15.0002345885404,40.1327056884766,2.0040941776354,8.940001539886,0.00345808248482646,0.0003213669186492,0.25,-1.66054287965935E-6,0.000623842131236677,8.4650943248004E-7,294.8251343,294.82724,1000.063,1000.063,57.1894138665637,20.6846726016641,9.15E-6,0,0,0,5906,287.0737,1000.063,,,,,,,,,,,,,,,,,207.902756,,,,,,294.82618715,,,,
,15328920.125,826.701965332031,1000.063,0.000828212025585666,1.48885441275182E-8,1,15.0002345885404,40.1327056884766,2.00414932003245,8.940001539886,0.00459060000719888,0.000429614784666857,0.25,-1.66405498258325E-6,0.000828176509918603,1.66044317887753E-6,294.8347473,294.8369751,1000.063,1000.063,56.8994296859291,20.6845254657702,9.15E-6,0,0,0,5906,287.3413,1000.063,,,,,,,,,,,,,,,,,207.902756,,,,,,294.8358612,,,,
,15329040.1,816.655334472656,1000.063,0.00126487240968973,2.07412566784277E-8,1,15.0002345885404,40.1327056884766,2.0040391822903,8.940001539886,0.00701003341803865,0.0006613722836738,0.25,-1.58289819592595E-6,0.00126481453619674,3.48968588341502E-6,294.8416138,294.8433533,1000.063,1000.063,57.2011382943522,20.6863263890249,9.2E-6,0,0,0,5906,287.56195,1000.063,,,,,,,,,,,,,,,,,207.170853,,,,,,294.84248355,,,,
,15329160.155,806.746032714844,1000.063,0.00228965663286617,5.33432586105929E-8,1,15.0002345885404,40.1327056884766,2.00400224365025,8.940001539886,0.0126888660328839,0.00120121720657997,0.25,-2.12882792083146E-6,0.00228954943982513,7.04429562869019E-6,294.8473511,294.8490601,1000.063,1000.063,57.6646440062561,20.6871186309637,9.2E-6,0,0,0,5906,287.8028,1000.063,,,,,,,,,,,,,,,,,207.902756,,,,,,294.8482056,,,,
,15329280.245,796.765441894531,1000.063,0.00482371415053261,1.25782645954738E-7,1,15.0002345885404,40.1327056884766,2.00400316099007,8.940001539886,0.02673174252716,0.00253517510717787,0.25,-3.65256920246614E-6,0.00482348591767439,1.5656094390181E-5,294.853302,294.8533325,1000.063,1000.063,58.0828152640446,20.6886352237321,9.2E-6,0,0,0,5906,288.0113,1000.063,,,,,,,,,,,,,,,,,207.170853,,,,,,294.85331725,,,,
,15329400.085,786.776306152344,1000.063,0.0102868078377996,1.65631726659952E-7,1,15.0002345885404,40.1327056884766,2.00403101891272,8.940001539886,0.0570068790322798,0.00541347908727941,0.25,-6.48225393552026E-6,0.0102863195495186,3.4653832395507E-5,294.8542786,294.8544006,1000.063,1000.063,56.8376810329099,20.6900303412739,9.15E-6,0,0,0,5906,288.2491,1000.063,,,,,,,,,,,,,,,,,207.536804,,,,,,294.8543396,,,,
,15329520.1,776.783020019531,1000.063,0.0195752461633999,5.06021271845307E-7,1,15.0002345885404,40.1327056884766,2.00403472969214,8.940001539886,0.108481170632026,0.0103025451427175,0.25,-1.20961068451262E-5,0.01957431970495,6.61181783460484E-5,294.8591919,294.8592224,1000.063,1000.063,57.6724602914484,20.6901086770603,9.15E-6,0,0,0,5906,288.45135,1000.063,,,,,,,,,,,,,,,,,207.536804,,,,,,294.85920715,,,,
,15329640.095,766.81884765625,1000.063,0.0323238889078654,7.81896368110921E-7,1,15.0002345885404,40.1327056884766,2.00411204430243,8.940001539886,0.179137389535934,0.0170170819224836,0.25,-1.90985439789284E-5,0.0323223648953213,0.000109939997542109,294.8608704,294.8614502,1000.063,1000.063,57.2245871499291,20.6879259780562,9.15E-6,0,0,0,5906,288.6646,1000.063,,,,,,,,,,,,,,,,,207.170853,,,,,,294.8611603,,,,
,15329775.12,755.59814453125,1000.063,0.0490149964833527,1.18580286452038E-6,1,15.0002345885404,40.1327056884766,2.0040391418226,8.940001539886,0.27154728490571,0.0256578105206597,2.5,-5.34075921937374E-5,0.049012798966947,0.000142074959059026,294.8623047,294.8635559,1000.063,1000.063,58.0476419806792,20.689806014135,9.2E-6,0,0,0,5906,288.89845,1000.063,,,,,,,,,,,,,,,,,207.170853,,,,,,294.8629303,,,,
,15329895.11,745.592956542969,1000.063,0.064219614345677,1.15892149520916E-6,1,15.0002345885404,40.1327056884766,2.0039404462829,8.940001539886,0.355764713539774,0.0336192087306219,2.5,-6.90677925177048E-5,0.064216736823453,0.000186846290493907,294.869873,294.8722534,1000.063,1000.063,57.65057469291,20.6930614206084,9.15E-6,0,0,0,5906,289.09505,1000.063,,,,,,,,,,,,,,,,,207.170853,,,,,,294.8710632,,,,
,15330015.1,735.609436035156,1000.063,0.0786674332564675,1.66859906708379E-6,1,15.0002345885404,40.1327056884766,2.00401455308974,8.940001539886,0.435819229165412,0.0411796438264235,2.5,-8.51820070022616E-5,0.0786639318551107,0.00022806073713701,294.8714905,294.8729553,1000.063,1000.063,57.4348452216022,20.6911954527035,9.2E-6,0,0,0,5906,289.28515,1000.063,,,,,,,,,,,,,,,,,207.536804,,,,,,294.8722229,,,,
,15330135.1,725.6708984375,1000.063,0.0919336784789992,2.16061596313261E-6,1,15.0002345885404,40.1327056884766,2.00401980218881,8.940001539886,0.509317448745379,0.0481080934196016,2.5,-0.000102174488547451,0.0919296164930912,0.000263614464345414,294.8746338,294.8755493,1000.063,1000.063,57.8326941378907,20.690213391211,9.15E-6,0,0,0,5906,289.46965,1000.063,,,,,,,,,,,,,,,,,207.536804,,,,,,294.87509155,,,,
,15330255.1,715.692138671875,1000.063,0.103858222605069,2.20362969621804E-6,1,15.0002345885404,40.1327056884766,2.00398016266729,8.940001539886,0.575368641207863,0.0543511670016003,2.5,-0.000114363824064698,0.103853647803059,0.000298548384643344,294.8790283,294.8798828,1000.063,1000.063,58.0499868662369,20.6929039265361,9.2E-6,0,0,0,5906,289.6592,1000.063,,,,,,,,,,,,,,,,,207.536804,,,,,,294.87945555,,,,
,15330375.1,705.745971679688,1000.063,0.114508160548839,2.28427462589894E-6,1,15.0002345885404,40.1327056884766,2.00404996467486,8.940001539886,0.634390287501466,0.0599278348856692,2.5,-0.00012552111961652,0.114503140642093,0.000329393989026629,294.8809204,294.8819275,1000.063,1000.063,58.0640561795831,20.6922940284376,9.15E-6,0,0,0,5906,289.83985,1000.063,,,,,,,,,,,,,,,,,207.170853,,,,,,294.88142395,,,,
,15330495.1,695.760375976563,1000.063,0.124113903364278,2.81073973397615E-6,1,15.0002345885404,40.1327056884766,2.00412494542798,8.940001539886,0.687633682491806,0.0649460072262284,2.5,-0.000137732447777578,0.124108488797586,0.000354972593555668,294.8859558,294.8860168,1000.063,1000.063,58.2235083975062,20.6901856102579,9.2E-6,0,0,0,5906,290.02315,1000.063,,,,,,,,,,,,,,,,,207.536804,,,,,,294.8859863,,,,
,15330615.14,685.82177734375,1000.063,0.132789301741651,3.22590303165101E-6,1,15.0002345885404,40.1327056884766,2.00410596899464,8.940001539886,0.735690414443196,0.0694988053458274,2.5,-0.000144535915154557,0.132783528463396,0.000382273045394363,294.885498,294.887207,1000.063,1000.063,57.6286890943715,20.692703868681,9.2E-6,0,0,0,5906,290.178,1000.063,,,,,,,,,,,,,,,,,207.170853,,,,,,294.8863525,,,,
,15330735.085,675.836486816406,1000.063,0.140692283819107,3.22820617882369E-6,1,15.0002345885404,40.1327056884766,2.00414532832234,8.940001539886,0.779491679642328,0.0736215137952194,2.5,-0.000155464266141804,0.140686199618496,0.000402325490066486,294.8887024,294.8902283,1000.063,1000.063,56.9963516223137,20.6920274748789,9.2E-6,0,0,0,5906,290.3405,1000.063,,,,,,,,,,,,,,,,,207.536804,,,,,,294.88946535,,,,
,15330855.125,665.796875,1000.063,0.14793157123402,3.19795165517437E-6,1,15.0002345885404,40.1327056884766,2.00412661033123,8.940001539886,0.819592908529701,0.0774083488950808,2.5,-0.000163194269500767,0.147925190278969,0.00042291080540086,294.8936157,294.8947144,1000.063,1000.063,57.7600026856023,20.6922696712738,9.2E-6,0,0,0,5906,290.5007,1000.063,,,,,,,,,,,,,,,,,207.170853,,,,,,294.89416505,,,,
,15330975.11,655.849670410156,1000.063,0.154608728087607,3.02904888076062E-6,1,15.0002345885404,40.1327056884766,2.00406324842084,8.940001539886,0.856562490349557,0.0808783112856085,2.5,-0.000174043602679888,0.154602106799746,0.000438114965696883,294.8950195,294.8954773,1000.063,1000.063,57.9311793313138,20.6933091167901,9.15E-6,0,0,0,5906,290.66055,1000.063,,,,,,,,,,,,,,,,,207.536804,,,,,,294.8952484,,,,
,15331095.17,645.868286132813,1000.063,0.160861129276207,2.10904524563982E-6,1,15.0002345885404,40.1327056884766,2.00413776459456,8.940001539886,0.891234521262113,0.084152809333003,2.5,-0.000180511574776215,0.160854277884868,0.000455957170179904,294.8956909,294.8960876,1000.063,1000.063,57.5372385576215,20.6929306591374,9.25E-6,0,0,0,5906,290.83125,1000.063,,,,,,,,,,,,,,,,,207.170853,,,,,,294.89588925,,,,
,15331215.1,635.913208007812,1000.063,0.166677118622799,4.40343794494934E-6,1,15.0002345885404,40.1327056884766,2.00411153015729,8.940001539886,0.923445310868591,0.0871985235380808,2.5,-0.000185877827073833,0.166670036587006,0.000473208717435561,294.8992615,294.899353,1000.063,1000.063,57.9882382132177,20.6952850908392,9.2E-6,0,0,0,5906,290.97705,1000.063,,,,,,,,,,,,,,,,,207.536804,,,,,,294.89930725,,,,
,15331335.095,625.929992675781,1000.063,0.172123439435011,3.20763783140435E-6,1,15.0002345885404,40.1327056884766,2.004126686586,8.940001539886,0.953627719891932,0.0900401729142857,2.5,-0.000193068749184461,0.172116165499008,0.000487169269812663,294.899292,294.9000854,1000.063,1000.063,57.9085121042561,20.6958245266386,9.1E-6,0,0,0,5906,291.11515,1000.063,,,,,,,,,,,,,,,,,207.170853,,,,,,294.8996887,,,,
,15331455.1,616.010131835938,1000.063,0.177277634080007,3.97601414583429E-6,1,15.0002345885404,40.1327056884766,2.00397412218367,8.940001539886,0.982112103786598,0.0927176211664127,2.5,-0.000200538379504335,0.177270172676784,0.000499609444145305,294.9029236,294.9045715,1000.063,1000.063,57.3277621144676,20.6970279243937,9.2E-6,0,0,0,5906,291.27555,1000.063,,,,,,,,,,,,,,,,,207.902756,,,,,,294.90374755,,,,
,15331575.145,606.00146484375,1000.063,0.182141655245172,3.09464832472665E-6,1,15.0002345885404,40.1327056884766,2.00404002984985,8.940001539886,1.00909241951039,0.0952512155638946,2.5,-0.0002081224089114,0.182134018577127,0.00051089895265362,294.905426,294.9063416,1000.063,1000.063,57.4684552479292,20.6992379918949,9.2E-6,0,0,0,5906,291.39,1000.063,,,,,,,,,,,,,,,,,207.536804,,,,,,294.9058838,,,,
,15331695.09,595.996520996094,1000.063,0.186714183259349,3.3708498460427E-6,1,15.0002345885404,40.1327056884766,2.00410321411366,8.940001539886,1.03445715464109,0.0976437382096888,2.5,-0.000213187711573956,0.186706395620114,0.000523415369931533,294.9057312,294.9073792,1000.063,1000.063,57.8819367346023,20.6969123396633,9.15E-6,0,0,0,5906,291.5456,1000.063,,,,,,,,,,,,,,,,,207.536804,,,,,,294.9065552,,,,
,15331815.125,586.069213867187,1000.063,0.190867627496389,4.05462907708842E-6,1,15.0002345885404,40.1327056884766,2.00384220876802,8.940001539886,1.05733182686943,0.0998278976269818,2.5,-0.00021305924831417,0.19085967028509,0.00053952982581861,294.9090271,294.9097595,1000.063,1000.063,57.2581971762561,20.7043741376203,9.15E-6,0,0,0,5906,291.67545,1000.063,,,,,,,,,,,,,,,,,208.268707,,,,,,294.9093933,,,,
,15331935.115,576.00390625,1000.063,0.195017420183341,3.8886342473048E-6,1,15.0002345885404,40.1327056884766,2.00391123472045,8.940001539886,1.08035812746119,0.101984239980661,2.5,-0.000220422250374858,0.195009312521808,0.000548096349872422,294.9144287,294.9150696,1000.063,1000.063,57.952283301333,20.7047176912083,9.2E-6,0,0,0,5906,291.8134,1000.063,,,,,,,,,,,,,,,,,208.268707,,,,,,294.91474915,,,,
,15332055.105,566.154602050781,1000.063,0.199184053969666,4.47993523520532E-6,1,15.0002345885404,40.1327056884766,2.0037862625587,8.940001539886,1.10337195712927,0.104173055407828,2.5,-0.00022186482446489,0.199175807852714,0.000562730949777328,294.9118042,294.9124451,1000.063,1000.063,58.1922432567369,20.7063215774913,9.2E-6,0,0,0,5906,291.9203,1000.063,,,,,,,,,,,,,,,,,208.634659,,,,,,294.91212465,,,,
,15332175.12,556.097839355469,1000.063,0.202987044572849,4.66566286680727E-6,1,15.0002345885404,40.1327056884766,2.00376664822743,8.95000208169222,1.12442840910335,0.106155971358259,2.5,-0.000226526963708262,0.202978682168416,0.000572563681406823,294.912323,294.9143372,1000.063,1000.063,57.8373839090061,20.7055897662941,9.1E-6,0,0,0,5906,292.0691,1000.063,,,,,,,,,,,,,,,,,207.902756,,,,,,294.9133301,,,,
,15332311.305,544.872924804687,1000.063,0.206994325430273,3.83007927887714E-6,1,15.0002345885404,40.1327056884766,2.00378024634848,8.940001539886,1.147040257332,0.108233720771401,25,-0.00024072271627454,0.206985880529172,0.000573670619201412,294.9132385,294.9137268,1000.063,1000.063,58.0718724647754,20.7069751162157,9.1E-6,0,0,0,5906,292.2115,1000.063,,,,,,,,,,,,,,,,,207.902756,,,,,,294.91348265,,,,
,15332430.09,534.990417480469,1000.063,0.210447478749308,4.64229515304475E-6,1,15.0002345885404,40.1327056884766,2.00376283366482,8.940001539886,1.16616470223706,0.110048822224745,25,-0.00024246932939355,0.210438886372436,0.000585125180166405,294.91922,294.9192505,1000.063,1000.063,57.7474966292946,20.7087813110143,9.2E-6,0,0,0,5906,292.3255,1000.063,,,,,,,,,,,,,,,,,208.268707,,,,,,294.91923525,,,,
,15332550.105,524.952087402344,1000.063,0.213734347832127,5.29006267329178E-6,1,15.0002345885404,40.1327056884766,2.00371885231014,8.940001539886,1.1843518753033,0.111777778417748,25,-0.00024354846954465,0.213725620660082,0.000596529472417718,294.9239197,294.9251404,1000.063,1000.063,57.3863842534099,20.7088959751175,9.15E-6,0,0,0,5906,292.45465,1000.063,,,,,,,,,,,,,,,,,208.634659,,,,,,294.92453005,,,,
,15332670.1,515.020080566406,1000.063,0.216897579919134,5.08505200392649E-6,1,15.0002345885404,40.1327056884766,2.00382719990753,8.940001539886,1.20194500879722,0.113425928501094,25,-0.000248925062872764,0.216888784688981,0.000603163646965316,294.9211731,294.9234009,1000.063,1000.063,57.8475450797561,20.7073166666696,9.25E-6,0,0,0,5906,292.57635,1000.063,,,,,,,,,,,,,,,,,209.00061,,,,,,294.922287,,,,
,15332790.125,505.058471679687,1000.063,0.219955627155172,5.02017711899317E-6,1,15.0002345885404,40.1327056884766,2.00386902098039,8.940001539886,1.2189161785731,0.115028811045846,25,-0.000251822847690548,0.219946739832842,0.000611906738423251,294.9217834,294.9231873,1000.063,1000.063,58.5236537488908,20.7085809300574,9.2E-6,0,0,0,5906,292.68235,1000.063,,,,,,,,,,,,,,,,,209.366577,,,,,,294.92248535,,,,
,15332910.09,495.025939941406,1000.063,0.222860165724258,4.84605723570697E-6,1,15.0002345885404,40.1327056884766,2.00374492745467,8.940001539886,1.23494161238641,0.116498246264772,25,-0.000262443355400864,0.222851217783662,0.000612317344759936,294.9233093,294.9240723,1000.063,1000.063,58.1961513993331,20.710733196187,9.2E-6,0,0,0,5906,292.78765,1000.063,,,,,,,,,,,,,,,,,208.634659,,,,,,294.9236908,,,,
,15333030.105,485.012878417969,1000.063,0.225655602615656,5.47628791531122E-6,1,15.0002345885404,40.1327056884766,2.00382285901439,8.940001539886,1.25047884575598,0.117972113033226,25,-0.000263982783353523,0.225646549350404,0.000621457685381809,294.9256897,294.9260864,1000.063,1000.063,58.0234114965831,20.7111041836239,9.25E-6,0,0,0,5906,292.8689,1000.063,,,,,,,,,,,,,,,,,209.00061,,,,,,294.92588805,,,,
,15333150.115,474.994659423828,1000.063,0.228363069339056,5.18846311236606E-6,1,15.0002345885404,40.1327056884766,2.00380252942616,8.940001539886,1.26546781544572,0.11940869854765,25,-0.000262684313031775,0.228353912003322,0.000632938937085517,294.9288635,294.9290466,1000.063,1000.063,58.3892136435831,20.7116100290077,9.25E-6,0,0,0,5906,292.9899,1000.063,,,,,,,,,,,,,,,,,208.634659,,,,,,294.92895505,,,,
,15333270.1,465.117462158203,1000.063,0.23095512347962,3.57765076046355E-6,1,15.0002345885404,40.1327056884766,2.00380019002393,8.940001539886,1.27983526269433,0.120711532373657,25,-0.000274742455343873,0.230945917922527,0.000630667223134012,294.9309692,294.9318237,1000.063,1000.063,58.2070941986023,20.712464362634,9.2E-6,0,0,0,5906,293.0931,1000.063,,,,,,,,,,,,,,,,,209.366577,,,,,,294.93139645,,,,
,15333390.08,455.156982421875,1000.063,0.233470447175556,3.24620078077826E-6,1,15.0002345885404,40.1327056884766,2.00371941500597,8.940001539886,1.29371976817619,0.122056888789178,25,-0.000270902997963732,0.233461151095178,0.000643938778687127,294.9317017,294.932373,1000.063,1000.063,57.6755868055253,20.7147407856338,9.15E-6,0,0,0,5906,293.20835,1000.063,,,,,,,,,,,,,,,,,209.732529,,,,,,294.93203735,,,,
,15333510.095,445.132476806641,1000.063,0.235897525985367,4.66325947755159E-6,1,15.0002345885404,40.1327056884766,2.00392226300239,8.940001539886,1.30729989276406,0.12331941569064,25,-0.000276738999327647,0.23588815366992,0.000647288640754145,294.9352417,294.9354858,1000.063,1000.063,57.9389956165061,20.7130795517267,9.2E-6,0,0,0,5906,293.29485,1000.063,,,,,,,,,,,,,,,,,209.00061,,,,,,294.93536375,,,,
,15333630.135,435.204833984375,1000.063,0.238213888022196,5.32335977778705E-6,1,15.0002345885404,40.1327056884766,2.00386426167358,8.940001539886,1.32010181076098,0.124503231847149,25,-0.000283365778799777,0.238204465411025,0.000649386811666853,294.9363098,294.9364014,1000.063,1000.063,58.1328394892754,20.7130689374389,9.2E-6,0,0,0,5906,293.3869,1000.063,,,,,,,,,,,,,,,,,209.732529,,,,,,294.9363556,,,,
,15333750.085,425.174011230469,1000.063,0.240465402925537,5.78624521087899E-6,1,15.0002345885404,40.1327056884766,2.00388363871145,8.940001539886,1.33259376740049,0.125661580535773,25,-0.000289202637562554,0.240455968726714,0.000651981788614229,294.9311829,294.9331665,1000.063,1000.063,57.87412044941,20.713329518323,9.2E-6,0,0,0,5906,293.48755,1000.063,,,,,,,,,,,,,,,,,209.732529,,,,,,294.9321747,,,,
,15333870.15,415.133575439453,1000.063,0.2426254263284,4.95854733000023E-6,1,15.0002345885404,40.1327056884766,2.00390790870954,8.940001539886,1.34457965639467,0.126795549193375,25,-0.000290780797384409,0.242615918245449,0.000658503224634664,294.9336243,294.9361877,1000.063,1000.063,57.66073586366,20.7141238749077,9.2E-6,0,0,0,5906,293.57965,1000.063,,,,,,,,,,,,,,,,,209.732529,,,,,,294.934906,,,,
,15333990.155,405.207458496094,1000.063,0.244700657921075,5.83038654150286E-6,1,15.0002345885404,40.1327056884766,2.00391593193324,8.940001539886,1.35608213762726,0.127915749145486,25,-0.000286569827079146,0.244691050341662,0.000670484960485947,294.9382019,294.9388123,1000.063,1000.063,58.2899468216408,20.7134777780807,9.15E-6,0,0,0,5906,293.6694,1000.063,,,,,,,,,,,,,,,,,209.366577,,,,,,294.9385071,,,,
,15334110.095,395.238677978516,1000.063,0.246691912391453,6.67002675501138E-6,1,15.0002345885404,40.1327056884766,2.00364660982874,8.940001539886,1.36693514886408,0.128968809632722,25,-0.000283313586483891,0.2466822253341,0.000681186274067441,294.9396973,294.9407349,1000.063,1000.063,58.2672795945831,20.7199708054658,9.15E-6,0,0,0,5906,293.75705,1000.063,,,,,,,,,,,,,,,,,210.464432,,,,,,294.9402161,,,,
,15334230.09,385.207824707031,1000.063,0.248590606481824,5.59394783671104E-6,1,15.0002345885404,40.1327056884766,2.00389033199508,8.940001539886,1.37762518155628,0.129919060313797,25,-0.000295578146960661,0.248580900651293,0.000675994700422483,294.9421997,294.9430237,1000.063,1000.063,57.789704569333,20.7159555621141,9.15E-6,0,0,0,5906,293.84615,1000.063,,,,,,,,,,,,,,,,,209.732529,,,,,,294.9426117,,,,
,15334350.11,375.288970947266,1000.063,0.250413351625061,5.32330381582395E-6,1,15.0002345885404,40.1327056884766,2.00387326595481,8.940001539886,1.38771409452054,0.130880739966204,25,-0.000295607784627875,0.250403610692337,0.00068278093824826,294.9402771,294.9406738,1000.063,1000.063,57.8827183631215,20.7179220806271,9.1E-6,0,0,0,5906,293.92385,1000.063,,,,,,,,,,,,,,,,,210.09848,,,,,,294.94047545,,,,
,15334470.11,365.351318359375,1000.063,0.252157398473767,5.46586586490089E-6,1,15.0002345885404,40.1327056884766,2.00392537950773,8.940001539886,1.39741289476524,0.131813663410621,25,-0.000294133438780594,0.252147586974781,0.000690789842941958,294.9423828,294.9428711,1000.063,1000.063,58.1570699733715,20.7178632181344,9.15E-6,0,0,0,5906,293.9939,1000.063,,,,,,,,,,,,,,,,,210.464432,,,,,,294.94262695,,,,
,15334590.1,355.312255859375,1000.063,0.253828078871284,5.74707083123035E-6,1,15.0002345885404,40.1327056884766,2.00401316162803,8.940001539886,1.40673801083998,0.132627042526667,25,-0.000307611464180513,0.25381825619018,0.000683522119232991,294.9454651,294.9456482,1000.063,1000.063,58.7073364509101,20.7186411804252,9.2E-6,0,0,0,5906,294.0726,1000.063,,,,,,,,,,,,,,,,,210.09848,,,,,,294.94555665,,,,
,15334710.09,345.41796875,1000.063,0.255405451902363,4.14275633287062E-6,1,15.0002345885404,40.1327056884766,2.00399643728518,8.940001539886,1.41546814067969,0.13345597413333,25,-0.000308114037225373,0.255395614322486,0.000688817243052706,294.9429321,294.9433899,1000.063,1000.063,57.4270289364099,20.7167796226869,9.2E-6,0,0,0,5906,294.1622,1000.063,,,,,,,,,,,,,,,,,210.09848,,,,,,294.943161,,,,
,15334830.11,335.445068359375,1000.063,0.256913736982927,6.27241022751845E-6,1,15.0002345885404,40.1327056884766,2.00397474258505,8.940001539886,1.42381092247703,0.134253746922544,25,-0.000307656139123325,0.256903817804662,0.000694884822462291,294.9481812,294.9493408,1000.063,1000.063,58.3141773057369,20.7198218959378,9.15E-6,0,0,0,5906,294.2306,1000.063,,,,,,,,,,,,,,,,,210.830383,,,,,,294.948761,,,,
,15334950.15,325.400848388672,1000.063,0.258341855013572,6.12518849370087E-6,1,15.0002345885404,40.1327056884766,2.00381361825269,8.940001539886,1.4316168355037,0.134953176656997,25,-0.00031561035536829,0.258331956052698,0.000692200726402425,294.9454651,294.9459839,1000.063,1000.063,57.8623960216215,20.7216119773305,9.15E-6,0,0,0,5906,294.30495,1000.063,,,,,,,,,,,,,,,,,210.830383,,,,,,294.9457245,,,,
,15335070.09,317.082733154297,1000.063,0.259597639071468,5.83124291363756E-6,1,15.0002345885404,40.1327056884766,2.00376549299651,8.940001539886,1.43853763420897,0.135653617440226,25,-0.000308211434792284,0.259587674318292,0.000704158563937536,294.9477234,294.9477844,1000.063,1000.063,57.7052886892561,20.7251319632546,9.15E-6,0,0,0,5910,294.3879,1000.063,,,,,,,,,,,,,,,,,210.830383,,,,,,294.9477539,,,,
,15335190.14,311.018829345703,1000.063,0.260515452905676,6.73818386737362E-6,1,15.0002345885404,40.1327056884766,2.00390549060344,8.940001539886,1.44372442027683,0.136116439903492,25,-0.000313762965443806,0.260505435652471,0.000701946141252203,294.9550171,294.9559937,1000.063,1000.063,58.2852570505254,20.721359843,9.15E-6,0,0,0,5910,294.4464,1000.063,,,,,,,,,,,,,,,,,210.830383,,,,,,294.9555054,,,,
,15335310.15,306.464233398438,1000.063,0.261176401143292,5.5003973570622E-6,1,15.0002345885404,40.1327056884766,2.00335453213352,8.940001539886,1.44699451709379,0.136465069003734,25,-0.000307182219459479,0.261166283892602,0.000710939987586154,294.9627991,294.9647217,1000.063,1000.063,58.1422190315062,20.7252831685935,9.2E-6,0,0,0,5910,294.4861,1000.063,,,,,,,,,,,,,,,,,211.196335,,,,,,294.9637604,,,,
,15335430.085,303.120880126953,1000.063,0.261677466436308,4.48745037602654E-6,1,15.0002345885404,40.1327056884766,2.00388397656536,8.940001539886,1.45014889460606,0.136717265402383,25,-0.000315714723317752,0.261667330688917,0.000704203538250547,294.9680176,294.9715881,1000.063,1000.063,58.19927791341,20.7190689469996,9.15E-6,0,0,0,5910,294.5243,1000.063,,,,,,,,,,,,,,,,,210.830383,,,,,,294.96980285,,,,