File: ZFC_FC/PPMS_Li0.6Al0.4Fe5O8_1 kOe.dat
[Header]
; VSM Data File (default extension .dat)
; Copyright (c) 2003, Quantum Design, Inc. All rights reserved.
TITLE,Li0.6Al0.4Fe5O8
FILEOPENTIME,15380191.52,06/28/2023,9:18 am
BYAPP,VSM,1.0,1.0
INFO,PPMS VSM Option Release 1.3.6 Build 0,APPNAME
INFO,LB510,COIL_SERIAL_NUMBER
INFO,0,MOMENT_UNITS
INFO,Li0.6Al0.4Fe5O8 +PVA,SAMPLE_MATERIAL
INFO,,SAMPLE_COMMENT
INFO,5.67,SAMPLE_MASS
INFO,,SAMPLE_VOLUME
INFO,,SAMPLE_MOLECULAR_WEIGHT
INFO,3 mm diameter,SAMPLE_SIZE
INFO,pellet,SAMPLE_SHAPE
INFO,35.06,SAMPLE_OFFSET
DATATYPE,COMMENT,1
DATATYPE,TIME,2
STARTUPAXIS,X,2
STARTUPAXIS,Y1,5
[Data]
Comment,Time Stamp (sec),Temperature (K),Magnetic Field (Oe),Moment (emu),M. Std. Err. (emu),Transport Action,Averaging Time (sec),Frequency (Hz),Peak Amplitude (mm),Center Position (mm),Coil Signal' (mV),Coil Signal" (mV),Range (mV),M. Quad. Signal (emu),M. Raw' (emu),M. Raw" (emu),Min. Temperature (K),Max. Temperature (K),Min. Field (Oe),Max. Field (Oe),Mass (grams),Motor Lag (deg),Pressure (Torr),VSM Status (code),Motor Status (code),Measure Status (code),PPMS Status (code),System Temp. (K),System Field (Oe),Sample Position (deg),Bridge 1 Resistance (ohms),Bridge 1 Excitation (µA),Bridge 2 Resistance (ohms),Bridge 2 Excitation (µA),Bridge 3 Resistance (ohms),Bridge 3 Excitation (µA),Bridge 4 Resistance (ohms),Bridge 4 Excitation (µA),Signal 1 Vin (V),Signal 2 Vin (V),Digital Inputs (code),Drive 1 Iout (mA),Drive 1 Ipower (W),Drive 2 Iout (mA),Drive 2 Ipower (W),Pressure (),Map 20 (),Map 21 (),Map 22 (),Map 23 (),Map 24 (),Map 25 (),Map 26 (),Map 27 (),Map 28 (),Map 29 ()
,15380926.89,303.083770751953,999.931,0.199187349026706,3.90808726539829E-6,1,15.0002345885404,40.1327056884766,1.98643859936651,10.3100021928549,1.09639669033743,0.102977344438027,250,-0.000309862147685171,0.199179906931391,0.000466016322621306,294.977417,294.977417,999.931,999.931,58.812074672487,20.4313650058271,9.2E-6,0,0,0,5906,294.6775,999.931,,,,,,,,,,,,,,,,,217.05159,,,,,,294.977417,,,,
,15381048.805,313.996398925781,999.931,0.197543452032399,2.20811224040307E-6,1,15.0002345885404,40.1327056884766,1.98660549612676,10.3100021928549,1.08554094299885,0.102026246165191,25,-0.000295047227314459,0.197535818697592,0.00047452757955575,295.010376,295.0140686,999.931,999.931,59.1755319339293,20.4388287788961,9.25E-6,0,0,0,5906,294.6451,999.931,,,,,,,,,,,,,,,,,217.05159,,,,,,295.0122223,,,,
,15381168.805,324.007019042969,999.931,0.196228789358304,2.58218087287973E-6,1,15.0002345885404,40.1327056884766,1.98682689199739,10.3100021928549,1.07843613415734,0.101325095166933,25,-0.000299273796485454,0.196221036153295,0.000465346190178971,295.0428162,295.0458374,999.931,999.931,59.7938000926409,20.430304616222,9.15E-6,0,0,0,5906,294.59105,999.931,,,,,,,,,,,,,,,,,217.783508,,,,,,295.0443268,,,,
,15381288.805,334.028717041016,999.931,0.194850133613858,2.4969048921786E-6,1,15.0002345885404,40.1327056884766,1.98703673828847,10.3100021928549,1.07096696509036,0.100647474653958,25,-0.000293107856304252,0.194842312853343,0.000466431630765222,295.0578918,295.0591736,999.931,999.931,59.6835904714294,20.4265779729601,9.15E-6,0,0,0,5906,294.4959,999.931,,,,,,,,,,,,,,,,,217.783508,,,,,,295.0585327,,,,
,15381408.785,343.983367919922,999.931,0.193410776072808,4.77814457486172E-6,1,15.0002345885404,40.1327056884766,1.98690597973254,10.3100021928549,1.06299003242823,0.0998647072313794,25,-0.000297319228380721,0.193402949865032,0.000457014489881742,295.0674133,295.0678101,999.931,999.931,59.9141708846025,20.4393598936121,9.2E-6,0,0,0,5906,294.3631,999.931,,,,,,,,,,,,,,,,,217.783508,,,,,,295.0676117,,,,
,15381528.81,354.004333496094,999.931,0.191947339713753,3.6531848515266E-6,1,15.0002345885404,40.1327056884766,1.98704472974677,10.3000016510487,1.05501936813436,0.0991093561961628,25,-0.000296483494852226,0.191939542325261,0.000452378606608046,295.0689087,295.0713196,999.931,999.931,59.3248229811024,20.4455467708468,9.15E-6,0,0,0,5906,294.28515,999.931,,,,,,,,,,,,,,,,,218.14946,,,,,,295.07011415,,,,
,15381648.79,364.040222167969,999.931,0.19041341851211,3.27823589072291E-6,1,15.0002345885404,40.1327056884766,1.98745380119943,10.3100021928549,1.04679627921169,0.0983622945134152,25,-0.000289833557331153,0.190405632182838,0.000453346996031498,295.0709229,295.0715027,999.931,999.931,60.0970719581025,20.4554748426792,9.15E-6,0,0,0,5906,294.1843,999.931,,,,,,,,,,,,,,,,,218.515411,,,,,,295.0712128,,,,
,15381768.875,373.992584228516,999.931,0.188856445718624,2.2325358838178E-6,1,15.0002345885404,40.1327056884766,1.98746903539313,10.3100021928549,1.03824080550678,0.0975950788705145,25,-0.000281196362004948,0.188848637037396,0.000456256944563413,295.075531,295.0775146,999.931,999.931,59.3826634915255,20.4754840052422,9.2E-6,0,0,0,5906,294.067,999.931,,,,,,,,,,,,,,,,,218.881363,,,,,,295.0765228,,,,
,15381888.82,384.035034179687,999.931,0.187226018038749,3.45862725700526E-6,1,15.0002345885404,40.1327056884766,1.98755254278556,10.3100021928549,1.02931834167212,0.0967692951567666,25,-0.000276766441478318,0.187218230856387,0.000454649394430812,295.0765686,295.0791016,999.931,999.931,60.0642435602948,20.4709866573075,9.15E-6,0,0,0,5906,293.9558,999.931,,,,,,,,,,,,,,,,,218.515411,,,,,,295.0778351,,,,
,15382008.805,393.998138427734,999.931,0.185549839232059,3.60027091572728E-6,1,15.0002345885404,40.1327056884766,1.98754202376313,10.3100021928549,1.02010160167037,0.0958612796712603,25,-0.000282121144933301,0.185542112104524,0.000443092821300624,295.0786133,295.0799255,999.931,999.931,59.6898434995832,20.4786234155453,9.15E-6,0,0,0,5906,293.838,999.931,,,,,,,,,,,,,,,,,218.515411,,,,,,295.0792694,,,,
,15382128.79,404.012115478516,999.931,0.183837581753531,4.12849287501797E-6,1,15.0002345885404,40.1327056884766,1.98760158511028,10.3100021928549,1.01071568919426,0.0949991628804908,25,-0.000276261520423737,0.183829892226853,0.000442591428279888,295.0767822,295.0777893,999.931,999.931,59.6351295032371,20.4820026089862,9.2E-6,0,0,0,5906,293.7242,999.931,,,,,,,,,,,,,,,,,219.247314,,,,,,295.07728575,,,,
,15382248.91,414.012329101562,999.931,0.182081404545876,3.25542776938975E-6,1,15.0002345885404,40.1327056884766,1.98768619904453,10.3100021928549,1.00110376038261,0.0940733672005306,25,-0.000278085227763072,0.18207372264026,0.000434333680332849,295.0847778,295.0861511,999.931,999.931,59.3857900056024,20.4907793849113,0.0001019,0,0,0,5906,293.57425,999.931,,,,,,,,,,,,,,,,,219.613266,,,,,,295.08546445,,,,
,15382368.775,424.049560546875,999.931,0.180291140154518,4.13910124747662E-6,1,15.0002345885404,40.1327056884766,1.98790849024625,10.3100021928549,0.991367684292703,0.0931687989851516,25,-0.000273908758953248,0.180283462399592,0.000431924691083663,295.0904541,295.0906372,999.931,999.931,59.5530585087178,20.488656557616,0.0004546,0,0,0,5906,293.42775,999.931,,,,,,,,,,,,,,,,,219.613266,,,,,,295.09054565,,,,
,15382488.87,434.039245605469,999.931,0.178451514207957,3.54894530753989E-6,1,15.0002345885404,40.1327056884766,1.98803395873079,10.3100021928549,0.981311936291226,0.092228347622449,25,-0.000270601381392718,0.178443861944178,0.000428344439447827,295.0928345,295.0965576,999.931,999.931,59.4866200845832,20.4941420087328,0.0008641,0,0,0,5906,293.31685,999.931,,,,,,,,,,,,,,,,,219.247314,,,,,,295.09469605,,,,
,15382608.765,444.066253662109,999.931,0.176595977048498,3.96894272299319E-6,1,15.0002345885404,40.1327056884766,1.98809970797686,10.3100021928549,0.971141554185354,0.0912482588053077,25,-0.000272584810572504,0.176588351088614,0.000419523392821301,295.0999756,295.1018982,999.931,999.931,59.1896012472755,20.4966503412823,0.00127915,0,0,0,5906,293.16385,999.931,,,,,,,,,,,,,,,,,219.613266,,,,,,295.1009369,,,,
,15382728.865,454.023376464844,999.931,0.174692874537827,3.66852465144955E-6,1,15.0002345885404,40.1327056884766,1.98840143356595,10.3100021928549,0.960820598691632,0.0902519544604845,25,-0.000274903165240268,0.17468528740993,0.000410217535654788,295.104187,295.1054688,999.931,999.931,59.3357657803716,20.5024161406862,0.0017433,0,0,0,5906,292.99465,999.931,,,,,,,,,,,,,,,,,219.613266,,,,,,295.1048279,,,,
,15382848.75,463.992095947266,999.931,0.172733459862964,3.08319884200867E-6,1,15.0002345885404,40.1327056884766,1.98827690475556,10.3100021928549,0.949989497721003,0.089190885217558,25,-0.000280140890644381,0.172725951280798,0.000397743823793943,295.104126,295.104187,999.931,999.931,59.3474902081601,20.5047262550199,0.0021396,0,0,0,5906,292.832,999.931,,,,,,,,,,,,,,,,,219.979218,,,,,,295.1041565,,,,
,15382968.9,473.966552734375,999.931,0.170739361002128,2.22759363480066E-6,1,15.0002345885404,40.1327056884766,1.98804415083116,10.3100021928549,0.938914196537929,0.0881576139725329,25,-0.000276130995362434,0.170731891352106,0.000394332026150903,295.1054688,295.1054688,999.931,999.931,59.4514468012178,20.5008342504265,0.00237615,0,0,0,5906,292.6838,999.931,,,,,,,,,,,,,,,,,219.247314,,,,,,295.1054688,,,,
,15383088.775,484.058288574219,999.931,0.168673931189361,3.00540477941364E-6,1,15.0002345885404,40.1327056884766,1.98823046846335,10.3100021928549,0.927639293171543,0.0871328871552975,25,-0.000266955337235577,0.168666779609608,0.000395673992329533,295.0290833,295.0663452,999.931,999.931,58.9973206315447,20.5054926135066,0.0010215,0,0,0,5906,292.58125,999.931,,,,,,,,,,,,,,,,,220.345184,,,,,,295.04771425,,,,
,15383208.75,494.037689208984,999.931,0.166318194417431,2.24978611474215E-6,1,15.0002345885404,40.1327056884766,1.98808155699925,10.3100021928549,0.914620124507742,0.0858889407468061,25,-0.000266790099489246,0.166311410659921,0.000386352588142161,294.9950867,295.0022583,999.931,999.931,59.2310275587947,20.513307718703,0.0002667,0,0,0,5906,292.66885,999.931,,,,,,,,,,,,,,,,,219.979218,,,,,,294.9986725,,,,
,15383328.735,504.068664550781,999.931,0.164031159707505,2.73352837735569E-6,1,15.0002345885404,40.1327056884766,1.98837159211839,10.3100021928549,0.902171139021687,0.084715692033941,25,-0.000264015477619485,0.164024277649217,0.00038028144557136,295.0350647,295.0404358,999.931,999.931,59.4240898030447,20.520371437386,9.25E-6,0,0,0,5906,292.617,999.931,,,,,,,,,,,,,,,,,219.613266,,,,,,295.03775025,,,,
,15383448.78,514.098571777344,999.931,0.161616907040793,3.03121682955058E-6,1,15.0002345885404,40.1327056884766,1.98846711517513,10.3100021928549,0.888932925728981,0.0834893139786723,25,-0.000257356708464221,0.161610119529784,0.000377696971122532,295.0299988,295.033783,999.931,999.931,59.0238960011986,20.5185728834973,9.15E-6,0,0,0,5906,292.52425,999.931,,,,,,,,,,,,,,,,,219.979218,,,,,,295.0318909,,,,
,15383568.785,524.089233398438,999.931,0.159190482877707,2.80973118380463E-6,1,15.0002345885404,40.1327056884766,1.98816274410947,10.3100021928549,0.875453737856959,0.0822378740051676,25,-0.00025108872741956,0.159183620458526,0.000374646094391225,295.0620422,295.0666504,999.931,999.931,59.4483202871409,20.5276442485085,9.15E-6,0,0,0,5906,292.4395,999.931,,,,,,,,,,,,,,,,,220.345184,,,,,,295.0643463,,,,
,15383688.825,534.116027832031,999.931,0.156854050969974,2.23969878441784E-6,1,15.0002345885404,40.1327056884766,1.98847563930521,10.3100021928549,0.862737913036897,0.0810325944672273,25,-0.000249646732165783,0.156847205317697,0.000367203163353231,295.0783691,295.0791931,999.931,999.931,59.1825665906024,20.5321212251758,9.15E-6,0,0,0,5906,292.3205,999.931,,,,,,,,,,,,,,,,,220.345184,,,,,,295.0787811,,,,
,15383808.845,544.153198242188,999.931,0.154536777276991,2.70361023396106E-6,1,15.0002345885404,40.1327056884766,1.98841514610014,10.3100021928549,0.849967613566874,0.079828019093665,25,-0.000247122310564039,0.154530052466111,0.000360854567709795,295.0697021,295.0705872,999.931,999.931,59.485838456064,20.5365649984368,9.2E-6,0,0,0,5906,292.2237,999.931,,,,,,,,,,,,,,,,,219.979218,,,,,,295.07014465,,,,
,15383928.8,554.212707519531,999.931,0.152146083661807,2.56335232787443E-6,1,15.0002345885404,40.1327056884766,1.98857946963141,10.3100021928549,0.836886219880127,0.0785961177253738,25,-0.00024416001878235,0.152139423420504,0.000354675319119214,295.0739746,295.0745239,999.931,999.931,59.0348388004678,20.5378558290484,9.2E-6,0,0,0,5906,292.1156,999.931,,,,,,,,,,,,,,,,,220.345184,,,,,,295.07424925,,,,
,15384048.74,564.214233398438,999.931,0.149525567815686,2.67529425353343E-6,1,15.0002345885404,40.1327056884766,1.98859071355363,10.3100021928549,0.822475000676715,0.0772558553710039,25,-0.000237890870270253,0.14951896674538,0.000350938998637333,295.0782471,295.0787354,999.931,999.931,59.0614141701216,20.539337301425,9.1E-6,0,0,0,5906,291.987,999.931,,,,,,,,,,,,,,,,,220.711136,,,,,,295.07849125,,,,
,15384168.81,574.278076171875,999.931,0.146818799855734,2.42709262638372E-6,1,15.0002345885404,40.1327056884766,1.98860363582468,10.3100021928549,0.807592277397165,0.0758458481688984,25,-0.000236067726873903,0.146812282877122,0.000342413052073848,295.0819092,295.0825806,999.931,999.931,58.7534525335447,20.5448335164467,9.2E-6,0,0,0,5906,291.85565,999.931,,,,,,,,,,,,,,,,,220.345184,,,,,,295.0822449,,,,
,15384288.735,584.240417480469,999.931,0.14375368116276,2.40761191569268E-6,1,15.0002345885404,40.1327056884766,1.98885203937732,10.3100021928549,0.790827455608216,0.0742819796654709,25,-0.000229489931395858,0.143747233848698,0.000337177302337783,295.0895386,295.09198,999.931,999.931,59.3115352962755,20.5467341165263,9.2E-6,0,0,0,5906,291.74175,999.931,,,,,,,,,,,,,,,,,220.345184,,,,,,295.0907593,,,,
,15384408.915,594.330932617187,999.931,0.141095141607249,2.23948389748081E-6,1,15.0002345885404,40.1327056884766,1.98887130799903,10.3100021928549,0.776208686827496,0.0729141723744932,25,-0.000224654691136755,0.141088759684124,0.000331901045947591,295.0935059,295.0961914,999.931,999.931,58.8206725861985,20.546669091945,9.2E-6,0,0,0,5906,291.5797,999.931,,,,,,,,,,,,,,,,,220.345184,,,,,,295.09484865,,,,
,15384528.79,604.264404296875,999.931,0.138156551665595,2.38712588751033E-6,1,15.0002345885404,40.1327056884766,1.98879631570188,10.3100021928549,0.760013456388888,0.0714038739621615,25,-0.000218243545655415,0.138150280733381,0.000326974410453732,295.0921936,295.092865,999.931,999.931,58.8456846988139,20.5476274089407,9.2E-6,0,0,0,5906,291.46585,999.931,,,,,,,,,,,,,,,,,221.077087,,,,,,295.0925293,,,,
,15384648.785,614.353698730469,999.931,0.13506573068076,2.25287065939331E-6,1,15.0002345885404,40.1327056884766,1.98863185241668,10.3100021928549,0.742949199842043,0.0698120828995774,25,-0.000211651455550262,0.135059553430826,0.000321715251197223,295.0940247,295.094574,999.931,999.931,58.8816396106985,20.5541647031703,9.2E-6,0,0,0,5906,291.307,999.931,,,,,,,,,,,,,,,,,220.345184,,,,,,295.09429935,,,,
,15384768.78,624.398681640625,999.931,0.131847303537493,2.4203398118984E-6,1,15.0002345885404,40.1327056884766,1.98869626696373,10.3100021928549,0.725267496806094,0.0681604527046075,25,-0.000205174074452236,0.131841214415115,0.000315824260082075,295.0990906,295.1006165,999.931,999.931,58.8542826125255,20.5598567798838,9.15E-6,0,0,0,5906,291.14695,999.931,,,,,,,,,,,,,,,,,220.345184,,,,,,295.09985355,,,,
,15384888.78,634.419982910156,999.931,0.12852135746838,1.95465008394143E-6,1,15.0002345885404,40.1327056884766,1.98873702602069,10.3100021928549,0.706985596003747,0.0664468194493945,25,-0.000199495423554682,0.128515378243686,0.000308667216764525,295.1026611,295.1038208,999.931,999.931,58.9472964063139,20.5583030866379,9.2E-6,0,0,0,5906,290.9994,999.931,,,,,,,,,,,,,,,,,221.077087,,,,,,295.10324095,,,,
,15385008.795,644.485290527344,999.931,0.125072569358654,2.3104761668672E-6,1,15.0002345885404,40.1327056884766,1.98876170191857,10.3100021928549,0.688018799133288,0.0647009923266712,25,-0.000187822849640756,0.125066697094239,0.000307012932446057,295.1018677,295.1039734,999.931,999.931,57.9944912413715,20.5589956448199,9.15E-6,0,0,0,5906,290.8466,999.931,,,,,,,,,,,,,,,,,221.077087,,,,,,295.10292055,,,,
,15385128.785,654.469787597656,999.931,0.12142710836289,2.29716746850885E-6,1,15.0002345885404,40.1327056884766,1.98882090204132,10.3100021928549,0.667986227259436,0.0627994790870807,25,-0.00018581862148919,0.121421392599683,0.000294882694798902,295.1029663,295.1033325,999.931,999.931,58.8011318732178,20.5590638890617,9.2E-6,0,0,0,5906,290.7003,999.931,,,,,,,,,,,,,,,,,221.077087,,,,,,295.1031494,,,,
,15385248.79,664.54541015625,999.931,0.117602859691781,2.14489563022885E-6,1,15.0002345885404,40.1327056884766,1.98879966937203,10.3100021928549,0.646940402747369,0.0608330131385403,25,-0.00017811288418082,0.117597271422021,0.000287778926420102,295.1071167,295.1072998,999.931,999.931,58.59556357266,20.5603570189464,9.15E-6,0,0,0,5906,290.5276,999.931,,,,,,,,,,,,,,,,,220.345184,,,,,,295.10720825,,,,
,15385368.735,674.608093261719,999.931,0.113576354715888,2.18806505724555E-6,1,15.0002345885404,40.1327056884766,1.98881577026665,10.3100021928549,0.624794267235436,0.0587594614092609,25,-0.000170701632338257,0.113570916887214,0.00027952774437487,295.1091309,295.1102295,999.931,999.931,58.9285373218524,20.5602930732953,9.3E-6,0,0,0,5906,290.3712,999.931,,,,,,,,,,,,,,,,,221.077087,,,,,,295.1096802,,,,
,15385488.8,684.650268554687,999.931,0.109275615668079,8.33128327090446E-7,1,15.0002345885404,40.1327056884766,1.98876729851791,10.3100021928549,0.601120328908188,0.0565393349510069,25,-0.000163422520101447,0.109270333443938,0.000270080753573744,295.1136475,295.1160889,999.931,999.931,58.6995201657177,20.5621538689303,9.2E-6,0,0,0,5906,290.18995,999.931,,,,,,,,,,,,,,,,,220.711136,,,,,,295.1148682,,,,
,15385608.875,694.6279296875,999.931,0.10467735110648,1.69366010414617E-6,1,15.0002345885404,40.1327056884766,1.98873928226316,10.3100021928549,0.575819156696062,0.0541405876479374,25,-0.000160275933864658,0.104672269134759,0.000255291364369862,295.1170959,295.1176758,999.931,999.931,59.0747018549486,20.5638450420408,9.2E-6,0,0,0,5906,290.01105,999.931,,,,,,,,,,,,,,,,,221.077087,,,,,,295.11738585,,,,
,15385728.755,704.716674804687,999.931,0.0997150433282143,1.60898946645699E-6,1,15.0002345885404,40.1327056884766,1.98875106728967,10.3100021928549,0.548524427657633,0.0515813232023038,25,-0.000151664015420637,0.0997101793311841,0.000244465497458371,295.1150513,295.1152649,999.931,999.931,58.6807610812562,20.5667347397869,9.2E-6,0,0,0,5906,289.84985,999.931,,,,,,,,,,,,,,,,,221.077087,,,,,,295.1151581,,,,
,15385848.78,714.746154785156,999.931,0.0943225308029213,1.79240782787485E-6,1,15.0002345885404,40.1327056884766,1.98880449890943,10.3100021928549,0.518874211345957,0.0487911895592961,25,-0.000144114742771581,0.094317886989811,0.000230896999057901,295.1204224,295.1219482,999.931,999.931,58.5056762929485,20.5668779511235,9.2E-6,0,0,0,5906,289.6524,999.931,,,,,,,,,,,,,,,,,221.077087,,,,,,295.1211853,,,,
,15385968.735,724.742370605469,999.931,0.088393878999742,1.65197971337912E-6,1,15.0002345885404,40.1327056884766,1.98885579124048,10.3100021928549,0.48627261199524,0.0457238459873735,25,-0.000135631691271638,0.0883895050157044,0.000216073222935939,295.1194763,295.1220093,999.931,999.931,58.5408495763139,20.5708939190263,9.2E-6,0,0,0,5906,289.4697,999.931,,,,,,,,,,,,,,,,,220.711136,,,,,,295.1207428,,,,
,15386088.775,734.796081542969,999.931,0.0814776674097344,1.03188025733313E-6,1,15.0002345885404,40.1327056884766,1.98887927213427,10.3100021928549,0.448230664041036,0.0421418347694802,25,-0.000126145123107666,0.0814736193932884,0.000198274062489948,295.119751,295.1203003,999.931,999.931,57.8983509335061,20.569128818414,9.2E-6,0,0,0,5906,289.2956,999.931,,,,,,,,,,,,,,,,,220.711136,,,,,,295.12002565,,,,
,15386223.775,746.091064453125,999.931,0.0736166178779792,1.49475763089253E-6,1,15.0002345885404,40.1327056884766,1.98890604391735,10.3100021928549,0.404846675910111,0.0380837757215319,2.5,-0.000110478980463188,0.0736129224574947,0.000182897683770017,295.1190186,295.1202393,999.931,999.931,58.7690851039293,20.5704606586377,9.1E-6,0,0,0,5906,289.0823,999.931,,,,,,,,,,,,,,,,,220.345184,,,,,,295.11962895,,,,
,15386343.77,756.166442871094,999.931,0.0650046174719677,1.35058243006594E-6,1,15.0002345885404,40.1327056884766,1.98887402806696,10.3100021928549,0.357479866109162,0.0336308811471637,2.5,-9.72391074245307E-5,0.0650013262394392,0.000162021152132942,295.12323,295.1237793,999.931,999.931,58.5830575163524,20.5731635527608,9.15E-6,0,0,0,5906,288.89145,999.931,,,,,,,,,,,,,,,,,220.711136,,,,,,295.12350465,,,,
,15386463.84,766.162048339844,999.931,0.0555362201537756,7.81446443134035E-7,1,15.0002345885404,40.1327056884766,1.98886135851715,10.3100021928549,0.305407911347295,0.0287356832189829,2.5,-8.26130752312399E-5,0.0555333769692657,0.000139072435108703,295.1301575,295.1311646,999.931,999.931,58.3094875346216,20.5743899965187,9.15E-6,0,0,0,5906,288.68555,999.931,,,,,,,,,,,,,,,,,220.345184,,,,,,295.13066105,,,,
,15386583.755,776.194213867187,999.931,0.0446918782917849,8.35754143645533E-7,1,15.0002345885404,40.1327056884766,1.98877901951576,10.3100021928549,0.245761522801347,0.0231294205682821,2.5,-6.55746759333181E-5,0.0446895720337886,0.000112968408336937,295.1308899,295.1313477,999.931,999.931,58.7995686161793,20.5756931122988,9.2E-6,0,0,0,5906,288.4886,999.931,,,,,,,,,,,,,,,,,220.345184,,,,,,295.1311188,,,,
,15386703.745,786.159851074219,999.931,0.0327799273439658,3.36222993591775E-7,1,15.0002345885404,40.1327056884766,1.98882907175218,10.3100021928549,0.180262290491478,0.0169598851445073,2.5,-4.91527442966899E-5,0.0327782208138608,8.19231529798457E-5,295.1370544,295.1412964,999.931,999.931,58.3704545591215,20.5743062864246,9.15E-6,0,0,0,5906,288.2658,999.931,,,,,,,,,,,,,,,,,220.345184,,,,,,295.1391754,,,,
,15386823.74,796.313720703125,999.931,0.0208001297206496,4.26047856323177E-7,1,15.0002345885404,40.1327056884766,1.98889778853395,10.3100021928549,0.114387372120675,0.0107601052388899,2.5,-3.16227800536907E-5,0.0207990372356889,5.16279553543827E-5,295.1438904,295.1473389,999.931,999.931,58.6010349722947,20.5756320502714,9.15E-6,0,0,0,5906,288.0394,999.931,,,,,,,,,,,,,,,,,220.711136,,,,,,295.14561465,,,,
,15386943.73,806.311096191406,999.931,0.0108980679498906,2.60895866197602E-7,1,15.0002345885404,40.1327056884766,1.98886737540498,10.3100021928549,0.0599312293386292,0.00563996182374265,2.5,-1.61805808112402E-5,0.0108974880462905,2.74819113862461E-5,295.1501465,295.1520081,999.931,999.931,58.7565790476216,20.5734152269345,9.2E-6,0,0,0,5906,287.79645,999.931,,,,,,,,,,,,,,,,,220.711136,,,,,,295.1510773,,,,
,15387078.795,817.513732910156,999.931,0.00429965107439051,8.4696530801951E-8,1,15.0002345885404,40.1327056884766,1.98892130003693,10.3100021928549,0.0236527599675516,0.00223628052301746,0.25,-4.53215734679168E-6,0.00429941263448308,1.27135510692516E-5,295.1532898,295.1542358,999.931,999.931,58.59556357266,20.577455790964,9.15E-6,0,0,0,5906,287.52355,999.931,,,,,,,,,,,,,,,,,219.979218,,,,,,295.1537628,,,,
,15387198.77,827.606201171875,999.931,0.00176760393388454,3.69348538451905E-8,1,15.0002345885404,40.1327056884766,1.98760428333708,10.3100021928549,0.00971797435705354,0.000913256330621631,0.25,-2.86889927210311E-6,0.00176750915940064,4.22748757039757E-6,295.1562195,295.1572571,999.931,999.931,59.3545248648332,20.5403582376447,9.2E-6,0,0,0,5906,287.30125,999.931,,,,,,,,,,,,,,,,,220.345184,,,,,,295.1567383,,,,
,15387318.8,837.672119140625,999.931,0.000792342067060608,1.30909763716736E-8,1,15.0002345885404,40.1327056884766,1.98727038075415,10.3100021928549,0.00435595556448687,0.000403907292355859,0.25,-2.27169063640617E-6,0.000792303093459691,9.12639683318415E-7,295.1624146,295.1630249,999.931,999.931,60.0361049336025,20.5282385162294,9.2E-6,0,0,0,5906,287.0547,999.931,,,,,,,,,,,,,,,,,220.345184,,,,,,295.16271975,,,,
,15387438.73,847.649353027344,999.931,0.000424939892571888,8.16215181866169E-9,1,15.0002345885404,40.1327056884766,1.98751646816656,10.3100021928549,0.00233667135384279,0.000213996038473768,0.25,-1.70210347853193E-6,0.000424920706984711,7.55698271136505E-9,295.1658936,295.1682739,999.931,999.931,59.7789491507756,20.5311709046333,9.2E-6,0,0,0,5906,286.79485,999.931,,,,,,,,,,,,,,,,,220.345184,,,,,,295.16708375,,,,
,15387573.755,858.9921875,999.931,0.000256933297414264,4.98508184483126E-9,1,15.0002345885404,40.1327056884766,1.98749664781192,10.3100021928549,0.00141316229826608,0.000125780648574135,0.25,-1.68672841705887E-6,0.000256924178409309,-6.5167660971253E-7,295.1731262,295.1733398,999.931,999.931,59.8391345467563,20.5321830472854,9.15E-6,0,0,0,5906,286.49505,999.931,,,,,,,,,,,,,,,,,220.711136,,,,,,295.173233,,,,
,15387693.77,868.996398925781,999.931,0.00019943204011612,4.2928289122536E-9,1,15.0002345885404,40.1327056884766,1.9875368818499,10.3100021928549,0.00109695425647312,9.72745417982914E-5,0.25,-1.3754091077182E-6,0.000199425119344329,-5.71044663017699E-7,295.1769714,295.177063,999.931,999.931,60.2971688590256,20.5340256660287,9.2E-6,0,0,0,5906,286.21125,999.931,,,,,,,,,,,,,,,,,219.979218,,,,,,295.1770172,,,,
,15387828.74,880.255493164062,999.931,0.000171410246856846,3.4991392662914E-9,1,15.0002345885404,40.1327056884766,1.98747419433318,10.3100021928549,0.000942838313144569,8.31377024056402E-5,0.25,-1.26793011208225E-6,0.000171404521444242,-5.75647001448379E-7,295.1846008,295.1847839,999.931,999.931,59.4483202871409,20.5319832737438,9.2E-6,0,0,0,5906,285.8883,999.931,,,,,,,,,,,,,,,,,219.613266,,,,,,295.18469235,,,,
,15387948.73,890.335083007812,999.931,0.000159666449236402,3.52936882619422E-9,1,15.0002345885404,40.1327056884766,1.98783013337239,10.3100021928549,0.0008785944576918,7.53705769972906E-5,0.25,-1.56101246496701E-6,0.000159662571194547,-9.15378445379667E-7,295.1868591,295.1875916,999.931,999.931,59.7453391244486,20.5408196815999,9.2E-6,0,0,0,5906,285.60765,999.931,,,,,,,,,,,,,,,,,219.979218,,,,,,295.18722535,,,,
,15388068.835,899.962646484375,999.931,0.000154713423340123,2.92719943869009E-9,1,15.0002345885404,40.1327056884766,1.98742078612802,10.3100021928549,0.000851400333633404,7.0585487341593E-5,0.25,-1.95588810210896E-6,0.000154711365762033,-1.32947186984807E-6,295.1915894,295.1939087,999.931,999.931,59.986862336891,20.5328498490864,9.2E-6,0,0,0,5909,285.30925,999.931,,,,,,,,,,,,,,,,,219.979218,,,,,,295.19274905,,,,
,15388188.74,896.806762695313,999.931,0.000155933272488761,2.8642314003353E-9,1,15.0002345885404,40.1327056884766,1.98750430569778,10.3100021928549,0.000857755103334599,7.52711301951603E-5,0.25,-1.22123047299941E-6,0.000155928387626456,-5.89352044511051E-7,295.1227417,295.1373901,999.931,999.931,59.6085541335832,20.534349896354,9.2E-6,0,0,0,5906,285.0928,999.931,,,,,,,,,,,,,,,,,219.979218,,,,,,295.1300659,,,,
,15388308.73,886.829223632813,999.931,0.000160537001751859,3.11815476799278E-9,1,15.0002345885404,40.1327056884766,1.98745197448981,10.3100021928549,0.000882996618684702,7.81605404465185E-5,0.25,-1.13535125637166E-6,0.000160532222915574,-4.85092389752791E-7,294.9624939,294.9821472,999.931,999.931,59.6406009028717,20.5356618022819,9.15E-6,0,0,0,5906,285.1901,999.931,,,,,,,,,,,,,,,,,219.613266,,,,,,294.97232055,,,,
,15388428.75,876.817138671875,999.931,0.000169406757855832,3.14893752239379E-9,1,15.0002345885404,40.1327056884766,1.98746507040359,10.3100021928549,0.000931999987114209,8.03069792265747E-5,0.25,-1.59256390150347E-6,0.000169403952287184,-9.07175357419502E-7,294.850769,294.8587952,999.931,999.931,59.7062576984871,20.5366892257795,9.2E-6,0,0,0,5906,285.4748,999.931,,,,,,,,,,,,,,,,,219.247314,,,,,,294.8547821,,,,
,15388548.725,866.897888183594,999.931,0.000188340417190395,3.59681689196356E-9,1,15.0002345885404,40.1327056884766,1.98754567438064,10.3100021928549,0.00103591281973216,9.23669036500692E-5,0.25,-1.20907087589524E-6,0.000188335380841574,-4.48137784492673E-7,294.8046265,294.8082581,999.931,999.931,59.4412856304678,20.5391398794335,9.15E-6,0,0,0,5906,285.79715,999.931,,,,,,,,,,,,,,,,,219.247314,,,,,,294.8064423,,,,
,15388668.74,856.902282714844,999.931,0.000226622957880274,3.56156865309505E-9,1,15.0002345885404,40.1327056884766,1.98739431335934,10.3100021928549,0.00124643394358743,0.000110602814251928,0.25,-1.55017050350897E-6,0.0002266174557203,-6.35762971749884E-7,294.7967529,294.7969055,999.931,999.931,59.6624865014102,20.5389929803556,9.2E-6,0,0,0,5906,286.11105,999.931,,,,,,,,,,,,,,,,,219.247314,,,,,,294.7968292,,,,
,15388788.73,846.951721191406,999.931,0.000321476212925898,3.44643130581697E-9,1,15.0002345885404,40.1327056884766,1.98745316289561,10.3100021928549,0.00176772204588603,0.000161705761553804,0.25,-1.32304090210355E-6,0.00032146495127204,-2.76469283846458E-8,294.805603,294.8063049,999.931,999.931,59.9368381116602,20.5459983199705,9.2E-6,0,0,0,5906,286.42445,999.931,,,,,,,,,,,,,,,,,219.247314,,,,,,294.80595395,,,,
,15388908.79,837.021118164062,999.931,0.000529161702075329,9.30743848654335E-9,1,15.0002345885404,40.1327056884766,1.98769502412741,10.3100021928549,0.00290966581527637,0.000270559255093156,0.25,-1.38315969636157E-6,0.000529140060568984,7.46466863742103E-7,294.8156433,294.8166199,999.931,999.931,60.0908189299487,20.5494623209319,9.2E-6,0,0,0,5906,286.7172,999.931,,,,,,,,,,,,,,,,,219.979218,,,,,,294.8161316,,,,
,15389028.78,826.976257324219,999.931,0.0010511174607797,2.04814104062822E-8,1,15.0002345885404,40.1327056884766,1.98756818575258,10.3100021928549,0.00577880080538957,0.000543136331829255,0.25,-1.69948990575003E-6,0.00105107043132177,2.52614326055006E-6,294.8242798,294.8258972,999.931,999.931,59.9110443705256,20.5534827609052,9.2E-6,0,0,0,5906,286.9767,999.931,,,,,,,,,,,,,,,,,219.979218,,,,,,294.8250885,,,,
,15389148.745,817.057495117187,999.931,0.00235795713687789,4.91735149310813E-8,1,15.0002345885404,40.1327056884766,1.98776915525327,10.3100021928549,0.0129641552356714,0.00122512249982135,0.25,-2.6037713462193E-6,0.00235784707811077,6.86586754684812E-6,294.8344727,294.8347168,999.931,999.931,58.9816880611601,20.5540263462481,9.15E-6,0,0,0,5906,287.2205,999.931,,,,,,,,,,,,,,,,,219.247314,,,,,,294.83459475,,,,
,15389268.735,807.074890136719,999.931,0.00542731494428994,1.16650044710255E-7,1,15.0002345885404,40.1327056884766,1.98776838684391,10.3100021928549,0.0298390042480142,0.00282627648011939,0.25,-4.80545508850958E-6,0.00542705781326969,1.69691234999713E-5,294.8410645,294.8431091,999.931,999.931,59.5858869065255,20.5552199746263,9.2E-6,0,0,0,5906,287.45975,999.931,,,,,,,,,,,,,,,,,218.881363,,,,,,294.8420868,,,,
,15389388.765,797.159606933594,999.931,0.0115722268756036,1.96615964781802E-7,1,15.0002345885404,40.1327056884766,1.9878848967377,10.3100021928549,0.0636266457333464,0.00602997749664695,0.25,-9.58295879763244E-6,0.0115716794732314,3.6798255357489E-5,294.8452759,294.8453979,999.931,999.931,59.760190066314,20.5575110293151,9.15E-6,0,0,0,5906,287.7035,999.931,,,,,,,,,,,,,,,,,219.613266,,,,,,294.8453369,,,,
,15389508.775,787.14208984375,999.931,0.0211013731393644,4.40305309555882E-7,1,15.0002345885404,40.1327056884766,1.98778889870184,10.3100021928549,0.116014641660611,0.0109938513815106,0.25,-1.75712447877328E-5,0.0211003822778147,6.69190627491081E-5,294.84729,294.8475342,999.931,999.931,59.6554518447371,20.5586460012935,9.15E-6,0,0,0,5906,287.9418,999.931,,,,,,,,,,,,,,,,,218.881363,,,,,,294.8474121,,,,
,15389643.72,775.9326171875,999.931,0.0344798107667994,6.91446128077312E-7,1,15.0002345885404,40.1327056884766,1.98788961802547,10.3100021928549,0.189521744677298,0.0178572617923155,2.5,-4.702377091781E-5,0.034478272307443,9.08976576935401E-5,294.8525696,294.8545532,999.931,999.931,59.8696180590063,20.5625993239226,9.2E-6,0,0,0,5906,288.18205,999.931,,,,,,,,,,,,,,,,,218.881363,,,,,,294.8535614,,,,
,15389763.715,765.953491210937,999.931,0.0468903067224263,9.52973794571929E-7,1,15.0002345885404,40.1327056884766,1.9878914652438,10.3100021928549,0.257737068307255,0.0242901926070261,2.5,-6.27862038017335E-5,0.0468882236671167,0.000124605776657099,294.8544617,294.8569946,999.931,999.931,59.7156372407179,20.5663995527693,9.2E-6,0,0,0,5906,288.40395,999.931,,,,,,,,,,,,,,,,,218.881363,,,,,,294.85572815,,,,
,15389883.765,756.049621582031,999.931,0.0585421746680458,7.5456374131084E-7,1,15.0002345885404,40.1327056884766,1.98790338054379,10.3100021928549,0.321785048514987,0.0303218705036226,2.5,-7.89797354123487E-5,0.0585395886215184,0.000154764223527583,294.8602905,294.8612671,999.931,999.931,60.2057183222756,20.56521197467,9.2E-6,0,0,0,5906,288.6247,999.931,,,,,,,,,,,,,,,,,218.515411,,,,,,294.8607788,,,,
,15390003.765,746.002502441406,999.931,0.0690312549098076,1.22517887945827E-6,1,15.0002345885404,40.1327056884766,1.98791414780581,10.3100021928549,0.379442013795194,0.0357523191911213,2.5,-9.33844615247546E-5,0.0690282169029541,0.000182028545271651,294.8656921,294.8661194,999.931,999.931,59.5694727076217,20.5657359091079,9.15E-6,0,0,0,5906,288.8102,999.931,,,,,,,,,,,,,,,,,219.247314,,,,,,294.86590575,,,,
,15390123.775,736.176025390625,999.931,0.0782843265741518,1.66588499020726E-6,1,15.0002345885404,40.1327056884766,1.98799028232159,10.3100021928549,0.43031931482648,0.0405464629025849,2.5,-0.000105559389320806,0.0782809078997058,0.000206484136618067,294.8650513,294.8665466,999.931,999.931,59.5085056831217,20.568327209611,9.2E-6,0,0,0,5906,289.03235,999.931,,,,,,,,,,,,,,,,,218.14946,,,,,,294.86579895,,,,
,15390243.735,726.148681640625,999.931,0.0865127841318799,1.65773920998359E-6,1,15.0002345885404,40.1327056884766,1.98796417558702,10.3100021928549,0.475543739670158,0.0448116832512382,2.5,-0.000115665790390526,0.0865090188890601,0.000228906848435345,294.8695374,294.8696594,999.931,999.931,59.516321968314,20.5706737793888,9.2E-6,0,0,0,5906,289.222,999.931,,,,,,,,,,,,,,,,,218.881363,,,,,,294.8695984,,,,
,15390363.725,716.233581542969,999.931,0.0938526853892122,1.43592477372351E-6,1,15.0002345885404,40.1327056884766,1.98799158219227,10.3100021928549,0.515896216998606,0.0486199551722924,2.5,-0.000124146182635266,0.0938486112722323,0.00024936571269143,294.8731384,294.8754883,999.931,999.931,59.6234050754486,20.5686324114314,9.2E-6,0,0,0,5906,289.4134,999.931,,,,,,,,,,,,,,,,,218.881363,,,,,,294.87431335,,,,
,15390483.75,706.239990234375,999.931,0.100439532514076,1.99479766758099E-6,1,15.0002345885404,40.1327056884766,1.98807625273274,10.3100021928549,0.552126668186172,0.0520308949785463,2.5,-0.000133212345737066,0.100435189618036,0.000266226675316164,294.8782654,294.8787231,999.931,999.931,59.8703996875256,20.5686909846251,9.15E-6,0,0,0,5906,289.58775,999.931,,,,,,,,,,,,,,,,,218.515411,,,,,,294.87849425,,,,
,15390603.71,696.234924316406,999.931,0.10648164749163,2.43310243784393E-6,1,15.0002345885404,40.1327056884766,1.98806394784813,10.3100021928549,0.585336270683977,0.0551725764106139,2.5,-0.000138694085564842,0.106477061518697,0.000284423779316773,294.8800659,294.8805542,999.931,999.931,59.963413481314,20.5720385985241,9.2E-6,0,0,0,5906,289.7886,999.931,,,,,,,,,,,,,,,,,218.14946,,,,,,294.88031005,,,,
,15390723.78,686.347900390625,999.931,0.112015140320859,2.19109429213147E-6,1,15.0002345885404,40.1327056884766,1.98797159313791,10.3000016510487,0.615725957904382,0.0580412770488875,2.5,-0.000144813631971784,0.112010328221065,0.000299967467045704,294.8847656,294.8851318,999.931,999.931,59.7211086403525,20.5708816234641,9.2E-6,0,0,0,5906,289.966,999.931,,,,,,,,,,,,,,,,,218.14946,,,,,,294.8849487,,,,
,15390843.71,676.320129394531,999.931,0.117142774189406,2.32477113067605E-6,1,15.0002345885404,40.1327056884766,1.98801742199335,10.3100021928549,0.643926993960613,0.0606918075102161,2.5,-0.000152514225445293,0.117137776349285,0.000312286350403634,294.8855286,294.8858948,999.931,999.931,59.4686426286409,20.5732666323469,9.25E-6,0,0,0,5906,290.1444,999.931,,,,,,,,,,,,,,,,,218.515411,,,,,,294.8857117,,,,
,15390963.745,666.388549804687,999.931,0.121917240500848,2.72327031790146E-6,1,15.0002345885404,40.1327056884766,1.98805930741059,10.3100021928549,0.67018513989953,0.063174572673705,2.5,-0.000156975873122005,0.121912057136381,0.000326432771094017,294.8874817,294.888092,999.931,999.931,59.5491503661217,20.5745859857665,9.15E-6,0,0,0,5906,290.31355,999.931,,,,,,,,,,,,,,,,,218.14946,,,,,,294.88778685,,,,
,15391083.75,656.388549804687,999.931,0.126412054479056,1.90664411743021E-6,1,15.0002345885404,40.1327056884766,1.98807421842739,10.3100021928549,0.694900303134716,0.0654859401462899,2.5,-0.000165755361489152,0.12640671359152,0.000335151598038125,294.8897705,294.8910522,999.931,999.931,59.3623411500255,20.5748411829454,9.2E-6,0,0,0,5906,290.47105,999.931,,,,,,,,,,,,,,,,,218.14946,,,,,,294.89041135,,,,
,15391203.71,646.447570800781,999.931,0.130636316935852,2.16664099818406E-6,1,15.0002345885404,40.1327056884766,1.98807769529497,10.3100021928549,0.718122272762472,0.0676807827701831,2.5,-0.000169807195326579,0.130630818507591,0.000347514824467204,294.8912964,294.8918152,999.931,999.931,59.5968297057948,20.5750787933078,9.2E-6,0,0,0,5906,290.6234,999.931,,,,,,,,,,,,,,,,,218.515411,,,,,,294.8915558,,,,
,15391323.775,636.516967773437,999.931,0.134648130250232,2.50698794535563E-6,1,15.0002345885404,40.1327056884766,1.98801566304187,10.3100021928549,0.740153760534442,0.0697515344534367,2.5,-0.000175635044202731,0.134642492367748,0.000357168741180879,294.8946533,294.8946838,999.931,999.931,59.9376197401794,20.5762600002579,9.2E-6,0,0,0,5906,290.80875,999.931,,,,,,,,,,,,,,,,,218.515411,,,,,,294.89466855,,,,
,15391443.72,626.568054199219,999.931,0.138459615674121,2.79141219483753E-6,1,15.0002345885404,40.1327056884766,1.98800626830799,10.3100021928549,0.761100900057851,0.0717354311051667,2.5,-0.0001785459828885,0.138453820343988,0.000369055913912073,294.8985901,294.899353,999.931,999.931,59.5217933679486,20.579585612187,9.15E-6,0,0,0,5906,290.9352,999.931,,,,,,,,,,,,,,,,,217.783508,,,,,,294.89897155,,,,
,15391563.715,616.564086914062,999.931,0.142089411324723,2.30457588042194E-6,1,15.0002345885404,40.1327056884766,1.98790597702086,10.3100021928549,0.78101414251043,0.0736237030516949,2.5,-0.00018079935755025,0.14208348199406,0.000380787549109802,294.9006653,294.9012451,999.931,999.931,59.5585299083524,20.5779569330651,9.15E-6,0,0,0,5906,291.09625,999.931,,,,,,,,,,,,,,,,,217.783508,,,,,,294.9009552,,,,
,15391683.735,606.650817871094,999.931,0.145568513288086,2.70953293088354E-6,1,15.0002345885404,40.1327056884766,1.98797223923728,10.3100021928549,0.800165346244423,0.0754121676913613,2.5,-0.000187934916002616,0.145562483423632,0.000387071613415181,294.8995667,294.9012756,999.931,999.931,59.4233081745255,20.5805997721497,9.15E-6,0,0,0,5906,291.2369,999.931,,,,,,,,,,,,,,,,,218.515411,,,,,,294.90042115,,,,
,15391803.715,596.66064453125,999.931,0.148874538314507,3.11794921763296E-6,1,15.0002345885404,40.1327056884766,1.98802590246519,10.3100021928549,0.818359181655555,0.0771326797981188,2.5,-0.000190792565825014,0.148868393524526,0.000396912054721802,294.9013672,294.902771,999.931,999.931,59.9954602506025,20.5842394483556,9.15E-6,0,0,0,5906,291.38695,999.931,,,,,,,,,,,,,,,,,217.783508,,,,,,294.9020691,,,,
,15391923.76,586.73779296875,999.931,0.151905033349263,2.21313615371206E-6,1,15.0002345885404,40.1327056884766,1.98796435596376,10.3100021928549,0.834991090727829,0.0787148152949913,2.5,-0.000191741168833778,0.151898752980551,0.000407611709631207,294.9082642,294.9093323,999.931,999.931,59.6249683324871,20.5823989837212,9.2E-6,0,0,0,5906,291.5154,999.931,,,,,,,,,,,,,,,,,217.417542,,,,,,294.90879825,,,,
,15392043.765,576.677124023437,999.931,0.15494263386499,3.00040156076023E-6,1,15.0002345885404,40.1327056884766,1.98799053510094,10.3100021928549,0.85170076925759,0.0802744337810199,2.5,-0.000198015125615478,0.154936269657763,0.000412948563570954,294.9095764,294.9096985,999.931,999.931,59.6570151017755,20.5794530984755,9.15E-6,0,0,0,5906,291.6653,999.931,,,,,,,,,,,,,,,,,218.14946,,,,,,294.90963745,,,,
,15392163.7,566.747680664063,999.931,0.158060888487927,2.70012079631868E-6,1,15.0002345885404,40.1327056884766,1.98807071057741,10.3100021928549,0.868877751833265,0.0818740149702157,2.5,-0.000205123983142937,0.158054453925608,0.000417764624866806,294.9074097,294.9074402,999.931,999.931,59.7383044677755,20.5838278615397,9.25E-6,0,0,0,5906,291.8111,999.931,,,,,,,,,,,,,,,,,217.417542,,,,,,294.90742495,,,,
,15392283.735,556.783752441406,999.931,0.160923828428911,3.7182054583278E-6,1,15.0002345885404,40.1327056884766,1.98809926313208,10.3100021928549,0.884626424061625,0.0833760162281042,2.5,-0.000205311725505388,0.16091727783836,0.000428578822774085,294.9091492,294.9111023,999.931,999.931,59.587450163564,20.5824912866532,9.2E-6,0,0,0,5906,291.91935,999.931,,,,,,,,,,,,,,,,,217.417542,,,,,,294.91012575,,,,
,15392403.715,546.847900390625,999.931,0.163661814683811,3.2931943796604E-6,1,15.0002345885404,40.1327056884766,1.9881559002674,10.3100021928549,0.899701460318828,0.0848103670635373,2.5,-0.000206043579656236,0.16365515817815,0.000438310030472211,294.912323,294.914093,999.931,999.931,59.7351779536986,20.5827627467277,9.2E-6,0,0,0,5906,292.04175,999.931,,,,,,,,,,,,,,,,,217.05159,,,,,,294.913208,,,,
,15392523.735,536.893310546875,999.931,0.16630462933464,1.48278665610341E-6,1,15.0002345885404,40.1327056884766,1.98820215965967,10.3100021928549,0.91425244465069,0.0861644552826433,2.5,-0.000212165094090834,0.166297902597789,0.000442221915658301,294.9146423,294.9156799,999.931,999.931,59.7476840100063,20.5836253875495,9.2E-6,0,0,0,5906,292.181,999.931,,,,,,,,,,,,,,,,,217.05159,,,,,,294.9151611,,,,
,15392643.695,526.935363769531,999.931,0.168857313350193,3.31513424355242E-6,1,15.0002345885404,40.1327056884766,1.98812572287581,10.3100021928549,0.928248903193486,0.0875053167873431,2.5,-0.000211186443018525,0.168850490174879,0.000452932082886732,294.9162903,294.916687,999.931,999.931,59.424871431564,20.5824306205977,9.15E-6,0,0,0,5906,292.2965,999.931,,,,,,,,,,,,,,,,,217.05159,,,,,,294.91648865,,,,
,15392763.78,516.994750976562,999.931,0.17132796215917,3.2408544841592E-6,1,15.0002345885404,40.1327056884766,1.98832754674564,10.3100021928549,0.941927326523539,0.0887615153141712,2.5,-0.000219902876406942,0.171321081546016,0.0004535638022141,294.9188843,294.9202271,999.931,999.931,59.7343963251794,20.5862406120058,9.15E-6,0,0,0,5906,292.431,999.931,,,,,,,,,,,,,,,,,218.14946,,,,,,294.9195557,,,,
,15392883.72,507.074462890625,999.931,0.173731636960543,3.63917032640964E-6,1,15.0002345885404,40.1327056884766,1.98825368957032,10.3100021928549,0.955106326434743,0.0900184593010545,2.5,-0.00021995896269906,0.17372467869594,0.000462637871262564,294.9189148,294.9200134,999.931,999.931,60.0189091061794,20.5862308778294,9.2E-6,0,0,0,5906,292.54545,999.931,,,,,,,,,,,,,,,,,217.05159,,,,,,294.9194641,,,,
,15393003.695,497.017730712891,999.931,0.176050824424008,1.37916585423759E-6,1,15.0002345885404,40.1327056884766,1.98820979416068,10.3100021928549,0.967835287392512,0.0912202143232923,2.5,-0.000222163552403392,0.176043786330214,0.000469184209656954,294.9226685,294.923645,999.931,999.931,59.6476355595448,20.5865463704995,9.2E-6,0,0,0,5906,292.67375,999.931,,,,,,,,,,,,,,,,,218.14946,,,,,,294.92315675,,,,
,15393123.74,487.068176269531,999.931,0.178318371523111,3.287015345788E-6,1,15.0002345885404,40.1327056884766,1.98812338980952,10.3100021928549,0.980259634737094,0.0923906516144848,2.5,-0.000224860300806003,0.178311267692045,0.000475122869611613,294.9221802,294.9241638,999.931,999.931,59.5858869065255,20.5934673389234,9.2E-6,0,0,0,5906,292.76825,999.931,,,,,,,,,,,,,,,,,217.783508,,,,,,294.923172,,,,
,15393243.725,477.082000732422,999.931,0.180516636460372,3.25067768891044E-6,1,15.0002345885404,40.1327056884766,1.9881578406893,10.3100021928549,0.992361130459715,0.0935297317254825,2.5,-0.000227544191135578,0.180509473676324,0.000480709616027619,294.9235535,294.9248047,999.931,999.931,59.435032602314,20.5929548331296,9.25E-6,0,0,0,5906,292.8927,999.931,,,,,,,,,,,,,,,,,217.417542,,,,,,294.9241791,,,,
,15393363.71,467.158660888672,999.931,0.182635344066969,4.31852724453034E-6,1,15.0002345885404,40.1327056884766,1.98803957374096,10.3100021928549,1.00394984690672,0.0946253689192569,2.5,-0.000229306930674233,0.182628121233181,0.000486965539258471,294.9230957,294.925415,999.931,999.931,59.475677285314,20.5864806231463,9.15E-6,0,0,0,5906,292.99365,999.931,,,,,,,,,,,,,,,,,217.783508,,,,,,294.92425535,,,,
,15393483.71,457.165374755859,999.931,0.18471829643145,3.72500399992842E-6,1,15.0002345885404,40.1327056884766,1.98812633936936,10.3100021928549,1.01544217325468,0.0957194375757305,2.5,-0.000229668546932787,0.184710988084945,0.000494481305413856,294.9284058,294.9284973,999.931,999.931,60.0095295639487,20.5895030403603,9.15E-6,0,0,0,5906,293.0927,999.931,,,,,,,,,,,,,,,,,217.783508,,,,,,294.92845155,,,,
,15393603.71,447.204620361328,999.931,0.186729150396954,4.25861296899194E-6,1,15.0002345885404,40.1327056884766,1.98802027489831,10.3100021928549,1.0264409842759,0.0967767622797,2.5,-0.000228177615484155,0.186721767133301,0.000503566945905359,294.9295654,294.9300232,999.931,999.931,59.3803186059678,20.5909303240431,9.15E-6,0,0,0,5906,293.18965,999.931,,,,,,,,,,,,,,,,,217.417542,,,,,,294.9297943,,,,
,15393723.71,437.257415771484,999.931,0.188682014066783,3.19254226004682E-6,1,15.0002345885404,40.1327056884766,1.98805554434397,10.3100021928549,1.0371944820691,0.0977863963401588,2.5,-0.00023094854410992,0.188674614722044,0.000508067850430257,294.9249878,294.9258728,999.931,999.931,59.2802701555063,20.5924440444387,9.2E-6,0,0,0,5906,293.3166,999.931,,,,,,,,,,,,,,,,,217.417542,,,,,,294.9254303,,,,
,15393843.705,427.271636962891,999.931,0.190575768308997,3.813240700881E-6,1,15.0002345885404,40.1327056884766,1.98806392070193,10.3100021928549,1.04760911169073,0.0987643733576548,2.5,-0.000233739974394753,0.19056827641847,0.00051246192629609,294.9326172,294.9338074,999.931,999.931,59.729706554064,20.5849289238151,9.25E-6,0,0,0,5906,293.3931,999.931,,,,,,,,,,,,,,,,,217.417542,,,,,,294.9332123,,,,
,15393963.735,417.241088867188,999.931,0.19243897378913,2.29775067953768E-6,1,15.0002345885404,40.1327056884766,1.98809755766063,10.3100021928549,1.05786979686808,0.0997230125675924,2.5,-0.00023728482911763,0.192431450055991,0.000515904147703004,294.9310913,294.9327087,999.931,999.931,59.3701574352178,20.5964574361681,9.2E-6,0,0,0,5906,293.494,999.931,,,,,,,,,,,,,,,,,217.417542,,,,,,294.9319,,,,
,15394083.71,407.298950195313,999.931,0.194230839468306,4.2787638693479E-6,1,15.0002345885404,40.1327056884766,1.98810527955389,10.3100021928549,1.06772390607466,0.100653892033905,2.5,-0.000238789560610432,0.194223253611441,0.000521060368414729,294.9354553,294.9365845,999.931,999.931,59.6734293006794,20.5934652672244,9.2E-6,0,0,0,5906,293.60825,999.931,,,,,,,,,,,,,,,,,217.417542,,,,,,294.9360199,,,,
,15394203.73,397.467803955078,999.931,0.195976279755105,3.79360743240054E-6,1,15.0002345885404,40.1327056884766,1.98813341939596,10.3100021928549,1.0773357293699,0.101541143807283,2.5,-0.000244083806556767,0.195968661048024,0.000522344115010632,294.9358215,294.9364929,999.931,999.931,59.0426550856601,20.5942854081855,9.2E-6,0,0,0,5906,293.68885,999.931,,,,,,,,,,,,,,,,,217.05159,,,,,,294.9361572,,,,
,15394323.725,387.479400634766,999.931,0.19766876728314,3.61571260125627E-6,1,15.0002345885404,40.1327056884766,1.98811616081175,10.3100021928549,1.08663181541573,0.102404460744213,2.5,-0.000248249109498014,0.197661094584658,0.000524536771897218,294.9393005,294.9404907,999.931,999.931,59.7484656385256,20.5963605550058,9.2E-6,0,0,0,5906,293.7722,999.931,,,,,,,,,,,,,,,,,217.05159,,,,,,294.9398956,,,,
,15394443.71,377.445739746094,999.931,0.199307297481929,3.57003274481915E-6,1,15.0002345885404,40.1327056884766,1.98809923252795,10.3100021928549,1.09562849435575,0.103271558528265,2.5,-0.000246562026152005,0.199299589480156,0.000532355448895555,294.936615,294.9371948,999.931,999.931,59.9469992824102,20.5961952333585,9.2E-6,0,0,0,5906,293.85905,999.931,,,,,,,,,,,,,,,,,217.783508,,,,,,294.9369049,,,,
,15394563.745,367.485717773438,999.931,0.200893263135018,3.89777685996175E-6,1,15.0002345885404,40.1327056884766,1.98805922705322,10.3100021928549,1.1043243832863,0.104099313143357,2.5,-0.00024679874792714,0.200885493255909,0.000538051922746099,294.9394531,294.940979,999.931,999.931,60.2643404612179,20.5968872639553,9.2E-6,0,0,0,5906,293.94235,999.931,,,,,,,,,,,,,,,,,218.14946,,,,,,294.94021605,,,,
,15394698.71,356.337982177734,999.931,0.202589143841161,3.77693053771211E-6,1,15.0002345885404,40.1327056884766,1.9880920607046,10.3100021928549,1.11406114634494,0.104941987772564,25,-0.000262144664045427,0.20258139326779,0.000529046769323558,294.9388733,294.9394531,999.931,999.931,59.5851052780063,20.5973152288809,9.1E-6,0,0,0,5906,294.0314,999.931,,,,,,,,,,,,,,,,,217.783508,,,,,,294.9391632,,,,
,15394818.72,346.445617675781,999.931,0.204057811230066,4.40145482639387E-6,1,15.0002345885404,40.1327056884766,1.98804215215361,10.3100021928549,1.1221089758604,0.105711730268164,25,-0.000261584663783417,0.20405001215906,0.000534982980267662,294.9397583,294.9443359,999.931,999.931,59.9602869672371,20.5975603462445,9.2E-6,0,0,0,5906,294.14285,999.931,,,,,,,,,,,,,,,,,217.05159,,,,,,294.9420471,,,,
,15394938.715,336.329772949219,999.931,0.205487189605904,4.34302183713238E-6,1,15.0002345885404,40.1327056884766,1.98801235121549,10.3100021928549,1.12995273521461,0.106449704039203,25,-0.000263325221073843,0.205479355099162,0.000538555311603362,294.9423523,294.9436951,999.931,999.931,59.4569182008524,20.5981657524062,9.2E-6,0,0,0,5906,294.2251,999.931,,,,,,,,,,,,,,,,,217.783508,,,,,,294.9430237,,,,
,15395058.72,326.444885253906,999.931,0.206869011262695,3.87299057105166E-6,1,15.0002345885404,40.1327056884766,1.98802113828294,10.3100021928549,1.13755738223019,0.107152758703437,25,-0.000267275732044228,0.206861129027404,0.000539769144755258,294.9470825,294.9475098,999.931,999.931,59.5303912816601,20.5977751124362,9.2E-6,0,0,0,5906,294.29495,999.931,,,,,,,,,,,,,,,,,217.05159,,,,,,294.94729615,,,,
,15395178.695,317.674194335937,999.931,0.208100120028451,3.49764627163648E-6,1,15.0002345885404,40.1327056884766,1.98812620429451,10.3100021928549,1.1443844985099,0.107815887746018,25,-0.000265059179259533,0.208092202504882,0.000546594425408142,294.9455872,294.9462585,999.931,999.931,59.5428973379678,20.5984978824234,9.2E-6,0,0,0,5910,294.35405,999.931,,,,,,,,,,,,,,,,,217.783508,,,,,,294.94592285,,,,
,15395298.765,311.684478759766,999.931,0.208996749390842,4.6413811040884E-6,1,15.0002345885404,40.1327056884766,1.9881120643142,10.3100021928549,1.14930626919444,0.108290206052578,25,-0.000263955042848931,0.208988793579287,0.000550864290191806,294.9502258,294.9506226,999.931,999.931,59.7453391244486,20.5963003235649,9.2E-6,0,0,0,5910,294.4546,999.931,,,,,,,,,,,,,,,,,217.05159,,,,,,294.9504242,,,,
,15395418.745,307.022186279297,999.931,0.209650781572485,4.67059400125446E-6,1,15.0002345885404,40.1327056884766,1.98811956559026,10.3000016510487,1.15290993221718,0.10859721006127,25,-0.000270532319934654,0.209642770240981,0.000546722871508734,294.9604492,294.9618225,999.931,999.931,59.902446456814,20.5969439261294,9.2E-6,0,0,0,5910,294.48915,999.931,,,,,,,,,,,,,,,,,217.783508,,,,,,294.96113585,,,,
,15395538.69,303.520538330078,999.931,0.210144452327954,5.06520089994093E-6,1,15.0002345885404,40.1327056884766,1.98812529811317,10.3100021928549,1.15562735114652,0.10885723422206,25,-0.000270341292182932,0.210136375053294,0.0005487418284476,294.9695435,294.970459,999.931,999.931,59.6304397321217,20.5985260483582,9.2E-6,0,0,0,5910,294.51825,999.931,,,,,,,,,,,,,,,,,217.783508,,,,,,294.97000125,,,,
,15395658.75,300.788665771484,999.931,0.210512260801075,4.22025220464617E-6,1,15.0002345885404,40.1327056884766,1.98814363768699,10.3100021928549,1.15766070330359,0.109045575361049,25,-0.000271258657903706,0.210504164489145,0.000549126291671593,294.9729919,294.9733887,999.931,999.931,59.4905282271794,20.5875964390615,9.15E-6,0,0,0,5909,294.558,999.931,,,,,,,,,,,,,,,,,217.783508,,,,,,294.9731903,,,,
,15395703.69,299.994781494141,999.931,0.210631104188983,5.00966923204446E-6,1,15.0002345885404,40.1327056884766,1.98813813362542,10.3100021928549,1.15831083865892,0.109108887608733,25,-0.00027101942680137,0.210622986373272,0.000549809869767395,294.9755554,294.9765625,999.931,999.931,59.4928731127371,20.5917167573369,9.15E-6,0,0,0,5909,294.56365,999.931,,,,,,,,,,,,,,,,,217.417542,,,,,,294.97605895,,,,