File: AC_Measurements/PPMS_Li0.6Al0.4Fe5O8 Xac.dat
[Header]
; ACMS Data File (default extension .dat)
; Copyright 1999, Quantum Design, Inc. All rights reserved.
TITLE,
FILEOPENTIME,15407431.56,06/28/2023,4:52 pm
BYAPP,ACMS,1.0,1.1
INFO,PPMS ACMS Option Version: 1.0.9 Build 14,APPNAME
INFO,HARMONICS,1
INFO,mass,85.25
DATATYPE,COMMENT,1
DATATYPE,TIME,2
FIELDGROUP,AC Mag,2,3,4,5,6,8,9,10,11,12
FIELDGROUP,DC Mag,2,3,4,7,8
STARTUPGROUP,All
STARTUPAXIS,X,2,LINEAR,AUTO
TIMEMODE,MINUTES,RELATIVE
PLOT_APPEARANCE,ALL,HORZ_GRID_ON,VERT_GRID_ON,MARKERS_AND_LINES
RECORDS,ALL_RECORDS
DATATYPE,TIME,2
DATATYPE,COMMENT,1
[Data]
Comment,Time Stamp (sec),Temperature (K),Magnetic Field (Oe),Frequency (Hz),Amplitude (Oe),M-DC (emu),M-Std.Dev. (emu),Mbar (emu),Mdoublebar (emu),Moment (emu),Phase (deg),Calcoil' (emu),Calcoil'' (emu),Calcoil (emu),CC Phase (deg),Count,Gain,Measure Type,Elapsed (sec),Sample Center (cm),Max.Signal (V),PPMS Status (code),DSP Status (code),Min.Temperature (K),Max.Temperature (K),Min.Field (Oe),Max.Field (Oe),DC Position (cm),PPMS Temperature (K),PPMS Position,Bridge 1 Resistance (ohms),Bridge 1 Excitation (uA),Bridge 2 Resistance (ohms),Bridge 2 Excitation (uA),Bridge 3 Resistance (ohms),Bridge 3 Excitation (uA),Bridge 4 Resistance (ohms),Bridge 4 Excitation (uA),Signal 1 Vin (V),Signal 2 Vin (V),Digital Inputs (code),Drive 1 Iout (mA),Drive 1 Ipower (watts),Drive 2 Iout (mA),Drive 2 Ipower (watts),Pressure (),Map 20 (),Map 21 (),Map 22 (),Map 23 (),Map 24 (),Map 25 (),Map 26 (),Map 27 (),Map 28 (),Map 29 ()
,15407584.87,5.00089175,-0.084,10,1.00159582016843,,6.90255619372828E-7,0.00133433345102766,-1.00611897395022E-5,0.00133437138236338,-0.432015538471717,1.48866767547781E-8,-5.88279361968104E-11,1.48867929900072E-8,-0.22641553733547,320,25,5,13.4965986394558,-0.14975871237181,0.00010719039702811,4369,0,4.9986672,5.0029669,-0.084,-0.084,,5.000425,,,,,,,,,,,,,,,,,,,,,,,5.00089175
,15407732.27,5.0006893,-0.084,117.879776328052,1.00158039191464,,5.45379506042296E-7,0.00134986878196412,1.28908828232458E-5,0.00134993033278805,0.5471426100717,1.48274724851109E-8,-2.92453114180359E-11,1.48275013264191E-8,-0.113008521419033,468,25,5,13.4965986394558,-0.14975871237181,0.000190975754742254,4369,0,4.9977469,5.0051031,-0.084,-0.084,,5.00065,,,,,,,,,,,,,,,,,,,,,,,5.0006893
,15407880.99,5.0020044375,-0.084,1389.5,0.999443386785438,,4.27782885292702E-7,0.00131723793403362,1.45392273190505E-5,0.00131731817112958,0.632385777929942,1.48268892276341E-8,-4.38370951999451E-10,1.48333682371904E-8,-1.69351037059283,463,25,5,13.4965986394558,-0.14975871237181,0.00112271553403732,4369,0,4.9979501,5.0059118,-0.084,-0.084,,5.000925,,,,,,,,,,,,,,,,,,,,,,,5.0020044375
,15408414.35,14.9998254875,-0.084,10,1.00159582016843,,6.70603778752742E-7,0.00135991974163472,2.27051362841445E-6,0.00135992163705119,0.0956605918529688,1.48416851826656E-8,-5.90654056345733E-12,1.48416863579775E-8,-0.0228019812964249,320,25,5,13.4965986394558,-0.14975871237181,0.000108107157536437,4369,0,14.999402,15.0004177,-0.084,-0.084,,15.0035,,,,,,,,,,,,,,,,,,,,,,,14.9998254875
,15408567.62,14.9997222375,-0.084,117.879776328052,1.00158039191464,,5.16997778577289E-7,0.00135618520476049,1.59927453416345E-5,0.00135627949830219,0.675626261312429,1.4829917940734E-8,-2.68419717180154E-11,1.48299422325358E-8,-0.1037045531844,468,25,5,13.4965986394558,-0.14975871237181,0.000191218726440399,4369,0,14.997756,15.0013084,-0.084,-0.084,,15.0039875,,,,,,,,,,,,,,,,,,,,,,,14.9997222375
,15408720.25,14.998250725,-0.084,1389.5,0.999443386785438,,4.21349627767037E-7,0.00132643641556785,1.67497959403781E-5,0.00132654216676611,0.723473510302659,1.48267794354489E-8,-4.37132514546729E-10,1.48332219447673E-8,-1.68874132315949,463,25,5,13.4965986394558,-0.14975871237181,0.00113453215802631,4369,0,14.9977436,14.9992657,-0.084,-0.084,,15.003525,,,,,,,,,,,,,,,,,,,,,,,14.998250725
,15409117.98,24.9846711125,-0.084,10,1.00127151076941,,1.08506316262875E-6,0.00138246723172048,1.59305398133027E-5,0.00138255901461009,0.660205376862889,1.49680005034642E-8,9.41808243944652E-11,1.4968296800217E-8,0.360508575342683,320,25,5,13.4965986394558,-0.14975871237181,0.000108901412879493,4369,0,24.963871,24.997673,-0.084,-0.084,,24.9936125,,,,,,,,,,,,,,,,,,,,,,,24.9846711125
,15409269.45,24.989086875,-0.084,117.879776328052,1.00125775082471,,5.66572239745577E-7,0.00139139291089052,1.69645010688931E-5,0.0013914963265395,0.698541831857836,1.48546089408549E-8,-2.88295218641591E-11,1.48546369167024E-8,-0.111198339913301,468,25,5,13.4965986394558,-0.14975871237181,0.000193824292801561,4369,0,24.9799557,24.9942818,-0.084,-0.084,,25.0232125,,,,,,,,,,,,,,,,,,,,,,,24.989086875
,15409420.33,24.9971132125,-0.084,1389.5,0.999121409183635,,4.30629499523594E-7,0.00136338019535317,1.7490666823448E-5,0.0013634923837364,0.735001447874329,1.48420381312391E-8,-4.43339234844803E-10,1.48486580392407E-8,-1.71094536138429,463,25,5,13.4965986394558,-0.14975871237181,0.00114816663790275,4369,0,24.9934216,24.9982967,-0.084,-0.084,,25.015425,,,,,,,,,,,,,,,,,,,,,,,24.9971132125
,15409819.57,35.0110445,-0.084,10,0.999910141448596,,8.28521210440432E-7,0.00142212548720046,2.25715796534587E-5,0.00142230460083387,0.90930630506491,1.47549656731815E-8,5.53187658839016E-11,1.4755069372342E-8,0.214810188841039,320,25,5,13.4965986394558,-0.14975871237181,0.000109625085776332,4369,0,35.0026588,35.0324364,-0.084,-0.084,,35.0124375,,,,,,,,,,,,,,,,,,,,,,,35.0110445
,15409973.08,35.0125923125,-0.084,117.879776328052,0.999892498571243,,5.50669530641862E-7,0.00141009502858448,1.7845255508532E-5,0.00141020794310018,0.725059818338144,1.48324320327243E-8,-2.40660380768041E-11,1.48324515566233E-8,-0.0929639318991917,468,25,5,13.4965986394558,-0.14975871237181,0.000194871622861146,4369,0,35.0061913,35.0226707,-0.084,-0.084,,34.9855875,,,,,,,,,,,,,,,,,,,,,,,35.0125923125
,15410127.00,35.0099063,-0.084,1389.5,1.00194151467022,,4.30342876584131E-7,0.00137000388015211,1.83292234190011E-5,0.00137012648761455,0.766512055668552,1.4830305599469E-8,-4.32859510371508E-10,1.48366212976324E-8,-1.67184578571744,463,25,5,13.4965986394558,-0.14975871237181,0.00115594663495349,4369,0,35.0040016,35.0198822,-0.084,-0.084,,34.9831375,,,,,,,,,,,,,,,,,,,,,,,35.0099063
,15410845.76,45.013991375,-0.084,10,1.001361712087,,9.12229670213289E-7,0.0014390695645755,1.66716037838698E-5,0.00143916613150124,0.663741231027489,1.47650678119552E-8,-1.05193620914129E-10,1.47654425328033E-8,-0.408196468433005,320,25,5,13.4965986394558,-0.14975871237181,0.000109098556953407,4369,0,45.0058899,45.036171,-0.084,-0.084,,44.9614125,,,,,,,,,,,,,,,,,,,,,,,45.013991375
,15410995.50,45.0026188125,-0.084,117.879776328052,1.00134749215228,,5.51075730770501E-7,0.00143425691775826,1.91391972544985E-5,0.00143438461195349,0.764528397022402,1.48196928371378E-8,-2.21286813296765E-11,1.48197093583393E-8,-0.0855536695675596,468,25,5,13.4965986394558,-0.14975871237181,0.000196601270703195,4369,0,44.9951706,45.0219612,-0.084,-0.084,,44.962675,,,,,,,,,,,,,,,,,,,,,,,45.0026188125
,15411143.22,45.001483925,-0.084,1389.5,0.999230266058884,,4.3062275219811E-7,0.0013842145923652,1.90506493108613E-5,0.00138434568116346,0.788499774342659,1.48282406972874E-8,-4.28739421711161E-10,1.48344376256203E-8,-1.65617202013459,463,25,5,13.4965986394558,-0.14975871237181,0.00116649995563759,4369,0,44.9952469,45.0165939,-0.084,-0.084,,44.9580125,,,,,,,,,,,,,,,,,,,,,,,45.001483925
,15411830.95,55.029308775,-0.084,10,1.00129025740582,,9.51861875555594E-7,0.00147228521335627,2.08927777399187E-5,0.00147243344760611,0.813013424248901,1.47802343470922E-8,-6.3865104064789E-11,1.47803723263821E-8,-0.247572403921993,320,25,5,13.4965986394558,-0.14975871237181,0.000109421451362535,4369,0,55.0190086,55.0599174,-0.084,-0.084,,54.8912375,,,,,,,,,,,,,,,,,,,,,,,55.029308775
,15411979.21,55.0035338375,-0.084,117.879776328052,1.00128567181149,,5.09824667312218E-7,0.00144582211164964,2.17930860912603E-5,0.00144598634749309,0.863562186511662,1.48268123386423E-8,-1.29273945501049E-11,1.4826817974294E-8,-0.0499557789776759,468,25,5,13.4965986394558,-0.14975871237181,0.000197123826273178,4369,0,54.990345,55.0256386,-0.084,-0.084,,54.9036875,,,,,,,,,,,,,,,,,,,,,,,55.0035338375
,15412129.51,54.9932041,-0.084,1389.5,0.999190614773353,,4.27030463424159E-7,0.00139534001619474,1.95421175910616E-5,0.00139547685582896,0.802390563404015,1.48283538446577E-8,-4.28252974850589E-10,1.48345366746941E-8,-1.65428135949975,463,25,5,13.4965986394558,-0.14975871237181,0.00117035883417475,4369,0,54.984848,55.009613,-0.084,-0.084,,54.90975,,,,,,,,,,,,,,,,,,,,,,,54.9932041
,15412576.08,65.0260095375,-0.084,10,0.999876866366417,,9.95297119645436E-7,0.0014740355163309,4.62926469448308E-5,0.0014747622562861,1.79880455294934,1.48191814012906E-8,1.45165778146449E-10,1.48198923919003E-8,0.5612402040562,320,25,5,13.4965986394558,-0.14975871237181,0.000110000714197001,4369,0,65.0218811,65.0394821,-0.084,-0.084,,64.962775,,,,,,,,,,,,,,,,,,,,,,,65.0260095375
,15412728.02,65.0158748625,-0.084,117.879776328052,0.999867917531617,,5.34575076725298E-7,0.00143276181878519,2.32047730847995E-5,0.0014329497167949,0.927871831322785,1.48270140961236E-8,-1.21042453600911E-11,1.48270190368599E-8,-0.0467742199988379,468,25,5,13.4965986394558,-0.14975871237181,0.000198285985422983,4369,0,65.0120392,65.0282516,-0.084,-0.084,,64.9537375,,,,,,,,,,,,,,,,,,,,,,,65.0158748625
,15412880.70,65.011463175,-0.084,1389.5,1.0019183878106,,4.25725210023487E-7,0.00141850270802046,2.05369979501599E-5,0.00141865136694897,0.829466940694813,1.48270650766927E-8,-4.26866652986404E-10,1.48332084839361E-8,-1.64907239894717,463,25,5,13.4965986394558,-0.14975871237181,0.00118976593168272,4369,0,65.0076294,65.0233231,-0.084,-0.084,,64.945225,,,,,,,,,,,,,,,,,,,,,,,65.011463175
,15413539.55,74.8039360125,-0.084,10,1.00171932842328,,6.82937329976336E-7,0.00150155016612226,4.07959776645158E-5,0.00150210426175262,1.55629995481369,1.47922065096351E-8,7.2056679150437E-11,1.47923820119919E-8,0.279100412990129,320,25,5,13.4965986394558,-0.14975871237181,0.000109931754335755,4369,0,74.8007584,74.8105927,-0.084,-0.084,,74.754125,,,,,,,,,,,,,,,,,,,,,,,74.8039360125
,15413692.97,74.845243475,-0.084,117.879776328052,1.00168456057156,,4.93906549158104E-7,0.00145417379841619,2.42612863470551E-5,0.00145437617073967,0.955828223493184,1.48212805912554E-8,-1.07936696121213E-11,1.4821284521526E-8,-0.0417259224731765,468,25,5,13.4965986394558,-0.14975871237181,0.000199584608129281,4369,0,74.8427277,74.8579407,-0.084,-0.084,,74.800425,,,,,,,,,,,,,,,,,,,,,,,74.845243475
,15413843.32,74.9029626625,-0.084,1389.5,0.999586830456834,,4.17985233670813E-7,0.0014132991703496,2.09341158779766E-5,0.00141345420234207,0.84861634724828,1.48261474831906E-8,-4.27941749633799E-10,1.48323222502209E-8,-1.65332567477799,463,25,5,13.4965986394558,-0.14975871237181,0.0011909810130239,4369,0,74.9006042,74.9145584,-0.084,-0.084,,74.8261875,,,,,,,,,,,,,,,,,,,,,,,74.9029626625
,15415353.57,84.6700935375,-0.084,10,0.998741634540724,,1.55797297986641E-6,0.00149918366524697,4.29841140960363E-5,0.00149979975203623,1.64231631556142,1.48072730862097E-8,5.88807976750207E-11,1.48073901548492E-8,0.227834213633481,320,25,5,13.4965986394558,-0.14975871237181,0.00010958452115207,4369,0,84.6581726,84.6995773,-0.084,-0.084,,84.6359375,,,,,,,,,,,,,,,,,,,,,,,84.6700935375
,15415505.08,84.78835775,-0.084,117.879776328052,0.998629641560285,,4.81853124071455E-7,0.00145845894978612,2.45867313924426E-5,0.00145866617687934,0.965801961555695,1.48230690785987E-8,-1.32702287338704E-11,1.48230750186282E-8,-0.0512935541532329,468,25,5,13.4965986394558,-0.14975871237181,0.000199820368338668,4369,0,84.7761765,84.8005295,-0.084,-0.084,,84.705,,,,,,,,,,,,,,,,,,,,,,,84.78835775
,15415659.26,84.86474515,-0.084,1389.5,1.00061918901316,,4.16124885912767E-7,0.0014286404216706,2.22021471078878E-5,0.00142881293029121,0.890347851991597,1.48253563820221E-8,-4.2702006178134E-10,1.48315049130938E-8,-1.64985474762835,463,25,5,13.4965986394558,-0.14975871237181,0.00120244382237224,4369,0,84.8592072,84.8818054,-0.084,-0.084,,84.747025,,,,,,,,,,,,,,,,,,,,,,,84.86474515
,15417548.10,94.666677475,-0.084,10,0.999281247250455,,7.87011929197001E-7,0.00153847927911602,4.55306555806115E-5,0.00153915286208581,1.69515003134045,1.47165239862707E-8,7.58537478623104E-12,1.47165259411449E-8,0.0295321044014024,320,25,5,13.4965986394558,-0.14975871237181,0.000109616161558994,4369,0,94.6513062,94.6822968,-0.084,-0.084,,94.6099625,,,,,,,,,,,,,,,,,,,,,,,94.666677475
,15417699.63,94.7943305875,-0.084,117.879776328052,0.999164919853271,,5.02242062189882E-7,0.00148163215684948,2.6920192457413E-5,0.00148187669695302,1.04090864210486,1.48086412683094E-8,-8.30321581064484E-12,1.48086435961187E-8,-0.0321257814178466,468,25,5,13.4965986394558,-0.14975871237181,0.000200868253128158,4369,0,94.7891922,94.8062286,-0.084,-0.084,,94.662825,,,,,,,,,,,,,,,,,,,,,,,94.7943305875
,15417850.10,94.8693533,-0.084,1389.5,1.00114939501806,,4.08701436424378E-7,0.00144621166705348,2.37477436638049E-5,0.00144640663067158,0.940749713055986,1.48241044575704E-8,-4.27941578665698E-10,1.48302800703058E-8,-1.65355274576251,463,25,5,13.4965986394558,-0.14975871237181,0.00121423297105633,4369,0,94.8620834,94.8821564,-0.084,-0.084,,94.6823,,,,,,,,,,,,,,,,,,,,,,,94.8693533
,15419971.04,104.6725025,-0.084,10,0.999497454491793,,8.18140942760034E-7,0.00157538900040566,4.96446655287161E-5,0.00157617102352968,1.80494393429411,1.48023788137807E-8,2.57928854810984E-12,1.4802379038499E-8,0.00998368899462694,320,25,5,13.4965986394558,-0.14975871237181,0.000109804381415571,4369,0,104.6557999,104.6867142,-0.084,-0.084,,104.622,,,,,,,,,,,,,,,,,,,,,,,104.6725025
,15420122.70,104.81073,-0.084,117.879776328052,0.999367482553447,,4.81652523230523E-7,0.00150387358308533,3.00740218449311E-5,0.00150417425875191,1.14563145684076,1.48092446453005E-8,-8.3094674799296E-12,1.48092469765215E-8,-0.0321486597081844,468,25,5,13.4965986394558,-0.14975871237181,0.000202491947558458,4369,0,104.8017426,104.8172379,-0.084,-0.084,,104.61645,,,,,,,,,,,,,,,,,,,,,,,104.81073
,15420271.67,104.880913725,-0.084,1389.5,1.00135370467961,,4.03562877980244E-7,0.00147463112977523,2.6005283191928E-5,0.00147486041497359,1.01031268735259,1.48259424464247E-8,-4.28645182493234E-10,1.48321376111865E-8,-1.65606472035353,463,25,5,13.4965986394558,-0.14975871237181,0.00123583528935374,4369,0,104.8763351,104.8863144,-0.084,-0.084,,104.6576,,,,,,,,,,,,,,,,,,,,,,,104.880913725
,15422504.68,114.6833085875,-0.084,10,0.999489310877155,,5.24051304290636E-7,0.00162509765393936,6.24190244633719E-5,0.00162629595075871,2.19961520649047,1.47543284001135E-8,4.29381352319469E-11,1.47543908793909E-8,0.16674205134628,320,25,5,13.4965986394558,-0.14975871237181,0.000108836509480673,4369,0,114.6718597,114.6911392,-0.084,-0.084,,114.5780625,,,,,,,,,,,,,,,,,,,,,,,114.6833085875
,15422656.70,114.8144454875,-0.084,117.879776328052,0.999368142314283,,4.54802436057461E-7,0.00152771515252924,3.42569569680282E-5,0.00152809918734621,1.28456549910586,1.48041999059614E-8,-6.69928875455698E-12,1.48042014217632E-8,-0.0259278412621029,468,25,5,13.4965986394558,-0.14975871237181,0.000202533552301292,4369,0,114.8018417,114.8232727,-0.084,-0.084,,114.586225,,,,,,,,,,,,,,,,,,,,,,,114.8144454875
,15422808.10,114.8850727125,-0.084,1389.5,1.00134861713449,,3.95654291247583E-7,0.00149161059914937,2.81177731795704E-5,0.00149187559423141,1.07993262449832,1.48304882548191E-8,-4.30876262374161E-10,1.48367461469759E-8,-1.66416966210323,463,25,5,13.4965986394558,-0.14975871237181,0.00124365005107599,4369,0,114.8773727,114.8918686,-0.084,-0.084,,114.65285,,,,,,,,,,,,,,,,,,,,,,,114.8850727125
,15425095.18,124.70002365,-0.084,10,0.999375358037122,,8.15768759937624E-7,0.00165450910465267,5.89511135358547E-5,0.00165555900262289,2.04061841051158,1.48764802367856E-8,-4.53151299426745E-11,1.48765492536567E-8,-0.174527685463318,320,25,5,13.4965986394558,-0.14975871237181,0.000108035763797736,4369,0,124.6835938,124.7234726,-0.084,-0.084,,124.5371875,,,,,,,,,,,,,,,,,,,,,,,124.70002365
,15425248.86,124.8378868375,-0.084,117.879776328052,0.999245345328652,,5.33742472122519E-7,0.00157502351559984,4.13805321124238E-5,0.00157556701638819,1.50498358934274,1.48220393444468E-8,-2.43455377848952E-12,1.48220395443873E-8,-0.00941096241950845,468,25,5,13.4965986394558,-0.14975871237181,0.000205170738267006,4369,0,124.8323898,124.8531113,-0.084,-0.084,,124.538825,,,,,,,,,,,,,,,,,,,,,,,124.8378868375
,15425401.91,124.9024190875,-0.084,1389.5,1.00122913827032,,3.92774697218132E-7,0.00152720936562951,3.15753328499688E-5,0.00152753574364434,1.18443196887905,1.48370155077401E-8,-4.31330307462326E-10,1.48432838351578E-8,-1.66518985182324,463,25,5,13.4965986394558,-0.14975871237181,0.00126634633508482,4369,0,124.8933182,124.9101791,-0.084,-0.084,,124.5762375,,,,,,,,,,,,,,,,,,,,,,,124.9024190875
,15427666.20,134.7035179125,-0.084,10,0.999242175624399,,6.27275149361754E-7,0.00171234251895939,8.67207877503869E-5,0.00171453707958277,2.89924098331777,1.47822099131074E-8,1.19151988048475E-10,1.47826901175471E-8,0.461822571178049,320,25,5,13.4965986394558,-0.14975871237181,0.000107425671848831,4369,0,134.6995392,134.706665,-0.084,-0.084,,134.517625,,,,,,,,,,,,,,,,,,,,,,,134.7035179125
,15427819.17,134.8414936125,-0.084,117.879776328052,0.999106267239496,,5.2747050783491E-7,0.00160409425801396,4.64509297113181E-5,0.00160476667383903,1.65869223088003,1.48254405039523E-8,-1.4095627453036E-11,1.48254472048212E-8,-0.0544752595430964,468,25,5,13.4965986394558,-0.14975871237181,0.000206247469011527,4369,0,134.8357849,134.8486481,-0.084,-0.084,,134.5176875,,,,,,,,,,,,,,,,,,,,,,,134.8414936125
,15427975.38,134.9166831875,-0.084,1389.5,1.00109056255944,,3.85200249780389E-7,0.0015478806244416,3.50094749534686E-5,0.00154827649044291,1.29567693146672,1.48466339322395E-8,-4.29569625445292E-10,1.485284717423E-8,-1.6573225860854,463,25,5,13.4965986394558,-0.14975871237181,0.00128466114904289,4369,0,134.9102478,134.9245605,-0.084,-0.084,,134.55735,,,,,,,,,,,,,,,,,,,,,,,134.9166831875
,15430128.06,144.7058582375,-0.084,10,0.999148504464363,,7.53337442767815E-7,0.00178134978959769,9.27389461564411E-5,0.00178376219968749,2.98018811417373,1.46735400353114E-8,6.34354752418663E-11,1.46736771542584E-8,0.247694990545928,320,25,5,13.4965986394558,-0.14975871237181,0.000107158756621185,4369,0,144.6965485,144.7158966,-0.084,-0.084,,144.5285375,,,,,,,,,,,,,,,,,,,,,,,144.7058582375
,15430283.28,144.8612403625,-0.084,117.879776328052,0.998996863201022,,5.50015134106091E-7,0.00163965591154276,5.34220711112503E-5,0.00164052596015392,1.8661091033576,1.48318910718088E-8,-1.14217172505102E-11,1.48318954696164E-8,-0.0441222269444097,468,25,5,13.4965986394558,-0.14975871237181,0.000207348053141939,4369,0,144.8550873,144.8699951,-0.084,-0.084,,144.4806375,,,,,,,,,,,,,,,,,,,,,,,144.8612403625
,15430438.65,144.9227542875,-0.084,1389.5,1.00097613144265,,3.91645653527802E-7,0.00158486295437653,3.95058318202827E-5,0.00158535525826324,1.42791449747744,1.48541316969985E-8,-4.31384723581215E-10,1.48603943841176E-8,-1.66348187594463,463,25,5,13.4965986394558,-0.14975871237181,0.0013105019536615,4369,0,144.9135895,144.9329834,-0.084,-0.084,,144.5307375,,,,,,,,,,,,,,,,,,,,,,,144.9227542875
,15432456.52,154.7092742875,-0.084,10,0.999106612565154,,1.15045983553331E-6,0.00182091268017238,9.68920836462299E-5,0.00182348870703547,3.04587744735613,1.48041177646482E-8,8.42775775314695E-11,1.48043576523822E-8,0.326172583448198,320,25,5,13.4965986394558,-0.14975871237181,0.0001070094788039,4369,0,154.7034302,154.7195587,-0.084,-0.084,,154.4879375,,,,,,,,,,,,,,,,,,,,,,,154.7092742875
,15432612.61,154.8661594375,-0.084,117.879776328052,0.998972419418957,,5.19247159187383E-7,0.00169216762427325,6.1512872146644E-5,0.0016932852984888,2.08187221332998,1.48362637075287E-8,-1.07470133038468E-11,1.48362675999602E-8,-0.0415036028692839,468,25,5,13.4965986394558,-0.14975871237181,0.000211071954990455,4369,0,154.8558655,154.8800964,-0.084,-0.084,,154.462075,,,,,,,,,,,,,,,,,,,,,,,154.8661594375
,15432765.21,154.9296359875,-0.084,1389.5,1.00095409297098,,3.97477514838401E-7,0.00161652511491862,4.35287403359933E-5,0.00161711106557277,1.54245087789825,1.48612617457655E-8,-4.34588882644836E-10,1.48676147439013E-8,-1.67502699502762,463,25,5,13.4965986394558,-0.14975871237181,0.00132920478621121,4369,0,154.9244537,154.9411316,-0.084,-0.084,,154.4906125,,,,,,,,,,,,,,,,,,,,,,,154.9296359875
,15434677.52,164.7029476375,-0.084,10,0.999167507272828,,9.95766574387334E-7,0.00189422810101798,8.6408264179712E-5,0.00189619790285844,2.61182859243494,1.48444793151655E-8,-7.71488428922417E-11,1.48446797904952E-8,-0.297771528457417,320,25,5,13.4965986394558,-0.14975871237181,0.000107235018114798,4369,0,164.6963043,164.7098389,-0.084,-0.084,,164.486775,,,,,,,,,,,,,,,,,,,,,,,164.7029476375
,15434832.23,164.8665485375,-0.084,117.879776328052,0.999032869961802,,5.73198741563615E-7,0.00173077343367542,6.85287055405308E-5,0.00173212957431009,2.26740001777296,1.48477633476032E-8,-1.30483040424066E-11,1.48477690810663E-8,-0.0503518638781202,468,25,5,13.4965986394558,-0.14975871237181,0.00021270507982913,4369,0,164.8454742,164.87677,-0.084,-0.084,,164.4811,,,,,,,,,,,,,,,,,,,,,,,164.8665485375
,15434985.33,164.9303798875,-0.084,1389.5,1.00101967593506,,4.13221907433944E-7,0.00165771420979944,4.80950652645931E-5,0.00165841175124689,1.66184945734373,1.48675988141704E-8,-4.34044026908951E-10,1.48739331959108E-8,-1.67221550981344,463,25,5,13.4965986394558,-0.14975871237181,0.0013549345681692,4369,0,164.9173279,164.9382172,-0.084,-0.084,,164.466025,,,,,,,,,,,,,,,,,,,,,,,164.9303798875
,15436820.00,174.7099266,-0.084,10,0.999322514924647,,5.38197159422318E-7,0.00194047461585884,0.000102904466530162,0.00194320124125742,3.03558413049787,1.48422120943429E-8,3.26351257157066E-11,1.48422479734334E-8,0.125982026270067,320,25,5,13.4965986394558,-0.14975871237181,0.000106934028602772,4369,0,174.6976318,174.7218018,-0.084,-0.084,,174.5174,,,,,,,,,,,,,,,,,,,,,,,174.7099266
,15436970.64,174.861019125,-0.084,117.879776328052,0.9991940332129,,5.63413047891586E-7,0.0017830900270394,7.67418698036178E-5,0.00178474069800302,2.46441475757887,1.48517856162615E-8,-1.28165333094821E-11,1.4851791146354E-8,-0.0494440940173035,468,25,5,13.4965986394558,-0.14975871237181,0.000215209685347683,4369,0,174.8524475,174.8746948,-0.084,-0.084,,174.4864375,,,,,,,,,,,,,,,,,,,,,,,174.861019125
,15437127.00,174.9384670375,-0.084,1389.5,1.0011664354578,,4.37991032454397E-7,0.00169806612232349,5.24824588168283E-5,0.00169887697149211,1.77028821584871,1.48724956535351E-8,-4.35715627851567E-10,1.48788768081725E-8,-1.67809952135093,463,25,5,13.4965986394558,-0.14975871237181,0.00137988663078237,4369,0,174.937149,174.9401093,-0.084,-0.084,,174.47065,,,,,,,,,,,,,,,,,,,,,,,174.9384670375
,15438862.59,184.6958046,-0.084,10,0.999592340221432,,8.49190982826006E-7,0.0019803191666608,8.72727785243756E-5,0.00198224129200143,2.52339549244406,1.50093780337949E-8,-3.91590739655492E-11,1.50094291162068E-8,-0.149482848135733,320,25,5,13.4965986394558,-0.14975871237181,0.00010711007907207,4369,0,184.6853333,184.7051849,-0.084,-0.084,,184.47595,,,,,,,,,,,,,,,,,,,,,,,184.6958046
,15439016.39,184.8510895,-0.084,117.879776328052,0.999457431269724,,5.09071817730413E-7,0.00183291802510958,8.29705406970821E-5,0.00183479497421242,2.59183372709791,1.48558090882856E-8,-2.0663283696179E-11,1.48558234587949E-8,-0.0796939551485707,468,25,5,13.4965986394558,-0.14975871237181,0.000217668803014072,4369,0,184.8466187,184.8576355,-0.084,-0.084,,184.4332125,,,,,,,,,,,,,,,,,,,,,,,184.8510895
,15439169.52,184.919923775,-0.084,1389.5,1.00143645886141,,4.55526918247967E-7,0.00172747852549581,5.66126699498845E-5,0.0017284059275668,1.87701700968018,1.48778345400602E-8,-4.3793998019119E-10,1.48842786868447E-8,-1.68605647000669,463,25,5,13.4965986394558,-0.14975871237181,0.00139110608743017,4369,0,184.9185944,184.9207611,-0.084,-0.084,,184.523775,,,,,,,,,,,,,,,,,,,,,,,184.919923775
,15440811.36,194.6652851,-0.084,10,0.999944476602214,,8.38360676075639E-7,0.00205633899997054,9.80283758327921E-5,0.00205867424457301,2.72929867847163,1.48874556177061E-8,7.54231532493727E-11,1.48876466716945E-8,0.290270647863902,320,25,5,13.4965986394558,-0.14975871237181,0.000107029761116031,4369,0,194.6577454,194.6755829,-0.084,-0.084,,194.505925,,,,,,,,,,,,,,,,,,,,,,,194.6652851
,15440961.90,194.8290043,-0.084,117.879776328052,0.999811715692674,,5.05401186855166E-7,0.00188900097020536,8.92342565155197E-5,0.00189110745807124,2.7045768649161,1.48541055557375E-8,-1.72025959485125E-11,1.48541155169299E-8,-0.0663544297685235,468,25,5,13.4965986394558,-0.14975871237181,0.000220689307343756,4369,0,194.8248749,194.8327637,-0.084,-0.084,,194.4799875,,,,,,,,,,,,,,,,,,,,,,,194.8290043
,15441116.66,194.90569305,-0.084,1389.5,1.00177442553689,,4.71415208729308E-7,0.00178795270897381,6.36503775996097E-5,0.00178908531381133,2.03884506818422,1.48814608574223E-8,-4.38368277132644E-10,1.48879160394391E-8,-1.68729342548176,463,25,5,13.4965986394558,-0.14975871237181,0.00143005597680907,4369,0,194.9036102,194.9075623,-0.084,-0.084,,194.4737375,,,,,,,,,,,,,,,,,,,,,,,194.90569305
,15442193.22,205.1249828375,-0.084,10,0.999999617169757,,8.76687630714332E-7,0.00209390989348033,8.29546967646684E-5,0.00209555246265278,2.2687078156693,1.48644611339448E-8,5.44469897698265E-11,1.48645608504674E-8,0.20986759905953,320,25,5,13.4965986394558,-0.14975871237181,0.000107428105726287,4369,0,205.1149902,205.137619,-0.084,-0.084,,204.39195,,,,,,,,,,,,,,,,,,,,,,,205.1249828375
,15442346.50,205.006620425,-0.084,117.879776328052,1.00008395281269,,5.12904558817066E-7,0.00194360848540998,9.13064916319904E-5,0.00194575199343899,2.68965342759754,1.4861976536928E-8,-2.12813362507868E-11,1.48619917736309E-8,-0.0820435904441297,468,25,5,13.4965986394558,-0.14975871237181,0.000223229970306098,4369,0,205.0034332,205.0097046,-0.084,-0.084,,204.4031875,,,,,,,,,,,,,,,,,,,,,,,205.006620425
,15442498.31,204.9664421,-0.084,1389.5,0.998426486892622,,4.81100661031351E-7,0.0018131648709905,6.85931320372679E-5,0.00181446186709908,2.16650111698729,1.48846589908954E-8,-4.39830209544617E-10,1.48911558949758E-8,-1.69255365040505,463,25,5,13.4965986394558,-0.14975871237181,0.00144310786807754,4369,0,204.9637756,204.9692688,-0.084,-0.084,,204.4365125,,,,,,,,,,,,,,,,,,,,,,,204.9664421
,15443574.74,215.1047897375,-0.084,10,1.00046169868554,,1.28230524390058E-6,0.00215632378329642,7.60645690381817E-5,0.00215766495941162,2.02027751224134,1.48282779130497E-8,8.81000499029782E-11,1.48285396275369E-8,0.340410509594688,320,25,5,13.4965986394558,-0.14975871237181,0.000107332373213028,4369,0,215.0942535,215.1191101,-0.084,-0.084,,214.4022,,,,,,,,,,,,,,,,,,,,,,,215.1047897375
,15443729.19,214.97969055,-0.084,117.879776328052,1.00055252708937,,5.62649689529419E-7,0.00199859089297886,9.16294932368889E-5,0.00200069026126707,2.62500419069895,1.48617507204245E-8,-1.30371071060462E-11,1.4861756438665E-8,-0.0502613074787632,468,25,5,13.4965986394558,-0.14975871237181,0.000226217190841515,4369,0,214.9753876,214.9850159,-0.084,-0.084,,214.3554375,,,,,,,,,,,,,,,,,,,,,,,214.97969055
,15443883.47,214.9500617875,-0.084,1389.5,0.998908791540278,,5.1303400389751E-7,0.00189056768278425,7.64869327460699E-5,0.00189211427088036,2.31675904787132,1.48987908084057E-8,-4.42762579148525E-10,1.49053683702929E-8,-1.70221619051205,463,25,5,13.4965986394558,-0.14975871237181,0.00148258875977767,4369,0,214.9380798,214.9556885,-0.084,-0.084,,214.3864375,,,,,,,,,,,,,,,,,,,,,,,214.9500617875
,15444936.17,225.1261005375,-0.084,10,1.00089799163035,,1.04150759453589E-6,0.00219745544351676,4.42344280780241E-5,0.00219790061442023,1.15319916983473,1.49056352474066E-8,-4.41969443329601E-11,1.4905700771806E-8,-0.169888160713015,320,25,5,13.4965986394558,-0.14975871237181,0.000107741264625592,4369,0,225.1054993,225.1572723,-0.084,-0.084,,224.456475,,,,,,,,,,,,,,,,,,,,,,,225.1261005375
,15445088.98,224.9624500375,-0.084,117.879776328052,1.00103714786368,,6.4655029523314E-7,0.00207076011423588,8.98564562579002E-5,0.00207270876715505,2.48467600083547,1.48917850216292E-8,-8.92019745164823E-12,1.48917876932335E-8,-0.0343202379388003,468,25,5,13.4965986394558,-0.14975871237181,0.000230008769738373,4369,0,224.9516602,224.9804535,-0.084,-0.084,,224.52435,,,,,,,,,,,,,,,,,,,,,,,224.9624500375
,15445242.01,224.9271106625,-0.084,1389.5,0.999425537621836,,5.41877985091537E-7,0.0019436870833124,8.18376493877638E-5,0.00194540918027359,2.41097658164829,1.49027052218004E-8,-4.43566481730478E-10,1.49093049519953E-8,-1.7048573398946,463,25,5,13.4965986394558,-0.14975871237181,0.00152137828309124,4369,0,224.9223175,224.9414978,-0.084,-0.084,,224.5404875,,,,,,,,,,,,,,,,,,,,,,,224.9271106625
,15446291.17,235.1115569875,-0.084,10,1.00139220522882,,1.00728828857872E-6,0.00221689343051793,1.8360769971559E-5,0.00221696946306157,0.474524648162834,1.49449427064827E-8,-1.44843990254429E-10,1.49456445923742E-8,-0.555284129358938,320,25,5,13.4965986394558,-0.14975871237181,0.000107651211159729,4369,0,235.0935974,235.1276398,-0.084,-0.084,,234.4647125,,,,,,,,,,,,,,,,,,,,,,,235.1115569875
,15446445.09,234.9555072625,-0.084,117.879776328052,1.00150336319268,,7.37918020385375E-7,0.002139372450024,8.23117445941932E-5,0.00214095532490051,2.20335198757003,1.48731866203628E-8,-2.00965171120589E-11,1.48732001974739E-8,-0.0774174991605037,468,25,5,13.4965986394558,-0.14975871237181,0.000234350085970532,4369,0,234.9452209,234.9676819,-0.084,-0.084,,234.5598,,,,,,,,,,,,,,,,,,,,,,,234.9555072625
,15446596.39,234.933427825,-0.084,1389.5,0.99990387778618,,5.79867820020763E-7,0.00198487324980039,8.44353652062762E-5,0.00198666835397121,2.43586086597906,1.48984563168177E-8,-4.42305264688174E-10,1.49050204485366E-8,-1.70049721718857,463,25,5,13.4965986394558,-0.14975871237181,0.00155032043284049,4369,0,234.9195404,234.9505463,-0.084,-0.084,,234.572425,,,,,,,,,,,,,,,,,,,,,,,234.933427825
,15447649.98,245.1275138875,-0.084,10,0.998209824484349,,8.96395891801648E-7,0.00221465176536017,4.80179104161888E-5,0.0022151722645279,1.2420881017975,1.49489653567698E-8,1.26750386807625E-10,1.49495026973629E-8,0.485792027660064,320,25,5,13.4965986394558,-0.14975871237181,0.000107411879876582,4369,0,245.0976868,245.1468201,-0.084,-0.084,,244.471475,,,,,,,,,,,,,,,,,,,,,,,245.1275138875
,15447801.69,244.9505901,-0.084,117.879776328052,0.998309475452554,,8.07792891677471E-7,0.00214468429310814,6.94965671417734E-5,0.00214580998458606,1.85596882153276,1.48850475185795E-8,-2.70171835014927E-11,1.48850720373995E-8,-0.103994890654235,468,25,5,13.4965986394558,-0.14975871237181,0.000235169422039392,4369,0,244.9440918,244.959671,-0.084,-0.084,,244.5359,,,,,,,,,,,,,,,,,,,,,,,244.9505901
,15447955.86,244.9161396125,-0.084,1389.5,1.00039518648946,,6.444660904659E-7,0.00205662343268741,8.72308770141805E-5,0.00205847253316229,2.42872231187091,1.49082296459324E-8,-4.45551113282562E-10,1.49148860864039E-8,-1.7118465794403,463,25,5,13.4965986394558,-0.14975871237181,0.00160094564464033,4369,0,244.9086914,244.9268494,-0.084,-0.084,,244.6133375,,,,,,,,,,,,,,,,,,,,,,,244.9161396125
,15449011.56,255.1152382,-0.084,10,0.998629861311638,,8.67925392908749E-7,0.00222562368817861,3.36988212855196E-5,0.0022258787954284,0.867465921491508,1.49797199369221E-8,8.45894958673066E-11,1.49799587706854E-8,0.323542069517433,320,25,5,13.4965986394558,-0.14975871237181,0.000107699077416359,4369,0,255.1020966,255.1344147,-0.084,-0.084,,254.469225,,,,,,,,,,,,,,,,,,,,,,,255.1152382
,15449167.25,254.9246292125,-0.084,117.879776328052,0.998770774631395,,8.37304171219632E-7,0.0021939268903468,6.13773548536266E-5,0.00219478526965068,1.60249021450609,1.48903205642643E-8,-1.38850077487966E-11,1.4890327038047E-8,-0.0534274670913533,468,25,5,13.4965986394558,-0.14975871237181,0.00023800686550061,4369,0,254.9159546,254.9374542,-0.084,-0.084,,254.6807875,,,,,,,,,,,,,,,,,,,,,,,254.9246292125
,15449318.96,254.89718245,-0.084,1389.5,1.00079187610633,,7.14923722528257E-7,0.00211825146904852,8.66198962984437E-5,0.00212002176700169,2.34164405126781,1.49064614021382E-8,-4.46202349701582E-10,1.49131381027038E-8,-1.71455043406371,463,25,5,13.4965986394558,-0.14975871237181,0.00164926124866705,4369,0,254.8830719,254.9126434,-0.084,-0.084,,254.74595,,,,,,,,,,,,,,,,,,,,,,,254.89718245
,15450384.59,265.1429367125,-0.084,10,0.99898868991788,,8.22268330558527E-7,0.00229225448605455,2.60566395473713E-5,0.00229240257749413,0.651267643043207,1.49543413118347E-8,5.97724166958771E-11,1.49544607663615E-8,0.229009683480347,320,25,5,13.4965986394558,-0.14975871237181,0.000107907579585067,4369,0,265.1270142,265.1559753,-0.084,-0.084,,264.427475,,,,,,,,,,,,,,,,,,,,,,,265.1429367125
,15450538.78,264.94444275,-0.084,117.879776328052,0.99912437549801,,8.94377767104369E-7,0.00225049650325047,5.27537165162685E-5,0.00225111471625701,1.34282007466195,1.48772812225368E-8,-9.33659299001316E-12,1.48772841522374E-8,-0.0359573295098698,468,25,5,13.4965986394558,-0.14975871237181,0.000242838562968295,4369,0,264.9386902,264.9497681,-0.084,-0.084,,264.61415,,,,,,,,,,,,,,,,,,,,,,,264.94444275
,15450694.55,264.9003791625,-0.084,1389.5,1.00117087158831,,7.86722870064129E-7,0.00217098076623137,8.21544938281567E-5,0.00217253465983921,2.16715913284614,1.49061010031449E-8,-4.46889067113212E-10,1.49127984280035E-8,-1.71722908785233,463,25,5,13.4965986394558,-0.14975871237181,0.00167777276506602,4369,0,264.8945923,264.9052734,-0.084,-0.084,,264.6798875,,,,,,,,,,,,,,,,,,,,,,,264.9003791625
,15451717.54,275.155639675,-0.084,10,0.999298605146032,,5.7335267314953E-7,0.0022787766324122,1.07504922750846E-5,0.00227880199085222,0.27029997442512,1.49542104232229E-8,1.29804131945512E-13,1.49542104237862E-8,0.000497333440761326,320,25,5,13.4965986394558,-0.14975871237181,0.000108201267464726,4369,0,275.1402283,275.1853638,-0.084,-0.084,,274.6188625,,,,,,,,,,,,,,,,,,,,,,,275.155639675
,15451873.63,274.9561843875,-0.084,117.879776328052,0.999430655422118,,9.44144226079947E-7,0.00226348223629175,4.09836710009837E-5,0.00226385324067109,1.0373109081537,1.48748322821741E-8,-1.64186550936659E-11,1.48748413435251E-8,-0.063242343998354,468,25,5,13.4965986394558,-0.14975871237181,0.000243075432637491,4369,0,274.947937,274.9779663,-0.084,-0.084,,274.6847,,,,,,,,,,,,,,,,,,,,,,,274.9561843875
,15452029.61,274.891418475,-0.084,1389.5,1.00148756544533,,8.43422878488211E-7,0.00219999390861236,7.29348870192493E-5,0.00220120255671213,1.89879219031998,1.4897310652836E-8,-4.47161799903628E-10,1.49040202080645E-8,-1.71928975369264,463,25,5,13.4965986394558,-0.14975871237181,0.00170031877597867,4369,0,274.8728943,274.9169312,-0.084,-0.084,,274.859925,,,,,,,,,,,,,,,,,,,,,,,274.891418475
,15453038.07,284.988952625,-0.084,10,0.999649392769626,,8.73979250321E-7,0.00232585994263455,2.72802037537796E-5,0.00232601992301632,0.671996124987938,1.49008742698204E-8,1.06332241511656E-10,1.49012536570109E-8,0.408854215208194,320,25,5,13.4965986394558,-0.14975871237181,0.000108331074262365,4369,0,284.9569397,285.0093994,-0.084,-0.084,,284.3307625,,,,,,,,,,,,,,,,,,,,,,,284.988952625
,15453191.93,284.706264475,-0.084,117.879776328052,0.999859230571421,,9.73251243924925E-7,0.00228424145463061,3.36187872142148E-5,0.00228448883689694,0.843201384982276,1.49003725390771E-8,-1.17433615525724E-11,1.49003771666969E-8,-0.0451562478175447,468,25,5,13.4965986394558,-0.14975871237181,0.000245591132754134,4369,0,284.6941223,284.7125854,-0.084,-0.084,,284.739825,,,,,,,,,,,,,,,,,,,,,,,284.706264475
,15453343.21,284.6730270625,-0.084,1389.5,0.998395166195295,,9.16463486461254E-7,0.00225108661354452,6.4338033210827E-5,0.00225200584461869,1.63711804635912,1.49162815541372E-8,-4.49114286095347E-10,1.49230412129789E-8,-1.72459747039471,463,25,5,13.4965986394558,-0.14975871237181,0.00175159161996544,4369,0,284.65802,284.68573,-0.084,-0.084,,284.8899125,,,,,,,,,,,,,,,,,,,,,,,284.6730270625
,15454341.32,295.0463294875,-0.084,10,0.99984369751765,,1.12639817496022E-6,0.00235704681912133,8.41470140618891E-6,0.00235706183939449,0.204546139813913,1.49069970877958E-8,-2.40424162824312E-12,1.49069972816771E-8,-0.00924082135537674,320,25,5,13.4965986394558,-0.14975871237181,0.000108735097920017,4369,0,295.0268555,295.0666504,-0.084,-0.084,,294.3208,,,,,,,,,,,,,,,,,,,,,,,295.0463294875
,15454495.36,294.7944831875,-0.084,117.879776328052,1.00001897002841,,1.03381635834136E-6,0.0023374112567177,2.74158806301159E-5,0.00233757203387218,0.672000795384418,1.48987675508659E-8,-1.57907358500379E-11,1.48987759189161E-8,-0.0607259746655018,468,25,5,13.4965986394558,-0.14975871237181,0.000249135856843514,4369,0,294.7874451,294.8010254,-0.084,-0.084,,294.6573375,,,,,,,,,,,,,,,,,,,,,,,294.7944831875
,15454652.49,294.716045375,-0.084,1389.5,0.998585424720537,,9.8631397006383E-7,0.00230723556606377,5.43393710795572E-5,0.00230787537023968,1.34916486544086,1.49203389056218E-8,-4.49606524239249E-10,1.49271115452806E-8,-1.72601731316939,463,25,5,13.4965986394558,-0.14975871237181,0.00179288924611201,4369,0,294.7135925,294.7202148,-0.084,-0.084,,294.85255,,,,,,,,,,,,,,,,,,,,,,,294.716045375
,15455537.04,305.3186683875,-0.084,10,0.999886766024824,,9.67657883656636E-7,0.00233026763054131,1.95549689134797E-5,0.00233034967907347,0.480799232393317,1.50174695967915E-8,8.76600692491516E-11,1.50177254395696E-8,0.334443490906427,320,25,5,13.4965986394558,-0.14975871237181,0.000108519294118942,4369,0,305.2897034,305.3442078,-0.084,-0.084,,304.4419875,,,,,,,,,,,,,,,,,,,,,,,305.3186683875
,15455692.98,305.0690117,-0.084,117.879776328052,1.00008377096094,,1.03787898992984E-6,0.00234240401365339,2.18714622511655E-5,0.00234250612038486,0.534965811098349,1.49035056841169E-8,-1.71917380675753E-11,1.49035155997624E-8,-0.0660927447368636,468,25,5,13.4965986394558,-0.14975871237181,0.000249833707063302,4369,0,305.0358582,305.086853,-0.084,-0.084,,304.743675,,,,,,,,,,,,,,,,,,,,,,,305.0690117
,15455846.44,304.8852806125,-0.084,1389.5,0.998715542270271,,1.01289134682982E-6,0.00232516260363426,4.22527311321526E-5,0.00232554647913719,1.04106127424195,1.49245097475732E-8,-4.50964534055507E-10,1.4931321449101E-8,-1.73074395923442,463,25,5,13.4965986394558,-0.14975871237181,0.00179836243899217,4369,0,304.8615112,304.9056396,-0.084,-0.084,,304.9893625,,,,,,,,,,,,,,,,,,,,,,,304.8852806125
,15456614.17,315.4443130625,-0.084,10,1.00009798908606,,1.19587658144158E-6,0.00232975755829196,1.37332359662015E-5,0.00232979803463489,0.337737866126709,1.50439449496358E-8,4.76327230101445E-11,1.50440203577359E-8,0.181411517019189,320,25,5,13.4965986394558,-0.14975871237181,0.000109028785799676,4369,0,315.4328918,315.4511719,-0.084,-0.084,,314.2105,,,,,,,,,,,,,,,,,,,,,,,315.4443130625
,15456768.66,315.2966423125,-0.084,117.879776328052,1.00016466265197,,1.08566875135479E-6,0.00237789346885601,1.93174489315804E-5,0.00237797193277408,0.465447238092209,1.49018445788763E-8,-1.4276204145382E-11,1.490185141729E-8,-0.0548902513663165,468,25,5,13.4965986394558,-0.14975871237181,0.000251852369185564,4369,0,315.2870483,315.3078613,-0.084,-0.084,,314.4991375,,,,,,,,,,,,,,,,,,,,,,,315.2966423125
,15456923.90,315.06287385,-0.084,1389.5,0.998865412764923,,1.04130250132945E-6,0.00235162467709954,3.18069525104243E-5,0.00235183977008884,0.774908104130943,1.49497681439369E-8,-4.55073398561405E-10,1.49566927947173E-8,-1.74355454715254,463,25,5,13.4965986394558,-0.14975871237181,0.00182791184905176,4369,0,315.054718,315.071106,-0.084,-0.084,,314.8017,,,,,,,,,,,,,,,,,,,,,,,315.06287385
,15457711.64,325.3567390625,-0.084,10,1.00052968084394,,1.20411920663164E-6,0.00238335579192564,2.01885735069095E-5,0.00238344129556525,0.485320905849669,1.50237751658746E-8,8.18577867208149E-11,1.50239981673321E-8,0.312175817142108,320,25,5,13.4965986394558,-0.14975871237181,0.000109359793133657,4369,0,325.3280945,325.3742371,-0.084,-0.084,,324.29755,,,,,,,,,,,,,,,,,,,,,,,325.3567390625
,15457864.77,325.2714233375,-0.084,117.879776328052,1.00055270174734,,1.09411218324E-6,0.0023999105437526,1.68798027192644E-5,0.00239996990517689,0.402983981863809,1.49027250900659E-8,-1.6177798350565E-11,1.49027338710466E-8,-0.0621979669887764,468,25,5,13.4965986394558,-0.14975871237181,0.000253558718371626,4369,0,325.2388916,325.2909241,-0.084,-0.084,,324.7223,,,,,,,,,,,,,,,,,,,,,,,325.2714233375
,15458018.11,325.0800895625,-0.084,1389.5,0.99923594331963,,1.08514503429096E-6,0.00238781564830659,2.41809633559496E-5,0.00238793808321879,0.580203830971264,1.4932818150055E-8,-4.50250860609789E-10,1.49396045376071E-8,-1.72704577882956,463,25,5,13.4965986394558,-0.14975871237181,0.00184871570134555,4369,0,325.0485535,325.099884,-0.084,-0.084,,324.9850125,,,,,,,,,,,,,,,,,,,,,,,325.0800895625
,15458813.57,335.25370025,-0.084,10,1.00111429829302,,9.20626459338001E-7,0.00245659186120893,1.73681840095606E-5,0.0024566532572534,0.405076267339276,1.48733029381942E-8,6.75025913813131E-11,1.48734561179015E-8,0.260035518247013,320,25,5,13.4965986394558,-0.14975871237181,0.000109442544967152,4369,0,335.2178955,335.2885437,-0.084,-0.084,,334.6642875,,,,,,,,,,,,,,,,,,,,,,,335.25370025
,15458967.71,335.2483825625,-0.084,117.879776328052,1.00108409264334,,1.11433665988501E-6,0.00242409328778234,1.54064093011491E-5,0.00242414224527336,0.364140418988696,1.48996977778017E-8,-1.71615445376023E-11,1.48997076611738E-8,-0.0659935289808118,468,25,5,13.4965986394558,-0.14975871237181,0.000254938886373877,4369,0,335.2313232,335.2654419,-0.084,-0.084,,334.8140875,,,,,,,,,,,,,,,,,,,,,,,335.2483825625
,15459121.53,335.1128006125,-0.084,1389.5,0.999757123078218,,1.09229731997928E-6,0.0023997185113491,1.68457580529154E-5,0.00239977763829816,0.402203417000083,1.49363816526446E-8,-4.52164851066037E-10,1.49432242145395E-8,-1.73396934221387,463,25,5,13.4965986394558,-0.14975871237181,0.00187042848158308,4369,0,335.0881348,335.1298828,-0.084,-0.084,,335.0055375,,,,,,,,,,,,,,,,,,,,,,,335.1128006125
,15460085.00,345.308113125,-0.084,10,0.998487683024012,,1.50640659569131E-6,0.00248307956479286,-2.72503383616644E-6,0.00248308106007462,-0.0628787242163185,1.49511600006494E-8,-5.22129039221021E-11,1.49512511701314E-8,-0.200089281993769,320,25,5,13.4965986394558,-0.14975871237181,0.000109880642909184,4369,0,345.2994385,345.3208313,-0.084,-0.084,,344.3378625,,,,,,,,,,,,,,,,,,,,,,,345.308113125
,15460237.38,345.044609075,-0.084,117.879776328052,0.998628972307982,,1.19662627234263E-6,0.00247757694053316,1.41030136335411E-5,0.00247761707922253,0.326138986526845,1.49031154160966E-8,-2.26063132283739E-11,1.49031325616762E-8,-0.0869110456939097,468,25,5,13.4965986394558,-0.14975871237181,0.000258589563875006,4369,0,345.0278931,345.0659485,-0.084,-0.084,,344.6700375,,,,,,,,,,,,,,,,,,,,,,,345.044609075
,15460390.16,344.87568665,-0.084,1389.5,1.00071206440865,,1.17280618667744E-6,0.00250239561723798,1.2713547325913E-5,0.00250242791293925,0.291091597212423,1.49302859866433E-8,-4.52748350881992E-10,1.49371490155311E-8,-1.73691400405721,463,25,5,13.4965986394558,-0.14975871237181,0.00193008914365142,4369,0,344.8693848,344.8806763,-0.084,-0.084,,344.9289625,,,,,,,,,,,,,,,,,,,,,,,344.87568665
,15460519.58,344.8313560625,-0.084,10000,0.998645382738575,,1.566785965367E-6,0.00245355051049909,4.43239394668992E-5,0.00245395083878635,1.03494851265777,1.4638380443204E-8,-3.5660158870815E-9,1.50664744153002E-8,-13.6909975193039,588,5,5,13.4965986394558,-0.14975871237181,0.0118427355367408,4369,0,344.8302002,344.8338013,-0.084,-0.084,,344.992675,,,,,,,,,,,,,,,,,,,,,,,344.8313560625