File: HysteresisLoop/Li0.5Al0.5 Loop 5K iter.dc.dc.dat
[Header]
TITLE,MPMS DC Measurement
BYAPP,MPMS Measurement,2.1,Summary
FILEOPENTIME, 1687420929.500000 6/22/2023, 10:02:09 AM

INFO, APPNAME, MPMS MultiVu Application, Revision 1.60,  Build 081

INFO, NAME, Li0.5Al0.5Fe5O8
INFO, WEIGHT, 84.430
INFO, AREA, 0.000
INFO, LENGTH, 0.000
INFO, SHAPE,
INFO, COMMENT, cotton: 15.1 mg, capsule:39.07 mg
INFO, SEQUENCE FILE: ciclo_histeresis_DC_1T linreg.seq


INFO, BACKGROUND DATA FILE:, None


STARTUPAXIS,X,4,LINEAR,AUTO,0.000000,0.000000
STARTUPAXIS,Y1,5,LINEAR,AUTO,0.000000,0.000000


STARTUPGROUP,Longitudinal
FIELDGROUP,Longitudinal,1,2,3,4,5,6,7,8,9,15,16,17,18,27,28
FIELDGROUP,Transverse,1,2,3,4,10,11,12,13,14,19,20,21,22,27,28

PLOT_APPEARANCE,ALL,HORZ_GRID_ON,VERT_GRID_ON,MARKERS_AND_LINES

[Data]
Time,Comment,Field (Oe),Temperature (K),Long Moment (emu),Long Scan Std Dev,Long Algorithm,Long Reg Fit,Long Percent Error (%),Trans Moment (emu),Trans Scan Std Dev,Trans Algorithm,Trans Reg Fit,Trans Percent Error (%),Long Moment [w/o ABS] (emu),Long Scan Std Dev [w/o ABS],Long Reg Fit [w/o ABS],Long Percent Error [w/o ABS] (%),Trans Moment [w/o ABS] (emu),Trans Scan Std Dev [w/o ABS],Trans Reg Fit [w/o ABS],Trans Percent Error [w/o ABS] (%),Points per Scan,Scans per Measurement,Scan Length (cm),Delta Temp (K),Rot Position (deg),Error,EC Comp. Running,Using ABS,
1687420929.500,,1.003808e+004,4.992199e+000,1.954666e+000,0.000000e+000,3,9.837857e-001,0.000000e+000,,,,,,,,,,,,,,24,1,4.000000e+000,7.786751e-003,0.000000e+000,0,,0,
1687420958.965,,8.783001e+003,5.003839e+000,1.954739e+000,0.000000e+000,3,9.832236e-001,0.000000e+000,,,,,,,,,,,,,,24,1,4.000000e+000,1.316500e-002,0.000000e+000,0,,0,
1687420988.629,,7.527458e+003,4.997116e+000,1.952764e+000,0.000000e+000,3,9.831524e-001,0.000000e+000,,,,,,,,,,,,,,24,1,4.000000e+000,2.076101e-002,0.000000e+000,0,,0,
1687421018.536,,6.272727e+003,5.000786e+000,1.949746e+000,0.000000e+000,3,9.831443e-001,0.000000e+000,,,,,,,,,,,,,,24,1,4.000000e+000,2.512598e-002,0.000000e+000,0,,0,
1687421092.301,,5.018112e+003,4.971282e+000,1.945490e+000,0.000000e+000,3,9.829386e-001,0.000000e+000,,,,,,,,,,,,,,24,1,4.000000e+000,1.672268e-002,0.000000e+000,0,,0,
1687421122.514,,4.014490e+003,5.017918e+000,1.938589e+000,0.000000e+000,3,9.831904e-001,0.000000e+000,,,,,,,,,,,,,,24,1,4.000000e+000,2.618074e-002,0.000000e+000,0,,0,
1687421149.165,,3.512505e+003,4.987792e+000,1.935322e+000,0.000000e+000,3,9.831883e-001,0.000000e+000,,,,,,,,,,,,,,24,1,4.000000e+000,3.207111e-002,0.000000e+000,0,,0,
1687421176.012,,3.010925e+003,5.006507e+000,1.929132e+000,0.000000e+000,3,9.832239e-001,0.000000e+000,,,,,,,,,,,,,,24,1,4.000000e+000,1.401711e-002,0.000000e+000,0,,0,
1687421203.788,,2.509229e+003,4.997378e+000,1.921409e+000,0.000000e+000,3,9.832600e-001,0.000000e+000,,,,,,,,,,,,,,24,1,4.000000e+000,2.524900e-002,0.000000e+000,0,,0,
1687421230.647,,2.007360e+003,4.998495e+000,1.910327e+000,0.000000e+000,3,9.832536e-001,0.000000e+000,,,,,,,,,,,,,,24,1,4.000000e+000,4.329491e-002,0.000000e+000,0,,0,
1687421257.835,,1.505723e+003,5.007764e+000,1.890393e+000,0.000000e+000,3,9.833128e-001,0.000000e+000,,,,,,,,,,,,,,24,1,4.000000e+000,1.586294e-002,0.000000e+000,0,,0,
1687421285.335,,1.003738e+003,4.994583e+000,1.849954e+000,0.000000e+000,3,9.833953e-001,0.000000e+000,,,,,,,,,,,,,,24,1,4.000000e+000,3.267717e-002,0.000000e+000,0,,0,
1687421311.988,,5.018922e+002,5.014471e+000,1.741354e+000,0.000000e+000,3,9.835152e-001,0.000000e+000,,,,,,,,,,,,,,24,1,4.000000e+000,2.328587e-002,0.000000e+000,0,,0,
1687421338.046,,4.015878e+002,4.987438e+000,1.695363e+000,0.000000e+000,3,9.836116e-001,0.000000e+000,,,,,,,,,,,,,,24,1,4.000000e+000,1.570225e-003,0.000000e+000,0,,0,
1687421363.219,,3.012834e+002,5.017909e+000,1.629045e+000,0.000000e+000,3,9.836279e-001,0.000000e+000,,,,,,,,,,,,,,24,1,4.000000e+000,2.349567e-002,0.000000e+000,0,,0,
1687421388.579,,2.008170e+002,4.982635e+000,1.516130e+000,0.000000e+000,3,9.836603e-001,0.000000e+000,,,,,,,,,,,,,,24,1,4.000000e+000,3.256607e-002,0.000000e+000,0,,0,
1687421415.485,,1.005127e+002,5.012805e+000,1.244839e+000,0.000000e+000,3,9.834365e-001,0.000000e+000,,,,,,,,,,,,,,24,1,4.000000e+000,3.766060e-003,0.000000e+000,0,,0,
1687421479.106,,1.272898e-001,5.004065e+000,8.452267e-002,0.000000e+000,3,9.853714e-001,0.000000e+000,,,,,,,,,,,,,,24,1,4.000000e+000,2.191639e-002,0.000000e+000,0,,0,
1687421511.485,,-5.040678e+001,4.985763e+000,-3.992603e-001,0.000000e+000,3,9.937714e-001,0.000000e+000,,,,,,,,,,,,,,24,1,4.000000e+000,4.013014e-002,0.000000e+000,0,,0,
1687421576.685,,-1.006515e+002,4.986508e+000,-8.896760e-001,0.000000e+000,3,9.895264e-001,0.000000e+000,,,,,,,,,,,,,,24,1,4.000000e+000,3.130674e-002,0.000000e+000,0,,0,
1687421601.917,,-1.508037e+002,4.998692e+000,-1.173138e+000,0.000000e+000,3,9.926183e-001,0.000000e+000,,,,,,,,,,,,,,24,1,4.000000e+000,3.216267e-002,0.000000e+000,0,,0,
1687421626.255,,-2.010022e+002,5.002906e+000,-1.352474e+000,0.000000e+000,3,9.901566e-001,0.000000e+000,,,,,,,,,,,,,,24,1,4.000000e+000,2.440214e-002,0.000000e+000,0,,0,
1687421652.219,,-2.511660e+002,4.994201e+000,-1.460984e+000,0.000000e+000,3,9.887431e-001,0.000000e+000,,,,,,,,,,,,,,24,1,4.000000e+000,4.718065e-002,0.000000e+000,0,,0,
1687421678.125,,-5.021468e+002,5.008584e+000,-1.704374e+000,0.000000e+000,3,9.882022e-001,0.000000e+000,,,,,,,,,,,,,,24,1,4.000000e+000,2.647495e-002,0.000000e+000,0,,0,
1687421704.221,,-7.530929e+002,4.989051e+000,-1.801285e+000,0.000000e+000,3,9.870034e-001,0.000000e+000,,,,,,,,,,,,,,24,1,4.000000e+000,3.804207e-003,0.000000e+000,0,,0,
1687421731.193,,-1.004016e+003,5.010526e+000,-1.851646e+000,0.000000e+000,3,9.863743e-001,0.000000e+000,,,,,,,,,,,,,,24,1,4.000000e+000,1.855993e-002,0.000000e+000,0,,0,
1687421757.736,,-1.254916e+003,4.993320e+000,-1.881586e+000,0.000000e+000,3,9.858851e-001,0.000000e+000,,,,,,,,,,,,,,24,1,4.000000e+000,2.735233e-002,0.000000e+000,0,,0,
1687421782.884,,-1.506012e+003,5.011794e+000,-1.900344e+000,0.000000e+000,3,9.856926e-001,0.000000e+000,,,,,,,,,,,,,,24,1,4.000000e+000,2.359104e-002,0.000000e+000,0,,0,
1687421808.410,,-1.756831e+003,4.986695e+000,-1.911459e+000,0.000000e+000,3,9.857772e-001,0.000000e+000,,,,,,,,,,,,,,24,1,4.000000e+000,3.056049e-003,0.000000e+000,0,,0,
1687421833.568,,-2.007708e+003,5.013745e+000,-1.921098e+000,0.000000e+000,3,9.855777e-001,0.000000e+000,,,,,,,,,,,,,,24,1,4.000000e+000,1.783609e-002,0.000000e+000,0,,0,
1687421860.615,,-2.258700e+003,4.985195e+000,-1.927398e+000,0.000000e+000,3,9.855933e-001,0.000000e+000,,,,,,,,,,,,,,24,1,4.000000e+000,2.129793e-002,0.000000e+000,0,,0,
1687421886.921,,-2.509577e+003,5.013143e+000,-1.932281e+000,0.000000e+000,3,9.856659e-001,0.000000e+000,,,,,,,,,,,,,,24,1,4.000000e+000,7.617950e-003,0.000000e+000,0,,0,
1687421912.681,,-2.760511e+003,4.994785e+000,-1.936487e+000,0.000000e+000,3,9.855328e-001,0.000000e+000,,,,,,,,,,,,,,24,1,4.000000e+000,4.064322e-002,0.000000e+000,0,,0,
1687421938.695,,-3.011330e+003,4.997454e+000,-1.940426e+000,0.000000e+000,3,9.855458e-001,0.000000e+000,,,,,,,,,,,,,,24,1,4.000000e+000,3.430223e-002,0.000000e+000,0,,0,
1687421966.558,,-3.512968e+003,4.998415e+000,-1.946267e+000,0.000000e+000,3,9.854339e-001,0.000000e+000,,,,,,,,,,,,,,24,1,4.000000e+000,3.556538e-002,0.000000e+000,0,,0,
1687421993.917,,-4.014836e+003,4.997683e+000,-1.950108e+000,0.000000e+000,3,9.854628e-001,0.000000e+000,,,,,,,,,,,,,,24,1,4.000000e+000,3.887510e-002,0.000000e+000,0,,0,
1687422020.975,,-4.516590e+003,4.998929e+000,-1.953578e+000,0.000000e+000,3,9.854035e-001,0.000000e+000,,,,,,,,,,,,,,24,1,4.000000e+000,2.917385e-002,0.000000e+000,0,,0,
1687422048.334,,-5.018575e+003,4.997346e+000,-1.972302e+000,0.000000e+000,3,9.877338e-001,0.000000e+000,,,,,,,,,,,,,,24,1,4.000000e+000,3.820324e-002,0.000000e+000,0,,0,
1687422123.136,,-6.274463e+003,5.012571e+000,-1.959643e+000,0.000000e+000,3,9.852395e-001,0.000000e+000,,,,,,,,,,,,,,24,1,4.000000e+000,1.665401e-002,0.000000e+000,0,,0,
1687422153.208,,-7.529773e+003,5.001626e+000,-1.963685e+000,0.000000e+000,3,9.852633e-001,0.000000e+000,,,,,,,,,,,,,,24,1,4.000000e+000,9.572029e-003,0.000000e+000,0,,0,
1687422182.745,,-8.786004e+003,4.998130e+000,-1.966720e+000,0.000000e+000,3,9.852373e-001,0.000000e+000,,,,,,,,,,,,,,24,1,4.000000e+000,5.733013e-003,0.000000e+000,0,,0,
1687422211.401,,-1.003993e+004,4.997797e+000,-1.968803e+000,0.000000e+000,3,9.852034e-001,0.000000e+000,,,,,,,,,,,,,,24,1,4.000000e+000,4.402161e-003,0.000000e+000,0,,0,
1687422240.304,,-8.784389e+003,4.999626e+000,-1.967190e+000,0.000000e+000,3,9.851965e-001,0.000000e+000,,,,,,,,,,,,,,24,1,4.000000e+000,7.067204e-003,0.000000e+000,0,,0,
1687422270.431,,-7.529542e+003,4.997714e+000,-1.963801e+000,0.000000e+000,3,9.852594e-001,0.000000e+000,,,,,,,,,,,,,,24,1,4.000000e+000,5.066872e-003,0.000000e+000,0,,0,
1687422300.392,,-6.273537e+003,4.998339e+000,-1.960574e+000,0.000000e+000,3,9.852332e-001,0.000000e+000,,,,,,,,,,,,,,24,1,4.000000e+000,7.147312e-003,0.000000e+000,0,,0,
1687422374.763,,-5.018344e+003,4.999249e+000,-1.956506e+000,0.000000e+000,3,9.850072e-001,0.000000e+000,,,,,,,,,,,,,,24,1,4.000000e+000,1.995087e-003,0.000000e+000,0,,0,
1687422404.556,,-4.014721e+003,4.998254e+000,-1.949920e+000,0.000000e+000,3,9.852301e-001,0.000000e+000,,,,,,,,,,,,,,24,1,4.000000e+000,4.820347e-003,0.000000e+000,0,,0,
1687422430.916,,-3.512852e+003,4.999880e+000,-1.946223e+000,0.000000e+000,3,9.852471e-001,0.000000e+000,,,,,,,,,,,,,,24,1,4.000000e+000,1.056194e-002,0.000000e+000,0,,0,
1687422458.785,,-3.011214e+003,4.999045e+000,-1.939782e+000,0.000000e+000,3,9.853547e-001,0.000000e+000,,,,,,,,,,,,,,24,1,4.000000e+000,7.896900e-003,0.000000e+000,0,,0,
1687422486.271,,-2.509403e+003,5.001130e+000,-1.932199e+000,0.000000e+000,3,9.854145e-001,0.000000e+000,,,,,,,,,,,,,,24,1,4.000000e+000,1.256514e-002,0.000000e+000,0,,0,
1687422512.130,,-2.007534e+003,5.001544e+000,-1.921270e+000,0.000000e+000,3,9.854367e-001,0.000000e+000,,,,,,,,,,,,,,24,1,4.000000e+000,1.090336e-002,0.000000e+000,0,,0,
1687422538.878,,-1.505897e+003,5.000796e+000,-1.901680e+000,0.000000e+000,3,9.854097e-001,0.000000e+000,,,,,,,,,,,,,,24,1,4.000000e+000,1.089811e-002,0.000000e+000,0,,0,
1687422565.614,,-1.003831e+003,4.999212e+000,-1.861542e+000,0.000000e+000,3,9.855093e-001,0.000000e+000,,,,,,,,,,,,,,24,1,4.000000e+000,8.229733e-003,0.000000e+000,0,,0,
1687422592.833,,-5.020311e+002,4.998879e+000,-1.754181e+000,0.000000e+000,3,9.856448e-001,0.000000e+000,,,,,,,,,,,,,,24,1,4.000000e+000,8.229256e-003,0.000000e+000,0,,0,
1687422619.093,,-4.016920e+002,5.000885e+000,-1.708843e+000,0.000000e+000,3,9.857327e-001,0.000000e+000,,,,,,,,,,,,,,24,1,4.000000e+000,1.439285e-002,0.000000e+000,0,,0,
1687422644.031,,-3.014223e+002,5.002009e+000,-1.642572e+000,0.000000e+000,3,9.857349e-001,0.000000e+000,,,,,,,,,,,,,,24,1,4.000000e+000,1.515102e-002,0.000000e+000,0,,0,
1687422669.867,,-2.009559e+002,5.002167e+000,-1.530095e+000,0.000000e+000,3,9.856771e-001,0.000000e+000,,,,,,,,,,,,,,24,1,4.000000e+000,8.491039e-003,0.000000e+000,0,,0,
1687422695.066,,-1.006168e+002,5.003132e+000,-1.258957e+000,0.000000e+000,3,9.851723e-001,0.000000e+000,,,,,,,,,,,,,,24,1,4.000000e+000,1.441002e-002,0.000000e+000,0,,0,
1687422764.023,,-2.314360e-001,4.994433e+000,-1.214096e-001,0.000000e+000,3,9.862818e-001,0.000000e+000,,,,,,,,,,,,,,24,1,4.000000e+000,9.951591e-004,0.000000e+000,0,,0,
1687422796.242,,5.037206e+001,4.997381e+000,4.041371e-001,0.000000e+000,3,9.939443e-001,0.000000e+000,,,,,,,,,,,,,,24,1,4.000000e+000,4.235744e-003,0.000000e+000,0,,0,
1687422863.300,,1.006168e+002,4.994931e+000,9.039418e-001,0.000000e+000,3,9.901510e-001,0.000000e+000,,,,,,,,,,,,,,24,1,4.000000e+000,3.323555e-004,0.000000e+000,0,,0,
1687422888.136,,1.507690e+002,4.998966e+000,1.187990e+000,0.000000e+000,3,9.927996e-001,0.000000e+000,,,,,,,,,,,,,,24,1,4.000000e+000,1.072264e-002,0.000000e+000,0,,0,
1687422912.546,,2.009559e+002,5.000421e+000,1.365029e+000,0.000000e+000,3,9.907506e-001,0.000000e+000,,,,,,,,,,,,,,24,1,4.000000e+000,1.064682e-002,0.000000e+000,0,,0,
1687422936.484,,2.511312e+002,4.999840e+000,1.471032e+000,0.000000e+000,3,9.891354e-001,0.000000e+000,,,,,,,,,,,,,,24,1,4.000000e+000,1.180792e-002,0.000000e+000,0,,0,
1687422962.632,,5.021237e+002,4.999341e+000,1.709792e+000,0.000000e+000,3,9.885712e-001,0.000000e+000,,,,,,,,,,,,,,24,1,4.000000e+000,1.113987e-002,0.000000e+000,0,,0,
1687422989.462,,7.530235e+002,4.998713e+000,1.803308e+000,0.000000e+000,3,9.870026e-001,0.000000e+000,,,,,,,,,,,,,,24,1,4.000000e+000,7.896423e-003,0.000000e+000,0,,0,
1687423017.275,,1.003970e+003,4.998758e+000,1.851984e+000,0.000000e+000,3,9.860287e-001,0.000000e+000,,,,,,,,,,,,,,24,1,4.000000e+000,1.047182e-002,0.000000e+000,0,,0,
1687423043.216,,1.254893e+003,5.001715e+000,1.881846e+000,0.000000e+000,3,9.854656e-001,0.000000e+000,,,,,,,,,,,,,,24,1,4.000000e+000,1.356792e-002,0.000000e+000,0,,0,
1687423069.216,,1.505954e+003,5.000588e+000,1.899067e+000,0.000000e+000,3,9.853238e-001,0.000000e+000,,,,,,,,,,,,,,24,1,4.000000e+000,1.131392e-002,0.000000e+000,0,,0,
1687423096.380,,1.756773e+003,4.998755e+000,1.910988e+000,0.000000e+000,3,9.852253e-001,0.000000e+000,,,,,,,,,,,,,,24,1,4.000000e+000,8.478165e-003,0.000000e+000,0,,0,
1687423122.752,,2.007592e+003,4.999587e+000,1.919663e+000,0.000000e+000,3,9.853026e-001,0.000000e+000,,,,,,,,,,,,,,24,1,4.000000e+000,8.647919e-003,0.000000e+000,0,,0,
1687423149.643,,2.258642e+003,5.000381e+000,1.925542e+000,0.000000e+000,3,9.853345e-001,0.000000e+000,,,,,,,,,,,,,,24,1,4.000000e+000,1.189518e-002,0.000000e+000,0,,0,
1687423174.491,,2.509519e+003,5.001634e+000,1.932027e+000,0.000000e+000,3,9.850757e-001,0.000000e+000,,,,,,,,,,,,,,24,1,4.000000e+000,1.439905e-002,0.000000e+000,0,,0,
1687423201.397,,2.760454e+003,4.998672e+000,1.935429e+000,0.000000e+000,3,9.851535e-001,0.000000e+000,,,,,,,,,,,,,,24,1,4.000000e+000,8.975983e-003,0.000000e+000,0,,0,
1687423227.295,,3.011272e+003,4.999423e+000,1.938890e+000,0.000000e+000,3,9.850804e-001,0.000000e+000,,,,,,,,,,,,,,24,1,4.000000e+000,1.047707e-002,0.000000e+000,0,,0,
1687423253.906,,3.512852e+003,5.000254e+000,1.944676e+000,0.000000e+000,3,9.851147e-001,0.000000e+000,,,,,,,,,,,,,,24,1,4.000000e+000,1.014709e-002,0.000000e+000,0,,0,
1687423279.484,,4.014836e+003,5.001045e+000,1.949139e+000,0.000000e+000,3,9.850906e-001,0.000000e+000,,,,,,,,,,,,,,24,1,4.000000e+000,1.056814e-002,0.000000e+000,0,,0,
1687423305.759,,4.516475e+003,4.999633e+000,1.952147e+000,0.000000e+000,3,9.850659e-001,0.000000e+000,,,,,,,,,,,,,,24,1,4.000000e+000,1.172400e-002,0.000000e+000,0,,0,
1687423332.127,,5.018460e+003,4.999465e+000,1.954606e+000,0.000000e+000,3,9.850863e-001,0.000000e+000,,,,,,,,,,,,,,24,1,4.000000e+000,1.089191e-002,0.000000e+000,0,,0,
1687423406.609,,6.275620e+003,4.997837e+000,1.959074e+000,0.000000e+000,3,9.848858e-001,0.000000e+000,,,,,,,,,,,,,,24,1,4.000000e+000,3.323078e-003,0.000000e+000,0,,0,
1687423435.648,,7.530698e+003,4.998754e+000,1.962362e+000,0.000000e+000,3,9.850124e-001,0.000000e+000,,,,,,,,,,,,,,24,1,4.000000e+000,6.316185e-003,0.000000e+000,0,,0,
1687423465.097,,8.786004e+003,4.999713e+000,1.964986e+000,0.000000e+000,3,9.849931e-001,0.000000e+000,,,,,,,,,,,,,,24,1,4.000000e+000,1.022816e-002,0.000000e+000,0,,0,
1687423493.113,,1.004039e+004,4.997422e+000,1.940150e+000,0.000000e+000,3,9.771044e-001,0.000000e+000,,,,,,,,,,,,,,24,1,4.000000e+000,4.318714e-003,0.000000e+000,0,,0,