File: HysteresisLoop/Li0.5Al0.5 Loop 293K.dc.dat
[Header]
TITLE,MPMS DC Measurement
BYAPP,MPMS Measurement,2.1,Summary
FILEOPENTIME, 1687355643.572000 6/21/2023, 3:54:03 PM

INFO, APPNAME, MPMS MultiVu Application, Revision 1.60,  Build 081

INFO, NAME, Li0.5Al0.5Fe5O8
INFO, WEIGHT, 84.430
INFO, AREA, 0.000
INFO, LENGTH, 0.000
INFO, SHAPE,
INFO, COMMENT, cotton: 15.1 mg, capsule:39.07 mg
INFO, SEQUENCE FILE: ciclo_histeresis_DC_300K_ fino 1T.seq


INFO, BACKGROUND DATA FILE:, None


STARTUPAXIS,X,4,LINEAR,AUTO,0.000000,0.000000
STARTUPAXIS,Y1,5,LINEAR,AUTO,0.000000,0.000000


STARTUPGROUP,Longitudinal
FIELDGROUP,Longitudinal,1,2,3,4,5,6,7,8,9,15,16,17,18,27,28
FIELDGROUP,Transverse,1,2,3,4,10,11,12,13,14,19,20,21,22,27,28

PLOT_APPEARANCE,ALL,HORZ_GRID_ON,VERT_GRID_ON,MARKERS_AND_LINES

[Data]
Time,Comment,Field (Oe),Temperature (K),Long Moment (emu),Long Scan Std Dev,Long Algorithm,Long Reg Fit,Long Percent Error (%),Trans Moment (emu),Trans Scan Std Dev,Trans Algorithm,Trans Reg Fit,Trans Percent Error (%),Long Moment [w/o ABS] (emu),Long Scan Std Dev [w/o ABS],Long Reg Fit [w/o ABS],Long Percent Error [w/o ABS] (%),Trans Moment [w/o ABS] (emu),Trans Scan Std Dev [w/o ABS],Trans Reg Fit [w/o ABS],Trans Percent Error [w/o ABS] (%),Points per Scan,Scans per Measurement,Scan Length (cm),Delta Temp (K),Rot Position (deg),Error,EC Comp. Running,Using ABS,
1687355643.572,,1.003623e+004,2.930782e+002,1.907778e+000,0.000000e+000,2,9.596914e-001,0.000000e+000,,,,,,,,,,,,,,24,1,4.000000e+000,2.648926e-002,0.000000e+000,0,,0,
1687355673.273,,8.781150e+003,2.930915e+002,1.908008e+000,0.000000e+000,2,9.597452e-001,0.000000e+000,,,,,,,,,,,,,,24,1,4.000000e+000,1.325073e-001,0.000000e+000,0,,0,
1687355706.398,,7.527227e+003,2.930649e+002,1.904342e+000,0.000000e+000,2,9.598156e-001,0.000000e+000,,,,,,,,,,,,,,24,1,4.000000e+000,1.589966e-001,0.000000e+000,0,,0,
1687355739.843,,6.271686e+003,2.930848e+002,1.900769e+000,0.000000e+000,2,9.599838e-001,0.000000e+000,,,,,,,,,,,,,,24,1,4.000000e+000,1.192017e-001,0.000000e+000,0,,0,
1687355818.986,,5.018112e+003,2.929457e+002,1.897268e+000,0.000000e+000,2,9.598505e-001,0.000000e+000,,,,,,,,,,,,,,24,1,4.000000e+000,2.651978e-002,0.000000e+000,0,,0,
1687355850.595,,4.014490e+003,2.929656e+002,1.889893e+000,0.000000e+000,2,9.598231e-001,0.000000e+000,,,,,,,,,,,,,,24,1,4.000000e+000,1.986084e-001,0.000000e+000,0,,0,
1687355879.895,,3.512620e+003,2.930385e+002,1.885389e+000,0.000000e+000,2,9.600503e-001,0.000000e+000,,,,,,,,,,,,,,24,1,4.000000e+000,2.914124e-001,0.000000e+000,0,,0,
1687355906.029,,3.010925e+003,2.929590e+002,1.879556e+000,0.000000e+000,2,9.609166e-001,0.000000e+000,,,,,,,,,,,,,,24,1,4.000000e+000,5.291748e-002,0.000000e+000,0,,0,
1687355935.127,,2.509229e+003,2.930715e+002,1.869421e+000,0.000000e+000,2,9.609759e-001,0.000000e+000,,,,,,,,,,,,,,24,1,4.000000e+000,3.970337e-002,0.000000e+000,0,,0,
1687355961.573,,2.007303e+003,2.930848e+002,1.854905e+000,0.000000e+000,2,9.617888e-001,0.000000e+000,,,,,,,,,,,,,,24,1,4.000000e+000,6.619263e-002,0.000000e+000,0,,0,
1687355991.002,,1.505781e+003,2.929656e+002,1.826285e+000,0.000000e+000,2,9.633049e-001,0.000000e+000,,,,,,,,,,,,,,24,1,4.000000e+000,3.970337e-002,0.000000e+000,0,,0,
1687356018.049,,1.003692e+003,2.930318e+002,1.755524e+000,0.000000e+000,2,9.659938e-001,0.000000e+000,,,,,,,,,,,,,,24,1,4.000000e+000,9.277344e-002,0.000000e+000,0,,0,
1687356046.409,,5.019964e+002,2.930516e+002,1.496305e+000,0.000000e+000,2,9.718152e-001,0.000000e+000,,,,,,,,,,,,,,24,1,4.000000e+000,1.324768e-001,0.000000e+000,0,,0,
1687356072.630,,4.016111e+002,2.929987e+002,1.377141e+000,0.000000e+000,2,9.733664e-001,0.000000e+000,,,,,,,,,,,,,,24,1,4.000000e+000,7.937622e-002,0.000000e+000,0,,0,
1687356102.599,,3.013066e+002,2.929854e+002,1.197937e+000,0.000000e+000,2,9.747432e-001,0.000000e+000,,,,,,,,,,,,,,24,1,4.000000e+000,1.325073e-001,0.000000e+000,0,,0,
1687356127.849,,2.008517e+002,2.931047e+002,9.203606e-001,0.000000e+000,2,9.750934e-001,0.000000e+000,,,,,,,,,,,,,,24,1,4.000000e+000,1.060181e-001,0.000000e+000,0,,0,
1687356175.219,,1.005358e+002,2.930252e+002,5.255319e-001,0.000000e+000,2,9.737092e-001,0.000000e+000,,,,,,,,,,,,,,24,1,4.000000e+000,5.300903e-002,0.000000e+000,0,,0,
1687356243.543,,1.388616e-001,2.930384e+002,4.386541e-002,0.000000e+000,2,9.784976e-001,0.000000e+000,,,,,,,,,,,,,,24,1,4.000000e+000,5.300903e-002,0.000000e+000,0,,0,
1687356319.997,,-5.040677e+001,2.930649e+002,-2.097742e-001,0.000000e+000,2,9.667863e-001,0.000000e+000,,,,,,,,,,,,,,24,1,4.000000e+000,1.059875e-001,0.000000e+000,0,,0,
1687356347.568,,-1.006399e+002,2.930649e+002,-4.399915e-001,0.000000e+000,2,9.687452e-001,0.000000e+000,,,,,,,,,,,,,,24,1,4.000000e+000,1.855164e-001,0.000000e+000,0,,0,
1687356374.452,,-1.508037e+002,2.930385e+002,-6.470926e-001,0.000000e+000,2,9.699431e-001,0.000000e+000,,,,,,,,,,,,,,24,1,4.000000e+000,2.648926e-002,0.000000e+000,0,,0,
1687356401.266,,-2.009790e+002,2.929789e+002,-8.289365e-001,0.000000e+000,2,9.697746e-001,0.000000e+000,,,,,,,,,,,,,,24,1,4.000000e+000,3.967285e-002,0.000000e+000,0,,0,
1687356430.294,,-2.511775e+002,2.930583e+002,-9.847423e-001,0.000000e+000,2,9.688299e-001,0.000000e+000,,,,,,,,,,,,,,24,1,4.000000e+000,1.192017e-001,0.000000e+000,0,,0,
1687356495.003,,-5.021352e+002,2.930450e+002,-1.453034e+000,0.000000e+000,2,9.648357e-001,0.000000e+000,,,,,,,,,,,,,,24,1,4.000000e+000,6.628418e-002,0.000000e+000,0,,0,
1687356522.389,,-7.530004e+002,2.930053e+002,-1.655822e+000,0.000000e+000,2,9.605625e-001,0.000000e+000,,,,,,,,,,,,,,24,1,4.000000e+000,3.979492e-002,0.000000e+000,0,,0,
1687356551.903,,-1.003993e+003,2.929656e+002,-1.751273e+000,0.000000e+000,2,9.578382e-001,0.000000e+000,,,,,,,,,,,,,,24,1,4.000000e+000,1.318359e-002,0.000000e+000,0,,0,
1687356576.887,,-1.254916e+003,2.929391e+002,-1.800356e+000,0.000000e+000,2,9.558035e-001,0.000000e+000,,,,,,,,,,,,,,24,1,4.000000e+000,9.262085e-002,0.000000e+000,0,,0,
1687356604.789,,-1.506013e+003,2.930119e+002,-1.826840e+000,0.000000e+000,2,9.538883e-001,0.000000e+000,,,,,,,,,,,,,,24,1,4.000000e+000,5.297852e-002,0.000000e+000,0,,0,
1687356633.133,,-1.756715e+003,2.929987e+002,-1.841414e+000,0.000000e+000,2,9.520085e-001,0.000000e+000,,,,,,,,,,,,,,24,1,4.000000e+000,1.324158e-001,0.000000e+000,0,,0,
1687356663.534,,-2.007592e+003,2.930186e+002,-1.852015e+000,0.000000e+000,2,9.505084e-001,0.000000e+000,,,,,,,,,,,,,,24,1,4.000000e+000,6.628418e-002,0.000000e+000,0,,0,
1687356689.933,,-2.258700e+003,2.930715e+002,-1.861905e+000,0.000000e+000,2,9.499121e-001,0.000000e+000,,,,,,,,,,,,,,24,1,4.000000e+000,9.268188e-002,0.000000e+000,0,,0,
1687356715.951,,-2.509577e+003,2.929789e+002,-1.867755e+000,0.000000e+000,2,9.487696e-001,0.000000e+000,,,,,,,,,,,,,,24,1,4.000000e+000,3.967285e-002,0.000000e+000,0,,0,
1687356741.987,,-2.760454e+003,2.930450e+002,-1.872110e+000,0.000000e+000,2,9.474855e-001,0.000000e+000,,,,,,,,,,,,,,24,1,4.000000e+000,1.192932e-001,0.000000e+000,0,,0,
1687356773.137,,-3.011215e+003,2.930649e+002,-1.875130e+000,0.000000e+000,2,9.463582e-001,0.000000e+000,,,,,,,,,,,,,,24,1,4.000000e+000,0.000000e+000,0.000000e+000,0,,0,
1687356800.528,,-3.513083e+003,2.929788e+002,-1.883224e+000,0.000000e+000,2,9.457157e-001,0.000000e+000,,,,,,,,,,,,,,24,1,4.000000e+000,1.192017e-001,0.000000e+000,0,,0,
1687356828.165,,-4.014836e+003,2.929656e+002,-1.886375e+000,0.000000e+000,2,9.447985e-001,0.000000e+000,,,,,,,,,,,,,,24,1,4.000000e+000,3.970337e-002,0.000000e+000,0,,0,
1687356855.410,,-4.516590e+003,2.929457e+002,-1.889743e+000,0.000000e+000,2,9.439779e-001,0.000000e+000,,,,,,,,,,,,,,24,1,4.000000e+000,7.940674e-002,0.000000e+000,0,,0,
1687356882.700,,-5.018460e+003,2.929656e+002,-1.891853e+000,0.000000e+000,2,9.428626e-001,0.000000e+000,,,,,,,,,,,,,,24,1,4.000000e+000,1.455994e-001,0.000000e+000,0,,0,
1687356963.577,,-6.273074e+003,2.930186e+002,-1.895398e+000,0.000000e+000,2,9.405523e-001,0.000000e+000,,,,,,,,,,,,,,24,1,4.000000e+000,6.628418e-002,0.000000e+000,0,,0,
1687356995.085,,-7.528847e+003,2.929921e+002,-1.899544e+000,0.000000e+000,2,9.401755e-001,0.000000e+000,,,,,,,,,,,,,,24,1,4.000000e+000,1.327515e-002,0.000000e+000,0,,0,
1687357027.570,,-8.783926e+003,2.930186e+002,-1.901282e+000,0.000000e+000,2,9.390935e-001,0.000000e+000,,,,,,,,,,,,,,24,1,4.000000e+000,3.970337e-002,0.000000e+000,0,,0,
1687357059.976,,-1.003831e+004,2.929921e+002,-1.903977e+000,0.000000e+000,2,9.384524e-001,0.000000e+000,,,,,,,,,,,,,,24,1,4.000000e+000,1.721802e-001,0.000000e+000,0,,0,
1687357092.601,,-8.783463e+003,2.930385e+002,-1.902080e+000,0.000000e+000,2,9.381967e-001,0.000000e+000,,,,,,,,,,,,,,24,1,4.000000e+000,7.949829e-002,0.000000e+000,0,,0,
1687357121.077,,-7.527921e+003,2.929259e+002,-1.899073e+000,0.000000e+000,2,9.383827e-001,0.000000e+000,,,,,,,,,,,,,,24,1,4.000000e+000,9.259033e-002,0.000000e+000,0,,0,
1687357150.592,,-6.272264e+003,2.930914e+002,-1.895964e+000,0.000000e+000,2,9.379994e-001,0.000000e+000,,,,,,,,,,,,,,24,1,4.000000e+000,2.651978e-002,0.000000e+000,0,,0,
1687357227.703,,-5.018344e+003,2.930054e+002,-1.891153e+000,0.000000e+000,2,9.370075e-001,0.000000e+000,,,,,,,,,,,,,,24,1,4.000000e+000,9.268188e-002,0.000000e+000,0,,0,
1687357258.353,,-4.014721e+003,2.930120e+002,-1.883977e+000,0.000000e+000,2,9.371080e-001,0.000000e+000,,,,,,,,,,,,,,24,1,4.000000e+000,1.058960e-001,0.000000e+000,0,,0,
1687357289.369,,-3.512852e+003,2.929921e+002,-1.879498e+000,0.000000e+000,2,9.373429e-001,0.000000e+000,,,,,,,,,,,,,,24,1,4.000000e+000,3.970337e-002,0.000000e+000,0,,0,
1687357317.240,,-3.011099e+003,2.930186e+002,-1.873793e+000,0.000000e+000,2,9.375793e-001,0.000000e+000,,,,,,,,,,,,,,24,1,4.000000e+000,1.330566e-002,0.000000e+000,0,,0,
1687357345.148,,-2.509345e+003,2.929655e+002,-1.864092e+000,0.000000e+000,2,9.378837e-001,0.000000e+000,,,,,,,,,,,,,,24,1,4.000000e+000,9.271240e-002,0.000000e+000,0,,0,
1687357371.773,,-2.007476e+003,2.930318e+002,-1.849824e+000,0.000000e+000,2,9.386376e-001,0.000000e+000,,,,,,,,,,,,,,24,1,4.000000e+000,1.986084e-001,0.000000e+000,0,,0,
1687357400.025,,-1.505897e+003,2.930053e+002,-1.821351e+000,0.000000e+000,2,9.395434e-001,0.000000e+000,,,,,,,,,,,,,,24,1,4.000000e+000,1.192017e-001,0.000000e+000,0,,0,
1687357427.839,,-1.003853e+003,2.930583e+002,-1.750971e+000,0.000000e+000,2,9.422899e-001,0.000000e+000,,,,,,,,,,,,,,24,1,4.000000e+000,6.619263e-002,0.000000e+000,0,,0,
1687357456.089,,-5.020311e+002,2.930252e+002,-1.494608e+000,0.000000e+000,2,9.485392e-001,0.000000e+000,,,,,,,,,,,,,,24,1,4.000000e+000,5.300903e-002,0.000000e+000,0,,0,
1687357485.094,,-4.017036e+002,2.929854e+002,-1.375732e+000,0.000000e+000,2,9.495396e-001,0.000000e+000,,,,,,,,,,,,,,24,1,4.000000e+000,1.058960e-001,0.000000e+000,0,,0,
1687357513.595,,-3.014339e+002,2.929854e+002,-1.197741e+000,0.000000e+000,2,9.512253e-001,0.000000e+000,,,,,,,,,,,,,,24,1,4.000000e+000,0.000000e+000,0.000000e+000,0,,0,
1687357542.896,,-2.009675e+002,2.929722e+002,-9.210522e-001,0.000000e+000,2,9.514354e-001,0.000000e+000,,,,,,,,,,,,,,24,1,4.000000e+000,1.323853e-001,0.000000e+000,0,,0,
1687357587.911,,-1.006284e+002,2.930715e+002,-5.279310e-001,0.000000e+000,2,9.490491e-001,0.000000e+000,,,,,,,,,,,,,,24,1,4.000000e+000,1.327515e-002,0.000000e+000,0,,0,
1687357654.671,,-2.430078e-001,2.930583e+002,-4.750868e-002,0.000000e+000,2,9.505025e-001,0.000000e+000,,,,,,,,,,,,,,24,1,4.000000e+000,9.280396e-002,0.000000e+000,0,,0,
1687357732.074,,5.037206e+001,2.930782e+002,2.065333e-001,0.000000e+000,2,9.437578e-001,0.000000e+000,,,,,,,,,,,,,,24,1,4.000000e+000,0.000000e+000,0.000000e+000,0,,0,
1687357759.347,,1.006168e+002,2.930120e+002,4.364094e-001,0.000000e+000,2,9.460614e-001,0.000000e+000,,,,,,,,,,,,,,24,1,4.000000e+000,2.651978e-002,0.000000e+000,0,,0,
1687357786.227,,1.507575e+002,2.929258e+002,6.435949e-001,0.000000e+000,2,9.464831e-001,0.000000e+000,,,,,,,,,,,,,,24,1,4.000000e+000,1.191101e-001,0.000000e+000,0,,0,
1687357812.272,,2.009559e+002,2.929921e+002,8.256676e-001,0.000000e+000,2,9.465180e-001,0.000000e+000,,,,,,,,,,,,,,24,1,4.000000e+000,1.721802e-001,0.000000e+000,0,,0,
1687357838.164,,2.511428e+002,2.929391e+002,9.814931e-001,0.000000e+000,2,9.462407e-001,0.000000e+000,,,,,,,,,,,,,,24,1,4.000000e+000,3.982544e-002,0.000000e+000,0,,0,
1687357903.321,,5.020889e+002,2.930318e+002,1.449568e+000,0.000000e+000,2,9.413885e-001,0.000000e+000,,,,,,,,,,,,,,24,1,4.000000e+000,1.192017e-001,0.000000e+000,0,,0,
1687357929.672,,7.529540e+002,2.930649e+002,1.652567e+000,0.000000e+000,2,9.384354e-001,0.000000e+000,,,,,,,,,,,,,,24,1,4.000000e+000,7.949829e-002,0.000000e+000,0,,0,
1687357956.274,,1.003947e+003,2.930252e+002,1.748175e+000,0.000000e+000,2,9.356344e-001,0.000000e+000,,,,,,,,,,,,,,24,1,4.000000e+000,1.059875e-001,0.000000e+000,0,,0,
1687357984.353,,1.254846e+003,2.929457e+002,1.795208e+000,0.000000e+000,2,9.334649e-001,0.000000e+000,,,,,,,,,,,,,,24,1,4.000000e+000,7.940674e-002,0.000000e+000,0,,0,
1687358014.111,,1.505954e+003,2.930252e+002,1.821748e+000,0.000000e+000,2,9.318048e-001,0.000000e+000,,,,,,,,,,,,,,24,1,4.000000e+000,1.059875e-001,0.000000e+000,0,,0,
1687358041.095,,1.756658e+003,2.929523e+002,1.837648e+000,0.000000e+000,2,9.300255e-001,0.000000e+000,,,,,,,,,,,,,,24,1,4.000000e+000,1.191101e-001,0.000000e+000,0,,0,
1687358072.829,,2.007592e+003,2.929854e+002,1.847974e+000,0.000000e+000,2,9.289784e-001,0.000000e+000,,,,,,,,,,,,,,24,1,4.000000e+000,0.000000e+000,0.000000e+000,0,,0,
1687358097.353,,2.258584e+003,2.929324e+002,1.857459e+000,0.000000e+000,2,9.281893e-001,0.000000e+000,,,,,,,,,,,,,,24,1,4.000000e+000,2.651978e-002,0.000000e+000,0,,0,
1687358126.126,,2.509461e+003,2.930649e+002,1.862004e+000,0.000000e+000,2,9.267794e-001,0.000000e+000,,,,,,,,,,,,,,24,1,4.000000e+000,2.648926e-002,0.000000e+000,0,,0,
1687358152.564,,2.760511e+003,2.929987e+002,1.868127e+000,0.000000e+000,2,9.260012e-001,0.000000e+000,,,,,,,,,,,,,,24,1,4.000000e+000,1.589966e-001,0.000000e+000,0,,0,
1687358181.423,,3.011215e+003,2.929523e+002,1.870620e+000,0.000000e+000,2,9.255071e-001,0.000000e+000,,,,,,,,,,,,,,24,1,4.000000e+000,6.622314e-002,0.000000e+000,0,,0,
1687358208.768,,3.512852e+003,2.929722e+002,1.877248e+000,0.000000e+000,2,9.246609e-001,0.000000e+000,,,,,,,,,,,,,,24,1,4.000000e+000,2.639771e-002,0.000000e+000,0,,0,
1687358238.315,,4.014721e+003,2.930450e+002,1.881241e+000,0.000000e+000,2,9.238111e-001,0.000000e+000,,,,,,,,,,,,,,24,1,4.000000e+000,1.192932e-001,0.000000e+000,0,,0,
1687358265.696,,4.516475e+003,2.930318e+002,1.884707e+000,0.000000e+000,2,9.227898e-001,0.000000e+000,,,,,,,,,,,,,,24,1,4.000000e+000,3.979492e-002,0.000000e+000,0,,0,
1687358293.963,,5.018575e+003,2.929722e+002,1.887639e+000,0.000000e+000,2,9.224561e-001,0.000000e+000,,,,,,,,,,,,,,24,1,4.000000e+000,2.639771e-002,0.000000e+000,0,,0,
1687358371.786,,6.273537e+003,2.929788e+002,1.891460e+000,0.000000e+000,2,9.204997e-001,0.000000e+000,,,,,,,,,,,,,,24,1,4.000000e+000,6.619263e-002,0.000000e+000,0,,0,
1687358403.718,,7.529542e+003,2.930715e+002,1.894446e+000,0.000000e+000,2,9.201500e-001,0.000000e+000,,,,,,,,,,,,,,24,1,4.000000e+000,9.268188e-002,0.000000e+000,0,,0,
1687358433.077,,8.784617e+003,2.930914e+002,1.897859e+000,0.000000e+000,2,9.196302e-001,0.000000e+000,,,,,,,,,,,,,,24,1,4.000000e+000,2.651978e-002,0.000000e+000,0,,0,
1687358463.417,,1.003808e+004,2.930318e+002,1.899809e+000,0.000000e+000,2,9.191477e-001,0.000000e+000,,,,,,,,,,,,,,24,1,4.000000e+000,3.979492e-002,0.000000e+000,0,,0,