File: HysteresisLoop/Li0.6Al0.4 Loop 5K.dc.dat
[Header]
TITLE,MPMS DC Measurement
BYAPP,MPMS Measurement,2.1,Summary
FILEOPENTIME, 1687537032.054000 6/23/2023, 6:17:12 PM

INFO, APPNAME, MPMS MultiVu Application, Revision 1.60,  Build 081

INFO, NAME, Li0.6Al0.4Fe5O8
INFO, WEIGHT, 85.250
INFO, AREA, 0.000
INFO, LENGTH, 0.000
INFO, SHAPE,
INFO, COMMENT, cotton: 29.92 mg, capsule:40.26 mg
INFO, SEQUENCE FILE: ciclo_histeresis_DC_1T linreg.seq


INFO, BACKGROUND DATA FILE:, None


STARTUPAXIS,X,4,LINEAR,AUTO,0.000000,0.000000
STARTUPAXIS,Y1,5,LINEAR,AUTO,0.000000,0.000000


STARTUPGROUP,Longitudinal
FIELDGROUP,Longitudinal,1,2,3,4,5,6,7,8,9,15,16,17,18,27,28
FIELDGROUP,Transverse,1,2,3,4,10,11,12,13,14,19,20,21,22,27,28

PLOT_APPEARANCE,ALL,HORZ_GRID_ON,VERT_GRID_ON,MARKERS_AND_LINES

[Data]
Time,Comment,Field (Oe),Temperature (K),Long Moment (emu),Long Scan Std Dev,Long Algorithm,Long Reg Fit,Long Percent Error (%),Trans Moment (emu),Trans Scan Std Dev,Trans Algorithm,Trans Reg Fit,Trans Percent Error (%),Long Moment [w/o ABS] (emu),Long Scan Std Dev [w/o ABS],Long Reg Fit [w/o ABS],Long Percent Error [w/o ABS] (%),Trans Moment [w/o ABS] (emu),Trans Scan Std Dev [w/o ABS],Trans Reg Fit [w/o ABS],Trans Percent Error [w/o ABS] (%),Points per Scan,Scans per Measurement,Scan Length (cm),Delta Temp (K),Rot Position (deg),Error,EC Comp. Running,Using ABS,
1687537032.046,,1.003808e+004,4.998793e+000,1.433989e+000,0.000000e+000,3,9.889182e-001,0.000000e+000,,,,,,,,,,,,,,24,1,4.000000e+000,2.410889e-003,0.000000e+000,0,,0,
1687537062.180,,8.784153e+003,5.000581e+000,1.431473e+000,0.000000e+000,3,9.886163e-001,0.000000e+000,,,,,,,,,,,,,,24,1,4.000000e+000,1.164913e-003,0.000000e+000,0,,0,
1687537092.652,,7.528615e+003,4.999999e+000,1.430079e+000,0.000000e+000,3,9.886655e-001,0.000000e+000,,,,,,,,,,,,,,24,1,4.000000e+000,3.493309e-003,0.000000e+000,0,,0,
1687537121.738,,6.273074e+003,5.000127e+000,1.427649e+000,0.000000e+000,3,9.887047e-001,0.000000e+000,,,,,,,,,,,,,,24,1,4.000000e+000,8.068085e-003,0.000000e+000,0,,0,
1687537197.101,,5.017881e+003,4.999001e+000,1.423900e+000,0.000000e+000,3,9.889758e-001,0.000000e+000,,,,,,,,,,,,,,24,1,4.000000e+000,3.326416e-003,0.000000e+000,0,,0,
1687537227.660,,4.014143e+003,4.999835e+000,1.417458e+000,0.000000e+000,3,9.885686e-001,0.000000e+000,,,,,,,,,,,,,,24,1,4.000000e+000,6.319046e-003,0.000000e+000,0,,0,
1687537254.208,,3.512505e+003,4.999921e+000,1.413035e+000,0.000000e+000,3,9.884858e-001,0.000000e+000,,,,,,,,,,,,,,24,1,4.000000e+000,9.646893e-003,0.000000e+000,0,,0,
1687537280.476,,3.010867e+003,5.000129e+000,1.406790e+000,0.000000e+000,3,9.885002e-001,0.000000e+000,,,,,,,,,,,,,,24,1,4.000000e+000,9.730816e-003,0.000000e+000,0,,0,
1687537308.304,,2.509172e+003,4.999585e+000,1.396526e+000,0.000000e+000,3,9.884348e-001,0.000000e+000,,,,,,,,,,,,,,24,1,4.000000e+000,6.485939e-003,0.000000e+000,0,,0,
1687537335.939,,2.007303e+003,4.998711e+000,1.379218e+000,0.000000e+000,3,9.883067e-001,0.000000e+000,,,,,,,,,,,,,,24,1,4.000000e+000,5.070210e-003,0.000000e+000,0,,0,
1687537362.746,,1.505665e+003,5.001128e+000,1.344238e+000,0.000000e+000,3,9.882604e-001,0.000000e+000,,,,,,,,,,,,,,24,1,4.000000e+000,1.073408e-002,0.000000e+000,0,,0,
1687537389.656,,1.003692e+003,5.000665e+000,1.262542e+000,0.000000e+000,3,9.881043e-001,0.000000e+000,,,,,,,,,,,,,,24,1,4.000000e+000,3.160954e-003,0.000000e+000,0,,0,
1687537416.523,,5.018691e+002,5.004211e+000,1.031612e+000,0.000000e+000,3,9.876140e-001,0.000000e+000,,,,,,,,,,,,,,24,1,4.000000e+000,1.158428e-002,0.000000e+000,0,,0,
1687537440.941,,4.014837e+002,5.002712e+000,9.317626e-001,0.000000e+000,3,9.874037e-001,0.000000e+000,,,,,,,,,,,,,,24,1,4.000000e+000,1.240778e-002,0.000000e+000,0,,0,
1687537465.269,,3.012141e+002,5.001294e+000,7.915460e-001,0.000000e+000,3,9.874372e-001,0.000000e+000,,,,,,,,,,,,,,24,1,4.000000e+000,1.023626e-002,0.000000e+000,0,,0,
1687537490.579,,2.008171e+002,5.000502e+000,5.974519e-001,0.000000e+000,3,9.869382e-001,0.000000e+000,,,,,,,,,,,,,,24,1,4.000000e+000,8.484840e-003,0.000000e+000,0,,0,
1687537534.174,,1.004432e+002,4.995429e+000,3.452106e-001,0.000000e+000,3,9.868331e-001,0.000000e+000,,,,,,,,,,,,,,24,1,4.000000e+000,1.162052e-003,0.000000e+000,0,,0,
1687537599.861,,3.471543e-002,4.993771e+000,4.298312e-002,0.000000e+000,3,9.883619e-001,0.000000e+000,,,,,,,,,,,,,,24,1,4.000000e+000,1.160145e-003,0.000000e+000,0,,0,
1687537633.508,,-5.027948e+001,4.997006e+000,-1.161657e-001,0.000000e+000,3,9.862490e-001,0.000000e+000,,,,,,,,,,,,,,24,1,4.000000e+000,1.162052e-003,0.000000e+000,0,,0,
1687537702.429,,-1.005937e+002,4.995679e+000,-2.665349e-001,0.000000e+000,3,9.859344e-001,0.000000e+000,,,,,,,,,,,,,,24,1,4.000000e+000,3.153801e-003,0.000000e+000,0,,0,
1687537727.281,,-1.507343e+002,5.001173e+000,-4.006825e-001,0.000000e+000,3,9.864810e-001,0.000000e+000,,,,,,,,,,,,,,24,1,4.000000e+000,1.314831e-002,0.000000e+000,0,,0,
1687537753.171,,-2.009328e+002,5.000009e+000,-5.227019e-001,0.000000e+000,3,9.866999e-001,0.000000e+000,,,,,,,,,,,,,,24,1,4.000000e+000,1.347208e-002,0.000000e+000,0,,0,
1687537778.673,,-2.511081e+002,5.001172e+000,-6.306227e-001,0.000000e+000,3,9.869654e-001,0.000000e+000,,,,,,,,,,,,,,24,1,4.000000e+000,1.164913e-002,0.000000e+000,0,,0,
1687537805.410,,-5.021237e+002,4.998672e+000,-9.884382e-001,0.000000e+000,3,9.876863e-001,0.000000e+000,,,,,,,,,,,,,,24,1,4.000000e+000,8.975983e-003,0.000000e+000,0,,0,
1687537829.904,,-7.530003e+002,5.001630e+000,-1.160036e+000,0.000000e+000,3,9.881302e-001,0.000000e+000,,,,,,,,,,,,,,24,1,4.000000e+000,1.240206e-002,0.000000e+000,0,,0,
1687537855.449,,-1.003946e+003,5.000004e+000,-1.252945e+000,0.000000e+000,3,9.884488e-001,0.000000e+000,,,,,,,,,,,,,,24,1,4.000000e+000,1.031303e-002,0.000000e+000,0,,0,
1687537900.539,,-1.254823e+003,4.994972e+000,-1.305001e+000,0.000000e+000,3,9.878318e-001,0.000000e+000,,,,,,,,,,,,,,24,1,4.000000e+000,2.493858e-004,0.000000e+000,0,,0,
1687537926.921,,-1.505955e+003,5.001046e+000,-1.342880e+000,0.000000e+000,3,9.886580e-001,0.000000e+000,,,,,,,,,,,,,,24,1,4.000000e+000,1.156569e-002,0.000000e+000,0,,0,
1687537953.773,,-1.756773e+003,5.000629e+000,-1.364955e+000,0.000000e+000,3,9.886819e-001,0.000000e+000,,,,,,,,,,,,,,24,1,4.000000e+000,1.106405e-002,0.000000e+000,0,,0,
1687537979.197,,-2.007592e+003,5.000094e+000,-1.379399e+000,0.000000e+000,3,9.887035e-001,0.000000e+000,,,,,,,,,,,,,,24,1,4.000000e+000,1.413822e-002,0.000000e+000,0,,0,
1687538006.666,,-2.258585e+003,4.998755e+000,-1.388799e+000,0.000000e+000,3,9.884475e-001,0.000000e+000,,,,,,,,,,,,,,24,1,4.000000e+000,7.813454e-003,0.000000e+000,0,,0,
1687538031.371,,-2.509461e+003,5.000670e+000,-1.396613e+000,0.000000e+000,3,9.886075e-001,0.000000e+000,,,,,,,,,,,,,,24,1,4.000000e+000,1.031590e-002,0.000000e+000,0,,0,
1687538057.408,,-2.760453e+003,4.999296e+000,-1.402146e+000,0.000000e+000,3,9.884925e-001,0.000000e+000,,,,,,,,,,,,,,24,1,4.000000e+000,9.561062e-003,0.000000e+000,0,,0,
1687538082.900,,-3.011272e+003,5.001213e+000,-1.407211e+000,0.000000e+000,3,9.885655e-001,0.000000e+000,,,,,,,,,,,,,,24,1,4.000000e+000,1.156712e-002,0.000000e+000,0,,0,
1687538108.857,,-3.512852e+003,4.999133e+000,-1.413800e+000,0.000000e+000,3,9.886079e-001,0.000000e+000,,,,,,,,,,,,,,24,1,4.000000e+000,1.055717e-002,0.000000e+000,0,,0,
1687538136.833,,-4.014837e+003,4.999877e+000,-1.417609e+000,0.000000e+000,3,9.884985e-001,0.000000e+000,,,,,,,,,,,,,,24,1,4.000000e+000,8.233070e-003,0.000000e+000,0,,0,
1687538163.460,,-4.516475e+003,5.000045e+000,-1.421662e+000,0.000000e+000,3,9.885803e-001,0.000000e+000,,,,,,,,,,,,,,24,1,4.000000e+000,9.563923e-003,0.000000e+000,0,,0,
1687538190.056,,-5.018459e+003,5.000835e+000,-1.423885e+000,0.000000e+000,3,9.885749e-001,0.000000e+000,,,,,,,,,,,,,,24,1,4.000000e+000,9.151936e-003,0.000000e+000,0,,0,
1687538264.982,,-6.275389e+003,4.997131e+000,-1.427959e+000,0.000000e+000,3,9.886657e-001,0.000000e+000,,,,,,,,,,,,,,24,1,4.000000e+000,3.405094e-003,0.000000e+000,0,,0,
1687538293.125,,-7.530930e+003,4.999667e+000,-1.430946e+000,0.000000e+000,3,9.886475e-001,0.000000e+000,,,,,,,,,,,,,,24,1,4.000000e+000,5.820751e-003,0.000000e+000,0,,0,
1687538321.399,,-8.786004e+003,4.998465e+000,-1.432228e+000,0.000000e+000,3,9.885333e-001,0.000000e+000,,,,,,,,,,,,,,24,1,4.000000e+000,8.393288e-003,0.000000e+000,0,,0,
1687538349.877,,-1.004039e+004,4.997755e+000,-1.433434e+000,0.000000e+000,3,9.885493e-001,0.000000e+000,,,,,,,,,,,,,,24,1,4.000000e+000,4.486084e-003,0.000000e+000,0,,0,
1687538381.807,,-8.785079e+003,4.997131e+000,-1.432125e+000,0.000000e+000,3,9.885019e-001,0.000000e+000,,,,,,,,,,,,,,24,1,4.000000e+000,2.408981e-003,0.000000e+000,0,,0,
1687538410.427,,-7.529772e+003,4.996926e+000,-1.430947e+000,0.000000e+000,3,9.886533e-001,0.000000e+000,,,,,,,,,,,,,,24,1,4.000000e+000,6.641865e-003,0.000000e+000,0,,0,
1687538439.490,,-6.274231e+003,4.998879e+000,-1.428108e+000,0.000000e+000,3,9.885761e-001,0.000000e+000,,,,,,,,,,,,,,24,1,4.000000e+000,6.566048e-003,0.000000e+000,0,,0,
1687538512.332,,-5.018228e+003,4.999416e+000,-1.424186e+000,0.000000e+000,3,9.887266e-001,0.000000e+000,,,,,,,,,,,,,,24,1,4.000000e+000,2.827168e-003,0.000000e+000,0,,0,
1687538542.264,,-4.014606e+003,4.996883e+000,-1.417605e+000,0.000000e+000,3,9.884381e-001,0.000000e+000,,,,,,,,,,,,,,24,1,4.000000e+000,5.562782e-003,0.000000e+000,0,,0,
1687538568.635,,-3.512736e+003,5.000884e+000,-1.413776e+000,0.000000e+000,3,9.884482e-001,0.000000e+000,,,,,,,,,,,,,,24,1,4.000000e+000,1.389503e-002,0.000000e+000,0,,0,
1687538595.081,,-3.011099e+003,4.999884e+000,-1.406712e+000,0.000000e+000,3,9.883815e-001,0.000000e+000,,,,,,,,,,,,,,24,1,4.000000e+000,1.322222e-002,0.000000e+000,0,,0,
1687538623.198,,-2.509345e+003,4.999087e+000,-1.396807e+000,0.000000e+000,3,9.883741e-001,0.000000e+000,,,,,,,,,,,,,,24,1,4.000000e+000,7.813931e-003,0.000000e+000,0,,0,
1687538650.359,,-2.007477e+003,4.999506e+000,-1.379748e+000,0.000000e+000,3,9.882083e-001,0.000000e+000,,,,,,,,,,,,,,24,1,4.000000e+000,1.064301e-002,0.000000e+000,0,,0,
1687538676.435,,-1.505723e+003,4.999171e+000,-1.345693e+000,0.000000e+000,3,9.881842e-001,0.000000e+000,,,,,,,,,,,,,,24,1,4.000000e+000,8.479595e-003,0.000000e+000,0,,0,
1687538704.587,,-1.003808e+003,4.999089e+000,-1.264399e+000,0.000000e+000,3,9.879083e-001,0.000000e+000,,,,,,,,,,,,,,24,1,4.000000e+000,9.974957e-003,0.000000e+000,0,,0,
1687538731.944,,-5.020194e+002,4.998841e+000,-1.035707e+000,0.000000e+000,3,9.875228e-001,0.000000e+000,,,,,,,,,,,,,,24,1,4.000000e+000,9.974003e-003,0.000000e+000,0,,0,
1687538757.577,,-4.015762e+002,5.000753e+000,-9.369299e-001,0.000000e+000,3,9.874780e-001,0.000000e+000,,,,,,,,,,,,,,24,1,4.000000e+000,1.048279e-002,0.000000e+000,0,,0,
1687538782.381,,-3.013182e+002,5.000297e+000,-7.974836e-001,0.000000e+000,3,9.872273e-001,0.000000e+000,,,,,,,,,,,,,,24,1,4.000000e+000,1.156187e-002,0.000000e+000,0,,0,
1687538806.760,,-2.008865e+002,5.001721e+000,-6.039183e-001,0.000000e+000,3,9.871541e-001,0.000000e+000,,,,,,,,,,,,,,24,1,4.000000e+000,1.656389e-002,0.000000e+000,0,,0,
1687538849.293,,-1.005242e+002,4.995471e+000,-3.507505e-001,0.000000e+000,3,9.866669e-001,0.000000e+000,,,,,,,,,,,,,,24,1,4.000000e+000,1.743317e-003,0.000000e+000,0,,0,
1687538916.250,,-1.272898e-001,4.999258e+000,-4.714056e-002,0.000000e+000,3,9.884041e-001,0.000000e+000,,,,,,,,,,,,,,24,1,4.000000e+000,1.130581e-002,0.000000e+000,0,,0,
1687538989.996,,5.025634e+001,4.996093e+000,1.155332e-001,0.000000e+000,3,9.858533e-001,0.000000e+000,,,,,,,,,,,,,,24,1,4.000000e+000,3.323555e-004,0.000000e+000,0,,0,
1687539014.458,,1.005590e+002,4.999926e+000,2.636555e-001,0.000000e+000,3,9.860709e-001,0.000000e+000,,,,,,,,,,,,,,24,1,4.000000e+000,1.280689e-002,0.000000e+000,0,,0,
1687539039.162,,1.506996e+002,5.000090e+000,4.000757e-001,0.000000e+000,3,9.862640e-001,0.000000e+000,,,,,,,,,,,,,,24,1,4.000000e+000,1.147699e-002,0.000000e+000,0,,0,
1687539100.587,,2.008865e+002,4.994599e+000,5.237823e-001,0.000000e+000,3,9.864135e-001,0.000000e+000,,,,,,,,,,,,,,24,1,4.000000e+000,0.000000e+000,0.000000e+000,0,,0,
1687539127.201,,2.510850e+002,4.999256e+000,6.315646e-001,0.000000e+000,3,9.868351e-001,0.000000e+000,,,,,,,,,,,,,,24,1,4.000000e+000,9.809971e-003,0.000000e+000,0,,0,
1687539153.796,,5.020773e+002,5.000337e+000,9.917375e-001,0.000000e+000,3,9.876140e-001,0.000000e+000,,,,,,,,,,,,,,24,1,4.000000e+000,9.480953e-003,0.000000e+000,0,,0,
1687539181.273,,7.528846e+002,4.998756e+000,1.162713e+000,0.000000e+000,3,9.880009e-001,0.000000e+000,,,,,,,,,,,,,,24,1,4.000000e+000,9.308815e-003,0.000000e+000,0,,0,
1687539207.695,,1.003854e+003,4.999467e+000,1.254964e+000,0.000000e+000,3,9.883335e-001,0.000000e+000,,,,,,,,,,,,,,24,1,4.000000e+000,1.205587e-002,0.000000e+000,0,,0,
1687539251.673,,1.254777e+003,4.994973e+000,1.306781e+000,0.000000e+000,3,9.878190e-001,0.000000e+000,,,,,,,,,,,,,,24,1,4.000000e+000,1.907825e-003,0.000000e+000,0,,0,
1687539276.980,,1.505896e+003,5.000592e+000,1.344050e+000,0.000000e+000,3,9.886035e-001,0.000000e+000,,,,,,,,,,,,,,24,1,4.000000e+000,1.364183e-002,0.000000e+000,0,,0,
1687539302.863,,1.756657e+003,5.000467e+000,1.365015e+000,0.000000e+000,3,9.885557e-001,0.000000e+000,,,,,,,,,,,,,,24,1,4.000000e+000,1.322603e-002,0.000000e+000,0,,0,
1687539327.019,,2.007534e+003,5.001925e+000,1.380222e+000,0.000000e+000,3,9.887143e-001,0.000000e+000,,,,,,,,,,,,,,24,1,4.000000e+000,1.465225e-002,0.000000e+000,0,,0,
1687539352.829,,2.258527e+003,5.000504e+000,1.388964e+000,0.000000e+000,3,9.884599e-001,0.000000e+000,,,,,,,,,,,,,,24,1,4.000000e+000,1.048088e-002,0.000000e+000,0,,0,
1687539377.393,,2.509403e+003,4.999253e+000,1.397412e+000,0.000000e+000,3,9.884907e-001,0.000000e+000,,,,,,,,,,,,,,24,1,4.000000e+000,7.315159e-003,0.000000e+000,0,,0,
1687539403.159,,2.760338e+003,4.998884e+000,1.401847e+000,0.000000e+000,3,9.884900e-001,0.000000e+000,,,,,,,,,,,,,,24,1,4.000000e+000,1.138735e-002,0.000000e+000,0,,0,
1687539429.918,,3.011156e+003,5.000051e+000,1.407130e+000,0.000000e+000,3,9.887037e-001,0.000000e+000,,,,,,,,,,,,,,24,1,4.000000e+000,1.338863e-002,0.000000e+000,0,,0,
1687539457.403,,3.512852e+003,5.000215e+000,1.412701e+000,0.000000e+000,3,9.884341e-001,0.000000e+000,,,,,,,,,,,,,,24,1,4.000000e+000,1.172686e-002,0.000000e+000,0,,0,
1687539484.695,,4.014721e+003,4.998255e+000,1.417459e+000,0.000000e+000,3,9.884838e-001,0.000000e+000,,,,,,,,,,,,,,24,1,4.000000e+000,7.146358e-003,0.000000e+000,0,,0,
1687539511.378,,4.516475e+003,5.001335e+000,1.421062e+000,0.000000e+000,3,9.885226e-001,0.000000e+000,,,,,,,,,,,,,,24,1,4.000000e+000,1.048517e-002,0.000000e+000,0,,0,
1687539537.714,,5.018459e+003,5.001006e+000,1.424125e+000,0.000000e+000,3,9.886932e-001,0.000000e+000,,,,,,,,,,,,,,24,1,4.000000e+000,1.198101e-002,0.000000e+000,0,,0,
1687539612.470,,6.275041e+003,4.997755e+000,1.427505e+000,0.000000e+000,3,9.886703e-001,0.000000e+000,,,,,,,,,,,,,,24,1,4.000000e+000,4.652023e-003,0.000000e+000,0,,0,
1687539641.644,,7.530930e+003,4.997964e+000,1.430397e+000,0.000000e+000,3,9.886422e-001,0.000000e+000,,,,,,,,,,,,,,24,1,4.000000e+000,6.064892e-003,0.000000e+000,0,,0,
1687539670.131,,8.786004e+003,4.998589e+000,1.432766e+000,0.000000e+000,3,9.887000e-001,0.000000e+000,,,,,,,,,,,,,,24,1,4.000000e+000,7.146835e-003,0.000000e+000,0,,0,
1687539700.553,,1.004016e+004,4.996426e+000,1.433353e+000,0.000000e+000,3,9.885927e-001,0.000000e+000,,,,,,,,,,,,,,24,1,4.000000e+000,4.484177e-003,0.000000e+000,0,,0,